Workbook
Name JR_PAGE_ANCHOR_4_1: CRONOGRAMA!$A$1

Sheet PLANILHA DE ADITIVO
A1: PLANILHA ORÇAMENTARIA DE ADITIVO
A2: CONVÊNIO : SEC. ESTADUAL DE EDUCAÇÃO. 469/2019. | G2: MODALIDADE: | H2: TOMADA DE PREÇOS 003 /2020
A3: Agente Promotor: PREFEITURA MUNICIPAL DE COREMAS. | G3: VALOR DO CONTRATO DA OBRA: R$ 114.076,39
A4: Contratada: FFJ CONSTRUTORA LTDA | G4: VALOR DO ADITIVO DA OBRA: R$ 50.448,14
A5: Localização: GINÁSIO DA ESCOLA FLÓRIDO NITÃO. | G5: VALOR TOTAL COM ADITIVO: R$ 164.524,53
A6: Objetivo: | B6: Reforma da quadra poliesportiva da Escola Municipal Flórido Nitão Diniz | G6: PERCENTUAL DO ADITIVO: 44,22%
A7: ITEM | B7: CODIGO | C7: DISCRIMINAÇÃO DOS SERVIÇOS | D7: UNID. | E7: PREÇO UNITARIO R$ | F7: QUANTIDADE | H7: VALOR CONTRATADO R$ | I7: VALOR ADITIVADO R$ | J7: =114076.4/123492.42 -> 0.92375224
F8: CONTRATADA | G8: ADITIVADA
A10: 1.0 | C10: SERVIÇOS PRELIMINARES | H10: =SUM(H11:H17) -> 2815.04 | I10: =SUM(I11:I17) -> 3769.7544 | J10: =H11+I12+I14+I15+I17+H22+I23+H27+H28+H29+H30++H31+I33+I34+H38 -> 110927.3
A11: 1.1 | C11: PLACA DE OBRA EM CHAPA DE ACO GALVANIZADO | D11: m² | E11: 351.88 | F11: 8 | H11: =E11*F11 -> 2815.04 | I11: =G11*E11 -> 0 | J11: =J10/(H54+I54) -> 0.6742295
A12: 1.2 - Aditivo | B12: 97633 | C12: DEMOLIÇÃO DE CONTRA-PISO, DE FORMA MANUAL, SEM REAPROVEITAMENTO | D12: m² | E12: =15.15*J7 -> 13.994846 | G12: ='MEMORIAL DE CALCULO'!E16 -> 33 | H12: =E12*F12 -> 0 | I12: =G12*E12 -> 461.82993
A13: 1.3 | C13: INFRA-ESTRUTURA E SUPER-ESTRUTURA | H13: =E13*F13 -> 0 | I13: =G13*E13 -> 0
A14: 1.3.1 - Aditivo | B14: 73965/009 | C14: ESCAVACAO MANUAL DE VALA DE 1,5 ATE 3M | D14: m³ | E14: =136.8*J7 -> 126.36931 | G14: ='MEMORIAL DE CALCULO'!E26 -> 1 | H14: =E14*F14 -> 0 | I14: =G14*E14 -> 126.36931
A15: 1.3.2 - Aditivo | B15: 95952 | C15: EXECUÇÃO DE ESTRUTURAS DE CONCRETO ARMADO | D15: m³ | E15: =1348.69*J7 -> 1245.8554 | G15: ='MEMORIAL DE CALCULO'!E50 -> 1.729 | H15: =E15*F15 -> 0 | I15: =G15*E15 -> 2154.084
A16: 1.4 | C16: ALVENARIA | H16: =E16*F16 -> 0 | I16: =G16*E16 -> 0
A17: 1.4.1 - Aditivo | B17: 87496 | C17: ALVENARIA DE VEDAÇÃO DE BLOCOS CERÂMICOS FURADOS NA HORIZONTAL DE 9X19X19CM (ESPESSURA 9CM) | D17: m² | E17: =57.04*J7 -> 52.690828 | G17: ='MEMORIAL DE CALCULO'!E59 -> 19.5 | H17: =E17*F17 -> 0 | I17: =G17*E17 -> 1027.4711
A18: 2.0 | C18: SISTEMAS DE COBERTURA | H18: =H19 -> 10837.632 | I18: =I19 -> 2155.1853 | J18: =275-202.8 -> 72.2
A19: 2.1 | C19: TELHA DE ALUMÍNIO ONDULADA, ESP.=0,5MM | D19: m² | E19: 53.44 | F19: 202.8 | G19: 40.329067 | H19: =E19*F19 -> 10837.632 | I19: =G19*E19 -> 2155.1853
H20: =E20*F20 -> 0
A21: 3.0 | C21: SISTEMA DE PISOS | H21: =SUM(H22:H23) -> 31838.334 | I21: =SUM(I22:I23) -> 13390.934
A22: 3.1 | C22: PISO INDUSTRIAL EM CONCRETO POLIDO PARA QUADRA POLIESPORTIVA, COM JUNTAS DE DILATAÇÃO PLÁSTICAS E POLIMENTO MECANIZADO, ESPESSURA 1CM. | D22: m² | E22: 64.67 | F22: 492.32 | H22: =E22*F22 -> 31838.334 | I22: =G22*E22 -> 0
A23: 3.2 - Aditivo | B23: 96623 | C23: LASTRO EM CONCRETO COM MATERIAL GRANULAR, APLICADO EM BLOCOS DE COROAMENTO, ESPESSURA 10CM(ARQUIBANCADAS) | D23: m² | E23: =142.12*J7 -> 131.28367 | G23: ='MEMORIAL DE CALCULO'!E77 -> 102 | I23: =G23*E23 -> 13390.934
H25: =E25*F25 -> 0
A26: 4.0 | C26: PINTURAS E ACABAMENTOS | H26: =SUM(H27:H34) -> 39990.747 | I26: =SUM(I27:I34) -> 17316
A27: 4.1 | C27: MASSA ÚNICA, PARA RECEBIMENTO DE PINTURA, EM ARGAMASSA TRAÇO 1:2:8, PREPARO MECÂNICO COM BETONEIRA 400L, APLICADA MANUALMENTE EM FACES INTERNAS DE PAREDES, ESPESSURA DE 10MM, COM EXECUÇÃO DE TALISCAS. AF_06/2014 | D27: m² | E27: 13.38 | F27: 596.21 | H27: =E27*F27 -> 7977.2898
A28: 4.2 | C28: APLICAÇÃO DE FUNDO SELADOR ACRÍLICO EM PAREDES, UMA DEMÃO. AF_06/2014 | D28: m² | E28: 1.66 | F28: 596.21 | H28: =E28*F28 -> 989.7086
A29: 4.3 | C29: APLICAÇÃO E LIXAMENTO DE MASSA LÁTEX EM PAREDES, DUAS DEMÃOS. AF_06/2014 | D29: m² | E29: 9.26 | F29: 596.21 | H29: =E29*F29 -> 5520.9046
A30: 4.4 | C30: APLICAÇÃO MANUAL DE PINTURA COM TINTA LÁTEX ACRÍLICA EM PAREDES, DUAS DEMÃOS. AF_06/2014 | D30: m² | E30: 10.96 | F30: 596.21 | H30: =E30*F30 -> 6534.4616
A31: 4.5 | C31: APLICACAO DE TINTA A BASE DE EPOXI SOBRE PISO | D31: m² | E31: 37.43 | F31: 492.32 | H31: =E31*F31 -> 18427.538
A32: 4.6 | C32: PINTURA ACRILICA DE FAIXAS DE DEMARCACAO EM QUADRA POLIESPORTIVA, 5 CM DE LARGURA | D32: m² | E32: 8.38 | F32: 64.54 | H32: =E32*F32 -> 540.8452
A33: 4.7 - Aditivo | B33: 100721 | C33: PINTURA COM TINTA ALQUÍDICA DE FUNDO (TIPO ZARCÃO) PULVERIZADA SOBRE SUPERFÍCIES METÁLICAS (EXCETO PERFIL) EXECUTADO EM OBRA | D33: m² | E33: =DESAGIO!F15 -> 15.41 | G33: ='MEMORIAL DE CALCULO'!E86 -> 600 | I33: =E33*G33 -> 9246
A34: 4.8 - Aditivo | B34: 100730 | C34: PINTURA COM TINTA EPOXÍDICA DE ACABAMENTO APLICADA A ROLO OU PINCEL SOBRE PERFIL METÁLICO EXECUTADO EM FÁBRICA (POR DEMÃO). AF_01/2020 | D34: m² | E34: =DESAGIO!F32 -> 13.45 | G34: ='MEMORIAL DE CALCULO'!E93 -> 600 | I34: =E34*G34 -> 8070
A36: 5.0 | C36: SERVIÇOS COMPLEMENTARES | H36: =SUM(H37:H45) -> 9180.96 | I36: =SUM(I37:I46) -> 5686.8405
A37: 5.1 | C37: ESTRUTURA/SUPORTE OFICIAL P/TABELA DE BASQUETE EM TUBO AÇO GALVANIZADO D=5", H=3,05M PISO/ARO, PINTURA SINTÉTICA, FORNECIMENTO E INSTALAÇÃO | D37: par | E37: 3135.71 | F37: 1 | H37: =E37*F37 -> 3135.71
A38: 5.2 | C38: CONJUNTO PARA FUTSAL COM TRAVES OFICIAIS DE 3,00 X 2,00 M EM TUBO DE ACO GALVANIZADO 3" COM REQUADRO EM TUBO DE 1", PINTURA EM PRIMER COM TINTA ESMALTE SINTETICO E REDES DE POLIETILENO FIO 4 MM | D38: und | E38: 2347.33 | F38: 1 | H38: =E38*F38 -> 2347.33
A39: 5.3 | C39: CONJUNTO PARA QUADRA DE VOLEI COM POSTES EM TUBO DE ACO GALVANIZADO 3", H = *255* CM, PINTURA EM TINTA ESMALTE SINTETICO, REDE DE NYLON COM 2 MM, MALHA 10 X 10 CM E ANTENAS OFICIAIS EM FIBRA DE VIDRO | D39: und | E39: 1425.03 | F39: 1 | H39: =E39*F39 -> 1425.03
A40: 5.4 | C40: FORNECIMENTO E INSTALAÇÃO DE REDE DE PROTEÇÃO EM NYLON MALHA 10 X 10 CM PARA QUADRA DE ESPORTE | D40: m² | E40: 11.95 | F40: 190.2 | H40: =E40*F40 -> 2272.89
A41: 5.5 | C41: INSTALAÇÕES ELETRICA
A42: 5.5.1 - Aditivo | B42: 74131/004 | C42: QUADRO DE DISTRIBUICAO DE ENERGIA DE EMBUTIR, EM CHAPA METALICA | D42: unid | E42: =416.85*J7 -> 385.06612 | G42: ='MEMORIAL DE CALCULO'!E99 -> 1 | I42: =E42*G42 -> 385.06612
A43: 5.5.2 - Aditivo | B43: 74130/005 | C43: DISJUNTOR TERMOMAGNETICO TRIPOLAR PADRAO NEMA (AMERICANO) 60 A 100A | D43: unid | E43: =99.39*J7 -> 91.811735 | G43: ='MEMORIAL DE CALCULO'!E103 -> 2 | I43: =E43*G43 -> 183.62347
...

Sheet MEMORIAL DE CALCULO
A1: MEMORIAL DE CALCULO
A2: CONVÊNIO : SEC. ESTADUAL DE EDUCAÇÃO. 469/2019. | G2: MODALIDADE: | H2: TOMADA DE PREÇOS 003 /2020
A3: Agente Promotor: PREFEITURA MUNICIPAL DE COREMAS.
A4: Contratada: FFJ CONSTRUTORA LTDA | G4: BDI = 19,21%
A5: Localização: GINÁSIO DA ESCOLA FLÓRIDO NITÃO.
A6: Objetivo: | B6: Reforma da quadra poliesportiva da Escola Municipal Flórido Nitão Diniz
A8: ='PLANILHA DE ADITIVO'!A10 -> 1.0 | B8: ='PLANILHA DE ADITIVO'!C10 -> SERVIÇOS PRELIMINARES
A10: ='PLANILHA DE ADITIVO'!A12 -> 1.2 - Aditivo | B10: ='PLANILHA DE ADITIVO'!C12 -> DEMOLIÇÃO DE CONTRA-PISO, DE FORMA MANUAL, SEM REAPROVEITAMENTO
B12: C (m) | C12: x | D12: L (m) | E12: = | F12: A (M²)
B13: 30 | C13: x | D13: 0.55 | E13: = | F13: =B13*D13 -> 16.5 | G13: m²
B14: 30 | C14: x | D14: 0.55 | E14: = | F14: =B14*D14 -> 16.5 | G14: m²
D16: A = | E16: =SUM(F13:F14) -> 33 | F16: m²
A18: ='PLANILHA DE ADITIVO'!A13 -> 1.3 | B18: ='PLANILHA DE ADITIVO'!C13 -> INFRA-ESTRUTURA E SUPER-ESTRUTURA
A20: ='PLANILHA DE ADITIVO'!A14 -> 1.3.1 - Aditivo | B20: ='PLANILHA DE ADITIVO'!C14 -> ESCAVACAO MANUAL DE VALA DE 1,5 ATE 3M
B22: C (m) | C22: x | D22: L (m) | E22: x | F22: H (m) | G22: = | H22: V (M³)
B23: 1 | C23: x | D23: 1 | E23: x | F23: 0.5 | G23: = | H23: =D23*F23*B23 -> 0.5 | I23: m³ - S1
B24: 1 | C24: x | D24: 1 | E24: x | F24: 0.5 | G24: = | H24: =D24*F24*B24 -> 0.5 | I24: m³ - S2
D26: V = | E26: =SUM(H23:H24) -> 1 | F26: m³
A28: ='PLANILHA DE ADITIVO'!A15 -> 1.3.2 - Aditivo | B28: ='PLANILHA DE ADITIVO'!C15 -> EXECUÇÃO DE ESTRUTURAS DE CONCRETO ARMADO
B30: C (m) | C30: x | D30: L (m) | E30: x | F30: H (m) | G30: = | H30: V (M³)
B31: 1 | C31: x | D31: 1 | E31: x | F31: 0.5 | G31: = | H31: =D31*F31*B31 -> 0.5 | I31: m³ - S1
B32: 1 | C32: x | D32: 1 | E32: x | F32: 0.5 | G32: = | H32: =D32*F32*B32 -> 0.5 | I32: m³ - S2
B33: 0.15 | C33: x | D33: 0.15 | E33: x | F33: 6.3 | G33: = | H33: =D33*F33*B33 -> 0.14175 | I33: m³ - P1
B34: 0.15 | C34: x | D34: 0.15 | E34: x | F34: 6.3 | G34: = | H34: =D34*F34*B34 -> 0.14175 | I34: m³ - P2
B35: 0.15 | C35: x | D35: 0.15 | E35: x | F35: 1.2 | G35: = | H35: =D35*F35*B35 -> 0.027 | I35: m³ - P3
B36: 0.15 | C36: x | D36: 0.15 | E36: x | F36: 1.2 | G36: = | H36: =D36*F36*B36 -> 0.027 | I36: m³ - P4
B37: 0.15 | C37: x | D37: 0.15 | E37: x | F37: 1.2 | G37: = | H37: =D37*F37*B37 -> 0.027 | I37: m³ - P5
B38: 0.15 | C38: x | D38: 0.15 | E38: x | F38: 1.2 | G38: = | H38: =D38*F38*B38 -> 0.027 | I38: m³ - P6
B39: 0.15 | C39: x | D39: 0.15 | E39: x | F39: 1.2 | G39: = | H39: =D39*F39*B39 -> 0.027 | I39: m³ - P7
B40: 0.15 | C40: x | D40: 0.15 | E40: x | F40: 1.2 | G40: = | H40: =D40*F40*B40 -> 0.027 | I40: m³ - P8
B41: 0.15 | C41: x | D41: 0.15 | E41: x | F41: 1.2 | G41: = | H41: =D41*F41*B41 -> 0.027 | I41: m³ - P9
B42: 0.15 | C42: x | D42: 0.15 | E42: x | F42: 1.2 | G42: = | H42: =D42*F42*B42 -> 0.027 | I42: m³ - P10
... B48: 1.35 | C48: x | D48: 0.15 | E48: x | F48: 0.3 | G48: = | H48: =D48*F48*B48 -> 0.06075 | I48: m³ - B2
D50: V = | E50: =SUM(H31:H48) -> 1.729 | F50: m³
A52: ='PLANILHA DE ADITIVO'!A16 -> 1.4 | B52: ='PLANILHA DE ADITIVO'!C16 -> ALVENARIA
A54: ='PLANILHA DE ADITIVO'!A17 -> 1.4.1 - Aditivo | B54: ='PLANILHA DE ADITIVO'!C17 -> ALVENARIA DE VEDAÇÃO DE BLOCOS CERÂMICOS FURADOS NA HORIZONTAL DE 9X19X19CM (ESPESSURA 9CM)
B56: C (m) | C56: x | D56: L (m) | E56: = | F56: A (M²)
B57: 30 | C57: x | D57: 0.65 | E57: = | F57: =B57*D57 -> 19.5 | G57: m²
D59: A = | E59: =SUM(F57:F57) -> 19.5 | F59: m²
A61: 2.0 | B61: ='PLANILHA DE ADITIVO'!C18 -> SISTEMAS DE COBERTURA
...

Sheet CRONOGRAMA
A2: ITEM | B2: DESCRIÇÃO | C2: VALOR (R$) | D2: MÊS 1 | E2: MÊS 2
A3: 1 | B3: SERVIÇOS PRELIMINARES | C3: 6584.7944 | D3: 100
D4: =C3 -> 6584.7944
A5: 2 | B5: SISTEMAS DE COBERTURA | C5: 12992.817 | D5: 100
D6: =C5 -> 12992.817
A7: 3 | B7: SISTEMA DE PISOS | C7: 45229.269 | D7: 40 | E7: 60
D8: =C7*0.4 -> 18091.707 | E8: =C7*0.6 -> 27137.561
A9: 4 | B9: PINTURAS E ACABAMENTOS | C9: 57306.75 | D9: 40 | E9: 60
D10: =C9*0.4 -> 22922.7 | E10: =C9*0.6 -> 34384.05
A11: 5 | B11: SERVIÇOS COMPLEMENTARES | C11: 14867.801 | E11: 100
E12: =C11 -> 14867.801
A13: 6 | B13: SERVIÇOS FINAIS | C13: 1030.94 | E13: 100
E14: =C13 -> 1030.94
A15: TOTAL (R$) | C15: =SUM(C3:C14) -> 138012.37 | D15: =D4+D6+D8+D10 -> 60592.019 | E15: =E8+E10+E12+E14 -> 77420.352
A16: TOTAL ACUMULADO (R$) | D16: =D15 -> 60592.019 | E16: =D16+E15 -> 138012.37
A17: PERCENTUAL SIMPLES | D17: =D15/E16*100 -> 43.903325 | E17: =E15/E16*100 -> 56.096675
A18: PERCENTUAL ACUMULADO | D18: =D17 -> 43.903325 | E18: =D18+E17 -> 100

Sheet DESAGIO
A2: Cálculo do Desconto da Licitação: | M2: =1-(B5/B4) -> 0.076247757
B3: Valor R$ | C3: Desconto % | L3: 276.97 | M3: =(L3*(1-M2)) -> 255.85166
A4: Projeto: | B4: 123492.42 | C4: =ROUND(1-(B5/B4),3) -> 0.076
A5: Licitado: | B5: 114076.4
A7: Cálculo do fator de reatroação
A9: INCC 10/2019 | B9: 774.939 | C9: =ROUND((B10-B9)/B10,3) -> 0.031
A10: INCC 07/2020 | B10: 799.589
A11: http://indiceseconomicos.secovi.com.br/indicadormensal.php?idindicador=59
A13: SERVIÇO | D13: Valor | F13: Preço com desconto
D14: 44013 | E14: 43739
A15: 4.7 PINTURA COM TINTA ALQUÍDICA DE FUNDO (TIPO ZARCÃO) PULVERIZADA SOBRE SUPERFÍCIES METÁLICAS (EXCETO PERFIL) EXECUTADO EM OBRA | D15: 17.21 | E15: =ROUND(D15*(1-C9),2) -> 16.68 | F15: =ROUND(E15*(1-C4),2) -> 15.41
A19: Cálculo do Desconto da Licitação:
B20: Valor R$ | C20: Desconto %
A21: Projeto: | B21: 123492.42 | C21: =ROUND(1-(B22/B21),3) -> 0.076
A22: Licitado: | B22: 114076.4
A24: Cálculo do fator de reatroação
A26: INCC 10/2019 | B26: 774.939 | C26: =ROUND((B27-B26)/B27,3) -> 0.031
A27: INCC 07/2020 | B27: 799.589
A28: http://indiceseconomicos.secovi.com.br/indicadormensal.php?idindicador=59
A30: SERVIÇO | D30: Valor | F30: Preço com desconto
D31: 44013 | E31: 43739
A32: 4.8 PINTURA COM TINTA EPOXÍDICA DE ACABAMENTO APLICADA A ROLO OU PINCEL SOBRE PERFIL METÁLICO EXECUTADO EM FÁBRICA (POR DEMÃO). AF_01/2020 | D32: 15.03 | E32: =ROUND(D32*(1-C26),2) -> 14.56 | F32: =ROUND(E32*(1-C21),2) -> 13.45
