Workbook
Name JR_PAGE_ANCHOR_0_1: 'PLANILHA ORCAMENTARIA'!$A$1
Name JR_PAGE_ANCHOR_1_1: #REF!
Name JR_PAGE_ANCHOR_2_1: COMPOSICOES!$A$1
Name JR_PAGE_ANCHOR_3_1: CRONOGRAMA!$A$1
Name JR_PAGE_ANCHOR_4_1: BDI!$A$1
Name JR_PAGE_ANCHOR_5_1: 'ENCARGOS SOCIAIS'!$A$1

Sheet Planilha Supressão
A1: FONTE DE RECURSO: Convenio com o Estado da Paraíba n° 0478/2021 (Ordinários: 1571 - Transferências do Estado referentes a Convénios e Instrumentos Congéneres vinculados à Educação).
A2: OBRA: Construção de 01 (uma) creche com capacidade para 50 (cinquenta) crianças.
A3: ENDEREÇO: Sede no Município de Coremas
A4: B.D.I: 22,47%
A5: MODALIDADE: Tomada de Preços 40001/2023
A6: CONTRATO Nº: 149/2023
A7: VALOR DO CONTRATO: R$ 912.926,02
A8: PERÍODO DE VIGÊNCIA: 13/07/2023 à 13/07/2024
A9: ITEM | B9: DESCRIÇÃO DOS SERVIÇOS | C9: UNID. | D9: QUANTIDADE | H9: VALORES (R$)
D10: LICITADA | E10: ACRESCIDA | F10: SUPRIMIDA | G10: REPROGRAMAÇÃO | H10: UNIT. | I10: LICITADO | J10: ACRESCIDO/ SUPRIMIDO | K10: TOTAL REPROGRAMADO | T10: =T11/I11 -> 0.013087141 | U10: =U11/I11 -> 0.012911079 | V10: =U10-T10 -> -0.00017606213
A11: REFORMA DA ESCOLA MUNICIPAL FLÓRIDO NITÃO DINIZ | I11: =SUM(I12+I17+I22+I32+I39+I47+I57+I61+I69+I270+I71+I75+I79+I81+I88+I92+I95+I104+I115+I119+I126+I175+I215+I239+I246+I255+I264+0.03) -> 912926.02 | J11: =K11-I11 -> -160.7317 | K11: =K12+K17+K22+K32+K39+K47+K57+K61+K69+K270+K71+K75+K79+K81+K88+K92+K95+K104+K115+K119+K126+K175+K215+K239+K246+K255+K264+0.03 -> 912765.28 | O11: =J11/K11 -> -0.00017609313 | T11: =SUM(T13:T274) -> 11947.592 | U11: =SUM(U13:U274) -> 11786.86 | V11: =U11-T11 -> -160.7317
A12: 1 | B12: SERVIÇOS PRELIMINARES | I12: =SUM(I13:I16) -> 18051.88 | J12: =SUM(J13:J16) -> -160.7317 | K12: =SUM(K13:K16) -> 17891.148 | N12: Desconto | O12: Proposta | P12: Projeto | T12: Suprimido | U12: Acrescido
A13: 1.1 | B13: PLACA INDICATIVA DA OBRA EM CHAPA DE AÇO GALVANIZADO (4,0M X 2,0M) | C13: M2 | D13: 1 | G13: =D13+E13-F13 -> 1 | H13: 187.44 | I13: =D13*H13 -> 187.44 | J13: =K13-I13 -> 0 | K13: =G13*H13 -> 187.44 | N13: =(O13)/P13 -> 0.056261931 | O13: =I13 -> 187.44 | P13: =Comparativo!K7 -> 3331.56 | R13: =N13-1 -> -0.94373807 | T13: =F13*H13 -> 0 | U13: =E13*H13 -> 0
A14: 1.2 | B14: EXECUÇÃO DE DEPÓSITO EM CANTEIRO DE OBRA EM CHAPA DE MADEIRA COMPENSADA, NÃO INCLUSO MOBILIÁRIO. AF_04/2016 | C14: M | D14: 12.43 | F14: 12.43 | G14: =D14+E14-F14 -> 0 | H14: 961.19 | I14: =D14*H14 -> 11947.592 | J14: =K14-I14 -> -11947.592 | K14: =G14*H14 -> 0 | N14: =(O14)/P14 -> 166.51696 | O14: =I14 -> 11947.592 | P14: =Comparativo!K8 -> 71.75 | R14: =N14-1 -> 165.51696 | T14: =F14*H14 -> 11947.592 | U14: =E14*H14 -> 0
A15: 1.2 | B15: BARRACÃO DA OBRA EM ALVENARIA | C15: M3 | E15: 27.3644 | G15: =D15+E15-F15 -> 27.3644 | H15: 430.73702 | I15: =D15*H15 -> 0 | J15: =K15-I15 -> 11786.86 | K15: =G15*H15 -> 11786.86 | N15: =(O15)/P15 -> 0 | O15: =I15 -> 0 | P15: =Comparativo!K9 -> 1798.608 | R15: =N15-1 -> -1 | T15: =F15*H15 -> 0 | U15: =E15*H15 -> 11786.86
A16: 1.4 | B16: LOCACAO CONVENCIONAL DE OBRA, UTILIZANDO GABARITO DE TÁBUAS CORRIDAS PONTALETADAS A CADA 2,00M - 2 UTILIZAÇÕES. AF_10/2018 | C16: M3 | D16: 101.16 | G16: =D16+E16-F16 -> 101.16 | H16: 58.49 | I16: =D16*H16 -> 5916.8484 | J16: =K16-I16 -> 0 | K16: =G16*H16 -> 5916.8484 | N16: =(O16)/P16 -> 2.8644023 | O16: =I16 -> 5916.8484 | P16: =Comparativo!K10 -> 2065.6485 | R16: =N16-1 -> 1.8644023 | T16: =F16*H16 -> 0 | U16: =E16*H16 -> 0
A17: 2 | B17: MOVIMENTO DE TERRA | I17: =SUM(I18:I21) -> 12961.552 | J17: =SUM(J18:J21) -> 0 | K17: =SUM(K18:K21) -> 12961.552
A18: 2.1 | B18: REATERRO MANUAL DE VALAS COM COMPACTAÇÃO MECANIZADA. AF_04/2016 | C18: M2 | D18: 136.71 | G18: =D18+E18-F18 -> 136.71 | H18: 27.19 | I18: =D18*H18 -> 3717.1449 | J18: =K18-I18 -> 0 | K18: =G18*H18 -> 3717.1449 | N18: =(O18)/P18 -> 34.851719 | O18: =I18 -> 3717.1449 | P18: =Comparativo!K13 -> 106.656 | R18: =N18-1 -> 33.851719 | T18: =F18*H18 -> 0 | U18: =E18*H18 -> 0
A19: 2.2 | B19: ESCAVAÇÃO MANUAL DE VALA COM PROFUNDIDADE MENOR OU IGUAL A 1,30 M. AF_02/2021 | D19: 72.61 | G19: =D19+E19-F19 -> 72.61 | H19: 72.97 | I19: =D19*H19 -> 5298.3517 | J19: =K19-I19 -> 0 | K19: =G19*H19 -> 5298.3517 | O19: =I19 -> 5298.3517 | T19: =F19*H19 -> 0 | U19: =E19*H19 -> 0
A20: 2.3 | B20: REATERRO MANUAL DE VALAS COM COMPACTAÇÃO MECANIZADA. AF_04/2016 | D20: 54.55 | G20: =D20+E20-F20 -> 54.55 | H20: 27.19 | I20: =D20*H20 -> 1483.2145 | J20: =K20-I20 -> 0 | K20: =G20*H20 -> 1483.2145
A21: 2.4 | B21: REATERRO MANUAL APILOADO COM SOQUETE. AF_10/2017 | C21: M | D21: 55.67 | G21: =D21+E21-F21 -> 55.67 | H21: 44.24 | I21: =D21*H21 -> 2462.8408 | J21: =K21-I21 -> 0 | K21: =G21*H21 -> 2462.8408 | N21: =(O21)/P21 -> 8.0250536 | O21: =I21 -> 2462.8408 | P21: =Comparativo!K15 -> 306.894 | R21: =N21-1 -> 7.0250536 | T21: =F21*H21 -> 0 | U21: =E21*H21 -> 0
A22: 3 | B22: SAPATAS | I22: =SUM(I23:I31) -> 37991.854 | J22: =SUM(J23:J29) -> 0 | K22: =SUM(K23:K31) -> 37991.854
A23: 3.1 | B23: LASTRO DE CONCRETO MAGRO, APLICADO EM BLOCOS DE COROAMENTO OU SAPATAS. AF_08/2017 | C23: M2 | D23: 1.46 | G23: =D23+E23-F23 -> 1.46 | H23: 675.67 | I23: =D23*H23 -> 986.4782 | J23: =K23-I23 -> 0 | K23: =G23*H23 -> 986.4782 | N23: =(O23)/P23 -> 0.16187291 | O23: =I23 -> 986.4782 | P23: =Comparativo!K17 -> 6094.1526 | R23: =N23-1 -> -0.83812709 | T23: =F23*H23 -> 0 | U23: =E23*H23 -> 0
A24: 3.2 | B24: FABRICAÇÃO, MONTAGEM E DESMONTAGEM DE FÔRMA PARA SAPATA, EM CHAPA DE MADEIRA COMPENSADA RESINADA, E=17 MM, 4 UTILIZAÇÕES. AF_06/2017 | C24: M2 | D24: 96.48 | G24: =D24+E24-F24 -> 96.48 | H24: 196.54 | I24: =D24*H24 -> 18962.179 | J24: =K24-I24 -> 0 | K24: =G24*H24 -> 18962.179 | N24: =(O24)/P24 -> 15.869313 | O24: =I24 -> 18962.179 | P24: =Comparativo!K18 -> 1194.896 | R24: =N24-1 -> 14.869313 | T24: =F24*H24 -> 0 | U24: =E24*H24 -> 0
A25: 3.3 | B25: CONCRETO FCK = 25MPA, TRAÇO 1:2,3:2,7 (EM MASSA SECA DE CIMENTO/ AREIA MÉDIA/ BRITA 1) - PREPARO MECÂNICO COM BETONEIRA 600 L. AF_05/2021 | C25: M2 | D25: 10.06 | G25: =D25+E25-F25 -> 10.06 | H25: 553.34 | I25: =D25*H25 -> 5566.6004 | J25: =K25-I25 -> 0 | K25: =G25*H25 -> 5566.6004 | N25: =(O25)/P25 -> 1.3246383 | O25: =I25 -> 5566.6004 | P25: =Comparativo!K19 -> 4202.355 | R25: =N25-1 -> 0.3246383 | T25: =F25*H25 -> 0 | U25: =E25*H25 -> 0
A26: 3.4 | B26: LANÇAMENTO COM USO DE BALDES, ADENSAMENTO E ACABAMENTO DE CONCRETO EM ESTRUTURAS. AF_02/2022 | C26: M2 | D26: 10.06 | G26: =D26+E26-F26 -> 10.06 | H26: 252.24 | I26: =D26*H26 -> 2537.5344 | J26: =K26-I26 -> 0 | K26: =G26*H26 -> 2537.5344 | N26: =(O26)/P26 -> 18.257955 | O26: =I26 -> 2537.5344 | P26: =Comparativo!K20 -> 138.9824 | R26: =N26-1 -> 17.257955 | T26: =F26*H26 -> 0 | U26: =E26*H26 -> 0
A27: 3.5 | B27: ARMAÇÃO DE BLOCO, VIGA BALDRAME OU SAPATA UTILIZANDO AÇO CA-50 DE 6,3 MM - MONTAGEM. AF_06/2017 | D27: 241 | G27: =D27+E27-F27 -> 241 | H27: 18.82 | I27: =D27*H27 -> 4535.62 | J27: =K27-I27 -> 0 | K27: =G27*H27 -> 4535.62 | O27: =I27 -> 4535.62
A28: 3.6 | B28: ARMAÇÃO DE BLOCO, VIGA BALDRAME OU SAPATA UTILIZANDO AÇO CA-50 DE 10 MM - MONTAGEM. AF_06/2017 | C28: M2 | D28: 235.2 | G28: =D28+E28-F28 -> 235.2 | H28: 16.04 | I28: =D28*H28 -> 3772.608 | J28: =K28-I28 -> 0 | K28: =G28*H28 -> 3772.608 | N28: =(O28)/P28 -> 24.564704 | O28: =I28 -> 3772.608 | P28: =Comparativo!K21 -> 153.5784 | R28: =N28-1 -> 23.564704 | T28: =F28*H28 -> 0 | U28: =E28*H28 -> 0
A29: 3.7 | B29: ARMAÇÃO DE BLOCO, VIGA BALDRAME OU SAPATA UTILIZANDO AÇO CA-50 DE 12,5 MM - MONTAGEM. AF_06/2017 | C29: M2 | D29: 18.1 | G29: =D29+E29-F29 -> 18.1 | H29: 13.64 | I29: =D29*H29 -> 246.884 | J29: =K29-I29 -> 0 | K29: =G29*H29 -> 246.884 | N29: =N28 -> 24.564704 | O29: =N29*P29 -> 3208.1504 | P29: 130.6 | R29: =N29-1 -> 23.564704 | T29: =F29*H29 -> 0 | U29: =E29*H29 -> 0
A30: 3.8 | B30: ARMAÇÃO DE BLOCO, VIGA BALDRAME OU SAPATA UTILIZANDO AÇO CA-50 DE 16 MM - MONTAGEM. AF_06/2017 | D30: 7.6 | G30: =D30+E30-F30 -> 7.6 | H30: 13.01 | I30: =D30*H30 -> 98.876 | J30: =K30-I30 -> 0 | K30: =G30*H30 -> 98.876
A31: 3.9 | B31: ARMAÇÃO DE BLOCO, VIGA BALDRAME E SAPATA UTILIZANDO AÇO CA-60 DE 5 MM - MONTAGEM. AF_06/2017 | D31: 65.1 | G31: =D31+E31-F31 -> 65.1 | H31: 19.74 | I31: =D31*H31 -> 1285.074 | J31: =K31-I31 -> 0 | K31: =G31*H31 -> 1285.074
A32: 4 | B32: VIGA BALDRAME | I32: =SUM(I33:I38) -> 42240.625 | J32: =SUM(J33:J38) -> 0 | K32: =SUM(K33:K38) -> 42240.625
A33: 4.1 | B33: LASTRO DE CONCRETO MAGRO, APLICADO EM PISOS, LAJES SOBRE SOLO OU RADIERS, ESPESSURA DE 3 CM. AF_07/2016 | C33: UN | D33: 2.2 | G33: =D33+E33-F33 -> 2.2 | H33: 19.6 | I33: =D33*H33 -> 43.12 | J33: =K33-I33 -> 0 | K33: =G33*H33 -> 43.12 | N33: =(O33)/P33 -> 0.014107547 | O33: =I33 -> 43.12 | P33: =Comparativo!K23 -> 3056.52 | R33: =N33-1 -> -0.98589245 | T33: =F33*H33 -> 0 | U33: =E33*H33 -> 0
A34: 4.2 | B34: FABRICAÇÃO, MONTAGEM E DESMONTAGEM DE FÔRMA PARA VIGA BALDRAME, EM CHAPA DE MADEIRA COMPENSADA RESINADA, E=17 MM, 4 UTILIZAÇÕES. AF_06/2017 | C34: UN | D34: 220.31 | G34: =D34+E34-F34 -> 220.31 | H34: 90.92 | I34: =D34*H34 -> 20030.585 | J34: =K34-I34 -> 0 | K34: =G34*H34 -> 20030.585 | N34: =N33 -> 0.014107547 | O34: =N34*P34 -> 0 | T34: =F34*H34 -> 0 | U34: =E34*H34 -> 0
A35: 4.3 | B35: CONCRETO FCK = 25MPA, TRAÇO 1:2,3:2,7 (EM MASSA SECA DE CIMENTO/ AREIA MÉDIA/ BRITA 1) - PREPARO MECÂNICO COM BETONEIRA 600 L. AF_05/2021 | C35: UN | D35: 13.22 | G35: =D35+E35-F35 -> 13.22 | H35: 553.34 | I35: =D35*H35 -> 7315.1548 | J35: =K35-I35 -> 0 | K35: =G35*H35 -> 7315.1548 | N35: =N33 -> 0.014107547 | O35: =N35*P35 -> 10.878612 | P35: 771.12 | R35: =N35-1 -> -0.98589245 | T35: =F35*H35 -> 0 | U35: =E35*H35 -> 0
A36: 4.4 | B36: LANÇAMENTO COM USO DE BALDES, ADENSAMENTO E ACABAMENTO DE CONCRETO EM ESTRUTURAS. AF_02/2022 | C36: M2 | D36: 13.22 | G36: =D36+E36-F36 -> 13.22 | H36: 252.24 | I36: =D36*H36 -> 3334.6128 | J36: =K36-I36 -> 0 | K36: =G36*H36 -> 3334.6128 | N36: =N38 -> 0.014107547 | O36: =N36*P36 -> 1.3900166 | P36: 98.53 | R36: =N36-1 -> -0.98589245 | T36: =F36*H36 -> 0 | U36: =E36*H36 -> 0
A37: 4.5 | B37: ARMAÇÃO DE BLOCO, VIGA BALDRAME OU SAPATA UTILIZANDO AÇO CA-50 DE 6,3 MM - MONTAGEM. AF_06/2017 | D37: 389.6 | G37: =D37+E37-F37 -> 389.6 | H37: 18.82 | I37: =D37*H37 -> 7332.272 | J37: =K37-I37 -> 0 | K37: =G37*H37 -> 7332.272
A38: 4.6 | B38: ARMAÇÃO DE BLOCO, VIGA BALDRAME E SAPATA UTILIZANDO AÇO CA-60 DE 5 MM - MONTAGEM. AF_06/2017 | C38: M2 | D38: 212 | G38: =D38+E38-F38 -> 212 | H38: 19.74 | I38: =D38*H38 -> 4184.88 | J38: =K38-I38 -> 0 | K38: =G38*H38 -> 4184.88 | N38: =N35 -> 0.014107547 | O38: =N38*P38 -> 0.36171751 | P38: 25.64 | R38: =N38-1 -> -0.98589245 | T38: =F38*H38 -> 0 | U38: =E38*H38 -> 0
A39: 5 | B39: PILARES | I39: =SUM(I40:I46) -> 31334.072 | J39: =SUM(J40:J46) -> 0 | K39: =SUM(K40:K46) -> 31334.072
A40: 5.1 | B40: MONTAGEM E DESMONTAGEM DE FÔRMA DE PILARES RETANGULARES E ESTRUTURAS SIMILARES, PÉ-DIREITO DUPLO, EM CHAPA DE MADEIRA COMPENSADA PLASTIFICADA, 18 UTILIZAÇÕES. AF_09/2020 | C40: UN | D40: 199.64 | G40: =D40+E40-F40 -> 199.64 | H40: 50.42 | I40: =D40*H40 -> 10065.849 | J40: =K40-I40 -> 0 | K40: =G40*H40 -> 10065.849 | N40: =(O40)/P40 -> 21.074133 | O40: =I40 -> 10065.849 | P40: =Comparativo!K26 -> 477.64 | R40: =N40-1 -> 20.074133 | T40: =F40*H40 -> 0 | U40: =E40*H40 -> 0
...

Sheet Reprogramado
A4: FONTE | B4: CÓDIGO | C4: ITEM | D4: DESCRIÇÃO DOS SERVIÇOS | E4: UNID. | F4: QUANTIDADE | J4: VALORES (R$) - COM BDI
F5: LICITADA | G5: ACRESCIDA | H5: SUPRIMIDA | I5: REPROGRAMAÇÃO | J5: UNIT. | K5: LICITADO | L5: ACRESCIDO/ SUPRIMIDO | M5: TOTAL REPROGRAMADO
C6: 1 | D6: SERVIÇOS PRELIMINARES | K6: =SUM(K7:K7) -> 0 | L6: =SUM(L7:L7,L8) -> -160.7317 | M6: =SUM(M7:M7) -> 11786.86
A7: PROPRIA | B7: PRO-PREF-01 | C7: 1.2 | D7: BARRACÃO DA OBRA EM ALVENARIA | E7: M | F7: 0 | G7: 27.3644 | I7: =F7+G7-H7 -> 27.3644 | J7: 430.73702 | K7: =F7*J7 -> 0 | L7: =M7-K7 -> 11786.86 | M7: =I7*J7 -> 11786.86
A8: SINAPI | B8: 93584 | C8: 1.2 | D8: EXECUÇÃO DE DEPÓSITO EM CANTEIRO DE OBRA EM CHAPA DE MADEIRA COMPENSADA, NÃO INCLUSO MOBILIÁRIO. AF_04/2016 | E8: M2 | F8: 12.43 | H8: 12.43 | I8: =F8+G8-H8 -> 0 | J8: 961.19 | K8: =F8*J8 -> 11947.592 | L8: =M8-K8 -> -11947.592 | M8: =I8*J8 -> 0
L9: Total reprogamado: | M9: =L6 -> -160.7317

Sheet Memorial de Calculo
A2: ITEM | B2: DESCRIÇÃO DOS SERVIÇOS | C2: MEMORIAL DE CALCULO ADITIVO/SUPRESSÃO
A4: 1 | B4: SERVIÇOS PRELIMINARES | C4: Quantidade | D4: Comprimento | E4: Largura | F4: Altura | G4: Total | H4: m²
A5: 1.2 | B5: BARRACÃO DA OBRA EM ALVENARIA | C5: ACRÉSCIMO | G5: =SUM(G6:G6) -> 27.3644 | H5: m²
C6: 1 | D6: 4.06 | E6: 6.74 | G6: =C6*D6*E6 -> 27.3644
A7: 1 | B7: SERVIÇOS PRELIMINARES | C7: Quantidade | D7: Comprimento | E7: Largura | F7: Altura | G7: Total
A8: 1.2 | B8: EXECUÇÃO DE DEPÓSITO EM CANTEIRO DE OBRA EM CHAPA DE MADEIRA COMPENSADA, NÃO INCLUSO MOBILIÁRIO. AF_04/2016 | C8: SUPRESSÃO | G8: 12.43 | H8: m²

Sheet PLANILHA ORCAMENTARIA
A3: ITEM | B3: CÓDIGO | C3: DESCRIÇÃO | D3: FONTE | E3: UND | F3: QUANTIDADE | G3: PREÇO UNITÁRIO R$ | H3: PREÇO TOTAL R$
A4: 1 | B4: SERVIÇOS PRELIMINARES | H4: 7571.29
A5: 1.1 | B5: 103689 | C5: FORNECIMENTO E INSTALAÇÃO DE PLACA DE OBRA COM CHAPA GALVANIZADA E ESTRUTURA DE MADEIRA. AF_03/2022_PS | D5: SINAPI | E5: M2 | F5: 6 | G5: 539.62 | H5: 3237.72
A6: 1.2 | B6: 99059 | C6: LOCAÇÃO CONVENCIONAL DE OBRA, UTILIZANDO GABARITO DE TÁBUAS CORRIDAS PONTALETADAS A CADA 2,00M - 2 UTILIZAÇÕES. AF_03/2024 | D6: SINAPI | E6: M | F6: 1 | G6: 69.97 | H6: 69.97
A7: 1.3 | B7: 104790 | C7: DEMOLIÇÃO DE PISO DE CONCRETO SIMPLES, DE FORMA MECANIZADA COM MARTELETE, SEM REAPROVEITAMENTO. AF_09/2023 | D7: SINAPI | E7: M3 | F7: 15.9 | G7: 110.29 | H7: 1753.61
A8: 1.4 | B8: COM-82872488 | C8: REMOÇÃO MANUAL DE ENTULHO (COREMAS 1) | D8: Composições Próprias | E8: M3 | F8: 23.85 | G8: 84.44 | H8: 2013.89
A9: 1.5 | B9: 97647 | C9: REMOÇÃO DE TELHAS DE FIBROCIMENTO METÁLICA E CERÂMICA, DE FORMA MANUAL, SEM REAPROVEITAMENTO. AF_09/2023 | D9: SINAPI | E9: M2 | F9: 128.19 | G9: 3.87 | H9: 496.1
A10: 2 | B10: PAREDES E PAINEIS | H10: 10522.33
A11: 2.1 | B11: 103317 | C11: ALVENARIA DE VEDAÇÃO DE BLOCOS VAZADOS DE CONCRETO DE 9X19X39 CM (ESPESSURA 9 CM) E ARGAMASSA DE ASSENTAMENTO COM PREPARO MANUAL. AF_12/2021 | D11: SINAPI | E11: M2 | F11: 1.2 | G11: 86.67 | H11: 104
A12: 2.2 | B12: 101158 | C12: ALVENARIA DE VEDAÇÃO DE BLOCOS DE GESSO DE 10X50X66CM (ESPESSURA 10CM). AF_05/2020 | D12: SINAPI | E12: M2 | F12: 100.16 | G12: 101.03 | H12: 10119.16
A13: 2.3 | B13: 105023 | C13: VERGA MOLDADA IN LOCO EM CONCRETO, ESPESSURA DE *15* CM. AF_03/2024 | D13: SINAPI | E13: M | F13: 4.2 | G13: 71.23 | H13: 299.17
A14: 3 | B14: COBERTURA | H14: 11488.43
A15: 3.1 | B15: 94201 | C15: TELHAMENTO COM TELHA CERÂMICA CAPA-CANAL, TIPO COLONIAL, COM ATÉ 2 ÁGUAS, INCLUSO TRANSPORTE VERTICAL. AF_07/2019 | D15: SINAPI | E15: M2 | F15: 128.19 | G15: 46.34 | H15: 5940.32
A16: 3.2 | B16: COM-96928931 | C16: REPARO DE FORRO EM RÁGUAS DE PVC, FRISADO, PARA AMBIENTES COMERCIAIS (COREMAS 2) | D16: Composições Próprias | E16: M2 | F16: 156.4 | G16: 7.45 | H16: 1165.18
A17: 3.3 | B17: 100328 | C17: RETIRADA E RECOLOCAÇÃO DE TELHA CERÂMICA DE ENCAIXE, COM ATÉ DUAS ÁGUAS, INCLUSO IÇAMENTO. AF_07/2019 | D17: SINAPI | E17: M2 | F17: 299.1 | G17: 13.7 | H17: 4097.67
A18: 3.4 | B18: 98555 | C18: IMPERMEABILIZAÇÃO DE SUPERFÍCIE COM ARGAMASSA POLIMÉRICA / MEMBRANA ACRÍLICA, 3 DEMÃOS. AF_09/2023 | D18: SINAPI | E18: M2 | F18: 3.56 | G18: 38.07 | H18: 135.53
A19: 3.5 | B19: 98563 | C19: PROTEÇÃO MECÂNICA DE SUPERFÍCIE HORIZONTAL COM ARGAMASSA DE CIMENTO E AREIA, TRAÇO 1:3, E=2CM. AF_09/2023 | D19: SINAPI | E19: M2 | F19: 3.56 | G19: 42.06 | H19: 149.73
A20: 4 | B20: ESQUADRIAS | H20: 2980.11
A21: 4.1 | B21: 91314 | C21: KIT DE PORTA DE MADEIRA PARA PINTURA, SEMI-OCA (LEVE OU MÉDIA), PADRÃO POPULAR, 80X210CM, ESPESSURA DE 3,5CM, ITENS INCLUSOS: DOBRADIÇAS, MONTAGEM E INSTALAÇÃO DO BATENTE, FECHADURA COM EXECUÇÃO DO FURO - FORNECIMENTO E INSTALAÇÃO. AF_12/2019 | D21: SINAPI | E21: UN | F21: 3 | G21: 993.37 | H21: 2980.11
A22: 5 | B22: INSTALAÇÕES ELÉTRICAS | H22: 3147.13
A23: 5.1 | B23: COM-76825377 | C23: LUMINARIA TIPO PLAFON 40X40QUADRADA DE EMBUTIR COM LED DE 36W FORNECIMENTO E INSTALAÇÃO (COREMAS 3) | D23: Composições Próprias | E23: UND | F23: 4 | G23: 116.42 | H23: 465.68
A24: 5.2 | B24: 91953 | C24: INTERRUPTOR SIMPLES (1 MÓDULO), 10A/250V, INCLUINDO SUPORTE E PLACA - FORNECIMENTO E INSTALAÇÃO. AF_03/2023 | D24: SINAPI | E24: UN | F24: 3 | G24: 31.3 | H24: 93.9
A25: 5.3 | B25: COM-41070178 | C25: PONTO DE LUZ EM TETO OU PAREDE, COM ELETRODUTO PVC RIGIDO EMBUTIDO 0 3/4 (COREMAS 5) | D25: Composições Próprias | E25: UND | F25: 7 | G25: 369.65 | H25: 2587.55
A26: 6 | B26: PISOS | H26: 45980.53
A27: 6.1 | B27: 87622 | C27: CONTRAPISO EM ARGAMASSA TRAÇO 1:4 (CIMENTO E AREIA), PREPARO MANUAL, APLICADO EM ÁREAS SECAS SOBRE LAJE, ADERIDO, ACABAMENTO NÃO REFORÇADO, ESPESSURA 2CM. AF_07/2021 | D27: SINAPI | E27: M2 | F27: 260.4 | G27: 39.61 | H27: 10314.44
A28: 6.2 | B28: 104596 | C28: REVESTIMENTO CERÂMICO PARA PISO COM PLACAS TIPO PORCELANATO DE DIMENSÕES 80X80 CM APLICADA EM AMBIENTES DE ÁREA MENOR QUE 5 M². AF_02/2023_PE | D28: SINAPI | E28: M2 | F28: 9.69 | G28: 181.07 | H28: 1754.57
A29: 6.3 | B29: 104162 | C29: PISO EM GRANILITE, MARMORITE OU GRANITINA EM AMBIENTES INTERNOS, COM ESPESSURA DE 8 MM, INCLUSO MISTURA EM BETONEIRA, COLOCAÇÃO DAS JUNTAS, APLICAÇÃO DO PISO, 4 POLIMENTOS COM POLITRIZ, ESTUCAMENTO, SELADOR E CERA. AF_06/2022 | D29: SINAPI | E29: M2 | F29: 318 | G29: 106.64 | H29: 33911.52
A30: 7 | B30: REVESTIMENTOS INTERNOS | H30: 2750.12
A31: 7.1 | B31: 104410 | C31: CHAPISCO APLICADO EM ALVENARIA E ESTRUTURAS DE CONCRETO INTERNAS, COM EQUIPAMENTO DE PROJEÇÃO. ARGAMASSA TRAÇO 1:3 COM PREPARO MANUAL. AF_10/2022 | D31: SINAPI | E31: M2 | F31: 1.2 | G31: 5.7 | H31: 6.84
A32: 7.2 | B32: 87528 | C32: EMBOÇO, EM ARGAMASSA TRAÇO 1:2:8, PREPARO MANUAL, APLICADO MANUALMENTE EM PAREDES INTERNAS DE AMBIENTES COM ÁREA MENOR QUE 5M², E = 17,5MM, COM TALISCAS. AF_03/2024 | D32: SINAPI | E32: M2 | F32: 19.89 | G32: 47.49 | H32: 944.58
A33: 7.3 | B33: 104612 | C33: REVESTIMENTO CERÂMICO PARA PAREDES INTERNAS COM PLACAS TIPO ESMALTADA DE DIMENSÕES 60X60 CM APLICADAS A MEIA ALTURA DAS PAREDES. AF_02/2023_PE | D33: SINAPI | E33: M2 | F33: 14.82 | G33: 121.37 | H33: 1798.7
A34: 8 | B34: PINTURAS INTERNA | H34: 14897.97
A35: 8.1 | B35: 88485 | C35: FUNDO SELADOR ACRÍLICO, APLICAÇÃO MANUAL EM PAREDE, UMA DEMÃO. AF_04/2023 | D35: SINAPI | E35: M2 | F35: 118.85 | G35: 4.42 | H35: 525.32
A36: 8.2 | B36: 88497 | C36: EMASSAMENTO COM MASSA LÁTEX, APLICAÇÃO EM PAREDE, DUAS DEMÃOS, LIXAMENTO MANUAL. AF_04/2023 | D36: SINAPI | E36: M2 | F36: 414.62 | G36: 17.7 | H36: 7338.77
A37: 8.3 | B37: 88489 | C37: PINTURA LÁTEX ACRÍLICA PREMIUM, APLICAÇÃO MANUAL EM PAREDES, DUAS DEMÃOS. AF_04/2023 | D37: SINAPI | E37: M2 | F37: 400.93 | G37: 14.66 | H37: 5877.63
A38: 8.4 | B38: 88488 | C38: PINTURA LÁTEX ACRÍLICA PREMIUM, APLICAÇÃO MANUAL EM TETO, DUAS DEMÃOS. AF_04/2023 | D38: SINAPI | E38: M2 | F38: 67.42 | G38: 17.15 | H38: 1156.25
A39: 9 | B39: REVESTIMENTO EXTERNO | H39: 11593.36
A40: 9.1 | B40: PINTURA EXTERNA | H40: 11593.36
A41: 9.1.1 | B41: 88497 | C41: EMASSAMENTO COM MASSA LÁTEX, APLICAÇÃO EM PAREDE, DUAS DEMÃOS, LIXAMENTO MANUAL. AF_04/2023 | D41: SINAPI | E41: M2 | F41: 362.38 | G41: 17.7 | H41: 6414.13
A42: 9.1.2 | B42: 88489 | C42: PINTURA LÁTEX ACRÍLICA PREMIUM, APLICAÇÃO MANUAL EM PAREDES, DUAS DEMÃOS. AF_04/2023 | D42: SINAPI | E42: M2 | F42: 353.29 | G42: 14.66 | H42: 5179.23
...

Sheet Comparativo
A1: PLANILHA ORÇAMENTÁRIA
A3: FONTE | B3: CÓDIGO | C3: ITEM | D3: DESCRIÇÃO DOS SERVIÇOS | E3: UNID. | F3: QUANTIDADE | J3: VALORES (R$) - COM BDI
F4: LICITADA | G4: ACRESCIDA | H4: SUPRIMIDA | I4: REPROGRAMAÇÃO | J4: UNIT. | K4: LICITADO | L4: ACRESCIDO/SUPRIMIDO | M4: TOTAL REPROGRAMADO
C5: 1.0 | D5: REFORMA DO POLO UNIVERSITÁRIO, NO MUNICÍPIO DE COREMAS/PB | K5: =SUM(K6,K12,K16,K22,K25,K29,K33,K37,K42) -> 113775.66 | M5: =SUM(M6,M12,M16,M22,M25,M29,M33,M37,M42) -> 98759.603
C6: 1.1 | D6: SERVIÇOS PRELIMINARES | K6: =SUM(K7:K11) -> 7775.1989 | M6: =SUM(M7:M11) -> 7775.1989
A7: SINAPI PB | B7: 103689 | C7: 1.1.1 | D7: FORNECIMENTO E INSTALAÇÃO DE PLACA DE OBRA COM CHAPA GALVANIZADA E ESTRUTURA DE MADEIRA. AF_03/2022_PS | E7: M2 | F7: 6 | I7: =F7+G7-H7 -> 6 | J7: 555.26 | K7: =F7*J7 -> 3331.56 | L7: =M7-K7 -> 0 | M7: =I7*J7 -> 3331.56
A8: SINAPI PB | B8: 99059 | C8: 1.1.2 | D8: LOCAÇÃO CONVENCIONAL DE OBRA, UTILIZANDO GABARITO DE TÁBUAS CORRIDAS PONTALETADAS A CADA 2,00M - 2 UTILIZAÇÕES. AF_03/2024 | E8: M | F8: 1 | I8: =F8+G8-H8 -> 1 | J8: 71.75 | K8: =F8*J8 -> 71.75 | L8: =M8-K8 -> 0 | M8: =I8*J8 -> 71.75
A9: SINAPI PB | B9: 104790 | C9: 1.1.3 | D9: DEMOLIÇÃO DE PISO DE CONCRETO SIMPLES, DE FORMA MECANIZADA COM MARTELETE, SEM REAPROVEITAMENTO. AF_09/2023 | E9: M3 | F9: 15.9 | I9: =F9+G9-H9 -> 15.9 | J9: 113.12 | K9: =F9*J9 -> 1798.608 | L9: =M9-K9 -> 0 | M9: =I9*J9 -> 1798.608
A10: composição | B10: 1 | C10: 1.1.4 | D10: REMOCAO MANUAL DE ENTULHO - [SUMÁRIO SINAPI 85387] | E10: M3 | F10: 23.85 | I10: =F10+G10-H10 -> 23.85 | J10: 86.61 | K10: =F10*J10 -> 2065.6485 | L10: =M10-K10 -> 0 | M10: =I10*J10 -> 2065.6485
A11: SINAPI PB | B11: 97647 | C11: 1.1.5 | D11: REMOÇÃO DE TELHAS DE FIBROCIMENTO METÁLICA E CERÂMICA, DE FORMA MANUAL, SEM REAPROVEITAMENTO. AF_09/2023 | E11: M2 | F11: 128.19 | I11: =F11+G11-H11 -> 128.19 | J11: 3.96 | K11: =F11*J11 -> 507.6324 | L11: =M11-K11 -> 0 | M11: =I11*J11 -> 507.6324
C12: 1.2 | D12: PAREDES E PAINÉIS | K12: =SUM(K13:K15) -> 10792.129 | M12: =SUM(M13:M15) -> 106.656
A13: SINAPI PB | B13: 103317 | C13: 1.2.1 | D13: ALVENARIA DE VEDAÇÃO DE BLOCOS VAZADOS DE CONCRETO DE 9X19X39 CM (ESPESSURA 9 CM) E ARGAMASSA DE ASSENTAMENTO COM PREPARO MANUAL. AF_12/2021 | E13: M2 | F13: 1.2 | I13: =F13+G13-H13 -> 1.2 | J13: 88.88 | K13: =F13*J13 -> 106.656 | L13: =M13-K13 -> 0 | M13: =I13*J13 -> 106.656
A14: SINAPI PB | B14: 101158 | C14: 1.2.2 | D14: ALVENARIA DE VEDAÇÃO DE BLOCOS DE GESSO DE 10X50X66CM (ESPESSURA 10CM). AF_05/2020 | E14: M2 | F14: 100.16 | H14: =(38.72+15.98-3.36)+(48.82) -> 100.16 | I14: =F14+G14-H14 -> 0 | J14: 103.62 | K14: =F14*J14 -> 10378.579 | L14: =M14-K14 -> -10378.579 | M14: =I14*J14 -> 0
A15: SINAPI PB | B15: 105023 | C15: 1.2.3 | D15: VERGA MOLDADA IN LOCO EM CONCRETO, ESPESSURA DE *15* CM. AF_03/2024 | E15: M | F15: 4.2 | H15: =3*1.4 -> 4.2 | I15: =F15+G15-H15 -> 0 | J15: 73.07 | K15: =F15*J15 -> 306.894 | L15: =M15-K15 -> -306.894 | M15: =I15*J15 -> 0
C16: 1.3 | D16: COBERTURA | K16: =SUM(K17:K21) -> 11783.964 | M16: =SUM(M17:M21) -> 11783.964
A17: SINAPI PB | B17: 94201 | C17: 1.3.1 | D17: TELHAMENTO COM TELHA CERÂMICA CAPA-CANAL, TIPO COLONIAL, COM ATÉ 2 ÁGUAS, INCLUSO TRANSPORTE VERTICAL. AF_07/2019 | E17: M2 | F17: 128.19 | I17: =F17+G17-H17 -> 128.19 | J17: 47.54 | K17: =F17*J17 -> 6094.1526 | L17: =M17-K17 -> 0 | M17: =I17*J17 -> 6094.1526
A18: composição | B18: 2 | C18: 1.3.2 | D18: REPARO DE FORRO EM RÉGUAS DE PVC, FRISADO, PARA AMBIENTES COMERCIAIS- [ADAPTADO DE SINAPI 96116] | E18: M2 | F18: 156.4 | I18: =F18+G18-H18 -> 156.4 | J18: 7.64 | K18: =F18*J18 -> 1194.896 | L18: =M18-K18 -> 0 | M18: =I18*J18 -> 1194.896
A19: SINAPI PB | B19: 100328 | C19: 1.3.3 | D19: RETIRADA E RECOLOCAÇÃO DE TELHA CERÂMICA DE ENCAIXE, COM ATÉ DUAS ÁGUAS, INCLUSO IÇAMENTO. AF_07/2019 | E19: M2 | F19: 299.1 | I19: =F19+G19-H19 -> 299.1 | J19: 14.05 | K19: =F19*J19 -> 4202.355 | L19: =M19-K19 -> 0 | M19: =I19*J19 -> 4202.355
A20: SINAPI PB | B20: 98555 | C20: 1.3.4 | D20: IMPERMEABILIZAÇÃO DE SUPERFÍCIE COM ARGAMASSA POLIMÉRICA / MEMBRANA ACRÍLICA, 3 DEMÃOS. AF_09/2023 | E20: M2 | F20: 3.56 | I20: =F20+G20-H20 -> 3.56 | J20: 39.04 | K20: =F20*J20 -> 138.9824 | L20: =M20-K20 -> 0 | M20: =I20*J20 -> 138.9824
A21: SINAPI PB | B21: 98563 | C21: 1.3.5 | D21: PROTEÇÃO MECÂNICA DE SUPERFÍCIE HORIZONTAL COM ARGAMASSA DE CIMENTO E AREIA, TRAÇO 1:3, E=2CM. AF_09/2023 | E21: M2 | F21: 3.56 | I21: =F21+G21-H21 -> 3.56 | J21: 43.14 | K21: =F21*J21 -> 153.5784 | L21: =M21-K21 -> 0 | M21: =I21*J21 -> 153.5784
C22: 1.4 | D22: ESQUADRIAS | K22: =K23 -> 3056.52 | M22: =M23 -> 0
A23: SINAPI PB | B23: 91314 | C23: 1.4.1 | D23: KIT DE PORTA DE MADEIRA PARA PINTURA, SEMI-OCA (LEVE OU MÉDIA), PADRÃO POPULAR, 80X210CM, ESPESSURA DE 3,5CM, ITENS INCLUSOS: DOBRADIÇAS, MONTAGEM E INSTALAÇÃO DO BATENTE, FECHADURA COM EXECUÇÃO DO | E23: UN | F23: 3 | H23: 3 | I23: =F23+G23-H23 -> 0 | J23: 1018.84 | K23: =F23*J23 -> 3056.52 | L23: =M23-K23 -> -3056.52 | M23: =I23*J23 -> 0
C25: 1.5 | D25: INSTALAÇÕES ELÉTRICAS | K25: =SUM(K26:K28) -> 3227.88 | M25: =SUM(M26:M28) -> 3227.88
A26: composição | B26: 3 | C26: 1.5.1 | D26: LUMINÁRIA TIPO PLAFON 40x40QUADRADA DE EMBUTIR COM LED DE 36W- FORNECIMENTO E INSTALAÇÃO [ADAPTADO DE SINAPI 103782] | E26: UND | F26: 4 | I26: =F26+G26-H26 -> 4 | J26: 119.41 | K26: =F26*J26 -> 477.64 | L26: =M26-K26 -> 0 | M26: =I26*J26 -> 477.64
A27: SINAPI PB | B27: 91953 | C27: 1.5.2 | D27: INTERRUPTOR SIMPLES (1 MÓDULO), 10A/250V, INCLUINDO SUPORTE E PLACA - FORNECIMENTO E INSTALAÇÃO. AF_03/2023 | E27: UN | F27: 3 | I27: =F27+G27-H27 -> 3 | J27: 32.11 | K27: =F27*J27 -> 96.33 | L27: =M27-K27 -> 0 | M27: =I27*J27 -> 96.33
A28: composição | B28: 5 | C28: 1.5.3 | D28: Ponto de luz em teto ou parede, com eletroduto pvc rígido embutido Ø 3/4 - (Adaptado de ORSE 642) | E28: UND | F28: 7 | I28: =F28+G28-H28 -> 7 | J28: 379.13 | K28: =F28*J28 -> 2653.91 | L28: =M28-K28 -> 0 | M28: =I28*J28 -> 2653.91
C29: 1.6 | D29: PISOS | K29: =SUM(K30:K32) -> 47156.541 | M29: =SUM(M30:M32) -> 47156.541
A30: SINAPI PB | B30: 87622 | C30: 1.6.1 | D30: CONTRAPISO EM ARGAMASSA TRAÇO 1:4 (CIMENTO E AREIA), PREPARO MANUAL, APLICADO EM ÁREAS SECAS SOBRE LAJE, ADERIDO, ACABAMENTO NÃO REFORÇADO, ESPESSURA 2CM. AF_07/2021 | E30: M2 | F30: 260.4 | I30: =F30+G30-H30 -> 260.4 | J30: 40.62 | K30: =F30*J30 -> 10577.448 | L30: =M30-K30 -> 0 | M30: =I30*J30 -> 10577.448
A31: SINAPI PB | B31: 104596 | C31: 1.6.2 | D31: REVESTIMENTO CERÂMICO PARA PISO COM PLACAS TIPO PORCELANATO DE DIMENSÕES 80X80 CM APLICADA EM AMBIENTES DE ÁREA MENOR QUE 5 M². AF_02/2023_PE | E31: M2 | F31: 9.69 | I31: =F31+G31-H31 -> 9.69 | J31: 185.7 | K31: =F31*J31 -> 1799.433 | L31: =M31-K31 -> 0 | M31: =I31*J31 -> 1799.433
A32: SINAPI PB | B32: 104162 | C32: 1.6.3 | D32: PISO EM GRANILITE, MARMORITE OU GRANITINA EM AMBIENTES INTERNOS, COM ESPESSURA DE 8 MM, INCLUSO MISTURA EM BETONEIRA, COLOCAÇÃO DAS JUNTAS, APLICAÇÃO DO PISO, 4 POLIMENTOS COM POLITRIZ, ESTUCAMENTO, SELADOR E CERA. AF_06/2022 | E32: M2 | F32: 318 | I32: =F32+G32-H32 -> 318 | J32: 109.37 | K32: =F32*J32 -> 34779.66 | L32: =M32-K32 -> 0 | M32: =I32*J32 -> 34779.66
C33: 1.7 | D33: REVESTIMENTOS INTERNOS | K33: =SUM(K34:K36) -> 2820.6435 | M33: =SUM(M34:M36) -> 4236.7848
A34: SINAPI PB | B34: 104410 | C34: 1.7.1 | D34: CHAPISCO APLICADO EM ALVENARIA E ESTRUTURAS DE CONCRETO INTERNAS, COM EQUIPAMENTO DE PROJEÇÃO. ARGAMASSA TRAÇO 1:3 COM PREPARO MANUAL. AF_10/2022 | E34: M2 | F34: 1.2 | I34: =F34+G34-H34 -> 1.2 | J34: 5.84 | K34: =F34*J34 -> 7.008 | L34: =M34-K34 -> 0 | M34: =I34*J34 -> 7.008
A35: SINAPI PB | B35: 87528 | C35: 1.7.2 | D35: EMBOÇO, EM ARGAMASSA TRAÇO 1:2:8, PREPARO MANUAL, APLICADO MANUALMENTE EM PAREDES INTERNAS DE AMBIENTES COM ÁREA MENOR QUE 5M², E = 17,5MM, COM TALISCAS. AF_03/2024 | E35: M2 | F35: 19.89 | H35: =G36 -> 18.69 | I35: =F35+G35-H35 -> 1.2 | J35: 48.71 | K35: =F35*J35 -> 968.8419 | L35: =M35-K35 -> -910.3899 | M35: =I35*J35 -> 58.452
A36: SINAPI PB | B36: 104612 | C36: 1.7.3 | D36: PISO CERÂMICO MARMORIZADO BRILHANTE BORDA ARREDONDADA INTERNO 46X46 | E36: M2 | F36: 14.82 | G36: =12.46*1.5 -> 18.69 | I36: =F36+G36-H36 -> 33.51 | J36: 124.48 | K36: =F36*J36 -> 1844.7936 | L36: =M36-K36 -> 2326.5312 | M36: =I36*J36 -> 4171.3248
C37: 1.8 | D37: PINTURAS INTERNA | K37: =SUM(K38:K41) -> 15275.639 | M37: =SUM(M38:M41) -> 12585.432
A38: SINAPI PB | B38: 88485 | C38: 1.8.1 | D38: FUNDO SELADOR ACRÍLICO, APLICAÇÃO MANUAL EM PAREDE, UMA DEMÃO. AF_04/2023 | E38: M2 | F38: 118.85 | H38: =38.72+48.82+18.69 -> 106.23 | I38: =F38+G38-H38 -> 12.62 | J38: 4.53 | K38: =F38*J38 -> 538.3905 | L38: =M38-K38 -> -481.2219 | M38: =I38*J38 -> 57.1686
A39: SINAPI PB | B39: 88497 | C39: 1.8.2 | D39: EMASSAMENTO COM MASSA LÁTEX, APLICAÇÃO EM PAREDE, DUAS DEMÃOS, LIXAMENTO MANUAL. AF_04/2023 | E39: M2 | F39: 414.62 | H39: =H38 -> 106.23 | I39: =F39+G39-H39 -> 308.39 | J39: 18.15 | K39: =F39*J39 -> 7525.353 | L39: =M39-K39 -> -1928.0745 | M39: =I39*J39 -> 5597.2785
A40: SINAPI PB | B40: 88489 | C40: 1.8.3 | D40: PINTURA LÁTEX ACRÍLICA PREMIUM, APLICAÇÃO MANUAL EM PAREDES, DUAS DEMÃOS. AF_04/2023 | E40: M2 | F40: 400.93 | H40: =G36 -> 18.69 | I40: =F40+G40-H40 -> 382.24 | J40: 15.03 | K40: =F40*J40 -> 6025.9779 | L40: =M40-K40 -> -280.9107 | M40: =I40*J40 -> 5745.0672
A41: SINAPI PB | B41: 88488 | C41: 1.8.4 | D41: PINTURA LÁTEX ACRÍLICA PREMIUM, APLICAÇÃO MANUAL EM TETO, DUAS DEMÃOS. AF_04/2023 | E41: M2 | F41: 67.42 | I41: =F41+G41-H41 -> 67.42 | J41: 17.59 | K41: =F41*J41 -> 1185.9178 | L41: =M41-K41 -> 0 | M41: =I41*J41 -> 1185.9178
C42: 1.9 | D42: REVESTIMENTO EXTERNO | K42: =K43 -> 11887.146 | M42: =M43 -> 11887.146
...

Sheet COMPOSICOES
A3: 103689 FORNECIMENTO E INSTALAÇÃO DE PLACA DE OBRA COM CHAPA GALVANIZADA E ESTRUTURA DE MADEIRA. AF_03/2022_PS (M2)
A4: Material | C4: FONTE | D4: UNID | E4: COEFICIENTE | F4: PREÇO UNITÁRIO | G4: TOTAL
A5: 00004813 | B5: PLACA DE OBRA (PARA CONSTRUCAO CIVIL) EM CHAPA GALVANIZADA *N. 22*, ADESIVADA, DE *2,4 X 1,2* M (SEM POSTES PARA FIXACAO) | C5: SINAPI | D5: M2 | E5: 0.99470252 | F5: 390 | G5: 387.93
A6: 00005065 | B6: PREGO DE ACO POLIDO COM CABECA 10 X 10 (7/8 X 17) | C6: SINAPI | D6: KG | E6: 0.01124013 | F6: 37.73 | G6: 0.42
A7: 00005069 | B7: PREGO DE ACO POLIDO COM CABECA 17 X 27 (2 1/2 X 11) | C7: SINAPI | D7: KG | E7: 0.01313006 | F7: 20.22 | G7: 0.26
A8: 00004509 | B8: SARRAFO *2,5 X 10* CM EM PINUS, MISTA OU EQUIVALENTE DA REGIAO - BRUTA | C8: SINAPI | D8: M | E8: 3.1913041 | F8: 5.27 | G8: 16.81
E9: TOTAL Material: | G9: 405.42
A10: Mão de Obra com Encargos Complementares | C10: FONTE | D10: UNID | E10: COEFICIENTE | F10: PREÇO UNITÁRIO | G10: TOTAL
A11: 88262 | B11: CARPINTEIRO DE FORMAS COM ENCARGOS COMPLEMENTARES | C11: SINAPI | D11: H | E11: 0.37092456 | F11: 24.68 | G11: 9.15
A12: 88316 | B12: SERVENTE COM ENCARGOS COMPLEMENTARES | C12: SINAPI | D12: H | E12: 1.1126742 | F12: 19.97 | G12: 22.22
E13: TOTAL Mão de Obra com Encargos Complementares: | G13: 31.37
A14: Serviço | C14: FONTE | D14: UNID | E14: COEFICIENTE | F14: PREÇO UNITÁRIO | G14: TOTAL
A15: 102234 | B15: PINTURA IMUNIZANTE PARA MADEIRA, 2 DEMÃOS. AF_01/2021 | C15: SINAPI | D15: M2 | E15: 0.49735125 | F15: 22.41 | G15: 11.14
E16: TOTAL Serviço: | G16: 11.14
E17: VALOR: | G17: 447.93
A19: 99059 LOCAÇÃO CONVENCIONAL DE OBRA, UTILIZANDO GABARITO DE TÁBUAS CORRIDAS PONTALETADAS A CADA 2,00M - 2 UTILIZAÇÕES. AF_03/2024 (M)
A20: Equipamento Custo Horário | C20: FONTE | D20: UNID | E20: COEFICIENTE | F20: PREÇO UNITÁRIO | G20: TOTAL
A21: 91693 | B21: SERRA CIRCULAR DE BANCADA COM MOTOR ELÉTRICO POTÊNCIA DE 5HP, COM COIFA PARA DISCO 10" - CHI DIURNO. AF_08/2015 | C21: SINAPI | D21: CHI | E21: 0.02760088 | F21: 23.62 | G21: 0.65
A22: 91692 | B22: SERRA CIRCULAR DE BANCADA COM MOTOR ELÉTRICO POTÊNCIA DE 5HP, COM COIFA PARA DISCO 10" - CHP DIURNO. AF_08/2015 | C22: SINAPI | D22: CHP | E22: 0.00690022 | F22: 24.59 | G22: 0.16
E23: TOTAL Equipamento Custo Horário: | G23: 0.81
A24: Material | C24: FONTE | D24: UNID | E24: COEFICIENTE | F24: PREÇO UNITÁRIO | G24: TOTAL
A25: 00004433 | B25: CAIBRO NAO APARELHADO *6 X 6* CM, EM MACARANDUBA/MASSARANDUBA, ANGELIM OU EQUIVALENTE DA REGIAO - BRUTA | C25: SINAPI | D25: M | E25: 0.40662013 | F25: 22.73 | G25: 9.24
A26: 00005068 | B26: PREGO DE ACO POLIDO COM CABECA 17 X 21 (2 X 11) | C26: SINAPI | D26: KG | E26: 0.10941778 | F26: 19.83 | G26: 2.16
A27: 00004417 | B27: SARRAFO NAO APARELHADO *2,5 X 7* CM, EM MACARANDUBA/MASSARANDUBA, ANGELIM, PEROBA-ROSA OU EQUIVALENTE DA REGIAO - BRUTA | C27: SINAPI | D27: M | E27: 0.73388774 | F27: 6.32 | G27: 4.63
A28: 00010567 | B28: TABUA *2,5 X 23* CM EM PINUS, MISTA OU EQUIVALENTE DA REGIAO - BRUTA | C28: SINAPI | D28: M | E28: 0.54216018 | F28: 11.74 | G28: 6.36
A29: 00007356 | B29: TINTA LATEX ACRILICA PREMIUM, COR BRANCO FOSCO | C29: SINAPI | D29: L | E29: 0.02523509 | F29: 30.26 | G29: 0.76
E30: TOTAL Material: | G30: 23.15
A31: Mão de Obra com Encargos Complementares | C31: FONTE | D31: UNID | E31: COEFICIENTE | F31: PREÇO UNITÁRIO | G31: TOTAL
A32: 88239 | B32: AJUDANTE DE CARPINTEIRO COM ENCARGOS COMPLEMENTARES | C32: SINAPI | D32: H | E32: 0.71436997 | F32: 20.68 | G32: 14.77
A33: 88262 | B33: CARPINTEIRO DE FORMAS COM ENCARGOS COMPLEMENTARES | C33: SINAPI | D33: H | E33: 0.71436997 | F33: 24.68 | G33: 17.63
E34: TOTAL Mão de Obra com Encargos Complementares: | G34: 32.4
A35: Serviço | C35: FONTE | D35: UNID | E35: COEFICIENTE | F35: PREÇO UNITÁRIO | G35: TOTAL
A36: 94974 | B36: CONCRETO MAGRO PARA LASTRO, TRAÇO 1:4,5:4,5 (EM MASSA SECA DE CIMENTO/ AREIA MÉDIA/ BRITA 1) - PREPARO MANUAL. AF_05/2021 | C36: SINAPI | D36: M3 | E36: 0.00394298 | F36: 437.61 | G36: 1.72
E37: TOTAL Serviço: | G37: 1.72
E38: VALOR: | G38: 58.08
A40: 104790 DEMOLIÇÃO DE PISO DE CONCRETO SIMPLES, DE FORMA MECANIZADA COM MARTELETE, SEM REAPROVEITAMENTO. AF_09/2023 (M3)
A41: Equipamento Custo Horário | C41: FONTE | D41: UNID | E41: COEFICIENTE | F41: PREÇO UNITÁRIO | G41: TOTAL
A42: 90965 | B42: COMPRESSOR DE AR REBOCÁVEL, VAZÃO 89 PCM, PRESSÃO EFETIVA DE TRABALHO 102 PSI, MOTOR DIESEL, POTÊNCIA 20 CV - CHI DIURNO. AF_06/2015 | C42: SINAPI | D42: CHI | E42: 0.85917673 | F42: 8.73 | G42: 7.5
A43: 90964 | B43: COMPRESSOR DE AR REBOCÁVEL, VAZÃO 89 PCM, PRESSÃO EFETIVA DE TRABALHO 102 PSI, MOTOR DIESEL, POTÊNCIA 20 CV - CHP DIURNO. AF_06/2015 | C43: SINAPI | D43: CHP | E43: 1.1238193 | F43: 31.4 | G43: 35.28
A44: 5952 | B44: MARTELETE OU ROMPEDOR PNEUMÁTICO MANUAL, 28 KG, COM SILENCIADOR - CHI DIURNO. AF_07/2016 | C44: SINAPI | D44: CHI | E44: 0.85917673 | F44: 18.03 | G44: 15.49
...

Sheet CRONOGRAMA
A2: ITEM | B2: DESCRIÇÃO | C2: VALOR (R$) | D2: MÊS 1 | E2: MÊS 2 | F2: MÊS 3 | G2: Total parcela
A3: 1 | B3: SERVIÇOS PRELIMINARES | C3: 7571.29 | D3: 1 | G3: 1
D4: 7571.29 | G4: 7571.29
A5: 2 | B5: PAREDES E PAINEIS | C5: 10522.33 | D5: 1 | G5: 1
D6: 10522.33 | G6: 10522.33
A7: 3 | B7: COBERTURA | C7: 11488.43 | D7: 1 | G7: 1
D8: 11488.43 | G8: 11488.43
A9: 4 | B9: ESQUADRIAS | C9: 2980.11 | E9: 1 | G9: 1
E10: 2980.11 | G10: 2980.11
A11: 5 | B11: INSTALAÇÕES ELÉTRICAS | C11: 3147.13 | E11: 1 | G11: 1
E12: 3147.13 | G12: 3147.13
A13: 6 | B13: PISOS | C13: 45980.53 | E13: 1 | G13: 1
E14: 45980.53 | G14: 45980.53
A15: 7 | B15: REVESTIMENTOS INTERNOS | C15: 2750.12 | F15: 1 | G15: 1
F16: 2750.12 | G16: 2750.12
A17: 8 | B17: PINTURAS INTERNA | C17: 14897.97 | F17: 1 | G17: 1
F18: 14897.97 | G18: 14897.97
A19: 9 | B19: REVESTIMENTO EXTERNO | C19: 11593.36 | F19: 1 | G19: 1
F20: 11593.36 | G20: 11593.36
C21: 110931.27 | D21: 29582.05 | E21: 52107.77 | F21: 29241.45 | G21: 110931.27
D22: 29582.05 | E22: 81689.82 | F22: 110931.27

Sheet BDI
A1: COMPOSIÇÃO DO BDI
A3: COD | B3: DESCRIÇÃO | C3: %
B4: Benefício
A5: S + G | B5: Garantia/seguros | C5: 0.8
A6: L | B6: Lucro | C6: 6.6
B7: TOTAL | C7: 7.4
B8: Despesas Indiretas
A9: AC | B9: Administração central | C9: 3
A10: DF | B10: Despesas financeiras | C10: 1.23
A11: R | B11: Riscos | C11: 0.97
B12: TOTAL | C12: 5.2
A13: I | B13: Impostos
B14: IMPOSTOS (I), PIS, COFINS, CPRB, ISSQN | C14: 6.15
B15: TOTAL | C15: 6.15
B16: BDI = 20,47%

Sheet ENCARGOS SOCIAIS
A1: TABELA DOS ENCARGOS SOCIAIS
A3: COD | B3: DESCRIÇÃO | C3: HORISTA % | E3: MENSALISTA %
A5: A | B5: GRUPO A
A6: A1 | B6: INSS | C6: 20 | E6: 20
A7: A2 | B7: SESI | C7: 1.5 | E7: 1.5
A8: A3 | B8: SENAI | C8: 1 | E8: 1
A9: A4 | B9: INCRA | C9: 0.2 | E9: 0.2
A10: A5 | B10: SEBRAE | C10: 0.6 | E10: 0.6
A11: A6 | B11: Salário Educação | C11: 2.5 | E11: 2.5
A12: A7 | B12: Seguro Contra Acidentes de Trabalho | C12: 3 | E12: 3
A13: A8 | B13: FGTS | C13: 8 | E13: 8
A14: A9 | B14: SECONCI | C14: 0 | E14: 0
B15: TOTAL | C15: 36.8 | E15: 36.8
A17: B | B17: GRUPO B
A18: B1 | B18: Repouso Semanal Remunerado | C18: 18.03 | E18: 0
A19: B2 | B19: Feriados | C19: 4.31 | E19: 0
A20: B3 | B20: Auxílio - Enfermidade | C20: 0.85 | E20: 0.64
A21: B4 | B21: 13º Salário | C21: 11.06 | E21: 8.33
A22: B5 | B22: Licença Paternidade | C22: 0.06 | E22: 0.04
A23: B6 | B23: Faltas Justificadas | C23: 0.74 | E23: 0.56
A24: B7 | B24: Dias de Chuvas | C24: 2.06 | E24: 0
A25: B8 | B25: Auxílio Acidente de Trabalho | C25: 0.1 | E25: 0.08
A26: B9 | B26: Férias Gozadas | C26: 11.29 | E26: 8.51
A27: B10 | B27: Salário Maternidade | C27: 0.04 | E27: 0.03
B28: TOTAL | C28: 48.54 | E28: 18.19
A30: C | B30: GRUPO C
A31: C1 | B31: Aviso Prévio Indenizado | C31: 4.57 | E31: 3.45
A32: C2 | B32: Aviso Prévio Trabalhado | C32: 0.11 | E32: 0.08
A33: C3 | B33: Férias Indenizadas | C33: 3.31 | E33: 2.5
A34: C4 | B34: Depósito Rescisão Sem Justa Causa | C34: 2.61 | E34: 1.96
A35: C5 | B35: Indenização Adicional | C35: 0.38 | E35: 0.29
B36: TOTAL | C36: 10.98 | E36: 8.28
A38: D | B38: GRUPO D
A39: D1 | B39: Reincidência de Grupo A sobre Grupo B | C39: 17.86 | E39: 6.69
A40: D2 | B40: Reincidência de Grupo A sobre Aviso Prévio Trabalhado e Reincidência do FGTS sobre Aviso Prévio Indenizado | C40: 0.41 | E40: 0.31
B41: TOTAL | C41: 18.27 | E41: 7
B43: A + B + C + D = | C43: 114.59 | E43: 70.27
