Workbook
Name _______MDO1: [1]INSUMOS!$C$8
Name _______MDO2: [2]INSUMOS!$C$6
Name _______R: #REF!
Name ______MDO1: [1]INSUMOS!$C$8
Name ______MDO2: [2]INSUMOS!$C$6
Name ______R: #REF!
Name ______R: #REF!
Name ______rua1: #REF!
Name ______rua1: #REF!
Name _____MDO1: [1]INSUMOS!$C$8
Name _____MDO2: [2]INSUMOS!$C$6
Name _____R: #REF!
Name _____R: #REF!
Name _____rua1: #REF!
Name _____rua1: #REF!
Name ____MDO1: [1]INSUMOS!$C$8
Name ____MDO2: [2]INSUMOS!$C$6
Name ____R: #REF!
Name ____R: #REF!
Name ____rua1: #REF!
Name ____rua1: #REF!
Name ___MDO1: [1]INSUMOS!$C$8
Name ___MDO2: [2]INSUMOS!$C$6
Name ___R: #REF!
Name ___R: #REF!
Name ___rua1: #REF!
Name ___rua1: #REF!
Name __MDO1: [3]INSUMOS!$C$8
Name __MDO1: [3]INSUMOS!$C$8
Name __MDO2: [2]INSUMOS!$C$6
Name __R: #REF!
Name __R: #REF!
Name __rua1: #REF!
Name __rua1: #REF!
Name __xlnm.Print_Titles_2: #REF!
Name __xlnm.Print_Titles_2: #REF!
Name _MDO1: [3]INSUMOS!$C$8
Name _MDO1: [3]INSUMOS!$C$8
Name _MDO2: [2]INSUMOS!$C$6
Name _R: #REF!
Name _R: #REF!
Name _rua1: #REF!
Name _rua1: #REF!
Name A: #REF!
Name AA: [4]CUBACAO!#REF!
Name AA: [4]CUBACAO!#REF!
Name AAA: [4]CUBACAO!#REF!
Name AAA: [4]CUBACAO!#REF!
Name Ac: #REF!
Name Ac: #REF!
Name artFiscal: [5]DADOS!$D$23
Name ASDFASDFAS: #REF!
Name ASDFASDFAS: #REF!
Name BB: [4]CUBACAO!#REF!
Name BB: [4]CUBACAO!#REF!
Name BBB: [4]CUBACAO!#REF!
Name BBB: [4]CUBACAO!#REF!
Name bdi: [6]Orçamento!$J$10
Name bdi: [6]Orçamento!$J$10
Name BDIc: #REF!

Sheet BM-03
A1: ESTADO DA PARAÍBA
A2: PREFEITURA MUNICIPAL DE COREMAS | Q2: VALOR EDITAL | R2: R$ 1.252.370,60
A3: CONTRATO Nº 10004/2023 | Q3: VALOR C/DESC. | R3: =L236 -> 1249356.4
A4: OBRA: CONSTRUÇÃO DE UMA UNIDADE ESCOLAR DE 06 (SEIS) SALAS DE AULA PARA O MUNICÍPIO DE COREMAS-PB | J4: BDI = | K4: 0.25
A5: LOCAL: MUNICÍPIO DE COREMAS-PB | Q5: DESCONTO: | R5: 0.17
A6: BOLETIM DE MEDIÇÃO - BM-03
A7: ITEM | B7: CÓDIGO | C7: REFERÊNCIA | D7: DESCRIÇÃO | E7: ORIGEM | F7: UNID | G7: QUANTIDADES | K7: VALOR UNIT COM BDI | L7: VALORES TOTAIS
G8: LICITADA | H8: ACUMULADA ATÉ O PERÍODO | I8: MEDIDA NO PERÍODO | J8: ACUMULADA INCLUINDO O PERÍODO | L8: LICITADO | M8: ACUMULADO ATÉ O PERÍODO | N8: MEDIDO NO PERÍODO | O8: ACUMULADO INCLUINDO O PERÍODO
A9: 1 ETAPA 01: GERAL | L9: =SUM(L10,L16) -> 66229.186 | M9: =SUM(M10,M16) -> 21240.562 | N9: =SUM(N10,N16) -> 10942.107 | O9: =SUM(O10,O16) -> 32182.669 | P9: =IF(O9<>L9,O9/L9,"") -> 0.4859288
A10: 1.1 1 ADMINISTRACAO LOCAL | L10: =SUM(L11:L15) -> 64365.338 | M10: =SUM(M11:M15) -> 21240.562 | N10: =SUM(N11:N15) -> 10942.107 | O10: =SUM(O11:O15) -> 32182.669 | P10: =IF(O10<>L10,O10/L10,"") -> 0.5
A11: 1.1.1 | B11: 164471 | C11: O13221 | D11: ADMINSTRACAO LOCAL - PESSOAL | E11: SUPLAN | F11: UN | G11: 8 | H11: 2.64 | I11: ='MEMORIAL DE CÁLCULOS'!J11 -> 1.36 | J11: =H11+I11 -> 4 | K11: 4208.9549 | L11: =G11*K11 -> 33671.639 | M11: =H11*K11 -> 11111.641 | N11: =I11*K11 -> 5724.1787 | O11: =J11*K11 -> 16835.82 | P11: =IF(O11<>L11,O11/L11,"") -> 0.5 | V11: 5071.03 | W11: =V11-V11*$R$5 -> 4208.9549
A12: 1.1.2 | B12: 164472 | C12: O13221 | D12: ADMINISTRACAO LOCAL - DESPESAS GERAIS MENSAIS | E12: SUPLAN | F12: UN | G12: 8 | H12: 2.64 | I12: ='MEMORIAL DE CÁLCULOS'!J14 -> 1.36 | J12: =H12+I12 -> 4 | K12: 1588.6449 | L12: =G12*K12 -> 12709.159 | M12: =H12*K12 -> 4194.0225 | N12: =I12*K12 -> 2160.5571 | O12: =J12*K12 -> 6354.5796 | P12: =IF(O12<>L12,O12/L12,"") -> 0.5 | V12: 1914.03 | W12: =V12-V12*$R$5 -> 1588.6449
A13: 1.1.3 | B13: 164473 | C13: O13221 | D13: ADMINISTRACAO LOCAL - DESPESAS GERAIS FIXAS | E13: SUPLAN | F13: UN | G13: 1 | H13: 0.33 | I13: ='MEMORIAL DE CÁLCULOS'!J17 -> 0.17 | J13: =H13+I13 -> 0.5 | K13: 2489.2862 | L13: =G13*K13 -> 2489.2862 | M13: =H13*K13 -> 821.46445 | N13: =I13*K13 -> 423.17865 | O13: =J13*K13 -> 1244.6431 | P13: =IF(O13<>L13,O13/L13,"") -> 0.5 | V13: 2999.14 | W13: =V13-V13*$R$5 -> 2489.2862
A14: 1.1.4 | B14: 164474 | C14: O13221 | D14: ADMINISTRACAO LOCAL - VECULOS E EQUIPAMENTOS | E14: SUPLAN | F14: UN | G14: 8 | H14: 2.64 | I14: ='MEMORIAL DE CÁLCULOS'!J20 -> 1.36 | J14: =H14+I14 -> 4 | K14: 1279.8185 | L14: =G14*K14 -> 10238.548 | M14: =H14*K14 -> 3378.7208 | N14: =I14*K14 -> 1740.5532 | O14: =J14*K14 -> 5119.274 | P14: =IF(O14<>L14,O14/L14,"") -> 0.5 | V14: 1541.95 | W14: =V14-V14*$R$5 -> 1279.8185
A15: 1.1.5 | B15: 164475 | C15: O13221 | D15: ADMINISTRACAO LOCAL - MOVEIS E UTENSILIOS | E15: SUPLAN | F15: UN | G15: 1 | H15: 0.33 | I15: ='MEMORIAL DE CÁLCULOS'!J23 -> 0.17 | J15: =H15+I15 -> 0.5 | K15: 5256.7054 | L15: =G15*K15 -> 5256.7054 | M15: =H15*K15 -> 1734.7128 | N15: =I15*K15 -> 893.63992 | O15: =J15*K15 -> 2628.3527 | P15: =IF(O15<>L15,O15/L15,"") -> 0.5 | V15: 6333.38 | W15: =V15-V15*$R$5 -> 5256.7054
A16: 1.2 DIVERSOS | L16: =SUM(L17) -> 1863.848 | M16: =SUM(M17) -> 0 | N16: =SUM(N17) -> 0 | O16: =SUM(O17) -> 0 | P16: =IF(O16<>L16,O16/L16,"") -> 0
A17: 1.2.1 | B17: 164476 | D17: "AS BUILT" DO PROJETO ARQUITETONICO E DOS PROJETOS DE ENGENHARIA DE ESTRUTURAS E DE INSTALACOES ELETRICAS, INSTALACOES HIDRAULICAS E INSTALACOES SANITARIAS - ESCOLAS | E17: SINAPI | F17: UN | G17: 1 | H17: 0 | J17: =H17+I17 -> 0 | K17: 1863.848 | L17: =G17*K17 -> 1863.848 | M17: =H17*K17 -> 0 | N17: =I17*K17 -> 0 | O17: =J17*K17 -> 0 | P17: =IF(O17<>L17,O17/L17,"") -> 0 | V17: 2245.6 | W17: =V17-V17*$R$5 -> 1863.848
A18: 2 ETAPA 02: CONSTRUCAO DA ESCOLA | L18: =SUM(L19,L29,L33,L40,L55,L66,L79,L89,L98,L111,L122,L153,L162,L186,L197,) -> 1144166 | M18: =SUM(M19,M29,M33,M40,M55,M66,M79,M89,M98,M111,M122,M153,M162,M186,M197,) -> 354180.12 | N18: =SUM(N19,N29,N33,N40,N55,N66,N79,N89,N98,N111,N122,N153,N162,N186,N197,) -> 225472.35 | O18: =SUM(O19,O29,O33,O40,O55,O66,O79,O89,O98,O111,O122,O153,O162,O186,O197,) -> 579652.47 | P18: =IF(O18<>L18,O18/L18,"") -> 0.50661571
A19: 2.1 1 SERVICOS PRELIMINARES | L19: =SUM(L20:L28) -> 21969.068 | M19: =SUM(M20:M28) -> 20020.236 | N19: =SUM(N20:N28) -> 0 | O19: =SUM(O20:O28) -> 20020.236 | P19: =IF(O19<>L19,O19/L19,"") -> 0.91129202
A20: 2.1.1 | B20: 132583 | C20: 74209/001 | D20: PLACA DE OBRA EM CHAPA DE ACO GALVANIZADO | E20: SINAPI | F20: M2 | G20: 10 | H20: 10 | J20: =H20+I20 -> 10 | K20: 342.8979 | L20: =G20*K20 -> 3428.979 | M20: =H20*K20 -> 3428.979 | N20: =I20*K20 -> 0 | O20: =J20*K20 -> 3428.979 | P20: =IF(O20<>L20,O20/L20,"") | V20: 413.13 | W20: =V20-V20*$R$5 -> 342.8979
A21: 2.1.2 | B21: 163387 | C21: 74077/3 | D21: LOCACAO CONVENCIONAL DE OBRA, ATRAVES DE GABARITO DE TABUAS CORRIDAS PONTALETADAS, COM REAPROVEITAMENTO DE 3 VEZES - | E21: SINAPI | F21: M2 | G21: 771.45 | H21: 771.45 | J21: =H21+I21 -> 771.45 | K21: 4.9551 | L21: =G21*K21 -> 3822.6119 | M21: =H21*K21 -> 3822.6119 | N21: =I21*K21 -> 0 | O21: =J21*K21 -> 3822.6119 | P21: =IF(O21<>L21,O21/L21,"") | V21: 5.97 | W21: =V21-V21*$R$5 -> 4.9551
A22: 2.1.3 | B22: 137043 | C22: 73822/002 | D22: LIMPEZA MECANIZADA DE TERRENO COM REMOCAO DE CAMADA VEGETAL, UTILIZAND O MOTONIVELADORA | E22: SINAPI | F22: M2 | G22: 2000 | H22: 2000 | J22: =H22+I22 -> 2000 | K22: 0.2739 | L22: =G22*K22 -> 547.8 | M22: =H22*K22 -> 547.8 | N22: =I22*K22 -> 0 | O22: =J22*K22 -> 547.8 | P22: =IF(O22<>L22,O22/L22,"") | V22: 0.33 | W22: =V22-V22*$R$5 -> 0.2739
A23: 2.1.4 | B23: 163443 | C23: C2851 | D23: INSTALACOES PROVISORIAS DE AGUA, INCLUSIVE CAIXA DAGUA DE 1000L | E23: SINAPI | F23: UN | G23: 1 | H23: 1 | J23: =H23+I23 -> 1 | K23: 1390.1255 | L23: =G23*K23 -> 1390.1255 | M23: =H23*K23 -> 1390.1255 | N23: =I23*K23 -> 0 | O23: =J23*K23 -> 1390.1255 | P23: =IF(O23<>L23,O23/L23,"") | V23: 1674.85 | W23: =V23-V23*$R$5 -> 1390.1255
A24: 2.1.5 | B24: 163442 | C24: 11122/ORS | D24: ENTRADA DE ENERGIA ELETRICA MONOFASICA COM POSTE DE CONCRETO, INCLUSIVE CABEAMENTO, CAIXA DE PROTECAO PARA MEDIDOR E | E24: SINAPI | F24: UN | G24: 1 | H24: 0 | J24: =H24+I24 -> 0 | K24: 1506.3255 | L24: =G24*K24 -> 1506.3255 | M24: =H24*K24 -> 0 | N24: =I24*K24 -> 0 | O24: =J24*K24 -> 0 | P24: =IF(O24<>L24,O24/L24,"") -> 0 | V24: 1814.85 | W24: =V24-V24*$R$5 -> 1506.3255
A25: 2.1.6 | B25: 135723 | C25: 73658 | D25: LIGACAO DOMICILIAR DE ESGOTO DN 100MM, DA CASA ATE A CAIXA, COMPOSTO P OR 10,0M TUBO DE PVC ESGOTO PREDIAL DN 100MM E CAIXA DE ALVENARIA COM TAMPA DE CONCRETO - FORNECIMENTO E | E25: SINAPI | F25: UN | G25: 1 | H25: 0 | J25: =H25+I25 -> 0 | K25: 442.5062 | L25: =G25*K25 -> 442.5062 | M25: =H25*K25 -> 0 | N25: =I25*K25 -> 0 | O25: =J25*K25 -> 0 | P25: =IF(O25<>L25,O25/L25,"") -> 0 | V25: 533.14 | W25: =V25-V25*$R$5 -> 442.5062
A26: 2.1.7 | B26: 162175 | D26: LOCACAO DE CONTAINER 2,30 X 4,30 M, ALT. 2,50 M, P/ SANITARIO, C/ 5 BACIAS, 1 LAVATORIO E 4 MICTORIOS, INCLUSIVE TRANSP/CARGA/DESCARGA | E26: SUPLAN | F26: MÊS | G26: 0 | H26: 0 | J26: =H26+I26 -> 0 | K26: 654.9198 | L26: =G26*K26 -> 0 | M26: =H26*K26 -> 0 | N26: =I26*K26 -> 0 | O26: =J26*K26 -> 0 | P26: =IF(O26<>L26,O26/L26,"") | V26: 789.06 | W26: =V26-V26*$R$5 -> 654.9198
A27: 2.1.8 | B27: 163536 | D27: ALUGUEL CONTAINER/ESCRIT INCL INST ELET LARG=2,20 COMP=6,20M ALT=2,50M CHAPA ACO C/NERV TRAPEZ FORRO C/ISOLTERMO/ACUSTICO CHASSIS REFORC P I S O C O M P E N S N A V A L I N C T R A N S P / C A R G A / D E S C A R G A | E27: SINAPI | F27: MÊS | G27: 0 | H27: 0 | J27: =H27+I27 -> 0 | K27: 565.4375 | L27: =G27*K27 -> 0 | M27: =H27*K27 -> 0 | N27: =I27*K27 -> 0 | O27: =J27*K27 -> 0 | P27: =IF(O27<>L27,O27/L27,"") | V27: 681.25 | W27: =V27-V27*$R$5 -> 565.4375
A28: 2.1.9 | C28: 93206/SINAPI (ALTERADA) | D28: EXECUÇÃO DE DEPÓSITO EM CANTEIRO DE OBRA EM ALVENARIA | E28: SINAPI | F28: M2 | G28: 32 | H28: 32 | J28: =H28+I28 -> 32 | K28: 338.46 | L28: =G28*K28 -> 10830.72 | M28: =H28*K28 -> 10830.72 | N28: =I28*K28 -> 0 | O28: =J28*K28 -> 10830.72 | P28: =IF(O28<>L28,O28/L28,"")
A29: 2.2 2 MOVIMENTO DE TERRA | L29: =SUM(L30:L32) -> 173993.72 | M29: =SUM(M30:M32) -> 166157.8 | N29: =SUM(N30:N32) -> 7835.917 | O29: =SUM(O30:O32) -> 173993.72 | P29: =IF(O29<>L29,O29/L29,"")
A30: 2.2.1 | B30: 160239 | D30: ESCAVACAO MANUAL DE VALA EM MATERIAL DE QUALQUER CATEGORIA, EXCETO ROCHA COM PROFUNDIDADE ATE 2M. | E30: SINAPI | F30: M3 | G30: 225.25 | H30: 225.25 | J30: =H30+I30 -> 225.25 | K30: 63.1132 | L30: =G30*K30 -> 14216.248 | M30: =H30*K30 -> 14216.248 | N30: =I30*K30 -> 0 | O30: =J30*K30 -> 14216.248 | P30: =IF(O30<>L30,O30/L30,"") | V30: 76.04 | W30: =V30-V30*$R$5 -> 63.1132
A31: 2.2.2 | B31: 164368 | C31: 24824/SIN | D31: ATERRO DO CAIXAO SEM AQUISICAO DO MATERIAL (REATERRO MANUAL) | E31: SINAPI | F31: M3 | G31: 205.7 | H31: 205.7 | J31: =H31+I31 -> 205.7 | K31: 38.1717 | L31: =G31*K31 -> 7851.9187 | M31: =H31*K31 -> 7851.9187 | N31: =I31*K31 -> 0 | O31: =J31*K31 -> 7851.9187 | P31: =IF(O31<>L31,O31/L31,"") | V31: 45.99 | W31: =V31-V31*$R$5 -> 38.1717
A32: 2.2.3 | B32: 153622 | D32: ATERRO DO CAIXAO COM AQUISICAO DO MATERIAL/AREIA, APILOADO EM CAMADAS DE 0,20M | E32: SINAPI | F32: M3 | G32: 1072.37 | H32: 1017.06 | I32: ='MEMORIAL DE CÁLCULOS'!J28 -> 55.31 | J32: =H32+I32 -> 1072.37 | K32: 141.6727 | L32: =G32*K32 -> 151925.55 | M32: =H32*K32 -> 144089.64 | N32: =I32*K32 -> 7835.917 | O32: =J32*K32 -> 151925.55 | P32: =IF(O32<>L32,O32/L32,"") | V32: 170.69 | W32: =V32-V32*$R$5 -> 141.6727
A33: 2.3 3 INFRAESTRUTURA | L33: =SUM(L34:L39) -> 97254.846 | M33: =SUM(M34:M39) -> 87752.738 | N33: =SUM(N34:N39) -> 4440.2844 | O33: =SUM(O34:O39) -> 92193.022 | P33: =IF(O33<>L33,O33/L33,"") -> 0.94795299
A34: 2.3.1 | B34: 146934 | C34: 95467 | D34: EMBASAMENTO C/PEDRA ARGAMASSADA UTILIZANDO ARG.CIM/AREIA 1:4 | E34: SINAPI | F34: M3 | G34: 105.04 | H34: 105.04 | J34: =H34+I34 -> 105.04 | K34: 316.5952 | L34: =G34*K34 -> 33255.16 | M34: =H34*K34 -> 33255.16 | N34: =I34*K34 -> 0 | O34: =J34*K34 -> 33255.16 | P34: =IF(O34<>L34,O34/L34,"") | V34: 381.44 | W34: =V34-V34*$R$5 -> 316.5952
A35: 2.3.2 | B35: 160126 | D35: ALVENARIA DE 1 VEZ VEDACAO COM BLOCOS CERAMICO FURADOS 9 X 19 X 19 CM FUROS HORIZONTAIS, ESPESSURA DA PAREDE 19 CM, JUNTAS DE 10 MM COM ARGAMASSA TRACO 1:2:8 (CIMENTO, CAL E AREIA MEDIA) | E35: SINAPI | F35: M2 | G35: 451.79 | H35: 242.65 | I35: ='MEMORIAL DE CÁLCULOS'!J36 -> 97.73 | J35: =H35+I35 -> 340.38 | K35: 45.4342 | L35: =G35*K35 -> 20526.717 | M35: =H35*K35 -> 11024.609 | N35: =I35*K35 -> 4440.2844 | O35: =J35*K35 -> 15464.893 | P35: =IF(O35<>L35,O35/L35,"") -> 0.75340313 | V35: 54.74 | W35: =V35-V35*$R$5 -> 45.4342
A36: 2.3.3 | B36: 154476 | C36: 96616 | D36: LASTRO DE CONCRETO MAGRO, APLICADO EM BLOCOS DE COROAMENTO OU SAPATAS.AF_08/2017 | E36: SINAPI | F36: M3 | G36: 6.13 | H36: 6.13 | J36: =H36+I36 -> 6.13 | K36: 463.804 | L36: =G36*K36 -> 2843.1185 | M36: =H36*K36 -> 2843.1185 | N36: =I36*K36 -> 0 | O36: =J36*K36 -> 2843.1185 | P36: =IF(O36<>L36,O36/L36,"") | V36: 558.8 | W36: =V36-V36*$R$5 -> 463.804
A37: 2.3.4 | B37: 161024 | D37: CONCRETO ARMADO (PREPARO E LANCAMENTO)PARA SAPATAS COM FCK >= 25MPA, COM FORMA DE TABUA, COM APROVEI TAMENTO DE 2 VEZES, COM BETONEIRA - | E37: SINAPI | F37: M3 | G37: 19.55 | H37: 19.55 | J37: =H37+I37 -> 19.55 | K37: 1008.533 | L37: =G37*K37 -> 19716.82 | M37: =H37*K37 -> 19716.82 | N37: =I37*K37 -> 0 | O37: =J37*K37 -> 19716.82 | P37: =IF(O37<>L37,O37/L37,"") | V37: 1215.1 | W37: =V37-V37*$R$5 -> 1008.533
A38: 2.3.5 | B38: 161026 | D38: CONCRETO ARMADO (PREPARO E LANCAMENTO) PARA RADIER COM FCK>=25MPA, COM TABUA DE MADEIRA, COM APROVEITAMENTO DE 3 VEZES COM BETONEIRA - | E38: SINAPI | F38: M3 | G38: 15.2 | H38: 15.2 | J38: =H38+I38 -> 15.2 | K38: 1006.9477 | L38: =G38*K38 -> 15305.605 | M38: =H38*K38 -> 15305.605 | N38: =I38*K38 -> 0 | O38: =J38*K38 -> 15305.605 | P38: =IF(O38<>L38,O38/L38,"") | V38: 1213.19 | W38: =V38-V38*$R$5 -> 1006.9477
A39: 2.3.6 | C39: 98557 | D39: IMPERMEABILIZAÇÃO DE SUPERFÍCIE COM EMULSÃO ASFÁLTICA, 2 DEMÃOS AF_06/2018 | E39: SINAPI | F39: M2 | G39: 195.79 | H39: 195.79 | J39: =H39+I39 -> 195.79 | K39: 28.64 | L39: =G39*K39 -> 5607.4256 | M39: =H39*K39 -> 5607.4256 | N39: =I39*K39 -> 0 | O39: =J39*K39 -> 5607.4256 | P39: =IF(O39<>L39,O39/L39,"")
A40: 2.4 4 SUPER-ESTRUTURA | L40: =SUM(L41:L54) -> 201473.62 | M40: =SUM(M41:M54) -> 42615.483 | N40: =SUM(N41:N54) -> 144001.76 | O40: =SUM(O41:O54) -> 186617.25 | P40: =IF(O40<>L40,O40/L40,"") -> 0.92626146
...

Sheet MEMORIAL DE CÁLCULOS
A1: =[14]ORÇAMENTO!A1:J1 -> ESTADO DA PARAÍBA
A2: ESTADO DA PARAÍBA
A3: PREFEITURA MUNICIPAL DE COREMAS
A4: ='BM-03'!A3 -> CONTRATO Nº 10004/2023
A5: ='BM-03'!A4 -> OBRA: CONSTRUÇÃO DE UMA UNIDADE ESCOLAR DE 06 (SEIS) SALAS DE AULA PARA O MUNICÍPIO DE COREMAS-PB
A6: MEMORIAL DE CÁLCULOS - BM-03
A7: ITEM | B7: DESCRIÇÃO | C7: DADOS | G7: Descontos | I7: RESULTADO | K7: UN.
C8: Quantid. | D8: Comprim. (m) | E8: Largura (m) | F8: Altura (m) | G8: Descrição | H8: Valor | I8: PARCIAL | J8: GERAL
A9: 1 | B9: ETAPA 01: GERAL
A10: 1.1 | B10: ADMINISTRAÇÃO LOCAL
A11: ='BM-03'!A11 -> 1.1.1 | B11: ='BM-03'!D11 -> ADMINSTRACAO LOCAL - PESSOAL | J11: =ROUND(SUM(J12:J12),2) -> 1.36 | K11: ='BM-03'!F11 -> UN
B12: Proporcional ao valor da medição | C12: 1.36 | J12: =C12 -> 1.36
A14: ='BM-03'!A12 -> 1.1.2 | B14: ='BM-03'!D12 -> ADMINISTRACAO LOCAL - DESPESAS GERAIS MENSAIS | J14: =ROUND(SUM(J15:J15),2) -> 1.36 | K14: ='BM-03'!F12 -> UN
B15: Proporcional ao valor da medição | C15: 1.36 | J15: =C15 -> 1.36
A17: ='BM-03'!A13 -> 1.1.3 | B17: ='BM-03'!D13 -> ADMINISTRACAO LOCAL - DESPESAS GERAIS FIXAS | J17: =ROUND(SUM(J18:J18),2) -> 0.17 | K17: ='BM-03'!F13 -> UN
B18: Proporcional ao valor da medição | C18: 0.17 | J18: =C18 -> 0.17
A20: ='BM-03'!A14 -> 1.1.4 | B20: ='BM-03'!D14 -> ADMINISTRACAO LOCAL - VECULOS E EQUIPAMENTOS | J20: =ROUND(SUM(J21:J21),2) -> 1.36 | K20: ='BM-03'!F14 -> UN
B21: Proporcional ao valor da medição | C21: 1.36 | J21: =C21 -> 1.36
A23: ='BM-03'!A15 -> 1.1.5 | B23: ='BM-03'!D15 -> ADMINISTRACAO LOCAL - MOVEIS E UTENSILIOS | J23: =ROUND(SUM(J24:J24),2) -> 0.17 | K23: ='BM-03'!F15 -> UN
B24: Proporcional ao valor da medição | C24: 0.17 | J24: =C24 -> 0.17
A26: 2 | B26: ETAPA 02: CONSTRUÇÃO DA ESCOLA
A27: 2.2 | B27: MOVIMENTO DE TERRA
A28: ='BM-03'!A32 -> 2.2.3 | B28: ='BM-03'!D32 -> ATERRO DO CAIXAO COM AQUISICAO DO MATERIAL/AREIA, APILOADO EM CAMADAS DE 0,20M | J28: =ROUND(SUM(J29:J29),2) -> 55.31 | K28: ='BM-03'!F32 -> M3
B29: Aterro da área entre murada e escola, considerando uma média de 0,60m abaixo das calçadas de contorno, sendo medido em torno de 10% restantes: | J29: =0.1*(SUM(J30:J33)) -> 55.306612
B30: Lateral esquerda | C30: 1 | D30: 53.3 | E30: 8 | F30: 0.3 | I30: =D30*E30*F30 -> 127.92 | J30: =C30*I30 -> 127.92
B31: Lateral direita | C31: 1 | D31: 19.81 | E31: 1.8 | F31: 0.4 | I31: =D31*E31*F31 -> 14.2632 | J31: =C31*I31 -> 14.2632
B32: Fundos bloco pedagógico | C32: 1 | D32: 12.35 | E32: 5 | F32: 0.8 | I32: =D32*E32*F32 -> 49.4 | J32: =C32*I32 -> 49.4
B33: Área de recreação + fundos | C33: 1 | D33: 29.65 | E33: =8.3+5 -> 13.3 | F33: 0.91666667 | I33: =D33*E33*F33 -> 361.48292 | J33: =C33*I33 -> 361.48292
A35: 2.3 | B35: INFRAESTRUTURA
A36: ='BM-03'!A35 -> 2.3.2 | B36: ='BM-03'!D35 -> ALVENARIA DE 1 VEZ VEDACAO COM BLOCOS CERAMICO FURADOS 9 X 19 X 19 CM FUROS HORIZONTAIS, ESPESSURA DA PAREDE 19 CM, JUNTAS DE 10 MM COM ARGAMASSA TRACO 1:2:8 (CIMENTO, CAL E AREIA MEDIA) | J36: =ROUND(SUM(J37:J39),2) -> 97.73 | K36: ='BM-03'!F35 -> M2
B37: Embasamento recreio | C37: 2 | D37: 12 | F37: 0.91666667 | I37: =D37*F37 -> 11 | J37: =C37*I37 -> 22
C38: 5 | D38: 6 | F38: 0.91666667 | I38: =D38*F38 -> 5.5 | J38: =C38*I38 -> 27.5
B39: Embasamento adicional da murada na parte dos fundos para compensar o desnível do terreno | C39: 1 | D39: =31+24.29+5 -> 60.29 | F39: 0.8 | I39: =D39*F39 -> 48.232 | J39: =C39*I39 -> 48.232
A41: 2.4 | B41: SUPER-ESTRUTURA
A42: ='BM-03'!A41 -> 2.4.1 | B42: ='BM-03'!D41 -> CONCRETO ARMADO (PREPARO E LANCAMENTO) PARA VIGA COM FCK>=30MPA, COM FORMA EM CHAPA DE MADEIRA COM- P E N S A D A R E S I N A D A , C O M APROVEITAMENTO DE 3 VEZES COM BETONEIRA - | J42: =ROUND(SUM(J43:J43),2) -> 24.23 | K42: ='BM-03'!F41 -> M3
B43: Vigas térreo, conforme projeto estrutural (24,23 m³) | C43: =24.23 -> 24.23 | J43: =C43 -> 24.23
A45: ='BM-03'!A49 -> 2.4.9 | B45: ='BM-03'!D49 -> MONTAGEM E DESMONTAGEM DE FÔRMA DE LAJE MACIÇA COM ÁREA MÉDIA MAIOR QUE 20 M², PÉ-DIREITO SIMPLES, EM CHAPA DE MADEIRA COMPENSADA RESINADA, 2 UTILIZAÇÕES | J45: =ROUND(SUM(J46:J46),2) -> 560.03 | K45: ='BM-03'!F49 -> M2
B46: Conforme projeto estrutural | C46: 560.03 | J46: =C46 -> 560.03
A48: ='BM-03'!A50 -> 2.4.10 | B48: ='BM-03'!D50 -> ARMAÇÃO DE LAJE DE UMA ESTRUTURA CONVENCIONAL DE CONCRETO ARMADO EM UMA EDIFICAÇÃO TÉRREA OU SOBRADO UTILIZANDO AÇO CA-60 DE 5,0 MM - MONTAGEM. AF_12/2015 | J48: =ROUND(SUM(J49:J49),2) -> 8.8 | K48: ='BM-03'!F50 -> KG
B49: Conforme projeto estrutural | C49: 8.8 | J49: =C49 -> 8.8
...
