Workbook
Name \C: #REF!
Name \C: #REF!
Name \D: #REF!
Name \D: #REF!
Name \G: #REF!
Name \G: #REF!
Name \I: #REF!
Name \I: #REF!
Name \l: #REF!
Name \l: #REF!
Name \M: #REF!
Name \M: #REF!
Name \P: #REF!
Name \P: #REF!
Name \q: #REF!
Name \q: #REF!
Name \R: #REF!
Name \R: #REF!
Name \s: #REF!
Name \s: #REF!
Name \t: #REF!
Name \t: #REF!
Name \Y: #REF!
Name \Y: #REF!
Name _: #REF!
Name _: #REF!
Name _________sub1: #REF!
Name _________sub1: #REF!
Name _________sub3: #REF!
Name _________sub3: #REF!
Name ________R: #REF!
Name ________sub1: #REF!
Name ________sub1: #REF!
Name ________sub2: #REF!
Name ________sub3: #REF!
Name ________sub3: #REF!
Name ________sub4: #REF!
Name _______MDO1: #REF!
Name _______MDO2: #REF!
Name _______R: #REF!
Name _______R: #REF!
Name _______sub1: #REF!
Name _______sub1: #REF!
Name _______sub2: #REF!
Name _______sub2: #REF!
Name _______sub3: #REF!
Name _______sub3: #REF!
Name _______sub4: #REF!
Name _______sub4: #REF!
Name ______MDO1: #REF!
Name ______MDO1: #REF!
Name ______MDO2: #REF!
Name ______MDO2: #REF!
Name ______R: #REF!
Name ______R: #REF!
Name ______sub1: #REF!
Name ______sub1: #REF!
Name ______sub2: #REF!
Name ______sub2: #REF!
Name ______sub3: #REF!

Sheet capa
M3: (*) COLAR TIMBRE DA PREFEITURA
B7: ESTADO DA PARAÍBA
B8: PREFEITURA MUNICIPAL DE COREMAS
B21: PLANILHA ORÇAMENTÁRIA
C23: CONSTRUÇÃO DE QUADRA POLIESPORTIVA COM VESTIÁRIOS E BANHEIROS, NO MUNICÍPIO DE COREMAS/PB | M23: (*) PREENCHER OBJETO
C26: RECURSOS GOVERNO DO ESTADO | M26: (*) PREENCHER NÚMERO DE CONTRATO
C27: Prefeitura Municipal de Coremas - PB | M27: (*) PREENCHER MINISTÉRIO
G33: LCL PROJETOS DE ENGENHARIA
G34: Av. Flávio R. Coutinho, 500, Sala 601, Jd. Oceania
G35: João Pessoa - PB
G36: CEP: 58038-320
G37: Tel: 83 99924-4447
G38: Eng. Responsável: Lincoln Cartaxo de Lira Júnior
G39: CPF 068.978.614-05
G40: CREA 160 814 689 - 8

Sheet Dados_Intesidade
A1: Nome | B1: Latitude | C1: Longitude | D1: N* | E1: Período | F1: B | G1: n | H1: m | I1: K
A2: Antenor Navarro | B2: 6°44’ | C2: 38°27’ | D2: 30 | E2: (65-94) | F2: 15 | G2: 0.693 | H2: 0.161 | I2: 936
A3: Barra de Santa Rosa | B3: 6°43’ | C3: 36°04’ | D3: 17 | E3: (65-89) | F3: 16 | G3: 0.786 | H3: 0.277 | I3: 765
A4: Bonito de Santa Fé | B4: 7°19’ | C4: 38°31’ | D4: 15 | E4: (67-94) | F4: 10 | G4: 0.729 | H4: 0.181 | I4: 813
A5: Campina Grande | B5: 7°14’ | C5: 35°52’ | D5: 11 | E5: (66-89) | F5: 5 | G5: 0.596 | H5: 0.227 | I5: 334
A6: Catolé do Rocha | B6: 6°21’ | C6: 37°45’ | D6: 27 | E6: (63-92) | F6: 13 | G6: 0.566 | H6: 0.095 | I6: 708
A7: Guarabira | B7: 6°50’ | C7: 35°29’ | D7: 12 | E7: (65-81) | F7: 5 | G7: 0.536 | H7: 0.239 | I7: 246
A8: Taperoá | B8: 7°12’ | C8: 36°50’ | D8: 15 | E8: (63-93) | F8: 7 | G8: 0.497 | H8: 0.074 | I8: 342
A9: Teixeira | B9: 7°13’ | C9: 37°15’ | D9: 17 | E9: (63-85) | F9: 18 | G9: 0.604 | H9: 0.16 | I9: 877
A10: Seridó | B10: 6°51’ | C10: 36°25’ | D10: 16 | E10: (79-94) | F10: 8 | G10: 0.543 | H10: 0.168 | I10: 492
A11: Itaporanga | B11: 7°19’ | C11: 38°09’ | D11: 12 | E11: (65-83) | F11: 15 | G11: 0.58 | H11: 0.083 | I11: 527
A12: João Pessoa | B12: 7°08’ | C12: 34°53’ | D12: 6 | E12: (81-86) | F12: 10 | G12: 0.398 | H12: 0.087 | I12: 290
A13: Monteiro | B13: 7°52’ | C13: 37°07’ | D13: 9 | E13: (67-86) | F13: 15 | G13: 0.724 | H13: 0.295 | I13: 302
... A16: São Gonçalo | B16: 6°50’ | C16: 38°19’ | D16: 7 | E16: (81-87) | F16: 7 | G16: 0.651 | H16: 0.301 | I16: 352

Sheet Encargos
A1: ENCARGOS SOCIAIS
A3: Item | B3: Discriminação | C3: Horista | D3: Mensalista
A4: A | B4: ENCARGOS SOCIAIS BÁSICOS | C4: =SUM(C5:C13) -> 36.8 | D4: =SUM(D5:D13) -> 36.8
A5: A-1 | B5: INSS | C5: 20 | D5: 20
A6: A-2 | B6: SESI | C6: 1.5 | D6: 1.5
A7: A-3 | B7: SENAI | C7: 1 | D7: 1
A8: A-4 | B8: INCRA | C8: 0.2 | D8: 0.2
A9: A-5 | B9: SEBRAE | C9: 0.6 | D9: 0.6
A10: A-6 | B10: SALÁRIO EDUCAÇÃO | C10: 2.5 | D10: 2.5
A11: A-7 | B11: SEGURO CONTRA ACIDENTES DE TRABALHO | C11: 3 | D11: 3
A12: A-8 | B12: FGTS | C12: 8 | D12: 8
A13: A-9 | B13: SECONCI | C13: 0 | D13: 0
A14: B | B14: ENCARGOS SOCIAIS QUE RECEBEM AS INCIDÊNCIAS DE "A" | C14: =SUM(C15:C25) -> 50.51 | D14: =SUM(D15:D25) -> 20.28
A15: B-1 | B15: REPOUSO SEMANAL REMUNERADO | C15: 18.01 | D15: 0
A16: B-2 | B16: FERIADOS | C16: 4.3 | D16: 0
A17: B-3 | B17: AUXILIO - ENFERMIDADE | C17: 0.87 | D17: 0.67
A18: B-4 | B18: 13º SALARIO | C18: 10.78 | D18: 8.33
A19: B-5 | B19: LICENÇA PATERNIDADE | C19: 0.07 | D19: 0.06
A20: B-6 | B20: FALTAS JUSTIFICADAS | C20: 0.72 | D20: 0.56
A21: B-7 | B21: DIAS DE CHUVAS | C21: 1.98 | D21: -
A22: B-8 | B22: AUXILIO ACIDENTE DE TRABALHO | C22: 0.11 | D22: 0.08
A23: B-9 | B23: FÉRIAS GOZADAS | C23: 13.64 | D23: 10.55
A24: B-10 | B24: SALÁRIO MATERNIDADE | C24: 0.03 | D24: 0.03
A26: C | B26: ENCARGOS SOCIAIS QUE NÃO RECEBEM AS INCIDÊNCIAS DE "A" | C26: =SUM(C27:C32) -> 9.52 | D26: =SUM(D27:D32) -> 7.38
A27: C-1 | B27: AVISO PRÉVIO INDENIZADO | C27: 4.45 | D27: 3.45
A28: C-2 | B28: AVISO PRÉVIO TRABALHADO | C28: 0.1 | D28: 0.08
A29: C-3 | B29: FÉRIAS INDENIZADAS | C29: 0.5 | D29: 0.39
A30: C-4 | B30: DEPÓSITO RECISÃO SEM JUSTA CAUSA | C30: 4.1 | D30: 3.17
A31: C-5 | B31: INDENIZAÇÃO ADICIONAL | C31: 0.37 | D31: 0.29
A33: D | B33: TAXAS DE REINCIDÊNCIAS DE UM GRUPO SOBRE O OUTRO | C33: =SUM(C34:C37) -> 18.98 | D33: =SUM(D34:D37) -> 7.77
A34: D-1 | B34: REINCIDENCIA DE GRUPO A SOBRE GRUPO B | C34: 18.59 | D34: 7.46
A35: D-2 | B35: REINCIDENCIA DE GRUPO A SOBRE AVISO PRÉVIO TRABALHADO E REINCIDENCIA DO FGTS SOBRE AVISO PRÉVIO INDENIZADO | C35: 0.39 | D35: 0.31
B38: TOTAL GERAL | C38: =C33+C26+C14+C4 -> 115.81 | D38: =D33+D26+D14+D4 -> 72.23
A42: ENCARGOS SOCIAIS
A44: Item | B44: Discriminação | C44: Horista | D44: Mensalista
A45: A | B45: ENCARGOS SOCIAIS BÁSICOS | C45: =SUM(C46:C54) -> 16.8 | D45: =SUM(D46:D54) -> 16.8
A46: A-1 | B46: INSS | C46: 0 | D46: 0
A47: A-2 | B47: SESI | C47: 1.5 | D47: 1.5
A48: A-3 | B48: SENAI | C48: 1 | D48: 1
A49: A-4 | B49: INCRA | C49: 0.2 | D49: 0.2
...

Sheet BDI
H1: ESPORTE, CIDADANIA E DESENVOLVIMENTO
A3: (*) | B3: PROGRAMA: | C3: Esporte, Cidadania e Desenvolvimento
A4: (*) | B4: CONCEDENTE: | C4: =capa!C27 -> Prefeitura Municipal de Coremas - PB
A5: (*) | B5: CONVENENTE: | C5: Município de Coremas- PB
B6: CONTRATO: | C6: =capa!C26 -> RECURSOS GOVERNO DO ESTADO
B7: OBRA: | C7: =capa!C23 -> CONSTRUÇÃO DE QUADRA POLIESPORTIVA COM VESTIÁRIOS E BANHEIROS, NO MUNICÍPIO DE COREMAS/PB
A8: (*) | B8: REF. PREÇOS: | C8: SINAPI PB - 06/2025
B10: CÁLCULO DA BONIFICAÇÃO E DESPESAS INDIRETAS
B12: CÁLCULO DE BDI | D12: 1 - Edificações | G12: 2 - Rodovias, Ferrovias, Pistas de Aeroportos, Infra Viária Urbana | J12: 3 - Abastecimento de Água, Coleta de Esgoto | M12: 4 - Estações e Redes de Distribuição de Energia Elétrica | P12: 5 - Portuárias, Marítimas e Fluviais | S12: 6 - Fornecimento de Materiais e Equipamentos
B13: Item componente do BDI | C13: % Info | D13: 1ºQ | E13: Médio | F13: 3º Q | G13: 1ºQ | H13: Médio | I13: 3º Q | J13: 1ºQ | K13: Médio | L13: 3º Q | M13: 1ºQ | N13: Médio | O13: 3º Q | P13: 1ºQ | Q13: Médio | R13: 3º Q | S13: 1ºQ | T13: Médio | U13: 3º Q
B14: Administração Central ( AC ) | C14: 3 | D14: 3 | E14: 4 | F14: 5.5 | G14: 3.8 | H14: 4.01 | I14: 4.67 | J14: 3.43 | K14: 4.93 | L14: 6.71 | M14: 5.29 | N14: 5.92 | O14: 7.93 | P14: 4 | Q14: 5.52 | R14: 7.85 | S14: 1.5 | T14: 3.45 | U14: 4.49
B15: Seguro e Garantia (G) | C15: 0.8 | D15: 0.8 | E15: 0.8 | F15: 1 | G15: 0.32 | H15: 0.4 | I15: 0.74 | J15: 0.28 | K15: 0.49 | L15: 0.75 | M15: 0.25 | N15: 0.51 | O15: 0.56 | P15: 0.81 | Q15: 1.22 | R15: 1.99 | S15: 0.3 | T15: 0.48 | U15: 0.82
B16: Risco (R) | C16: 0.97 | D16: 0.97 | E16: 1.27 | F16: 1.27 | G16: 0.5 | H16: 0.56 | I16: 0.97 | J16: 1 | K16: 1.39 | L16: 1.74 | M16: 1 | N16: 1.48 | O16: 1.97 | P16: 1.46 | Q16: 2.32 | R16: 3.16 | S16: 0.56 | T16: 0.85 | U16: 0.89
B17: Despesas Financeiras (DF) | C17: 0.59 | D17: 0.59 | E17: 1.23 | F17: 1.39 | G17: 1.02 | H17: 1.11 | I17: 1.21 | J17: 0.94 | K17: 0.99 | L17: 1.17 | M17: 1.01 | N17: 1.07 | O17: 1.11 | P17: 0.94 | Q17: 1.02 | R17: 1.33 | S17: 0.85 | T17: 0.85 | U17: 1.11
B18: Lucro (L) | C18: 6.16 | D18: 6.16 | E18: 7.4 | F18: 8.96 | G18: 6.64 | H18: 7.3 | I18: 8.69 | J18: 6.74 | K18: 8.04 | L18: 9.4 | M18: 8 | N18: 8.31 | O18: 9.51 | P18: 7.14 | Q18: 8.4 | R18: 10.43 | S18: 3.5 | T18: 5.11 | U18: 6.22
B19: Impostos (I) - PIS, COFINS, CPRB, ISSQN | C19: =6.15+4.5 -> 10.65 | D19: Conforme Legislação Específica
B20: Observações | G20: VALORES DE BDI POR TIPO DE OBRA
B21: 1) Preencher apenas a coluna % Informado (Coluna C) | G21: Tipo de Obra | M21: 1ºQ | N21: Médio | O21: 3º Q
B22: 2) Os impostos (I) normalmente aplicáveis são: PIS (0,65%), COFINS (3,00%), ISS (2,50% município Coremas-PB). | G22: 1 - Edificações | M22: 20.34 | N22: 22.12 | O22: 25
G23: 2 - Rodovias, Ferrovias, Pistas de Aeroportos, Infra Viária Urbana | M23: 19.6 | N23: 20.97 | O23: 24.23
B24: 3) O cálculo do BDI se baseia na fórmula abaixo utilizada pelo Acórdão 2622/13 do TCU, conforme CE GEPAD 354/2013 de 17/10/2013. | G24: 3 - Abastecimento de Água, Coleta de Esgotos | M24: 20.76 | N24: 24.18 | O24: 26.44
G25: 4 - Estações e Redes de Distribuição de Energia Elétrica | M25: 24 | N25: 25.84 | O25: 27.86
G26: 5 - Portuárias, Marítimas e Fluviais | M26: 22.8 | N26: 27.48 | O26: 30.95
B27: Fórmula Utilizada: | G27: 6 - Fornecimento de Materiais e Equipamentos | M27: 11.1 | N27: 14.02 | O27: 16.8
B31: B.D.I = | C31: =ROUND(((1+(C14+C15+C16)/100)*((1+C17/100)*(1+C18/100))/(1-C19/100))-1,4) -> 0.2522
B32: Observações sobre os % informados no cálculo do BDI, neste caso:
B33: =C7 -> CONSTRUÇÃO DE QUADRA POLIESPORTIVA COM VESTIÁRIOS E BANHEIROS, NO MUNICÍPIO DE COREMAS/PB
B34: Os valores % informados se enquadram nos limites do Acordão 2622/2013-TCU-Plenário | U34: PROJETO: Lincoln Cartaxo de Lira Júnior – Eng° Civil CREA 160 814 689 - 8 – Tel. (83) 9 9924 4447
F36: ='Plan.Orçam.'!#REF! -> #REF! | I36: 99346.74 | K36: =F36-I36 -> #REF!

Sheet BDI-Fornecimento
H1: ESPORTE, CIDADANIA E DESENVOLVIMENTO
A3: (*) | B3: PROGRAMA: | C3: =BDI!C3 -> Esporte, Cidadania e Desenvolvimento
A4: (*) | B4: CONCEDENTE: | C4: =BDI!C4 -> Prefeitura Municipal de Coremas - PB
A5: (*) | B5: CONVENENTE: | C5: =BDI!C5 -> Município de Coremas- PB
B6: CONTRATO: | C6: =BDI!C6 -> RECURSOS GOVERNO DO ESTADO
B7: OBRA: | C7: =BDI!C7 -> CONSTRUÇÃO DE QUADRA POLIESPORTIVA COM VESTIÁRIOS E BANHEIROS, NO MUNICÍPIO DE COREMAS/PB
A8: (*) | B8: REF. PREÇOS: | C8: =BDI!C8 -> SINAPI PB - 06/2025
B10: CÁLCULO DA BONIFICAÇÃO E DESPESAS INDIRETAS - FORNECIMENTO
B12: CÁLCULO DE BDI | D12: 1 - Edificações | G12: 2 - Rodovias, Ferrovias, Pistas de Aeroportos, Infra Viária Urbana | J12: 3 - Abastecimento de Água, Coleta de Esgoto | M12: 4 - Estações e Redes de Distribuição de Energia Elétrica | P12: 5 - Portuárias, Marítimas e Fluviais | S12: 6 - Fornecimento de Materiais e Equipamentos
B13: Item componente do BDI | C13: % Info | D13: 1ºQ | E13: Médio | F13: 3º Q | G13: 1ºQ | H13: Médio | I13: 3º Q | J13: 1ºQ | K13: Médio | L13: 3º Q | M13: 1ºQ | N13: Médio | O13: 3º Q | P13: 1ºQ | Q13: Médio | R13: 3º Q | S13: 1ºQ | T13: Médio | U13: 3º Q
B14: Administração Central ( AC ) | C14: 4 | D14: 3 | E14: 4 | F14: 5.5 | G14: 3.8 | H14: 4.01 | I14: 4.67 | J14: 3.43 | K14: 4.93 | L14: 6.71 | M14: 5.29 | N14: 5.92 | O14: 7.93 | P14: 4 | Q14: 5.52 | R14: 7.85 | S14: 1.5 | T14: 3.45 | U14: 4.49
B15: Seguro e Garantia (G) | C15: =T15 -> 0.48 | D15: 0.8 | E15: 0.8 | F15: 1 | G15: 0.32 | H15: 0.4 | I15: 0.74 | J15: 0.28 | K15: 0.49 | L15: 0.75 | M15: 0.25 | N15: 0.51 | O15: 0.56 | P15: 0.81 | Q15: 1.22 | R15: 1.99 | S15: 0.3 | T15: 0.48 | U15: 0.82
B16: Risco (R) | C16: =T16 -> 0.85 | D16: 0.97 | E16: 1.27 | F16: 1.27 | G16: 0.5 | H16: 0.56 | I16: 0.97 | J16: 1 | K16: 1.39 | L16: 1.74 | M16: 1 | N16: 1.48 | O16: 1.97 | P16: 1.46 | Q16: 2.32 | R16: 3.16 | S16: 0.56 | T16: 0.85 | U16: 0.89
B17: Despesas Financeiras (DF) | C17: =T17 -> 0.85 | D17: 0.59 | E17: 1.23 | F17: 1.39 | G17: 1.02 | H17: 1.11 | I17: 1.21 | J17: 0.94 | K17: 0.99 | L17: 1.17 | M17: 1.01 | N17: 1.07 | O17: 1.11 | P17: 0.94 | Q17: 1.02 | R17: 1.33 | S17: 0.85 | T17: 0.85 | U17: 1.11
B18: Lucro (L) | C18: 5.9 | D18: 6.16 | E18: 7.4 | F18: 8.96 | G18: 6.64 | H18: 7.3 | I18: 8.69 | J18: 6.74 | K18: 8.04 | L18: 9.4 | M18: 8 | N18: 8.31 | O18: 9.51 | P18: 7.14 | Q18: 8.4 | R18: 10.43 | S18: 3.5 | T18: 5.11 | U18: 6.22
B19: Impostos (I) - PIS, COFINS | C19: =0.65+3 -> 3.65 | D19: Conforme Legislação Específica
B20: Observações | G20: VALORES DE BDI POR TIPO DE OBRA
B21: 1) Preencher apenas a coluna % Informado (Coluna C) | G21: Tipo de Obra | M21: 1ºQ | N21: Médio | O21: 3º Q
B22: 2) Os impostos (I) normalmente aplicáveis são: PIS (0,65%), COFINS (3,00%). | G22: 1 - Edificações | M22: 20.34 | N22: 22.12 | O22: 25
G23: 2 - Rodovias, Ferrovias, Pistas de Aeroportos, Infra Viária Urbana | M23: 19.6 | N23: 20.97 | O23: 24.23
B24: 3) O cálculo do BDI se baseia na fórmula abaixo utilizada pelo Acórdão 2622/13 do TCU, conforme CE GEPAD 354/2013 de 17/10/2013. | G24: 3 - Abastecimento de Água, Coleta de Esgotos | M24: 20.76 | N24: 24.18 | O24: 26.44
G25: 4 - Estações e Redes de Distribuição de Energia Elétrica | M25: 24 | N25: 25.84 | O25: 27.86
G26: 5 - Portuárias, Marítimas e Fluviais | M26: 22.8 | N26: 27.48 | O26: 30.95
B27: Fórmula Utilizada: | G27: 6 - Fornecimento de Materiais e Equipamentos | M27: 11.1 | N27: 14.02 | O27: 16.8
B31: B.D.I = | C31: =ROUND(((1+(C14+C15+C16)/100)*((1+C17/100)*(1+C18/100))/(1-C19/100))-1,4) -> 0.1675
B32: Observações sobre os % informados no cálculo do BDI, neste caso:
B33: =C7 -> CONSTRUÇÃO DE QUADRA POLIESPORTIVA COM VESTIÁRIOS E BANHEIROS, NO MUNICÍPIO DE COREMAS/PB
B34: Os valores % informados se enquadram nos limites do Acordão 2622/2013-TCU-Plenário (CPRB desconsiderado) | U34: PROJETO: Lincoln Cartaxo de Lira Júnior – Eng° Civil CREA 160 814 689 - 8 – Tel. (83) 9 9924 4447
F36: ='Plan.Orçam.'!#REF! -> #REF! | I36: 99346.74 | K36: =F36-I36 -> #REF!

Sheet Cotação
B2: PROGRAMA: | C2: =Composição!D2 -> Esporte, Cidadania e Desenvolvimento
B3: CONCEDENTE: | C3: =Composição!D3 -> Prefeitura Municipal de Coremas - PB
B4: CONVENENTE: | C4: =Composição!D4 -> Município de Coremas- PB
B5: CONTRATO: | C5: =Composição!D5 -> RECURSOS GOVERNO DO ESTADO
B6: OBRA: | C6: =Composição!D6 -> CONSTRUÇÃO DE QUADRA POLIESPORTIVA COM VESTIÁRIOS E BANHEIROS, NO MUNICÍPIO DE COREMAS/PB
B7: REF. PREÇOS: | C7: =Composição!D7 -> SINAPI PB - 06/2025
B9: COTAÇÃO DE INSUMOS (MEDIANA)
B11: ITEM | C11: DESCRIÇÃO/FONTE | D11: TIPO | E11: UND | F11: CUSTO
B12: 1 | C12: PISO PODOTATIL DE CONCRETO - DIRECIONAL E ALERTA, 30 X 30 CM [MEDIANA] | E12: M2 | F12: =MEDIAN(F13:F15) -> 48
B13: =CONCATENATE(B12,".1") -> 1.1 | C13: IAC BLOCOS E PISOS (CNPJ: 15.170.465/0001-68) | E13: M2 | F13: 44
B14: =CONCATENATE(B12,".2") -> 1.2 | C14: CONSTRUFACIL COMERCIO DE MATERIAIS DE CONSTRUCAO EIRELI - ME (CNPJ 04.376.116/0001-80) | E14: M2 | F14: 64
B15: =CONCATENATE(B12,".3") -> 1.3 | C15: INTERBLOCK (CNPJ: 11.803.338/0001-06) | E15: M2 | F15: 48

Sheet Composição
B2: PROGRAMA: | D2: =BDI!C3 -> Esporte, Cidadania e Desenvolvimento
B3: CONCEDENTE: | D3: =BDI!C4 -> Prefeitura Municipal de Coremas - PB
B4: CONVENENTE: | D4: =BDI!C5 -> Município de Coremas- PB
B5: CONTRATO: | D5: =BDI!C6 -> RECURSOS GOVERNO DO ESTADO
B6: OBRA: | D6: =BDI!C7 -> CONSTRUÇÃO DE QUADRA POLIESPORTIVA COM VESTIÁRIOS E BANHEIROS, NO MUNICÍPIO DE COREMAS/PB
B7: REF. PREÇOS: | D7: =BDI!C8 -> SINAPI PB - 06/2025
B9: COMPOSIÇÃO DE CUSTOS
B11: ITEM | C11: FONTE | D11: TIPO | E11: CÓD | F11: Descrição da Composição | G11: Unid | H11: Quant | I11: Custo Unit, | J11: Custo Total
A12: =COUNTIF('Plan.Orçam.'!E:E,Composição!B12) -> 1 | B12: 1 | C12: PLACA DE OBRA EM CHAPA DE ACO GALVANIZADO [ADAPTADO SINAPI 74209/01] | G12: M2 | I12: =SUM(J13:J19) -> 497.93
B13: =CONCATENATE(B12,".1") -> 1.1 | C13: SINAPI PB | D13: COMPOSIÇÃO | E13: 88262 | F13: =IF(C13="COMPOSIÇÃO",VLOOKUP(E13,B:J,2,FALSE),IF($D13="COMPOSIÇÃO",VLOOKUP(Composição!$E13,'Sinapi_Comp-06.2023'!$G:$L,2,FALSE),VLOOKUP($E13,'Sinapi_Insum-06.2023'!$A:$E,2,FALSE))) -> CARPINTEIRO DE FORMAS COM ENCARGOS COMPLEMENTARES | G13: =IF(C13="COMPOSIÇÃO",VLOOKUP(E13,B:J,6,FALSE),IF($D13="COMPOSIÇÃO",VLOOKUP(Composição!$E13,'Sinapi_Comp-06.2023'!$G:$L,3,FALSE),VLOOKUP($E13,'Sinapi_Insum-06.2023'!$A:$E,3,FALSE))) -> H | H13: 1 | I13: =IF(C13="COMPOSIÇÃO",VLOOKUP(E13,B:J,8,FALSE),IF(C13="COTAÇÃO",VLOOKUP(E13,Cotação!B:F,7,FALSE),IF($D13="COMPOSIÇÃO",VLOOKUP(Composição!$E13,'Sinapi_Comp-06.2023'!$G:$L,5,FALSE),VLOOKUP($E13,'Sinapi_Insum-06.2023'!$A:$E,5,FALSE)))) -> 22.51 | J13: =ROUND(I13*H13,2) -> 22.51
B14: =CONCATENATE(B12,".2") -> 1.2 | C14: SINAPI PB | D14: COMPOSIÇÃO | E14: 88316 | F14: =IF(C14="COMPOSIÇÃO",VLOOKUP(E14,B:J,2,FALSE),IF($D14="COMPOSIÇÃO",VLOOKUP(Composição!$E14,'Sinapi_Comp-06.2023'!$G:$L,2,FALSE),VLOOKUP($E14,'Sinapi_Insum-06.2023'!$A:$E,2,FALSE))) -> SERVENTE COM ENCARGOS COMPLEMENTARES | G14: =IF(C14="COMPOSIÇÃO",VLOOKUP(E14,B:J,6,FALSE),IF($D14="COMPOSIÇÃO",VLOOKUP(Composição!$E14,'Sinapi_Comp-06.2023'!$G:$L,3,FALSE),VLOOKUP($E14,'Sinapi_Insum-06.2023'!$A:$E,3,FALSE))) -> H | H14: 2 | I14: =IF(C14="COMPOSIÇÃO",VLOOKUP(E14,B:J,8,FALSE),IF(C14="COTAÇÃO",VLOOKUP(E14,Cotação!B:F,7,FALSE),IF($D14="COMPOSIÇÃO",VLOOKUP(Composição!$E14,'Sinapi_Comp-06.2023'!$G:$L,5,FALSE),VLOOKUP($E14,'Sinapi_Insum-06.2023'!$A:$E,5,FALSE)))) -> 18.67 | J14: =ROUND(I14*H14,2) -> 37.34
B15: =CONCATENATE(B12,".3") -> 1.3 | C15: SINAPI PB | D15: COMPOSIÇÃO | E15: 94962 | F15: =IF(C15="COMPOSIÇÃO",VLOOKUP(E15,B:J,2,FALSE),IF($D15="COMPOSIÇÃO",VLOOKUP(Composição!$E15,'Sinapi_Comp-06.2023'!$G:$L,2,FALSE),VLOOKUP($E15,'Sinapi_Insum-06.2023'!$A:$E,2,FALSE))) -> CONCRETO MAGRO PARA LASTRO, TRAÇO 1:4,5:4,5 (EM MASSA SECA DE CIMENTO/ AREIA MÉDIA/ BRITA 1) - PREPARO MECÂNICO COM BETONEIRA 400 L. AF_05/2021 | G15: =IF(C15="COMPOSIÇÃO",VLOOKUP(E15,B:J,6,FALSE),IF($D15="COMPOSIÇÃO",VLOOKUP(Composição!$E15,'Sinapi_Comp-06.2023'!$G:$L,3,FALSE),VLOOKUP($E15,'Sinapi_Insum-06.2023'!$A:$E,3,FALSE))) -> M3 | H15: 0.01 | I15: =IF(C15="COMPOSIÇÃO",VLOOKUP(E15,B:J,8,FALSE),IF(C15="COTAÇÃO",VLOOKUP(E15,Cotação!B:F,7,FALSE),IF($D15="COMPOSIÇÃO",VLOOKUP(Composição!$E15,'Sinapi_Comp-06.2023'!$G:$L,5,FALSE),VLOOKUP($E15,'Sinapi_Insum-06.2023'!$A:$E,5,FALSE)))) -> 389.61 | J15: =ROUND(I15*H15,2) -> 3.9
B16: =CONCATENATE(B12,".4") -> 1.4 | C16: SINAPI PB | D16: INSUMO | E16: 4417 | F16: =IF(C16="COMPOSIÇÃO",VLOOKUP(E16,B:J,2,FALSE),IF($D16="COMPOSIÇÃO",VLOOKUP(Composição!$E16,'Sinapi_Comp-06.2023'!$G:$L,2,FALSE),VLOOKUP($E16,'Sinapi_Insum-06.2023'!$A:$E,2,FALSE))) -> SARRAFO NAO APARELHADO *2,5 X 7* CM, EM MACARANDUBA/MASSARANDUBA, ANGELIM, PEROBA-ROSA OU EQUIVALENTE DA REGIAO - BRUTA | G16: =IF(C16="COMPOSIÇÃO",VLOOKUP(E16,B:J,6,FALSE),IF($D16="COMPOSIÇÃO",VLOOKUP(Composição!$E16,'Sinapi_Comp-06.2023'!$G:$L,3,FALSE),VLOOKUP($E16,'Sinapi_Insum-06.2023'!$A:$E,3,FALSE))) -> M | H16: 1 | I16: =IF(C16="COMPOSIÇÃO",VLOOKUP(E16,B:J,8,FALSE),IF(C16="COTAÇÃO",VLOOKUP(E16,Cotação!B:F,7,FALSE),IF($D16="COMPOSIÇÃO",VLOOKUP(Composição!$E16,'Sinapi_Comp-06.2023'!$G:$L,5,FALSE),VLOOKUP($E16,'Sinapi_Insum-06.2023'!$A:$E,5,FALSE)))) -> 6.21 | J16: =ROUND(I16*H16,2) -> 6.21
B17: =CONCATENATE(B12,".5") -> 1.5 | C17: SINAPI PB | D17: INSUMO | E17: 4491 | F17: =IF(C17="COMPOSIÇÃO",VLOOKUP(E17,B:J,2,FALSE),IF($D17="COMPOSIÇÃO",VLOOKUP(Composição!$E17,'Sinapi_Comp-06.2023'!$G:$L,2,FALSE),VLOOKUP($E17,'Sinapi_Insum-06.2023'!$A:$E,2,FALSE))) -> PONTALETE *7,5 X 7,5* CM EM PINUS, MISTA OU EQUIVALENTE DA REGIAO - BRUTA | G17: =IF(C17="COMPOSIÇÃO",VLOOKUP(E17,B:J,6,FALSE),IF($D17="COMPOSIÇÃO",VLOOKUP(Composição!$E17,'Sinapi_Comp-06.2023'!$G:$L,3,FALSE),VLOOKUP($E17,'Sinapi_Insum-06.2023'!$A:$E,3,FALSE))) -> M | H17: 4 | I17: =IF(C17="COMPOSIÇÃO",VLOOKUP(E17,B:J,8,FALSE),IF(C17="COTAÇÃO",VLOOKUP(E17,Cotação!B:F,7,FALSE),IF($D17="COMPOSIÇÃO",VLOOKUP(Composição!$E17,'Sinapi_Comp-06.2023'!$G:$L,5,FALSE),VLOOKUP($E17,'Sinapi_Insum-06.2023'!$A:$E,5,FALSE)))) -> 12.03 | J17: =ROUND(I17*H17,2) -> 48.12
B18: =CONCATENATE(B12,".6") -> 1.6 | C18: SINAPI PB | D18: INSUMO | E18: 4813 | F18: =IF(C18="COMPOSIÇÃO",VLOOKUP(E18,B:J,2,FALSE),IF($D18="COMPOSIÇÃO",VLOOKUP(Composição!$E18,'Sinapi_Comp-06.2023'!$G:$L,2,FALSE),VLOOKUP($E18,'Sinapi_Insum-06.2023'!$A:$E,2,FALSE))) -> PLACA DE OBRA (PARA CONSTRUCAO CIVIL) EM CHAPA GALVANIZADA *N. 22*, ADESIVADA, DE *2,4 X 1,2* M (SEM POSTES PARA FIXACAO) | G18: =IF(C18="COMPOSIÇÃO",VLOOKUP(E18,B:J,6,FALSE),IF($D18="COMPOSIÇÃO",VLOOKUP(Composição!$E18,'Sinapi_Comp-06.2023'!$G:$L,3,FALSE),VLOOKUP($E18,'Sinapi_Insum-06.2023'!$A:$E,3,FALSE))) -> M2 | H18: 1 | I18: =IF(C18="COMPOSIÇÃO",VLOOKUP(E18,B:J,8,FALSE),IF(C18="COTAÇÃO",VLOOKUP(E18,Cotação!B:F,7,FALSE),IF($D18="COMPOSIÇÃO",VLOOKUP(Composição!$E18,'Sinapi_Comp-06.2023'!$G:$L,5,FALSE),VLOOKUP($E18,'Sinapi_Insum-06.2023'!$A:$E,5,FALSE)))) -> 377.5 | J18: =ROUND(I18*H18,2) -> 377.5
B19: =CONCATENATE(B12,".7") -> 1.7 | C19: SINAPI PB | D19: INSUMO | E19: 5075 | F19: =IF(C19="COMPOSIÇÃO",VLOOKUP(E19,B:J,2,FALSE),IF($D19="COMPOSIÇÃO",VLOOKUP(Composição!$E19,'Sinapi_Comp-06.2023'!$G:$L,2,FALSE),VLOOKUP($E19,'Sinapi_Insum-06.2023'!$A:$E,2,FALSE))) -> PREGO DE ACO POLIDO COM CABECA 18 X 30 (2 3/4 X 10) | G19: =IF(C19="COMPOSIÇÃO",VLOOKUP(E19,B:J,6,FALSE),IF($D19="COMPOSIÇÃO",VLOOKUP(Composição!$E19,'Sinapi_Comp-06.2023'!$G:$L,3,FALSE),VLOOKUP($E19,'Sinapi_Insum-06.2023'!$A:$E,3,FALSE))) -> KG | H19: 0.11 | I19: =IF(C19="COMPOSIÇÃO",VLOOKUP(E19,B:J,8,FALSE),IF(C19="COTAÇÃO",VLOOKUP(E19,Cotação!B:F,7,FALSE),IF($D19="COMPOSIÇÃO",VLOOKUP(Composição!$E19,'Sinapi_Comp-06.2023'!$G:$L,5,FALSE),VLOOKUP($E19,'Sinapi_Insum-06.2023'!$A:$E,5,FALSE)))) -> 21.36 | J19: =ROUND(I19*H19,2) -> 2.35
A20: =COUNTIF('Plan.Orçam.'!E:E,Composição!B20) -> 1 | B20: 2 | C20: =UPPER("Piso tátil direcional e/ou alerta, de concreto, na cor natural, p/deficientes visuais, dimensões 25x25cm, aplicado com argamassa industrializada ac-ii, rejuntado, exclusive regularização de base (ADAPTADO DE 09418/ORSE)") -> PISO TÁTIL DIRECIONAL E/OU ALERTA, DE CONCRETO, NA COR NATURAL, P/DEFICIENTES VISUAIS, DIMENSÕES 25X25CM, APLICADO COM ARGAMASSA INDUSTRIALIZADA AC-II, REJUNTADO, EXCLUSIVE REGULARIZAÇÃO DE BASE (ADAPTADO DE 09418/ORSE) | G20: M2 | I20: =SUM(J21:J25) -> 90.74
B21: =CONCATENATE(B20,".1") -> 2.1 | C21: SINAPI PB | D21: INSUMO | E21: 34357 | F21: =IF(C21="COMPOSIÇÃO",VLOOKUP(E21,B:J,2,FALSE),IF($D21="COMPOSIÇÃO",VLOOKUP(Composição!$E21,'Sinapi_Comp-06.2023'!$G:$L,2,FALSE),VLOOKUP($E21,'Sinapi_Insum-06.2023'!$A:$E,2,FALSE))) -> REJUNTE CIMENTICIO, QUALQUER COR | G21: =IF(C21="COMPOSIÇÃO",VLOOKUP(E21,B:J,6,FALSE),IF($D21="COMPOSIÇÃO",VLOOKUP(Composição!$E21,'Sinapi_Comp-06.2023'!$G:$L,3,FALSE),VLOOKUP($E21,'Sinapi_Insum-06.2023'!$A:$E,3,FALSE))) -> KG | H21: 0.52 | I21: =IF(C21="COMPOSIÇÃO",VLOOKUP(E21,B:J,8,FALSE),IF(C21="COTAÇÃO",VLOOKUP(E21,Cotação!B:F,7,FALSE),IF($D21="COMPOSIÇÃO",VLOOKUP(Composição!$E21,'Sinapi_Comp-06.2023'!$G:$L,5,FALSE),VLOOKUP($E21,'Sinapi_Insum-06.2023'!$A:$E,5,FALSE)))) -> 5.05 | J21: =ROUND(I21*H21,2) -> 2.63
B22: =CONCATENATE(B20,".2") -> 2.2 | C22: SINAPI PB | D22: INSUMO | E22: 371 | F22: =IF(C22="COMPOSIÇÃO",VLOOKUP(E22,B:J,2,FALSE),IF($D22="COMPOSIÇÃO",VLOOKUP(Composição!$E22,'Sinapi_Comp-06.2023'!$G:$L,2,FALSE),VLOOKUP($E22,'Sinapi_Insum-06.2023'!$A:$E,2,FALSE))) -> ARGAMASSA INDUSTRIALIZADA MULTIUSO, PARA REVESTIMENTO INTERNO E EXTERNO E ASSENTAMENTO DE BLOCOS DIVERSOS | G22: =IF(C22="COMPOSIÇÃO",VLOOKUP(E22,B:J,6,FALSE),IF($D22="COMPOSIÇÃO",VLOOKUP(Composição!$E22,'Sinapi_Comp-06.2023'!$G:$L,3,FALSE),VLOOKUP($E22,'Sinapi_Insum-06.2023'!$A:$E,3,FALSE))) -> KG | H22: 4 | I22: =IF(C22="COMPOSIÇÃO",VLOOKUP(E22,B:J,8,FALSE),IF(C22="COTAÇÃO",VLOOKUP(E22,Cotação!B:F,7,FALSE),IF($D22="COMPOSIÇÃO",VLOOKUP(Composição!$E22,'Sinapi_Comp-06.2023'!$G:$L,5,FALSE),VLOOKUP($E22,'Sinapi_Insum-06.2023'!$A:$E,5,FALSE)))) -> 0.94 | J22: =ROUND(I22*H22,2) -> 3.76
B23: =CONCATENATE(B20,".3") -> 2.3 | C23: MERCADO | D23: COTAÇÃO | E23: =Cotação!B12 -> 1 | F23: =Cotação!C12 -> PISO PODOTATIL DE CONCRETO - DIRECIONAL E ALERTA, 30 X 30 CM [MEDIANA] | G23: =Cotação!E12 -> M2 | H23: 1.05 | I23: =Cotação!F12 -> 48 | J23: =ROUND(I23*H23,2) -> 50.4
B24: =CONCATENATE(B20,".4") -> 2.4 | C24: SINAPI PB | D24: COMPOSIÇÃO | E24: 88309 | F24: =IF(C24="COMPOSIÇÃO",VLOOKUP(E24,B:J,2,FALSE),IF($D24="COMPOSIÇÃO",VLOOKUP(Composição!$E24,'Sinapi_Comp-06.2023'!$G:$L,2,FALSE),VLOOKUP($E24,'Sinapi_Insum-06.2023'!$A:$E,2,FALSE))) -> PEDREIRO COM ENCARGOS COMPLEMENTARES | G24: =IF(C24="COMPOSIÇÃO",VLOOKUP(E24,B:J,6,FALSE),IF($D24="COMPOSIÇÃO",VLOOKUP(Composição!$E24,'Sinapi_Comp-06.2023'!$G:$L,3,FALSE),VLOOKUP($E24,'Sinapi_Insum-06.2023'!$A:$E,3,FALSE))) -> H | H24: 0.5 | I24: =IF(C24="COMPOSIÇÃO",VLOOKUP(E24,B:J,8,FALSE),IF(C24="COTAÇÃO",VLOOKUP(E24,Cotação!B:F,7,FALSE),IF($D24="COMPOSIÇÃO",VLOOKUP(Composição!$E24,'Sinapi_Comp-06.2023'!$G:$L,5,FALSE),VLOOKUP($E24,'Sinapi_Insum-06.2023'!$A:$E,5,FALSE)))) -> 23.1 | J24: =ROUND(I24*H24,2) -> 11.55
B25: =CONCATENATE(B20,".5") -> 2.5 | C25: SINAPI PB | D25: COMPOSIÇÃO | E25: 88316 | F25: =Cotação!C12 -> PISO PODOTATIL DE CONCRETO - DIRECIONAL E ALERTA, 30 X 30 CM [MEDIANA] | G25: =IF(C25="COMPOSIÇÃO",VLOOKUP(E25,B:J,6,FALSE),IF($D25="COMPOSIÇÃO",VLOOKUP(Composição!$E25,'Sinapi_Comp-06.2023'!$G:$L,3,FALSE),VLOOKUP($E25,'Sinapi_Insum-06.2023'!$A:$E,3,FALSE))) -> H | H25: 1.2 | I25: =IF(C25="COMPOSIÇÃO",VLOOKUP(E25,B:J,8,FALSE),IF(C25="COTAÇÃO",VLOOKUP(E25,Cotação!B:F,7,FALSE),IF($D25="COMPOSIÇÃO",VLOOKUP(Composição!$E25,'Sinapi_Comp-06.2023'!$G:$L,5,FALSE),VLOOKUP($E25,'Sinapi_Insum-06.2023'!$A:$E,5,FALSE)))) -> 18.67 | J25: =ROUND(I25*H25,2) -> 22.4
A26: =COUNTIF('Plan.Orçam.'!E:E,Composição!B26) -> 1 | B26: 3 | C26: ESTRUTURA METÁLICA MÓVEL PARA TABELA EM AÇO COM ARO PARA BASQUETE, PADRÃO OFICIAL, EM TUBO GALVANIZADO D=5" - INSTALADA (ADAPTADO DE ORSE 2419)") | G26: UN | I26: =SUM(J27:J30) -> 6887.88
B27: =CONCATENATE(B26,".1") -> 3.1 | C27: ORSE | D27: INSUMO | E27: 206 | F27: ARO PARA CESTA BASQUETE STANDART D=45 CM (COD. 4001) | G27: PAR | H27: 1 | I27: 488.82 | J27: =ROUND(I27*H27,2) -> 488.82
B28: =CONCATENATE(B26,".2") -> 3.2 | C28: ORSE | D28: INSUMO | E28: 932 | F28: ESTRUTURA / SUPORTE OFICIAL P/ TABELA DE BASQUETE EM TUBO AÇO GALVANIZADO D=5" H=3,05M PISO ARO, PINTURA SINTÉTICA, FORNECIMENTO E INSTALAÇÃO | G28: PAR | H28: 1 | I28: 3432.32 | J28: =ROUND(I28*H28,2) -> 3432.32
B29: =CONCATENATE(B26,".3") -> 3.3 | C29: ORSE | D29: INSUMO | E29: 1929 | F29: REDE PARA CESTA BASQUETE SEDA FIO 3 MM, MEDINDO 45X45 CM (COD. 2019) | G29: PAR | H29: 1 | I29: 46.65 | J29: =ROUND(I29*H29,2) -> 46.65
B30: =CONCATENATE(B26,".4") -> 3.4 | C30: ORSE | D30: INSUMO | E30: 4811 | F30: TABELA PARA BASQUETE OFICIAL EM CHAPA METÁLICA MEDINDO 1,80X1,05 (COD. 4006) | G30: PAR | H30: 1 | I30: 2920.09 | J30: =ROUND(I30*H30,2) -> 2920.09
A31: =COUNTIF('Plan.Orçam.'!E:E,Composição!B31) -> 1 | B31: 4 | C31: FUNDO PREPARADOR PRIMER A BASE DE EPOXI, PARA ESTRUTURA METALICA, UMA DEMAO, ESPESSURA DE 25 MICRA (ADAPTADO DE SINAPI 73865/1) | G31: M2 | I31: =SUM(J32:J36) -> 16.95
B32: =CONCATENATE(B31,".1") -> 4.1 | C32: SINAPI PB | D32: INSUMO | E32: 3768 | F32: =IF(C32="COMPOSIÇÃO",VLOOKUP(E32,B:J,2,FALSE),IF($D32="COMPOSIÇÃO",VLOOKUP(Composição!$E32,'Sinapi_Comp-06.2023'!$G:$L,2,FALSE),VLOOKUP($E32,'Sinapi_Insum-06.2023'!$A:$E,2,FALSE))) -> LIXA EM FOLHA PARA FERRO, NUMERO 150 | G32: =IF(C32="COMPOSIÇÃO",VLOOKUP(E32,B:J,6,FALSE),IF($D32="COMPOSIÇÃO",VLOOKUP(Composição!$E32,'Sinapi_Comp-06.2023'!$G:$L,3,FALSE),VLOOKUP($E32,'Sinapi_Insum-06.2023'!$A:$E,3,FALSE))) -> UN | H32: 0.25 | I32: =IF(C32="COMPOSIÇÃO",VLOOKUP(E32,B:J,8,FALSE),IF(C32="COTAÇÃO",VLOOKUP(E32,Cotação!B:F,7,FALSE),IF($D32="COMPOSIÇÃO",VLOOKUP(Composição!$E32,'Sinapi_Comp-06.2023'!$G:$L,5,FALSE),VLOOKUP($E32,'Sinapi_Insum-06.2023'!$A:$E,5,FALSE)))) -> 2.54 | J32: =ROUND(I32*H32,2) -> 0.64
B33: =CONCATENATE(B31,".2") -> 4.2 | C33: SINAPI PB | D33: INSUMO | E33: 5318 | F33: =IF(C33="COMPOSIÇÃO",VLOOKUP(E33,B:J,2,FALSE),IF($D33="COMPOSIÇÃO",VLOOKUP(Composição!$E33,'Sinapi_Comp-06.2023'!$G:$L,2,FALSE),VLOOKUP($E33,'Sinapi_Insum-06.2023'!$A:$E,2,FALSE))) -> DILUENTE AGUARRAS | G33: =IF(C33="COMPOSIÇÃO",VLOOKUP(E33,B:J,6,FALSE),IF($D33="COMPOSIÇÃO",VLOOKUP(Composição!$E33,'Sinapi_Comp-06.2023'!$G:$L,3,FALSE),VLOOKUP($E33,'Sinapi_Insum-06.2023'!$A:$E,3,FALSE))) -> L | H33: 0.03 | I33: =IF(C33="COMPOSIÇÃO",VLOOKUP(E33,B:J,8,FALSE),IF(C33="COTAÇÃO",VLOOKUP(E33,Cotação!B:F,7,FALSE),IF($D33="COMPOSIÇÃO",VLOOKUP(Composição!$E33,'Sinapi_Comp-06.2023'!$G:$L,5,FALSE),VLOOKUP($E33,'Sinapi_Insum-06.2023'!$A:$E,5,FALSE)))) -> 19.39 | J33: =ROUND(I33*H33,2) -> 0.58
B34: =CONCATENATE(B31,".3") -> 4.3 | C34: SINAPI PB | D34: INSUMO | E34: 44072 | F34: =IF(C34="COMPOSIÇÃO",VLOOKUP(E34,B:J,2,FALSE),IF($D34="COMPOSIÇÃO",VLOOKUP(Composição!$E34,'Sinapi_Comp-06.2023'!$G:$L,2,FALSE),VLOOKUP($E34,'Sinapi_Insum-06.2023'!$A:$E,2,FALSE))) -> PRIMER EPOXI / EPOXIDICO | G34: =IF(C34="COMPOSIÇÃO",VLOOKUP(E34,B:J,6,FALSE),IF($D34="COMPOSIÇÃO",VLOOKUP(Composição!$E34,'Sinapi_Comp-06.2023'!$G:$L,3,FALSE),VLOOKUP($E34,'Sinapi_Insum-06.2023'!$A:$E,3,FALSE))) -> L | H34: =0.033*3.6 -> 0.1188 | I34: =IF(C34="COMPOSIÇÃO",VLOOKUP(E34,B:J,8,FALSE),IF(C34="COTAÇÃO",VLOOKUP(E34,Cotação!B:F,7,FALSE),IF($D34="COMPOSIÇÃO",VLOOKUP(Composição!$E34,'Sinapi_Comp-06.2023'!$G:$L,5,FALSE),VLOOKUP($E34,'Sinapi_Insum-06.2023'!$A:$E,5,FALSE)))) -> 109.62 | J34: =ROUND(I34*H34,2) -> 13.02
B35: =CONCATENATE(B31,".4") -> 4.4 | C35: SINAPI PB | D35: COMPOSIÇÃO | E35: 88310 | F35: =IF(C35="COMPOSIÇÃO",VLOOKUP(E35,B:J,2,FALSE),IF($D35="COMPOSIÇÃO",VLOOKUP(Composição!$E35,'Sinapi_Comp-06.2023'!$G:$L,2,FALSE),VLOOKUP($E35,'Sinapi_Insum-06.2023'!$A:$E,2,FALSE))) -> PINTOR COM ENCARGOS COMPLEMENTARES | G35: =IF(C35="COMPOSIÇÃO",VLOOKUP(E35,B:J,6,FALSE),IF($D35="COMPOSIÇÃO",VLOOKUP(Composição!$E35,'Sinapi_Comp-06.2023'!$G:$L,3,FALSE),VLOOKUP($E35,'Sinapi_Insum-06.2023'!$A:$E,3,FALSE))) -> H | H35: 0.08 | I35: =IF(C35="COMPOSIÇÃO",VLOOKUP(E35,B:J,8,FALSE),IF(C35="COTAÇÃO",VLOOKUP(E35,Cotação!B:F,7,FALSE),IF($D35="COMPOSIÇÃO",VLOOKUP(Composição!$E35,'Sinapi_Comp-06.2023'!$G:$L,5,FALSE),VLOOKUP($E35,'Sinapi_Insum-06.2023'!$A:$E,5,FALSE)))) -> 24.53 | J35: =ROUND(I35*H35,2) -> 1.96
B36: =CONCATENATE(B31,".5") -> 4.5 | C36: SINAPI PB | D36: COMPOSIÇÃO | E36: 88316 | F36: =IF(C36="COMPOSIÇÃO",VLOOKUP(E36,B:J,2,FALSE),IF($D36="COMPOSIÇÃO",VLOOKUP(Composição!$E36,'Sinapi_Comp-06.2023'!$G:$L,2,FALSE),VLOOKUP($E36,'Sinapi_Insum-06.2023'!$A:$E,2,FALSE))) -> SERVENTE COM ENCARGOS COMPLEMENTARES | G36: =IF(C36="COMPOSIÇÃO",VLOOKUP(E36,B:J,6,FALSE),IF($D36="COMPOSIÇÃO",VLOOKUP(Composição!$E36,'Sinapi_Comp-06.2023'!$G:$L,3,FALSE),VLOOKUP($E36,'Sinapi_Insum-06.2023'!$A:$E,3,FALSE))) -> H | H36: 0.04 | I36: =IF(C36="COMPOSIÇÃO",VLOOKUP(E36,B:J,8,FALSE),IF(C36="COTAÇÃO",VLOOKUP(E36,Cotação!B:F,7,FALSE),IF($D36="COMPOSIÇÃO",VLOOKUP(Composição!$E36,'Sinapi_Comp-06.2023'!$G:$L,5,FALSE),VLOOKUP($E36,'Sinapi_Insum-06.2023'!$A:$E,5,FALSE)))) -> 18.67 | J36: =ROUND(I36*H36,2) -> 0.75
A37: =COUNTIF('Plan.Orçam.'!E:E,Composição!B37) -> 1 | B37: 5 | C37: PINTURA ESMALTE FOSCO, DUAS DEMAOS, SOBRE SUPERFICIE METALICA, INCLUSO UMA DEMAO DE FUNDO ANTICORROSIVO. UTILIZACAO DE REVOLVER ( AR-COMPRIMIDO) (ADAPTADO DE SINAPI 74145/1) | G37: M2 | I37: =SUM(J38:J43) -> 20.77
B38: =CONCATENATE(B37,".1") -> 5.1 | C38: SINAPI PB | D38: INSUMO | E38: 3768 | F38: =IF(C38="COMPOSIÇÃO",VLOOKUP(E38,B:J,2,FALSE),IF($D38="COMPOSIÇÃO",VLOOKUP(Composição!$E38,'Sinapi_Comp-06.2023'!$G:$L,2,FALSE),VLOOKUP($E38,'Sinapi_Insum-06.2023'!$A:$E,2,FALSE))) -> LIXA EM FOLHA PARA FERRO, NUMERO 150 | G38: =IF(C38="COMPOSIÇÃO",VLOOKUP(E38,B:J,6,FALSE),IF($D38="COMPOSIÇÃO",VLOOKUP(Composição!$E38,'Sinapi_Comp-06.2023'!$G:$L,3,FALSE),VLOOKUP($E38,'Sinapi_Insum-06.2023'!$A:$E,3,FALSE))) -> UN | H38: 0.55 | I38: =IF(C38="COMPOSIÇÃO",VLOOKUP(E38,B:J,8,FALSE),IF(C38="COTAÇÃO",VLOOKUP(E38,Cotação!B:F,7,FALSE),IF($D38="COMPOSIÇÃO",VLOOKUP(Composição!$E38,'Sinapi_Comp-06.2023'!$G:$L,5,FALSE),VLOOKUP($E38,'Sinapi_Insum-06.2023'!$A:$E,5,FALSE)))) -> 2.54 | J38: =ROUND(I38*H38,2) -> 1.4
B39: =CONCATENATE(B37,".2") -> 5.2 | C39: SINAPI PB | D39: INSUMO | E39: 5318 | F39: =IF(C39="COMPOSIÇÃO",VLOOKUP(E39,B:J,2,FALSE),IF($D39="COMPOSIÇÃO",VLOOKUP(Composição!$E39,'Sinapi_Comp-06.2023'!$G:$L,2,FALSE),VLOOKUP($E39,'Sinapi_Insum-06.2023'!$A:$E,2,FALSE))) -> DILUENTE AGUARRAS | G39: =IF(C39="COMPOSIÇÃO",VLOOKUP(E39,B:J,6,FALSE),IF($D39="COMPOSIÇÃO",VLOOKUP(Composição!$E39,'Sinapi_Comp-06.2023'!$G:$L,3,FALSE),VLOOKUP($E39,'Sinapi_Insum-06.2023'!$A:$E,3,FALSE))) -> L | H39: 0.044 | I39: =IF(C39="COMPOSIÇÃO",VLOOKUP(E39,B:J,8,FALSE),IF(C39="COTAÇÃO",VLOOKUP(E39,Cotação!B:F,7,FALSE),IF($D39="COMPOSIÇÃO",VLOOKUP(Composição!$E39,'Sinapi_Comp-06.2023'!$G:$L,5,FALSE),VLOOKUP($E39,'Sinapi_Insum-06.2023'!$A:$E,5,FALSE)))) -> 19.39 | J39: =ROUND(I39*H39,2) -> 0.85
B40: =CONCATENATE(B37,".3") -> 5.3 | C40: SINAPI PB | D40: INSUMO | E40: 7288 | F40: =IF(C40="COMPOSIÇÃO",VLOOKUP(E40,B:J,2,FALSE),IF($D40="COMPOSIÇÃO",VLOOKUP(Composição!$E40,'Sinapi_Comp-06.2023'!$G:$L,2,FALSE),VLOOKUP($E40,'Sinapi_Insum-06.2023'!$A:$E,2,FALSE))) -> TINTA ESMALTE SINTETICO PREMIUM FOSCO | G40: =IF(C40="COMPOSIÇÃO",VLOOKUP(E40,B:J,6,FALSE),IF($D40="COMPOSIÇÃO",VLOOKUP(Composição!$E40,'Sinapi_Comp-06.2023'!$G:$L,3,FALSE),VLOOKUP($E40,'Sinapi_Insum-06.2023'!$A:$E,3,FALSE))) -> L | H40: 0.176 | I40: =IF(C40="COMPOSIÇÃO",VLOOKUP(E40,B:J,8,FALSE),IF(C40="COTAÇÃO",VLOOKUP(E40,Cotação!B:F,7,FALSE),IF($D40="COMPOSIÇÃO",VLOOKUP(Composição!$E40,'Sinapi_Comp-06.2023'!$G:$L,5,FALSE),VLOOKUP($E40,'Sinapi_Insum-06.2023'!$A:$E,5,FALSE)))) -> 35.77 | J40: =ROUND(I40*H40,2) -> 6.3
B41: =CONCATENATE(B37,".4") -> 5.4 | C41: SINAPI PB | D41: INSUMO | E41: 7307 | F41: =IF(C41="COMPOSIÇÃO",VLOOKUP(E41,B:J,2,FALSE),IF($D41="COMPOSIÇÃO",VLOOKUP(Composição!$E41,'Sinapi_Comp-06.2023'!$G:$L,2,FALSE),VLOOKUP($E41,'Sinapi_Insum-06.2023'!$A:$E,2,FALSE))) -> FUNDO ANTICORROSIVO PARA METAIS FERROSOS (ZARCAO) | G41: =IF(C41="COMPOSIÇÃO",VLOOKUP(E41,B:J,6,FALSE),IF($D41="COMPOSIÇÃO",VLOOKUP(Composição!$E41,'Sinapi_Comp-06.2023'!$G:$L,3,FALSE),VLOOKUP($E41,'Sinapi_Insum-06.2023'!$A:$E,3,FALSE))) -> L | H41: 0.132 | I41: =IF(C41="COMPOSIÇÃO",VLOOKUP(E41,B:J,8,FALSE),IF(C41="COTAÇÃO",VLOOKUP(E41,Cotação!B:F,7,FALSE),IF($D41="COMPOSIÇÃO",VLOOKUP(Composição!$E41,'Sinapi_Comp-06.2023'!$G:$L,5,FALSE),VLOOKUP($E41,'Sinapi_Insum-06.2023'!$A:$E,5,FALSE)))) -> 38.06 | J41: =ROUND(I41*H41,2) -> 5.02
B42: =CONCATENATE(B37,".5") -> 5.5 | C42: SINAPI PB | D42: COMPOSIÇÃO | E42: 88310 | F42: =IF(C42="COMPOSIÇÃO",VLOOKUP(E42,B:J,2,FALSE),IF($D42="COMPOSIÇÃO",VLOOKUP(Composição!$E42,'Sinapi_Comp-06.2023'!$G:$L,2,FALSE),VLOOKUP($E42,'Sinapi_Insum-06.2023'!$A:$E,2,FALSE))) -> PINTOR COM ENCARGOS COMPLEMENTARES | G42: =IF(C42="COMPOSIÇÃO",VLOOKUP(E42,B:J,6,FALSE),IF($D42="COMPOSIÇÃO",VLOOKUP(Composição!$E42,'Sinapi_Comp-06.2023'!$G:$L,3,FALSE),VLOOKUP($E42,'Sinapi_Insum-06.2023'!$A:$E,3,FALSE))) -> H | H42: 0.21 | I42: =IF(C42="COMPOSIÇÃO",VLOOKUP(E42,B:J,8,FALSE),IF(C42="COTAÇÃO",VLOOKUP(E42,Cotação!B:F,7,FALSE),IF($D42="COMPOSIÇÃO",VLOOKUP(Composição!$E42,'Sinapi_Comp-06.2023'!$G:$L,5,FALSE),VLOOKUP($E42,'Sinapi_Insum-06.2023'!$A:$E,5,FALSE)))) -> 24.53 | J42: =ROUND(I42*H42,2) -> 5.15
B43: =CONCATENATE(B37,".6") -> 5.6 | C43: SINAPI PB | D43: COMPOSIÇÃO | E43: 88316 | F43: =IF(C43="COMPOSIÇÃO",VLOOKUP(E43,B:J,2,FALSE),IF($D43="COMPOSIÇÃO",VLOOKUP(Composição!$E43,'Sinapi_Comp-06.2023'!$G:$L,2,FALSE),VLOOKUP($E43,'Sinapi_Insum-06.2023'!$A:$E,2,FALSE))) -> SERVENTE COM ENCARGOS COMPLEMENTARES | G43: =IF(C43="COMPOSIÇÃO",VLOOKUP(E43,B:J,6,FALSE),IF($D43="COMPOSIÇÃO",VLOOKUP(Composição!$E43,'Sinapi_Comp-06.2023'!$G:$L,3,FALSE),VLOOKUP($E43,'Sinapi_Insum-06.2023'!$A:$E,3,FALSE))) -> H | H43: 0.11 | I43: =IF(C43="COMPOSIÇÃO",VLOOKUP(E43,B:J,8,FALSE),IF(C43="COTAÇÃO",VLOOKUP(E43,Cotação!B:F,7,FALSE),IF($D43="COMPOSIÇÃO",VLOOKUP(Composição!$E43,'Sinapi_Comp-06.2023'!$G:$L,5,FALSE),VLOOKUP($E43,'Sinapi_Insum-06.2023'!$A:$E,5,FALSE)))) -> 18.67 | J43: =ROUND(I43*H43,2) -> 2.05
...

Sheet M.Cálc.Quant.
G2: PROGRAMA: | I2: =BDI!C3 -> Esporte, Cidadania e Desenvolvimento
G3: CONCEDENTE: | I3: =BDI!C4 -> Prefeitura Municipal de Coremas - PB
G4: CONVENENTE: | I4: =BDI!C5 -> Município de Coremas- PB
G5: CONTRATO: | I5: =BDI!C6 -> RECURSOS GOVERNO DO ESTADO
G6: OBRA: | I6: =BDI!C7 -> CONSTRUÇÃO DE QUADRA POLIESPORTIVA COM VESTIÁRIOS E BANHEIROS, NO MUNICÍPIO DE COREMAS/PB
G7: REF. PREÇOS: | I7: =BDI!C8 -> SINAPI PB - 06/2025
G8: DESONERADO | I8: SIM
C10: ITEM | D10: SINAPI | G10: MEMÓRIA DE CÁLCULO DE QUANTIDADES
A12: NÍVEL | C12: FONTE | D12: CÓDIGO | E12: TIPO | F12: ITEM | G12: ITEM | H12: SERVIÇO | I12: DESCRIÇÃO | J12: VEZ | K12: DADOS | Q12: RESULTADO | T12: UNID
K13: X1 | L13: X2 | M13: Y1 | N13: Y2 | O13: Z1 | P13: Z2 | Q13: PARCIAL | R13: TOTAL | S13: GERAL
F14: 1.0 | G14: =F14 -> 1.0 | H14: =I6 -> CONSTRUÇÃO DE QUADRA POLIESPORTIVA COM VESTIÁRIOS E BANHEIROS, NO MUNICÍPIO DE COREMAS/PB
A15: 3 | B15: =G15 -> 1.1 | C15: COMPOSIÇÃO | D15: =Composição!B11 -> ITEM | F15: 1.1 | G15: =F15 -> 1.1 | H15: SERVIÇOS PRELIMINARES
A16: 3 | B16: =G16 -> 1.1.1 | C16: COMPOSIÇÃO | D16: =Composição!B12 -> 1 | E16: COMPOSIÇÃO | F16: 1.1.1 | G16: =F16 -> 1.1.1 | H16: =IF(C16="GIDUR JP",VLOOKUP(D16,GIDUR!A:D,2,FALSE),IF(C16="DER PB",VLOOKUP('M.Cálc.Quant.'!D16,DER!A:D,2,FALSE),IF(C16="COMPOSIÇÃO",VLOOKUP(D16,Composição!B:J,2,FALSE),IF(E16="COMPOSIÇÃO",VLOOKUP(D16,'Sinapi_Comp-06.2023'!G:H,2,FALSE),VLOOKUP(D16,'Sinapi_Insum-06.2023'!A:B,2,FALSE))))) -> PLACA DE OBRA EM CHAPA DE ACO GALVANIZADO [ADAPTADO SINAPI 74209/01] | I16: A placa terá 2,0m de largura por 4,0m de comprimento, conforme modelo de placas de obras da Secretaria. | S16: =SUM(R17) -> 8 | T16: =IF(C16="GIDUR JP",VLOOKUP(D16,GIDUR!A:D,3,FALSE),IF(C16="DER PB",VLOOKUP('M.Cálc.Quant.'!D16,DER!A:D,3,FALSE),IF(C16="COMPOSIÇÃO",VLOOKUP(D16,Composição!B:J,6,FALSE),IF(E16="COMPOSIÇÃO",VLOOKUP(D16,'Sinapi_Comp-06.2023'!G:I,3,FALSE),VLOOKUP(D16,'Sinapi_Insum-06.2023'!A:C,3,FALSE))))) -> M2 | V16: 10
A17: 4 | B17: =G17 -> 1.1.1.1 | F17: =CONCATENATE(F16,".1") -> 1.1.1.1 | G17: =F17 -> 1.1.1.1 | H17: =LEFT(H16,SEARCH(" ",H16)-1) -> PLACA | J17: 1 | K17: 2 | M17: 4 | Q17: =IF(SUM(K17:L17)=0,1,IF(L17<>0,SUM(K17:L17)/2,K17))*IF(SUM(M17:N17)=0,1,IF(N17<>0,SUM(M17:N17)/2,M17))*IF(SUM(O17:P17)=0,1,IF(P17<>0,SUM(O17:P17)/2,O17)) -> 8 | R17: =ROUND(J17*Q17,2) -> 8
A18: 3 | B18: =G18 -> 1.1.2 | C18: SINAPI | D18: 99059 | E18: COMPOSIÇÃO | F18: 1.1.2 | G18: =F18 -> 1.1.2 | H18: =IF(C18="GIDUR JP",VLOOKUP(D18,GIDUR!A:D,2,FALSE),IF(C18="DER PB",VLOOKUP('M.Cálc.Quant.'!D18,DER!A:D,2,FALSE),IF(C18="COMPOSIÇÃO",VLOOKUP(D18,Composição!B:J,2,FALSE),IF(E18="COMPOSIÇÃO",VLOOKUP(D18,'Sinapi_Comp-06.2023'!G:H,2,FALSE),VLOOKUP(D18,'Sinapi_Insum-06.2023'!A:B,2,FALSE))))) -> LOCAÇÃO CONVENCIONAL DE OBRA, UTILIZANDO GABARITO DE TÁBUAS CORRIDAS PONTALETADAS A CADA 2,00M - 2 UTILIZAÇÕES. AF_03/2024 | I18: locação geral | S18: =SUM(R19) -> 106.5 | T18: =IF(C18="GIDUR JP",VLOOKUP(D18,GIDUR!A:D,3,FALSE),IF(C18="DER PB",VLOOKUP('M.Cálc.Quant.'!D18,DER!A:D,3,FALSE),IF(C18="COMPOSIÇÃO",VLOOKUP(D18,Composição!B:J,6,FALSE),IF(E18="COMPOSIÇÃO",VLOOKUP(D18,'Sinapi_Comp-06.2023'!G:I,3,FALSE),VLOOKUP(D18,'Sinapi_Insum-06.2023'!A:C,3,FALSE))))) -> M | U18: =(24+37)*2 -> 122 | V18: 122
A19: 4 | B19: =G19 -> 1.1.2.1 | F19: =CONCATENATE(F18,".1") -> 1.1.2.1 | G19: =F19 -> 1.1.2.1 | H19: =LEFT(H18,SEARCH(" ",H18)-1) -> LOCAÇÃO | I19: (24+37)*2 | J19: 1 | K19: 2 | M19: 53.25 | Q19: =IF(SUM(K19:L19)=0,1,IF(L19<>0,SUM(K19:L19)/2,K19))*IF(SUM(M19:N19)=0,1,IF(N19<>0,SUM(M19:N19)/2,M19))*IF(SUM(O19:P19)=0,1,IF(P19<>0,SUM(O19:P19)/2,O19)) -> 106.5 | R19: =ROUND(J19*Q19,2) -> 106.5
A20: 2 | B20: =G20 -> 1.2 | E20: 0 | F20: 1.2 | G20: =F20 -> 1.2 | H20: MOVIMENTO DE TERRA
A21: 3 | B21: =G21 -> 1.2.1 | C21: COMPOSIÇÃO | D21: =Composição!B50 -> 8 | E21: COMPOSIÇÃO | F21: 1.2.1 | G21: =F21 -> 1.2.1 | H21: =IF(C21="GIDUR JP",VLOOKUP(D21,GIDUR!A:D,2,FALSE),IF(C21="DER PB",VLOOKUP('M.Cálc.Quant.'!D21,DER!A:D,2,FALSE),IF(C21="COMPOSIÇÃO",VLOOKUP(D21,Composição!B:J,2,FALSE),IF(E21="COMPOSIÇÃO",VLOOKUP(D21,'Sinapi_Comp-06.2023'!G:H,2,FALSE),VLOOKUP(D21,'Sinapi_Insum-06.2023'!A:B,2,FALSE))))) -> ESCAVACAO MANUAL EM SOLO-PROF. ATE 1,50 M [ADAPTADO SINAPI 79561/001] | S21: =SUM(R22:R32) -> 74.74 | T21: =IF(C21="GIDUR JP",VLOOKUP(D21,GIDUR!A:D,3,FALSE),IF(C21="DER PB",VLOOKUP('M.Cálc.Quant.'!D21,DER!A:D,3,FALSE),IF(C21="COMPOSIÇÃO",VLOOKUP(D21,Composição!B:J,6,FALSE),IF(E21="COMPOSIÇÃO",VLOOKUP(D21,'Sinapi_Comp-06.2023'!G:I,3,FALSE),VLOOKUP(D21,'Sinapi_Insum-06.2023'!A:C,3,FALSE))))) -> M3 | U21: =27*44*0.8 -> 950.4 | V21: 0
A22: 4 | B22: =G22 -> 1.2.1.1 | F22: =CONCATENATE(F21,".1") -> 1.2.1.1 | G22: =F22 -> 1.2.1.1 | H22: S11=S12 | J22: 2 | K22: 0.75 | M22: 0.75 | O22: 1.65 | Q22: =IF(SUM(K22:L22)=0,1,IF(L22<>0,SUM(K22:L22)/2,K22))*IF(SUM(M22:N22)=0,1,IF(N22<>0,SUM(M22:N22)/2,M22))*IF(SUM(O22:P22)=0,1,IF(P22<>0,SUM(O22:P22)/2,O22)) -> 0.93 | R22: =ROUND(J22*Q22,2) -> 1.86
A23: 4 | B23: =G23 -> 1.2.1.2 | F23: =CONCATENATE(F21,".2") -> 1.2.1.2 | G23: =F23 -> 1.2.1.2 | H23: S21=S22 | J23: 2 | K23: 0.85 | M23: 0.85 | O23: 1.65 | Q23: =IF(SUM(K23:L23)=0,1,IF(L23<>0,SUM(K23:L23)/2,K23))*IF(SUM(M23:N23)=0,1,IF(N23<>0,SUM(M23:N23)/2,M23))*IF(SUM(O23:P23)=0,1,IF(P23<>0,SUM(O23:P23)/2,O23)) -> 1.19 | R23: =ROUND(J23*Q23,2) -> 2.38
A24: 4 | B24: =G24 -> 1.2.1.3 | F24: =CONCATENATE(F21,".3") -> 1.2.1.3 | G24: =F24 -> 1.2.1.3 | H24: S14 | J24: 1 | K24: 1 | M24: 1.2 | O24: 1.65 | Q24: =IF(SUM(K24:L24)=0,1,IF(L24<>0,SUM(K24:L24)/2,K24))*IF(SUM(M24:N24)=0,1,IF(N24<>0,SUM(M24:N24)/2,M24))*IF(SUM(O24:P24)=0,1,IF(P24<>0,SUM(O24:P24)/2,O24)) -> 1.98 | R24: =ROUND(J24*Q24,2) -> 1.98
A25: 5 | B25: =G25 -> 1.2.1.4 | F25: 1.2.1.4 | G25: =F25 -> 1.2.1.4 | H25: S19 | J25: 1 | K25: 1.1 | M25: 1.3 | O25: 1.65 | Q25: =IF(SUM(K25:L25)=0,1,IF(L25<>0,SUM(K25:L25)/2,K25))*IF(SUM(M25:N25)=0,1,IF(N25<>0,SUM(M25:N25)/2,M25))*IF(SUM(O25:P25)=0,1,IF(P25<>0,SUM(O25:P25)/2,O25)) -> 2.36 | R25: =ROUND(J25*Q25,2) -> 2.36
A26: 6 | B26: =G26 -> 1.2.1.5 | F26: 1.2.1.5 | G26: =F26 -> 1.2.1.5 | H26: S18 | J26: 1 | K26: 1.05 | M26: 1.4 | O26: 1.65 | Q26: =IF(SUM(K26:L26)=0,1,IF(L26<>0,SUM(K26:L26)/2,K26))*IF(SUM(M26:N26)=0,1,IF(N26<>0,SUM(M26:N26)/2,M26))*IF(SUM(O26:P26)=0,1,IF(P26<>0,SUM(O26:P26)/2,O26)) -> 2.43 | R26: =ROUND(J26*Q26,2) -> 2.43
A27: 7 | B27: =G27 -> 1.2.1.6 | F27: 1.2.1.6 | G27: =F27 -> 1.2.1.6 | H27: S16=S17 | J27: 2 | K27: 1.15 | M27: 1.35 | O27: 1.65 | Q27: =IF(SUM(K27:L27)=0,1,IF(L27<>0,SUM(K27:L27)/2,K27))*IF(SUM(M27:N27)=0,1,IF(N27<>0,SUM(M27:N27)/2,M27))*IF(SUM(O27:P27)=0,1,IF(P27<>0,SUM(O27:P27)/2,O27)) -> 2.56 | R27: =ROUND(J27*Q27,2) -> 5.12
A28: 8 | B28: =G28 -> 1.2.1.7 | F28: 1.2.1.7 | G28: =F28 -> 1.2.1.7 | H28: S15 | J28: 1 | K28: 1.1 | M28: 1.45 | O28: 1.65 | Q28: =IF(SUM(K28:L28)=0,1,IF(L28<>0,SUM(K28:L28)/2,K28))*IF(SUM(M28:N28)=0,1,IF(N28<>0,SUM(M28:N28)/2,M28))*IF(SUM(O28:P28)=0,1,IF(P28<>0,SUM(O28:P28)/2,O28)) -> 2.63 | R28: =ROUND(J28*Q28,2) -> 2.63
A29: 9 | B29: =G29 -> 1.2.1.8 | F29: 1.2.1.8 | G29: =F29 -> 1.2.1.8 | H29: S1=S2=S6=S13=S20 | J29: 5 | K29: 1.25 | M29: 1.45 | O29: 1.65 | Q29: =IF(SUM(K29:L29)=0,1,IF(L29<>0,SUM(K29:L29)/2,K29))*IF(SUM(M29:N29)=0,1,IF(N29<>0,SUM(M29:N29)/2,M29))*IF(SUM(O29:P29)=0,1,IF(P29<>0,SUM(O29:P29)/2,O29)) -> 2.99 | R29: =ROUND(J29*Q29,2) -> 14.95
A30: 10 | B30: =G30 -> 1.2.1.9 | F30: 1.2.1.9 | G30: =F30 -> 1.2.1.9 | H30: S3=S4=S5 | J30: 3 | K30: 1.3 | M30: 1.5 | O30: 1.65 | Q30: =IF(SUM(K30:L30)=0,1,IF(L30<>0,SUM(K30:L30)/2,K30))*IF(SUM(M30:N30)=0,1,IF(N30<>0,SUM(M30:N30)/2,M30))*IF(SUM(O30:P30)=0,1,IF(P30<>0,SUM(O30:P30)/2,O30)) -> 3.22 | R30: =ROUND(J30*Q30,2) -> 9.66
A31: 11 | B31: =G31 -> 1.2.1.10 | F31: 1.2.1.10 | G31: =F31 -> 1.2.1.10 | H31: S7=S8=S9=S10 | J31: 4 | K31: 1.75 | M31: 1.85 | O31: 1.65 | Q31: =IF(SUM(K31:L31)=0,1,IF(L31<>0,SUM(K31:L31)/2,K31))*IF(SUM(M31:N31)=0,1,IF(N31<>0,SUM(M31:N31)/2,M31))*IF(SUM(O31:P31)=0,1,IF(P31<>0,SUM(O31:P31)/2,O31)) -> 5.34 | R31: =ROUND(J31*Q31,2) -> 21.36
A32: 12 | B32: =G32 -> 1.2.1.11 | F32: 1.2.1.11 | G32: =F32 -> 1.2.1.11 | H32: baldrames | J32: 1 | K32: =13+8+10+94.1 -> 125.1 | M32: 0.2 | O32: 0.4 | Q32: =IF(SUM(K32:L32)=0,1,IF(L32<>0,SUM(K32:L32)/2,K32))*IF(SUM(M32:N32)=0,1,IF(N32<>0,SUM(M32:N32)/2,M32))*IF(SUM(O32:P32)=0,1,IF(P32<>0,SUM(O32:P32)/2,O32)) -> 10.01 | R32: =ROUND(J32*Q32,2) -> 10.01
A33: 3 | B33: =G33 -> 1.2.2 | C33: SINAPI | D33: 93382 | E33: COMPOSIÇÃO | F33: 1.2.2 | G33: =F33 -> 1.2.2 | H33: =IF(C33="GIDUR JP",VLOOKUP(D33,GIDUR!A:D,2,FALSE),IF(C33="DER PB",VLOOKUP('M.Cálc.Quant.'!D33,DER!A:D,2,FALSE),IF(C33="COMPOSIÇÃO",VLOOKUP(D33,Composição!B:J,2,FALSE),IF(E33="COMPOSIÇÃO",VLOOKUP(D33,'Sinapi_Comp-06.2023'!G:H,2,FALSE),VLOOKUP(D33,'Sinapi_Insum-06.2023'!A:B,2,FALSE))))) -> REATERRO MANUAL DE VALAS, COM COMPACTADOR DE SOLOS DE PERCUSSÃO. AF_08/2023 | S33: =SUM(R34:R34) -> 63.7 | T33: =IF(C33="GIDUR JP",VLOOKUP(D33,GIDUR!A:D,3,FALSE),IF(C33="DER PB",VLOOKUP('M.Cálc.Quant.'!D33,DER!A:D,3,FALSE),IF(C33="COMPOSIÇÃO",VLOOKUP(D33,Composição!B:J,6,FALSE),IF(E33="COMPOSIÇÃO",VLOOKUP(D33,'Sinapi_Comp-06.2023'!G:I,3,FALSE),VLOOKUP(D33,'Sinapi_Insum-06.2023'!A:C,3,FALSE))))) -> M3 | U33: =27*44 -> 1188 | V33: 1188
A34: 4 | B34: =G34 -> 1.2.2.1 | F34: =CONCATENATE(F33,".1") -> 1.2.2.1 | G34: =F34 -> 1.2.2.1 | H34: Volume de escavação-volume de concreto | J34: 1 | K34: =S21-S81 -> 63.7 | Q34: =IF(SUM(K34:L34)=0,1,IF(L34<>0,SUM(K34:L34)/2,K34))*IF(SUM(M34:N34)=0,1,IF(N34<>0,SUM(M34:N34)/2,M34))*IF(SUM(O34:P34)=0,1,IF(P34<>0,SUM(O34:P34)/2,O34)) -> 63.7 | R34: =ROUND(J34*Q34,2) -> 63.7
B35: =G35 -> 1.3 | E35: #N/A | F35: 1.3 | G35: =F35 -> 1.3 | H35: INFRA-ESTRUTURA: FUNDAÇÕES (TODA A QUADRA)
B36: =G36 -> 1.3.1 | E36: #N/A | F36: 1.3.1 | G36: =F36 -> 1.3.1 | H36: SAPATAS ISOLADAS/ARRANQUE DOS PILARES
B37: =G37 -> 1.3.1.1 | C37: SINAPI | D37: 101616 | E37: COMPOSIÇÃO | F37: 1.3.1.1 | G37: =F37 -> 1.3.1.1 | H37: =IF(C37="GIDUR JP",VLOOKUP(D37,GIDUR!A:D,2,FALSE),IF(C37="DER PB",VLOOKUP('M.Cálc.Quant.'!D37,DER!A:D,2,FALSE),IF(C37="COMPOSIÇÃO",VLOOKUP(D37,Composição!B:J,2,FALSE),IF(E37="COMPOSIÇÃO",VLOOKUP(D37,'Sinapi_Comp-06.2023'!G:H,2,FALSE),VLOOKUP(D37,'Sinapi_Insum-06.2023'!A:B,2,FALSE))))) -> PREPARO DE FUNDO DE VALA COM LARGURA MENOR QUE 1,5 M (ACERTO DO SOLO NATURAL). AF_08/2020 | S37: =SUM(R38:R48) -> 64.24 | T37: =IF(C37="GIDUR JP",VLOOKUP(D37,GIDUR!A:D,3,FALSE),IF(C37="DER PB",VLOOKUP('M.Cálc.Quant.'!D37,DER!A:D,3,FALSE),IF(C37="COMPOSIÇÃO",VLOOKUP(D37,Composição!B:J,6,FALSE),IF(E37="COMPOSIÇÃO",VLOOKUP(D37,'Sinapi_Comp-06.2023'!G:I,3,FALSE),VLOOKUP(D37,'Sinapi_Insum-06.2023'!A:C,3,FALSE))))) -> M2 | V37: 38.6
A38: 4 | B38: =G38 -> 1.3.1.1.1 | F38: 1.3.1.1.1 | G38: =F38 -> 1.3.1.1.1 | H38: S11=S12 | J38: 2 | K38: 0.75 | M38: 0.75 | Q38: =IF(SUM(K38:L38)=0,1,IF(L38<>0,SUM(K38:L38)/2,K38))*IF(SUM(M38:N38)=0,1,IF(N38<>0,SUM(M38:N38)/2,M38))*IF(SUM(O38:P38)=0,1,IF(P38<>0,SUM(O38:P38)/2,O38)) -> 0.56 | R38: =ROUND(J38*Q38,2) -> 1.12
A39: 4 | B39: =G39 -> 1.3.1.1.2 | F39: 1.3.1.1.2 | G39: =F39 -> 1.3.1.1.2 | H39: S21=S22 | J39: 2 | K39: 0.85 | M39: 0.85 | Q39: =IF(SUM(K39:L39)=0,1,IF(L39<>0,SUM(K39:L39)/2,K39))*IF(SUM(M39:N39)=0,1,IF(N39<>0,SUM(M39:N39)/2,M39))*IF(SUM(O39:P39)=0,1,IF(P39<>0,SUM(O39:P39)/2,O39)) -> 0.72 | R39: =ROUND(J39*Q39,2) -> 1.44
A40: 4 | B40: =G40 -> 1.3.1.1.3 | F40: 1.3.1.1.3 | G40: =F40 -> 1.3.1.1.3 | H40: S14 | J40: 1 | K40: 1 | M40: 1.2 | Q40: =IF(SUM(K40:L40)=0,1,IF(L40<>0,SUM(K40:L40)/2,K40))*IF(SUM(M40:N40)=0,1,IF(N40<>0,SUM(M40:N40)/2,M40))*IF(SUM(O40:P40)=0,1,IF(P40<>0,SUM(O40:P40)/2,O40)) -> 1.2 | R40: =ROUND(J40*Q40,2) -> 1.2
A41: 4 | B41: =G41 -> 1.3.1.1.4 | F41: 1.3.1.1.4 | G41: =F41 -> 1.3.1.1.4 | H41: S19 | J41: 1 | K41: 1.1 | M41: 1.3 | Q41: =IF(SUM(K41:L41)=0,1,IF(L41<>0,SUM(K41:L41)/2,K41))*IF(SUM(M41:N41)=0,1,IF(N41<>0,SUM(M41:N41)/2,M41))*IF(SUM(O41:P41)=0,1,IF(P41<>0,SUM(O41:P41)/2,O41)) -> 1.43 | R41: =ROUND(J41*Q41,2) -> 1.43
A42: 4 | B42: =G42 -> 1.3.1.1.5 | F42: 1.3.1.1.5 | G42: =F42 -> 1.3.1.1.5 | H42: S18 | J42: 1 | K42: 1.05 | M42: 1.4 | Q42: =IF(SUM(K42:L42)=0,1,IF(L42<>0,SUM(K42:L42)/2,K42))*IF(SUM(M42:N42)=0,1,IF(N42<>0,SUM(M42:N42)/2,M42))*IF(SUM(O42:P42)=0,1,IF(P42<>0,SUM(O42:P42)/2,O42)) -> 1.47 | R42: =ROUND(J42*Q42,2) -> 1.47
A43: 4 | B43: =G43 -> 1.3.1.1.6 | F43: 1.3.1.1.6 | G43: =F43 -> 1.3.1.1.6 | H43: S16=S17 | J43: 2 | K43: 1.15 | M43: 1.35 | Q43: =IF(SUM(K43:L43)=0,1,IF(L43<>0,SUM(K43:L43)/2,K43))*IF(SUM(M43:N43)=0,1,IF(N43<>0,SUM(M43:N43)/2,M43))*IF(SUM(O43:P43)=0,1,IF(P43<>0,SUM(O43:P43)/2,O43)) -> 1.55 | R43: =ROUND(J43*Q43,2) -> 3.1
...

Sheet Planilha2
C4: DATA BASE 08/2020
G5: composições | L5: Qtd | M5: Valor Total
C6: 1 | D6: ATERRO APILOADO(MANUAL) EM CAMADAS DE 20 CM COM EMPRÉSTIMO DE MATERIAL [ADAPTADO SINAPI 73904/001] | H6: M3 | J6: =SUM(K7:K8) -> 63.99 | L6: 58.37 | M6: =L6*J6 -> 3735.1
C7: =CONCATENATE(C6,".1") -> 1.1 | D7: SINAPI PB | E7: INSUMO | F7: 6079 | G7: ARGILA, ARGILA VERMELHA OU ARGILA ARENOSA (RETIRADA NA JAZIDA, SEM TRANSPORTE) | H7: M³ | I7: 1.1 | J7: =9.43*1.3024 -> 12.281632 | K7: =ROUND(J7*I7,2) -> 13.51
C8: =CONCATENATE(C6,".2") -> 1.2 | D8: SINAPI PB | E8: COMPOSIÇÃO | F8: 88316 | G8: SERVENTE COM ENCARGOS COMPLEMENTARES | H8: H | I8: 3 | J8: =12.92*1.3024 -> 16.827008 | K8: =ROUND(J8*I8,2) -> 50.48
C10: 2 | D10: ALVENARIA EM TIJOLO CERAMICO FURADO 9X19X19CM, 1 VEZ (ESPESSURA 19 CM) , ASSENTADO ARGAMASSA TRACO 1:4 (CIMENTO E AREIA MEDIA NAO PENEIRADA), PREPARO MANUAL, JUNTA1 CM [ADAPTADO DE SINAPI 73935/002] | H10: M2 | J10: =SUM(K11:K14) -> 79.61 | L10: 253.76 | M10: =J10*L10 -> 20201.83
C11: =CONCATENATE(C10,".1") -> 2.1 | D11: SINAPI PB | E11: COMPOSIÇÃO | F11: 87373 | G11: ARGAMASSA TRAÇO 1:4 (EM VOLUME DE CIMENTO E AREIA MÉDIA ÚMIDA) PARA CONTRAPISO, PREPARO MANUAL. AF_08/2019 | H11: M3 | I11: 0.0138 | J11: =445.97*1.3024 -> 580.83133 | K11: =ROUND(J11*I11,2) -> 8.02
C12: =CONCATENATE(C10,".2") -> 2.2 | D12: SINAPI PB | E12: COMPOSIÇÃO | F12: 88309 | G12: PEDREIRO COM ENCARGOS COMPLEMENTARES | H12: H | I12: 1.14 | J12: =16.35*1.3024 -> 21.29424 | K12: =ROUND(J12*I12,2) -> 24.28
C13: =CONCATENATE(C10,".3") -> 2.3 | D13: SINAPI PB | E13: COMPOSIÇÃO | F13: 88316 | G13: SERVENTE COM ENCARGOS COMPLEMENTARES | H13: H | I13: 0.88 | J13: =12.92*1.3024 -> 17 | K13: =ROUND(J13*I13,2) -> 14.96
C14: =CONCATENATE(C10,".4") -> 2.4 | D14: SINAPI PB | E14: INSUMO | F14: 7271 | G14: BLOCO CERAMICO / TIJOLO VAZADO PARA ALVENARIA DE VEDACAO, 8 FUROS NA HORIZONTAL, DE 9 X 19 X 19 CM (L XA X C) | H14: UN | I14: 54 | J14: =0.46*1.3024 -> 0.599104 | K14: =ROUND(J14*I14,2) -> 32.35
C15: 3 | D15: DEMOLIÇÃO DE PILARES E VIGAS EM CONCRETO ARMADO, DE FORMA MANUAL, SEM REAPROVEITAMENTO. AF_12/2017 97627 | H15: M3 | J15: =1.3024*163.5 -> 212.94 | L15: 380.64 | M15: =J15*L15 -> 81053.48
L17: total | M17: =SUM(M6:M15) -> 104990.41

Sheet Plan.Orçam.
D2: PROGRAMA: | G2: ='M.Cálc.Quant.'!I2 -> Esporte, Cidadania e Desenvolvimento
D3: CONCEDENTE: | G3: ='M.Cálc.Quant.'!I3 -> Prefeitura Municipal de Coremas - PB
D4: CONVENENTE: | G4: ='M.Cálc.Quant.'!I4 -> Município de Coremas- PB
D5: CONTRATO: | G5: ='M.Cálc.Quant.'!I5 -> RECURSOS GOVERNO DO ESTADO
D6: OBRA: | G6: ='M.Cálc.Quant.'!I6 -> CONSTRUÇÃO DE QUADRA POLIESPORTIVA COM VESTIÁRIOS E BANHEIROS, NO MUNICÍPIO DE COREMAS/PB | J6: Encargos: | K6: =Encargos!C79 -> 85.69
D7: REF. PREÇOS: | G7: ='M.Cálc.Quant.'!I7 -> SINAPI PB - 06/2025 | J7: B.D.I.: | K7: =BDI!$C$31 -> 0.2522
J8: B.D.I fornecimento: | K8: ='BDI-Fornecimento'!C31 -> 0.1675
D9: PLANILHA ORÇAMENTÁRIA
C11: ITEM BASE | D11: FONTE | E11: CÓDIGO | F11: ITEM | G11: DESCRIÇÃO DOS SERVIÇOS | H11: UNID. | I11: QUANT. | J11: VALORES (R$)
J12: UNIT. | K12: TOTAL
F13: 0.0 | G13: CONSTRUÇÃO DE QUADRA POLIESPORTIVA | K13: =K14+K156 -> 845804.73
F14: 1.0 | G14: QUADRA | K14: =K15+K18+K22+K38+K62+K68+K72+K79+K82+K90+K100+K106+K114+K117+K123+K127+K133+K152+K138 -> 716912.86
C15: 1 | F15: 1.1 | G15: =VLOOKUP(F15,'M.Cálc.Quant.'!G:T,2,FALSE) -> SERVIÇOS PRELIMINARES | K15: =SUM(K16:K17) -> 12614.55
A16: =VLOOKUP(F16,'M.Cálc.Quant.'!B:T,4,FALSE) -> COMPOSIÇÃO | C16: 1.1 | D16: =VLOOKUP(F16,'M.Cálc.Quant.'!B:T,2,FALSE) -> COMPOSIÇÃO | E16: =VLOOKUP(F16,'M.Cálc.Quant.'!B:T,3,FALSE) -> 1 | F16: 1.1.1 | G16: =VLOOKUP(F16,'M.Cálc.Quant.'!G:T,2,FALSE) -> PLACA DE OBRA EM CHAPA DE ACO GALVANIZADO [ADAPTADO SINAPI 74209/01] | H16: =VLOOKUP(F16,'M.Cálc.Quant.'!G:T,14,FALSE) -> M2 | I16: =VLOOKUP(F16,'M.Cálc.Quant.'!G:T,13,FALSE) -> 8 | J16: =(1+$K$7)*IF(D16="GIDUR JP",VLOOKUP(E16,GIDUR!A:D,4,FALSE),IF(D16="DER PB",VLOOKUP(E16,DER!A:D,4,FALSE)/(1+DER!$E$2),IF(D16="COMPOSIÇÃO",VLOOKUP(E16,Composição!B:J,8,FALSE),IF(A16="COMPOSIÇÃO",VLOOKUP(E16,'Sinapi_Comp-06.2023'!G:K,5,FALSE),VLOOKUP(E16,'Sinapi_Insum-06.2023'!A:E,5,FALSE))))) -> 623.51 | K16: =IFERROR(ROUND(I16*J16,2),0) -> 4988.08 | M16: =ROUND(I16*J16,2) -> 4988.08
A17: =VLOOKUP(F17,'M.Cálc.Quant.'!B:T,4,FALSE) -> COMPOSIÇÃO | C17: 1.1 | D17: =VLOOKUP(F17,'M.Cálc.Quant.'!B:T,2,FALSE) -> SINAPI | E17: =VLOOKUP(F17,'M.Cálc.Quant.'!B:T,3,FALSE) -> 99059 | F17: 1.1.2 | G17: =VLOOKUP(F17,'M.Cálc.Quant.'!G:T,2,FALSE) -> LOCAÇÃO CONVENCIONAL DE OBRA, UTILIZANDO GABARITO DE TÁBUAS CORRIDAS PONTALETADAS A CADA 2,00M - 2 UTILIZAÇÕES. AF_03/2024 | H17: =VLOOKUP(F17,'M.Cálc.Quant.'!G:T,14,FALSE) -> M | I17: =VLOOKUP(F17,'M.Cálc.Quant.'!G:T,13,FALSE) -> 106.5 | J17: =(1+$K$7)*IF(D17="GIDUR JP",VLOOKUP(E17,GIDUR!A:D,4,FALSE),IF(D17="DER PB",VLOOKUP(E17,DER!A:D,4,FALSE)/(1+DER!$E$2),IF(D17="COMPOSIÇÃO",VLOOKUP(E17,Composição!B:J,8,FALSE),IF(A17="COMPOSIÇÃO",VLOOKUP(E17,'Sinapi_Comp-06.2023'!G:K,5,FALSE),VLOOKUP(E17,'Sinapi_Insum-06.2023'!A:E,5,FALSE))))) -> 71.61 | K17: =IFERROR(ROUND(I17*J17,2),0) -> 7626.47 | L17: =(24+37)*2 -> 122 | M17: =ROUND(I17*J17,2) -> 7626.47
C18: 2 | F18: 1.2 | G18: =VLOOKUP(F18,'M.Cálc.Quant.'!G:T,2,FALSE) -> MOVIMENTO DE TERRA | K18: =K19 -> 5269.52 | M18: =ROUND(I18*J18,2) -> 0
A19: =VLOOKUP(F19,'M.Cálc.Quant.'!B:E,4,FALSE) -> 0 | C19: 3.2 | F19: ='M.Cálc.Quant.'!G20 -> 1.2 | G19: =VLOOKUP(F19,'M.Cálc.Quant.'!G:T,2,FALSE) -> MOVIMENTO DE TERRA | K19: =SUM(K20:K21) -> 5269.52 | M19: =ROUND(I19*J19,2) -> 0
A20: =VLOOKUP(F20,'M.Cálc.Quant.'!B:T,4,FALSE) -> COMPOSIÇÃO | C20: 2.1 | D20: =VLOOKUP(F20,'M.Cálc.Quant.'!B:T,2,FALSE) -> COMPOSIÇÃO | E20: =VLOOKUP(F20,'M.Cálc.Quant.'!B:T,3,FALSE) -> 8 | F20: ='M.Cálc.Quant.'!$G$21 -> 1.2.1 | G20: =VLOOKUP(F20,'M.Cálc.Quant.'!G:T,2,FALSE) -> ESCAVACAO MANUAL EM SOLO-PROF. ATE 1,50 M [ADAPTADO SINAPI 79561/001] | H20: =VLOOKUP(F20,'M.Cálc.Quant.'!G:T,14,FALSE) -> M3 | I20: =VLOOKUP(F20,'M.Cálc.Quant.'!G:T,13,FALSE) -> 74.74 | J20: =(1+$K$7)*IF(D20="GIDUR JP",VLOOKUP(E20,GIDUR!A:D,4,FALSE),IF(D20="DER PB",VLOOKUP(E20,DER!A:D,4,FALSE)/(1+DER!$E$2),IF(D20="COMPOSIÇÃO",VLOOKUP(E20,Composição!B:J,8,FALSE),IF(A20="COMPOSIÇÃO",VLOOKUP(E20,'Sinapi_Comp-06.2023'!G:K,5,FALSE),VLOOKUP(E20,'Sinapi_Insum-06.2023'!A:E,5,FALSE))))) -> 46.76 | K20: =IFERROR(ROUND(I20*J20,2),0) -> 3494.84 | L20: =27*44*0.8 -> 950.4 | M20: =ROUND(I20*J20,2) -> 3494.84
A21: =VLOOKUP(F21,'M.Cálc.Quant.'!B:T,4,FALSE) -> COMPOSIÇÃO | C21: 2.2 | D21: =VLOOKUP(F21,'M.Cálc.Quant.'!B:T,2,FALSE) -> SINAPI | E21: =VLOOKUP(F21,'M.Cálc.Quant.'!B:T,3,FALSE) -> 93382 | F21: ='M.Cálc.Quant.'!$G$33 -> 1.2.2 | G21: =VLOOKUP(F21,'M.Cálc.Quant.'!G:T,2,FALSE) -> REATERRO MANUAL DE VALAS, COM COMPACTADOR DE SOLOS DE PERCUSSÃO. AF_08/2023 | H21: =VLOOKUP(F21,'M.Cálc.Quant.'!G:T,14,FALSE) -> M3 | I21: =VLOOKUP(F21,'M.Cálc.Quant.'!G:T,13,FALSE) -> 63.7 | J21: =(1+$K$7)*IF(D21="GIDUR JP",VLOOKUP(E21,GIDUR!A:D,4,FALSE),IF(D21="DER PB",VLOOKUP(E21,DER!A:D,4,FALSE)/(1+DER!$E$2),IF(D21="COMPOSIÇÃO",VLOOKUP(E21,Composição!B:J,8,FALSE),IF(A21="COMPOSIÇÃO",VLOOKUP(E21,'Sinapi_Comp-06.2023'!G:K,5,FALSE),VLOOKUP(E21,'Sinapi_Insum-06.2023'!A:E,5,FALSE))))) -> 27.86 | K21: =IFERROR(ROUND(I21*J21,2),0) -> 1774.68 | L21: =27*44 -> 1188 | M21: =ROUND(I21*J21,2) -> 1774.68
C22: 3 | F22: 1.3 | G22: =VLOOKUP(F22,'M.Cálc.Quant.'!G:T,2,FALSE) -> INFRA-ESTRUTURA: FUNDAÇÕES (TODA A QUADRA) | K22: =K23 -> 70701.3 | M22: =ROUND(I22*J22,2) -> 0 | S22: =CONCATENATE(#REF!,".1") -> #REF! | T22: SINAPI PB | U22: INSUMO | V22: 6079 | W22: #N/A | X22: #N/A | Y22: 1.1 | Z22: =9.43*1.3024 -> 12.281632 | AA22: =ROUND(Z22*Y22,2) -> 13.51
C23: 3.2 | F23: 1.3.1 | G23: =VLOOKUP(F23,'M.Cálc.Quant.'!G:T,2,FALSE) -> SAPATAS ISOLADAS/ARRANQUE DOS PILARES | K23: =SUM(K24:K37) -> 70701.3 | M23: =ROUND(I23*J23,2) -> 0 | S23: =CONCATENATE(#REF!,".2") -> #REF! | T23: SINAPI PB | U23: COMPOSIÇÃO | V23: 88316 | W23: #N/A | X23: #N/A | Y23: 3 | Z23: =12.92*1.3024 -> 16.827008 | AA23: =ROUND(Z23*Y23,2) -> 50.48
A24: =VLOOKUP(F24,'M.Cálc.Quant.'!B:T,4,FALSE) -> COMPOSIÇÃO | C24: 3.3 | D24: =VLOOKUP(F24,'M.Cálc.Quant.'!B:T,2,FALSE) -> SINAPI | E24: =VLOOKUP(F24,'M.Cálc.Quant.'!B:T,3,FALSE) -> 101616 | F24: 1.3.1.1 | G24: =VLOOKUP(F24,'M.Cálc.Quant.'!G:T,2,FALSE) -> PREPARO DE FUNDO DE VALA COM LARGURA MENOR QUE 1,5 M (ACERTO DO SOLO NATURAL). AF_08/2020 | H24: =VLOOKUP(F24,'M.Cálc.Quant.'!G:T,14,FALSE) -> M2 | I24: =VLOOKUP(F24,'M.Cálc.Quant.'!G:T,13,FALSE) -> 64.24 | J24: =(1+$K$7)*IF(D24="GIDUR JP",VLOOKUP(E24,GIDUR!A:D,4,FALSE),IF(D24="DER PB",VLOOKUP(E24,DER!A:D,4,FALSE)/(1+DER!$E$2),IF(D24="COMPOSIÇÃO",VLOOKUP(E24,Composição!B:J,8,FALSE),IF(A24="COMPOSIÇÃO",VLOOKUP(E24,'Sinapi_Comp-06.2023'!G:K,5,FALSE),VLOOKUP(E24,'Sinapi_Insum-06.2023'!A:E,5,FALSE))))) -> 6.74 | K24: =IFERROR(ROUND(I24*J24,2),0) -> 432.98 | M24: =ROUND(I24*J24,2) -> 432.98
A25: =VLOOKUP(F25,'M.Cálc.Quant.'!B:T,4,FALSE) -> COMPOSIÇÃO | C25: 3.4 | D25: =VLOOKUP(F25,'M.Cálc.Quant.'!B:T,2,FALSE) -> COMPOSIÇÃO | E25: =VLOOKUP(F25,'M.Cálc.Quant.'!B:T,3,FALSE) -> 10 | F25: 1.3.1.2 | G25: =VLOOKUP(F25,'M.Cálc.Quant.'!G:T,2,FALSE) -> ALVENARIA EM TIJOLO CERAMICO FURADO 9X19X19CM, 1 VEZ (ESPESSURA 19 CM), ASSENTADO EM ARGAMASSA TRACO 1:4 (CIMENTO E AREIA MEDIA NAO PENEIRADA), PREPARO MANUAL, JUNTA1 CM [ADAPTADO SINAPI 73935/002] | H25: =VLOOKUP(F25,'M.Cálc.Quant.'!G:T,14,FALSE) -> M2 | I25: =VLOOKUP(F25,'M.Cálc.Quant.'!G:T,13,FALSE) -> 50.04 | J25: =(1+$K$7)*IF(D25="GIDUR JP",VLOOKUP(E25,GIDUR!A:D,4,FALSE),IF(D25="DER PB",VLOOKUP(E25,DER!A:D,4,FALSE)/(1+DER!$E$2),IF(D25="COMPOSIÇÃO",VLOOKUP(E25,Composição!B:J,8,FALSE),IF(A25="COMPOSIÇÃO",VLOOKUP(E25,'Sinapi_Comp-06.2023'!G:K,5,FALSE),VLOOKUP(E25,'Sinapi_Insum-06.2023'!A:E,5,FALSE))))) -> 122.67 | K25: =IFERROR(ROUND(I25*J25,2),0) -> 6138.41 | M25: =ROUND(I25*J25,2) -> 6138.41 | S25: 6 | T25: ALVENARIA EM TIJOLO CERAMICO FURADO 9X19X19CM, 1 VEZ (ESPESSURA 19 CM) , ASSENTADO ARGAMASSA TRACO 1:4 (CIMENTO E AREIA MEDIA NAO PENEIRADA), PREPARO MANUAL, JUNTA1 CM [ADAPTADO DE SINAPI 73935/002] | X25: M2 | Z25: =SUM(AA26:AA29) -> 79.61 | AB25: =Z25*253.76 -> 20201.834
A26: =VLOOKUP(F26,'M.Cálc.Quant.'!B:T,4,FALSE) -> COMPOSIÇÃO | C26: 3.5 | D26: =VLOOKUP(F26,'M.Cálc.Quant.'!B:T,2,FALSE) -> SINAPI | E26: =VLOOKUP(F26,'M.Cálc.Quant.'!B:T,3,FALSE) -> 96620 | F26: 1.3.1.3 | G26: =VLOOKUP(F26,'M.Cálc.Quant.'!G:T,2,FALSE) -> LASTRO DE CONCRETO MAGRO, APLICADO EM PISOS, LAJES SOBRE SOLO OU RADIERS. AF_01/2024 | H26: =VLOOKUP(F26,'M.Cálc.Quant.'!G:T,14,FALSE) -> M3 | I26: =VLOOKUP(F26,'M.Cálc.Quant.'!G:T,13,FALSE) -> 3.22 | J26: =(1+$K$7)*IF(D26="GIDUR JP",VLOOKUP(E26,GIDUR!A:D,4,FALSE),IF(D26="DER PB",VLOOKUP(E26,DER!A:D,4,FALSE)/(1+DER!$E$2),IF(D26="COMPOSIÇÃO",VLOOKUP(E26,Composição!B:J,8,FALSE),IF(A26="COMPOSIÇÃO",VLOOKUP(E26,'Sinapi_Comp-06.2023'!G:K,5,FALSE),VLOOKUP(E26,'Sinapi_Insum-06.2023'!A:E,5,FALSE))))) -> 860.29 | K26: =IFERROR(ROUND(I26*J26,2),0) -> 2770.13 | M26: =ROUND(I26*J26,2) -> 2770.13 | S26: =CONCATENATE(S25,".1") -> 6.1 | T26: SINAPI PB | U26: COMPOSIÇÃO | V26: 87373 | W26: #N/A | X26: #N/A | Y26: 0.0138 | Z26: =445.97*1.3024 -> 580.83133 | AA26: =ROUND(Z26*Y26,2) -> 8.02
