Workbook
Name activatedados.form2: IF(ISNUMBER(Eventograma_e_Quantitativos!$K1),Eventograma_e_Quantitativos!$K1&"-"&INDEX(Eventos,Eventograma_e_Quantitativos!$K1,2),"")
Name artExec: DADOS!$D$26
Name artFiscal: DADOS!$D$23
Name cargoTomador: DADOS!$C$30
Name creaExec: DADOS!$C$26
Name creaFiscal: DADOS!$C$23
Name creaPLE: DADOS!$C$20
Name Cronograma: Cronograma!$B$38:$BB$43
Name Cronograma.LinhaPadrão: Cronograma!$19:$19
Name Cronograma.MesesQuadro: COUNTA(OFFSET(Cronograma,0,0,,1))*4
Name Cronograma.NumPeríodos: MAX(Cronograma.Períodos)
Name Cronograma.Padrão: Cronograma!$B$38:$BB$43
Name Cronograma.Períodos: OFFSET(Cronograma!$E$33,1,0):OFFSET(Cronograma!$BB$38,-1,0)
Name Cronograma.Períodos.LinhaPadrão: Cronograma!$B$19:$BB$19
Name CronoPrev: OFFSET(CronoPrev!$B$13,1,0):OFFSET(CronoPrev!$G$26,-1,0)
Name CronoPrev.LinhaPadrão: CronoPrev!$B$8:$G$8
Name DADOS.LinhaPadrão: DADOS!$A$1:$C$1
Name dataInicioObra: DADOS!$H$13
Name deactivatedados.form1: IF(Eventograma_e_Quantitativos!B1="","",VALUE(LEFT(Eventograma_e_Quantitativos!B1,(FIND("-",Eventograma_e_Quantitativos!B1,1))-1)))
Name Detalhamento: OFFSET(Detalhamento!$A$16,1,0):OFFSET(Detalhamento!$A$40,-1,0)
Name Detalhamento.Filtro: Detalhamento!$A$16:$J$16
Name Detalhamento.Imprimir: Detalhamento!$E$2:OFFSET(Detalhamento!$K$43,0,MAX(TRUNC(numFrentes/6,0)+IF(MOD(numFrentes,6)<>0,1,0),1)*6)
Name Detalhamento.LinhaPadrão: Detalhamento!$1:$1
Name Detalhamento.OpçãoServiços: Detalhamento!$B$12
Name Detalhamento.OpçõesExibição: Detalhamento!$B$6:$B$7
Name Detalhamento.OpçõesServiços: Detalhamento!$B$9:$B$11
Name Eventograma_e_Quantitativos.Imprimir: Eventograma_e_Quantitativos!$C$4:OFFSET(Eventograma_e_Quantitativos!$M$44,0,MAX(TRUNC(numFrentes/6,0)+IF(MOD(numFrentes,6)<>0,1,0),1)*6)
Name Eventograma_e_Quantitativos.LinhaPadrão: Eventograma_e_Quantitativos!$1:$1
Name Eventos: OFFSET(DADOS!$A$33,1,0):OFFSET(DADOS!$C$38,-1,0)
Name EventosVariaveis: OFFSET(DADOS!$A$34,1,0):OFFSET(DADOS!$C$38,-1,0)
Name FaltaEvento: Eventograma_e_Quantitativos!$B$16
Name hoje: TODAY()
Name Import.Ação: DADOS!$F$7
Name Import.CNPJ: DADOS!$D$13
Name Import.Convênio: DADOS!$B$7
Name Import.CR: DADOS!$A$7
Name Import.CTEF: DADOS!$A$13
Name Import.DataAssinaturaCR: DADOS!$H$7
Name Import.DataInícioObra: DADOS!$H$13
Name Import.Descrição: Eventograma_e_Quantitativos!$E$18:$E$35
Name Import.Empresa: DADOS!$B$13
Name Import.FrenteDeObra: Eventograma_e_Quantitativos!$N$15:$BK$15
Name Import.Gestor: DADOS!$D$7
Name Import.Gigov: DADOS!$C$7
Name Import.Item: OFFSET(Eventograma_e_Quantitativos!$D$17,1,0):OFFSET(Eventograma_e_Quantitativos!$D$37,-1,0)
Name Import.Localidade: DADOS!$E$10
Name Import.Município: DADOS!$D$10
Name Import.numEventos: OFFSET(Eventograma_e_Quantitativos!$K$17,1,0):OFFSET(Eventograma_e_Quantitativos!$K$37,-1,0)
Name Import.ObjetoCR: DADOS!$F$10
Name Import.ObjetoCTEF: DADOS!$E$13
Name Import.PLE: OFFSET(PLE!$E$33,1,0):OFFSET(PLE!$BB$38,-1,0)
Name Import.PLQ: OFFSET(Eventograma_e_Quantitativos!$N$17,1,0):OFFSET(Eventograma_e_Quantitativos!$BK$37,-1,0)
Name Import.PreçoTotal: OFFSET(Eventograma_e_Quantitativos!$I$17,1,0):OFFSET(Eventograma_e_Quantitativos!$I$37,-1,0)
Name Import.Programa: DADOS!$E$7
Name Import.Proponente: DADOS!$A$10
Name Import.Unidade: OFFSET(Eventograma_e_Quantitativos!$F$17,1,0):OFFSET(Eventograma_e_Quantitativos!$F$37,-1,0)
Name Item: Eventograma_e_Quantitativos!$D1
Name LForçamento: OFFSET(Eventograma_e_Quantitativos!$37:$37,-1,0)
Name LIorçamento: OFFSET(Eventograma_e_Quantitativos!$17:$17,1,0)
Name mais_um: OFFSET(Detalhamento!A1,-1,0)+1

Sheet DADOS
A1: =OFFSET(A1,-1,0)+1 -> #REF! | J1: =CONCATENATE(A1,"-",B1) -> #REF!
A2: 27477 | B2: PLE - Planilha de Levantamento de Eventos
A3: v006
A6: Nº OPERAÇÃO | B6: Nº SICONV | C6: GIGOV | D6: GESTOR | E6: PROGRAMA | F6: AÇÃO / MODALIDADE | H6: DATA ASSINATURA
A7: 1080659-09 | B7: 923417/2021 | C7: JOÃO PESSOA | D7: MDR | E7: DESENVOLVIMENTO REGIONAL, TERRITORIAL E URBANO | F7: APOIO À POLITICA NACIONAL DE DESENVOLVIMENTO URBANO | H7: 44498
A9: PROPONENTE / TOMADOR | D9: MUNICÍPIO / UF | E9: LOCALIDADE / ENDEREÇO | F9: OBJETO
A10: PREFEITURA MUNICIPAL DE COREMAS | D10: COREMAS/PB | E10: ZONA URBANO | F10: PAVIMENTAÇÃO EM PARALELEPÍPEDO
A12: Nº CTEF | B12: EMPRESA EXECUTORA | D12: CNPJ | E12: OBJETO DO CTEF | H12: INÍCIO DA OBRA
A18: RESPONSÁVEIS TÉCNICOS:
A19: Elaboração do documento | C19: CREA/CAU
A22: Fiscalização | C22: CREA/CAU | D22: ART/RRT
A23: FERNANDO
A25: Execução | C25: CREA/CAU | D25: ART/RRT
A28: REPRESENTANTE TOMADOR / AG. PROMOTOR / TOMADOR
A29: Nome | C29: Cargo
A32: EVENTOS
A33: Núm do Evento | B33: Título do Evento
A34: 1 | B34: Administração Local | J34: =CONCATENATE(A34,"-",B34) -> 1-Administração Local
A35: =OFFSET(A35,-1,0)+1 -> 2 | B35: PAVIMENTAÇÃO | J35: =CONCATENATE(A35,"-",B35) -> 2-PAVIMENTAÇÃO
A36: =OFFSET(A36,-1,0)+1 -> 3 | B36: CALÇADAS E RAMPAS | J36: =CONCATENATE(A36,"-",B36) -> 3-CALÇADAS E RAMPAS
A37: =OFFSET(A37,-1,0)+1 -> 4 | B37: SINALIZAÇÃO E SERVIÇOS FINAIS | J37: =CONCATENATE(A37,"-",B37) -> 4-SINALIZAÇÃO E SERVIÇOS FINAIS
A40: INSTRUÇÕES DE USO E PREENCHIMENTO
A42: Informações gerais:
A44: 1. Este documento somente pode ser utilizado nas versões do Excel 2003 ou superior. Não devem ser utilizadas versões do BROffice.
A46: 2. Para funcionamento pleno desse arquivo, a Segurança de Macros do Excel deve ser habilitada.
A48: a. Na Versão Excel 2003, selecione na Faixa de Opções: Ferramentas --> Macro --> Segurança --> Na aba Nível de Segurança selecione a Opção "Baixo" --> Clique em OK --> Feche e abra o Excel novamente para utilizar a Planilha.
A49: b. Na Versão Excel 2007 ou superior, selecione na Faixa de Opções: Arquivo --> Opções --> Central de Confiabilidade --> Configurações da Central de Confiabilidade --> Configurações de Macro --> Habilitar todas as Macros --> Clique em OK --> Feche e abra o excel novamente para utilizar a Planilha.
A51: 3. O Preenchimento deve ser feito somente nas células em amarelo. As demais células são de preenchimento Automático e estão bloqueadas para edição.
A53: Instruções de preenchimento:
A55: Aba DADOS
A57: 1º passo: Na aba Dados, preencher os dados do contrato e identificação dos responsáveis;
A59: 2º passo: Incluir e nomear os eventos (pode ser alterado posteriormente também);
A61: Aba EVENTOGRAMA E QUANTITATIVOS
... A125: VT - VITORIA

Sheet Eventograma_e_Quantitativos
B1: =ROW(Nível)-ROW(LIorçamento)+1 -> -16 | C1: =IF(D1="","",IF(ISNUMBER(VALUE(D1)),"Meta",IF(AND(F1<>"",I1<>""),"Serviço","Nível"))) | G1: =IF(Nível="Serviço",SUMIF($N$15:$BK$15,"<>"&"",N1:BK1),"") | H1: =IF(AND(ISNUMBER(G1),G1<>0),I1/G1,IF(G1=0,0,"")) | K1: =IF(L1="","",VALUE(LEFT(L1,(FIND("-",L1,1))-1))) | BM1: =IF(N$15="",0,IF(ISNUMBER(PreçoUnit),PreçoUnit*INDEX(Import.PLQ,$B1,BM$16),0)) -> 0 | BN1: =IF(O$15="",0,IF(ISNUMBER(PreçoUnit),PreçoUnit*INDEX(Import.PLQ,$B1,BN$16),0)) -> 0 | BO1: =IF(P$15="",0,IF(ISNUMBER(PreçoUnit),PreçoUnit*INDEX(Import.PLQ,$B1,BO$16),0)) -> 0 | BP1: =IF(Q$15="",0,IF(ISNUMBER(PreçoUnit),PreçoUnit*INDEX(Import.PLQ,$B1,BP$16),0)) -> 0 | BQ1: =IF(R$15="",0,IF(ISNUMBER(PreçoUnit),PreçoUnit*INDEX(Import.PLQ,$B1,BQ$16),0)) -> 0 | BR1: =IF(S$15="",0,IF(ISNUMBER(PreçoUnit),PreçoUnit*INDEX(Import.PLQ,$B1,BR$16),0)) -> 0 | BS1: =IF(T$15="",0,IF(ISNUMBER(PreçoUnit),PreçoUnit*INDEX(Import.PLQ,$B1,BS$16),0)) -> 0 | BT1: =IF(U$15="",0,IF(ISNUMBER(PreçoUnit),PreçoUnit*INDEX(Import.PLQ,$B1,BT$16),0)) -> 0 | ... DJ1: =IF(BK$15="",0,IF(ISNUMBER(PreçoUnit),PreçoUnit*INDEX(Import.PLQ,$B1,DJ$16),0)) -> 0 | DK1: =IF(D1="",0,IF(ISNUMBER(VALUE(D1)),VALUE(D1),LEFT(D1,FIND(".",D1)-1))) -> 0 | DL1: =SUM(DM1:FJ1) -> 0 | DM1: =IF($K1<>1,IF(ISNUMBER(INDEX(Import.PLE,$K1,DM$16)),IF(INDEX(Import.PLE,$K1,DM$16)<=mediçao,BM1,0),0),PLE!$AA$28*BM1) -> 0 | DN1: =IF($K1<>1,IF(ISNUMBER(INDEX(Import.PLE,$K1,DN$16)),IF(INDEX(Import.PLE,$K1,DN$16)<=mediçao,BN1,0),0),PLE!$AA$28*BN1) -> 0 | DO1: =IF($K1<>1,IF(ISNUMBER(INDEX(Import.PLE,$K1,DO$16)),IF(INDEX(Import.PLE,$K1,DO$16)<=mediçao,BO1,0),0),PLE!$AA$28*BO1) -> 0 | DP1: =IF($K1<>1,IF(ISNUMBER(INDEX(Import.PLE,$K1,DP$16)),IF(INDEX(Import.PLE,$K1,DP$16)<=mediçao,BP1,0),0),PLE!$AA$28*BP1) -> 0 | DQ1: =IF($K1<>1,IF(ISNUMBER(INDEX(Import.PLE,$K1,DQ$16)),IF(INDEX(Import.PLE,$K1,DQ$16)<=mediçao,BQ1,0),0),PLE!$AA$28*BQ1) -> 0 | DR1: =IF($K1<>1,IF(ISNUMBER(INDEX(Import.PLE,$K1,DR$16)),IF(INDEX(Import.PLE,$K1,DR$16)<=mediçao,BR1,0),0),PLE!$AA$28*BR1) -> 0 | DS1: =IF($K1<>1,IF(ISNUMBER(INDEX(Import.PLE,$K1,DS$16)),IF(INDEX(Import.PLE,$K1,DS$16)<=mediçao,BS1,0),0),PLE!$AA$28*BS1) -> 0 | DT1: =IF($K1<>1,IF(ISNUMBER(INDEX(Import.PLE,$K1,DT$16)),IF(INDEX(Import.PLE,$K1,DT$16)<=mediçao,BT1,0),0),PLE!$AA$28*BT1) -> 0 | ... FJ1: =IF($K1<>1,IF(ISNUMBER(INDEX(Import.PLE,$K1,FJ$16)),IF(INDEX(Import.PLE,$K1,FJ$16)<=mediçao,DJ1,0),0),PLE!$AA$28*DJ1) -> 0
B3: =ROW(Nível)-ROW(LIorçamento)+1 -> -14 | C3: Evento | D3: Evento | E3: =INDEX(Eventos,K3,2) -> #VALUE! | F3: R$ | G3: =IF(Nível="Serviço",SUMIF($N$15:$BK$15,"<>"&"",N3:BK3),"") | H3: =IF(AND(ISNUMBER(G3),G3<>0),I3/G3,IF(G3=0,0,"")) | I3: =SUM(N3:BK3) -> 0 | K3: =INDEX(Eventos,ROW(Nível)-ROW(LForçamento),1) -> #VALUE! | L3: =IF(AND(NumEvento<>"",Nível="Serviço"),INDEX(Eventos,NumEvento,2),"") -> #VALUE! | N3: =IF(N$15="",0,SUMIF(Import.numEventos,$K3,OFFSET(PreçoServiçoPorFrente,0,N$16-1,,1))) -> 0 | O3: =IF(O$15="",0,SUMIF(Import.numEventos,$K3,OFFSET(PreçoServiçoPorFrente,0,O$16-1,,1))) -> 0 | P3: =IF(P$15="",0,SUMIF(Import.numEventos,$K3,OFFSET(PreçoServiçoPorFrente,0,P$16-1,,1))) -> 0 | Q3: =IF(Q$15="",0,SUMIF(Import.numEventos,$K3,OFFSET(PreçoServiçoPorFrente,0,Q$16-1,,1))) -> 0 | R3: =IF(R$15="",0,SUMIF(Import.numEventos,$K3,OFFSET(PreçoServiçoPorFrente,0,R$16-1,,1))) -> 0 | S3: =IF(S$15="",0,SUMIF(Import.numEventos,$K3,OFFSET(PreçoServiçoPorFrente,0,S$16-1,,1))) -> 0 | T3: =IF(T$15="",0,SUMIF(Import.numEventos,$K3,OFFSET(PreçoServiçoPorFrente,0,T$16-1,,1))) -> 0 | U3: =IF(U$15="",0,SUMIF(Import.numEventos,$K3,OFFSET(PreçoServiçoPorFrente,0,U$16-1,,1))) -> 0 | ... BK3: =IF(BK$15="",0,SUMIF(Import.numEventos,$K3,OFFSET(PreçoServiçoPorFrente,0,BK$16-1,,1))) -> 0
E4: PLE - Planilha de Levantamento de Eventos Eventograma e Quantitativos | R4: Grau de Sigilo #PUBLICO | X4: Grau de Sigilo #PUBLICO | AD4: Grau de Sigilo #PUBLICO | AJ4: Grau de Sigilo #PUBLICO | AP4: Grau de Sigilo #PUBLICO | AV4: Grau de Sigilo #PUBLICO | BB4: Grau de Sigilo #PUBLICO | BH4: Grau de Sigilo #PUBLICO
BM14: Preço do Serviço por frente | DM14: Preço dos Serviços executados
C15: ="Valor Total do Orçamento: R$ "&TEXT(SUMIF(C18:C40,"Serviço",I18:I40),"#.#0,00") -> Valor Total do Orçamento: R$ 797.972,21 | L15: Frentes de Obra: | N15: Rua Oficial de Justiça Vicente Gregório Antão | O15: Rua Francisca Garrido de Sousa | P15: Rua Francisco Batista Silva | Q15: Rua Bartolomeu Buriti | R15: Rua Maria Farias de Assis | S15: Rua Roberto Wilson Moura | T15: Rua Cícero Eufrásio da Silva | U15: Rua Firmino da Silva Lacerda
B16: =COUNTA(OFFSET(Eventograma_e_Quantitativos!$K$17,1,0):OFFSET(Eventograma_e_Quantitativos!$K$37,-1,0))-COUNTBLANK(OFFSET(Eventograma_e_Quantitativos!$L$17,1,0):OFFSET(Eventograma_e_Quantitativos!$L$37,-1,0))<COUNTIF(OFFSET(Eventograma_e_Quantitativos!$C$17,1,0):OFFSET(Eventograma_e_Quantitativos!$C$37,-1,0),"Serviço") -> FALSE | C16: Nível | D16: Item | E16: Descrição | F16: Unid. | G16: Qtde. | H16: Preço Unit. (R$) | I16: Preço Total (R$) | K16: Núm. Evento | L16: Agrupador de Eventos | N16: 1 | O16: 2 | P16: 3 | Q16: 4 | R16: 5 | S16: 6 | T16: 7 | U16: 8 | V16: 9 | W16: 10 | X16: 11 | Y16: 12 | Z16: 13 | AA16: 14 | AB16: 15 | AC16: 16 | AD16: 17 | AE16: 18 | AF16: 19 | AG16: 20 | AH16: 21 | AI16: 22 | AJ16: 23 | AK16: 24 | AL16: 25 | AM16: 26 | AN16: 27 | AO16: 28 | AP16: 29 | AQ16: 30 | AR16: 31 | AS16: 32 | AT16: 33 | AU16: 34 | AV16: 35 | AW16: 36 | AX16: 37 | AY16: 38 | AZ16: 39 | BA16: 40 | BB16: 41 | BC16: 42 | BD16: 43 | BE16: 44 | BF16: 45 | BG16: 46 | BH16: 47 | BI16: 48 | BJ16: 49 | BK16: 50 | BM16: 1 | BN16: 2 | BO16: 3 | BP16: 4 | BQ16: 5 | BR16: 6 | BS16: 7 | BT16: 8 | BU16: 9 | BV16: 10 | BW16: 11 | BX16: 12 | BY16: 13 | BZ16: 14 | CA16: 15 | CB16: 16 | CC16: 17 | CD16: 18 | CE16: 19 | CF16: 20 | CG16: 21 | CH16: 22 | CI16: 23 | CJ16: 24 | CK16: 25 | CL16: 26 | CM16: 27 | CN16: 28 | CO16: 29 | CP16: 30 | CQ16: 31 | CR16: 32 | CS16: 33 | CT16: 34 | CU16: 35 | CV16: 36 | CW16: 37 | CX16: 38 | CY16: 39 | CZ16: 40 | DA16: 41 | DB16: 42 | DC16: 43 | DD16: 44 | DE16: 45 | DF16: 46 | DG16: 47 | DH16: 48 | DI16: 49 | DJ16: 50 | DK16: meta | DM16: 1 | DN16: 2 | DO16: 3 | DP16: 4 | DQ16: 5 | DR16: 6 | DS16: 7 | DT16: 8 | DU16: 9 | DV16: 10 | DW16: 11 | DX16: 12 | DY16: 13 | DZ16: 14 | EA16: 15 | EB16: 16 | EC16: 17 | ED16: 18 | EE16: 19 | EF16: 20 | EG16: 21 | EH16: 22 | EI16: 23 | EJ16: 24 | EK16: 25 | EL16: 26 | EM16: 27 | EN16: 28 | EO16: 29 | EP16: 30 | EQ16: 31 | ER16: 32 | ES16: 33 | ET16: 34 | EU16: 35 | EV16: 36 | EW16: 37 | EX16: 38 | EY16: 39 | EZ16: 40 | FA16: 41 | FB16: 42 | FC16: 43 | FD16: 44 | FE16: 45 | FF16: 46 | FG16: 47 | FH16: 48 | FI16: 49 | FJ16: 50
B18: =ROW(Nível)-ROW(LIorçamento)+1 -> 1 | C18: =IF(D18="","",IF(ISNUMBER(VALUE(D18)),"Meta",IF(AND(F18<>"",I18<>""),"Serviço","Nível"))) -> Nível | D18: I | E18: PAVIMENTAÇÃO DE RUAS | G18: =IF(Nível="Serviço",SUMIF($N$15:$BK$15,"<>"&"",N18:BK18),"") | H18: =IF(AND(ISNUMBER(G18),G18<>0),I18/G18,IF(G18=0,0,"")) | K18: =deactivatedados.form1 | BM18: =IF(N$15="",0,IF(ISNUMBER(PreçoUnit),PreçoUnit*INDEX(Import.PLQ,$B18,BM$16),0)) -> 0 | BN18: =IF(O$15="",0,IF(ISNUMBER(PreçoUnit),PreçoUnit*INDEX(Import.PLQ,$B18,BN$16),0)) -> 0 | BO18: =IF(P$15="",0,IF(ISNUMBER(PreçoUnit),PreçoUnit*INDEX(Import.PLQ,$B18,BO$16),0)) -> 0 | BP18: =IF(Q$15="",0,IF(ISNUMBER(PreçoUnit),PreçoUnit*INDEX(Import.PLQ,$B18,BP$16),0)) -> 0 | BQ18: =IF(R$15="",0,IF(ISNUMBER(PreçoUnit),PreçoUnit*INDEX(Import.PLQ,$B18,BQ$16),0)) -> 0 | BR18: =IF(S$15="",0,IF(ISNUMBER(PreçoUnit),PreçoUnit*INDEX(Import.PLQ,$B18,BR$16),0)) -> 0 | BS18: =IF(T$15="",0,IF(ISNUMBER(PreçoUnit),PreçoUnit*INDEX(Import.PLQ,$B18,BS$16),0)) -> 0 | BT18: =IF(U$15="",0,IF(ISNUMBER(PreçoUnit),PreçoUnit*INDEX(Import.PLQ,$B18,BT$16),0)) -> 0 | ... DJ18: =IF(BK$15="",0,IF(ISNUMBER(PreçoUnit),PreçoUnit*INDEX(Import.PLQ,$B18,DJ$16),0)) -> 0 | DK18: =IF(D18="",0,IF(ISNUMBER(VALUE(D18)),VALUE(D18),LEFT(D18,FIND(".",D18)-1))) -> #VALUE! | DL18: =SUM(DM18:FJ18) -> 0 | DM18: =IF($K18<>1,IF(ISNUMBER(INDEX(Import.PLE,$K18,DM$16)),IF(INDEX(Import.PLE,$K18,DM$16)<=mediçao,BM18,0),0),PLE!$AA$28*BM18) -> 0 | DN18: =IF($K18<>1,IF(ISNUMBER(INDEX(Import.PLE,$K18,DN$16)),IF(INDEX(Import.PLE,$K18,DN$16)<=mediçao,BN18,0),0),PLE!$AA$28*BN18) -> 0 | DO18: =IF($K18<>1,IF(ISNUMBER(INDEX(Import.PLE,$K18,DO$16)),IF(INDEX(Import.PLE,$K18,DO$16)<=mediçao,BO18,0),0),PLE!$AA$28*BO18) -> 0 | DP18: =IF($K18<>1,IF(ISNUMBER(INDEX(Import.PLE,$K18,DP$16)),IF(INDEX(Import.PLE,$K18,DP$16)<=mediçao,BP18,0),0),PLE!$AA$28*BP18) -> 0 | DQ18: =IF($K18<>1,IF(ISNUMBER(INDEX(Import.PLE,$K18,DQ$16)),IF(INDEX(Import.PLE,$K18,DQ$16)<=mediçao,BQ18,0),0),PLE!$AA$28*BQ18) -> 0 | DR18: =IF($K18<>1,IF(ISNUMBER(INDEX(Import.PLE,$K18,DR$16)),IF(INDEX(Import.PLE,$K18,DR$16)<=mediçao,BR18,0),0),PLE!$AA$28*BR18) -> 0 | DS18: =IF($K18<>1,IF(ISNUMBER(INDEX(Import.PLE,$K18,DS$16)),IF(INDEX(Import.PLE,$K18,DS$16)<=mediçao,BS18,0),0),PLE!$AA$28*BS18) -> 0 | DT18: =IF($K18<>1,IF(ISNUMBER(INDEX(Import.PLE,$K18,DT$16)),IF(INDEX(Import.PLE,$K18,DT$16)<=mediçao,BT18,0),0),PLE!$AA$28*BT18) -> 0 | ... FJ18: =IF($K18<>1,IF(ISNUMBER(INDEX(Import.PLE,$K18,FJ$16)),IF(INDEX(Import.PLE,$K18,FJ$16)<=mediçao,DJ18,0),0),PLE!$AA$28*DJ18) -> 0
B19: =ROW(Nível)-ROW(LIorçamento)+1 -> 2 | C19: =IF(D19="","",IF(ISNUMBER(VALUE(D19)),"Meta",IF(AND(F19<>"",I19<>""),"Serviço","Nível"))) -> Meta | D19: 1 | E19: SERVIÇOS PRELIMINARES | G19: =IF(Nível="Serviço",SUMIF($N$15:$BK$15,"<>"&"",N19:BK19),"") | H19: =IF(AND(ISNUMBER(G19),G19<>0),I19/G19,IF(G19=0,0,"")) | K19: =deactivatedados.form1 | BM19: =IF(N$15="",0,IF(ISNUMBER(PreçoUnit),PreçoUnit*INDEX(Import.PLQ,$B19,BM$16),0)) -> 0 | BN19: =IF(O$15="",0,IF(ISNUMBER(PreçoUnit),PreçoUnit*INDEX(Import.PLQ,$B19,BN$16),0)) -> 0 | BO19: =IF(P$15="",0,IF(ISNUMBER(PreçoUnit),PreçoUnit*INDEX(Import.PLQ,$B19,BO$16),0)) -> 0 | BP19: =IF(Q$15="",0,IF(ISNUMBER(PreçoUnit),PreçoUnit*INDEX(Import.PLQ,$B19,BP$16),0)) -> 0 | BQ19: =IF(R$15="",0,IF(ISNUMBER(PreçoUnit),PreçoUnit*INDEX(Import.PLQ,$B19,BQ$16),0)) -> 0 | BR19: =IF(S$15="",0,IF(ISNUMBER(PreçoUnit),PreçoUnit*INDEX(Import.PLQ,$B19,BR$16),0)) -> 0 | BS19: =IF(T$15="",0,IF(ISNUMBER(PreçoUnit),PreçoUnit*INDEX(Import.PLQ,$B19,BS$16),0)) -> 0 | BT19: =IF(U$15="",0,IF(ISNUMBER(PreçoUnit),PreçoUnit*INDEX(Import.PLQ,$B19,BT$16),0)) -> 0 | ... DJ19: =IF(BK$15="",0,IF(ISNUMBER(PreçoUnit),PreçoUnit*INDEX(Import.PLQ,$B19,DJ$16),0)) -> 0 | DK19: =IF(D19="",0,IF(ISNUMBER(VALUE(D19)),VALUE(D19),LEFT(D19,FIND(".",D19)-1))) -> 1 | DL19: =SUM(DM19:FJ19) -> 0 | DM19: =IF($K19<>1,IF(ISNUMBER(INDEX(Import.PLE,$K19,DM$16)),IF(INDEX(Import.PLE,$K19,DM$16)<=mediçao,BM19,0),0),PLE!$AA$28*BM19) -> 0 | DN19: =IF($K19<>1,IF(ISNUMBER(INDEX(Import.PLE,$K19,DN$16)),IF(INDEX(Import.PLE,$K19,DN$16)<=mediçao,BN19,0),0),PLE!$AA$28*BN19) -> 0 | DO19: =IF($K19<>1,IF(ISNUMBER(INDEX(Import.PLE,$K19,DO$16)),IF(INDEX(Import.PLE,$K19,DO$16)<=mediçao,BO19,0),0),PLE!$AA$28*BO19) -> 0 | DP19: =IF($K19<>1,IF(ISNUMBER(INDEX(Import.PLE,$K19,DP$16)),IF(INDEX(Import.PLE,$K19,DP$16)<=mediçao,BP19,0),0),PLE!$AA$28*BP19) -> 0 | DQ19: =IF($K19<>1,IF(ISNUMBER(INDEX(Import.PLE,$K19,DQ$16)),IF(INDEX(Import.PLE,$K19,DQ$16)<=mediçao,BQ19,0),0),PLE!$AA$28*BQ19) -> 0 | DR19: =IF($K19<>1,IF(ISNUMBER(INDEX(Import.PLE,$K19,DR$16)),IF(INDEX(Import.PLE,$K19,DR$16)<=mediçao,BR19,0),0),PLE!$AA$28*BR19) -> 0 | DS19: =IF($K19<>1,IF(ISNUMBER(INDEX(Import.PLE,$K19,DS$16)),IF(INDEX(Import.PLE,$K19,DS$16)<=mediçao,BS19,0),0),PLE!$AA$28*BS19) -> 0 | DT19: =IF($K19<>1,IF(ISNUMBER(INDEX(Import.PLE,$K19,DT$16)),IF(INDEX(Import.PLE,$K19,DT$16)<=mediçao,BT19,0),0),PLE!$AA$28*BT19) -> 0 | ... FJ19: =IF($K19<>1,IF(ISNUMBER(INDEX(Import.PLE,$K19,FJ$16)),IF(INDEX(Import.PLE,$K19,FJ$16)<=mediçao,DJ19,0),0),PLE!$AA$28*DJ19) -> 0
B20: =ROW(Nível)-ROW(LIorçamento)+1 -> 3 | C20: =IF(D20="","",IF(ISNUMBER(VALUE(D20)),"Meta",IF(AND(F20<>"",I20<>""),"Serviço","Nível"))) -> Serviço | D20: 1.1 | E20: Placa indicativa da obra em chapa de aço galvanizado (4,0m x 2,0m) | F20: m² | G20: =IF(Nível="Serviço",SUMIF($N$15:$BK$15,"<>"&"",N20:BK20),"") -> 8 | H20: =IF(AND(ISNUMBER(G20),G20<>0),I20/G20,IF(G20=0,0,"")) -> 170.69 | I20: 1365.52 | K20: =deactivatedados.form1 -> 2 | L20: 2-PAVIMENTAÇÃO | N20: 8 | O20: 0 | P20: 0 | Q20: 0 | R20: 0 | S20: 0 | T20: 0 | U20: 0 | BM20: =IF(N$15="",0,IF(ISNUMBER(PreçoUnit),PreçoUnit*INDEX(Import.PLQ,$B20,BM$16),0)) -> 1365.52 | BN20: =IF(O$15="",0,IF(ISNUMBER(PreçoUnit),PreçoUnit*INDEX(Import.PLQ,$B20,BN$16),0)) -> 0 | BO20: =IF(P$15="",0,IF(ISNUMBER(PreçoUnit),PreçoUnit*INDEX(Import.PLQ,$B20,BO$16),0)) -> 0 | BP20: =IF(Q$15="",0,IF(ISNUMBER(PreçoUnit),PreçoUnit*INDEX(Import.PLQ,$B20,BP$16),0)) -> 0 | BQ20: =IF(R$15="",0,IF(ISNUMBER(PreçoUnit),PreçoUnit*INDEX(Import.PLQ,$B20,BQ$16),0)) -> 0 | BR20: =IF(S$15="",0,IF(ISNUMBER(PreçoUnit),PreçoUnit*INDEX(Import.PLQ,$B20,BR$16),0)) -> 0 | BS20: =IF(T$15="",0,IF(ISNUMBER(PreçoUnit),PreçoUnit*INDEX(Import.PLQ,$B20,BS$16),0)) -> 0 | BT20: =IF(U$15="",0,IF(ISNUMBER(PreçoUnit),PreçoUnit*INDEX(Import.PLQ,$B20,BT$16),0)) -> 0 | ... DJ20: =IF(BK$15="",0,IF(ISNUMBER(PreçoUnit),PreçoUnit*INDEX(Import.PLQ,$B20,DJ$16),0)) -> 0 | DK20: =IF(D20="",0,IF(ISNUMBER(VALUE(D20)),VALUE(D20),LEFT(D20,FIND(".",D20)-1))) -> 1 | DL20: =SUM(DM20:FJ20) -> 0 | DM20: =IF($K20<>1,IF(ISNUMBER(INDEX(Import.PLE,$K20,DM$16)),IF(INDEX(Import.PLE,$K20,DM$16)<=mediçao,BM20,0),0),PLE!$AA$28*BM20) -> 0 | DN20: =IF($K20<>1,IF(ISNUMBER(INDEX(Import.PLE,$K20,DN$16)),IF(INDEX(Import.PLE,$K20,DN$16)<=mediçao,BN20,0),0),PLE!$AA$28*BN20) -> 0 | DO20: =IF($K20<>1,IF(ISNUMBER(INDEX(Import.PLE,$K20,DO$16)),IF(INDEX(Import.PLE,$K20,DO$16)<=mediçao,BO20,0),0),PLE!$AA$28*BO20) -> 0 | DP20: =IF($K20<>1,IF(ISNUMBER(INDEX(Import.PLE,$K20,DP$16)),IF(INDEX(Import.PLE,$K20,DP$16)<=mediçao,BP20,0),0),PLE!$AA$28*BP20) -> 0 | DQ20: =IF($K20<>1,IF(ISNUMBER(INDEX(Import.PLE,$K20,DQ$16)),IF(INDEX(Import.PLE,$K20,DQ$16)<=mediçao,BQ20,0),0),PLE!$AA$28*BQ20) -> 0 | DR20: =IF($K20<>1,IF(ISNUMBER(INDEX(Import.PLE,$K20,DR$16)),IF(INDEX(Import.PLE,$K20,DR$16)<=mediçao,BR20,0),0),PLE!$AA$28*BR20) -> 0 | DS20: =IF($K20<>1,IF(ISNUMBER(INDEX(Import.PLE,$K20,DS$16)),IF(INDEX(Import.PLE,$K20,DS$16)<=mediçao,BS20,0),0),PLE!$AA$28*BS20) -> 0 | DT20: =IF($K20<>1,IF(ISNUMBER(INDEX(Import.PLE,$K20,DT$16)),IF(INDEX(Import.PLE,$K20,DT$16)<=mediçao,BT20,0),0),PLE!$AA$28*BT20) -> 0 | ... FJ20: =IF($K20<>1,IF(ISNUMBER(INDEX(Import.PLE,$K20,FJ$16)),IF(INDEX(Import.PLE,$K20,FJ$16)<=mediçao,DJ20,0),0),PLE!$AA$28*DJ20) -> 0
B21: =ROW(Nível)-ROW(LIorçamento)+1 -> 4 | C21: =IF(D21="","",IF(ISNUMBER(VALUE(D21)),"Meta",IF(AND(F21<>"",I21<>""),"Serviço","Nível"))) -> Meta | D21: 2 | E21: SERVIÇOS DE TERRAPLENAGEM | G21: =IF(Nível="Serviço",SUMIF($N$15:$BK$15,"<>"&"",N21:BK21),"") | H21: =IF(AND(ISNUMBER(G21),G21<>0),I21/G21,IF(G21=0,0,"")) | K21: =deactivatedados.form1 | BM21: =IF(N$15="",0,IF(ISNUMBER(PreçoUnit),PreçoUnit*INDEX(Import.PLQ,$B21,BM$16),0)) -> 0 | BN21: =IF(O$15="",0,IF(ISNUMBER(PreçoUnit),PreçoUnit*INDEX(Import.PLQ,$B21,BN$16),0)) -> 0 | BO21: =IF(P$15="",0,IF(ISNUMBER(PreçoUnit),PreçoUnit*INDEX(Import.PLQ,$B21,BO$16),0)) -> 0 | BP21: =IF(Q$15="",0,IF(ISNUMBER(PreçoUnit),PreçoUnit*INDEX(Import.PLQ,$B21,BP$16),0)) -> 0 | BQ21: =IF(R$15="",0,IF(ISNUMBER(PreçoUnit),PreçoUnit*INDEX(Import.PLQ,$B21,BQ$16),0)) -> 0 | BR21: =IF(S$15="",0,IF(ISNUMBER(PreçoUnit),PreçoUnit*INDEX(Import.PLQ,$B21,BR$16),0)) -> 0 | BS21: =IF(T$15="",0,IF(ISNUMBER(PreçoUnit),PreçoUnit*INDEX(Import.PLQ,$B21,BS$16),0)) -> 0 | BT21: =IF(U$15="",0,IF(ISNUMBER(PreçoUnit),PreçoUnit*INDEX(Import.PLQ,$B21,BT$16),0)) -> 0 | ... DJ21: =IF(BK$15="",0,IF(ISNUMBER(PreçoUnit),PreçoUnit*INDEX(Import.PLQ,$B21,DJ$16),0)) -> 0 | DK21: =IF(D21="",0,IF(ISNUMBER(VALUE(D21)),VALUE(D21),LEFT(D21,FIND(".",D21)-1))) -> 2 | DL21: =SUM(DM21:FJ21) -> 0 | DM21: =IF($K21<>1,IF(ISNUMBER(INDEX(Import.PLE,$K21,DM$16)),IF(INDEX(Import.PLE,$K21,DM$16)<=mediçao,BM21,0),0),PLE!$AA$28*BM21) -> 0 | DN21: =IF($K21<>1,IF(ISNUMBER(INDEX(Import.PLE,$K21,DN$16)),IF(INDEX(Import.PLE,$K21,DN$16)<=mediçao,BN21,0),0),PLE!$AA$28*BN21) -> 0 | DO21: =IF($K21<>1,IF(ISNUMBER(INDEX(Import.PLE,$K21,DO$16)),IF(INDEX(Import.PLE,$K21,DO$16)<=mediçao,BO21,0),0),PLE!$AA$28*BO21) -> 0 | DP21: =IF($K21<>1,IF(ISNUMBER(INDEX(Import.PLE,$K21,DP$16)),IF(INDEX(Import.PLE,$K21,DP$16)<=mediçao,BP21,0),0),PLE!$AA$28*BP21) -> 0 | DQ21: =IF($K21<>1,IF(ISNUMBER(INDEX(Import.PLE,$K21,DQ$16)),IF(INDEX(Import.PLE,$K21,DQ$16)<=mediçao,BQ21,0),0),PLE!$AA$28*BQ21) -> 0 | DR21: =IF($K21<>1,IF(ISNUMBER(INDEX(Import.PLE,$K21,DR$16)),IF(INDEX(Import.PLE,$K21,DR$16)<=mediçao,BR21,0),0),PLE!$AA$28*BR21) -> 0 | DS21: =IF($K21<>1,IF(ISNUMBER(INDEX(Import.PLE,$K21,DS$16)),IF(INDEX(Import.PLE,$K21,DS$16)<=mediçao,BS21,0),0),PLE!$AA$28*BS21) -> 0 | DT21: =IF($K21<>1,IF(ISNUMBER(INDEX(Import.PLE,$K21,DT$16)),IF(INDEX(Import.PLE,$K21,DT$16)<=mediçao,BT21,0),0),PLE!$AA$28*BT21) -> 0 | ... FJ21: =IF($K21<>1,IF(ISNUMBER(INDEX(Import.PLE,$K21,FJ$16)),IF(INDEX(Import.PLE,$K21,FJ$16)<=mediçao,DJ21,0),0),PLE!$AA$28*DJ21) -> 0
B22: =ROW(Nível)-ROW(LIorçamento)+1 -> 5 | C22: =IF(D22="","",IF(ISNUMBER(VALUE(D22)),"Meta",IF(AND(F22<>"",I22<>""),"Serviço","Nível"))) -> Serviço | D22: 2.1 | E22: Regularização e compactação de sub-leito até 20cm de espessura | F22: m² | G22: =IF(Nível="Serviço",SUMIF($N$15:$BK$15,"<>"&"",N22:BK22),"") -> 5349.12 | H22: =IF(AND(ISNUMBER(G22),G22<>0),I22/G22,IF(G22=0,0,"")) -> 2.5999996 | I22: 13907.71 | K22: =deactivatedados.form1 -> 2 | L22: 2-PAVIMENTAÇÃO | N22: 1102.85 | O22: 452.76 | P22: 727.62 | Q22: 1032.9 | R22: 390.01 | S22: 733.74 | T22: 523.8 | U22: 385.44 | BM22: =IF(N$15="",0,IF(ISNUMBER(PreçoUnit),PreçoUnit*INDEX(Import.PLQ,$B22,BM$16),0)) -> 2867.4096 | BN22: =IF(O$15="",0,IF(ISNUMBER(PreçoUnit),PreçoUnit*INDEX(Import.PLQ,$B22,BN$16),0)) -> 1177.1758 | BO22: =IF(P$15="",0,IF(ISNUMBER(PreçoUnit),PreçoUnit*INDEX(Import.PLQ,$B22,BO$16),0)) -> 1891.8117 | BP22: =IF(Q$15="",0,IF(ISNUMBER(PreçoUnit),PreçoUnit*INDEX(Import.PLQ,$B22,BP$16),0)) -> 2685.5396 | BQ22: =IF(R$15="",0,IF(ISNUMBER(PreçoUnit),PreçoUnit*INDEX(Import.PLQ,$B22,BQ$16),0)) -> 1014.0259 | BR22: =IF(S$15="",0,IF(ISNUMBER(PreçoUnit),PreçoUnit*INDEX(Import.PLQ,$B22,BR$16),0)) -> 1907.7237 | BS22: =IF(T$15="",0,IF(ISNUMBER(PreçoUnit),PreçoUnit*INDEX(Import.PLQ,$B22,BS$16),0)) -> 1361.8798 | BT22: =IF(U$15="",0,IF(ISNUMBER(PreçoUnit),PreçoUnit*INDEX(Import.PLQ,$B22,BT$16),0)) -> 1002.1439 | ... DJ22: =IF(BK$15="",0,IF(ISNUMBER(PreçoUnit),PreçoUnit*INDEX(Import.PLQ,$B22,DJ$16),0)) -> 0 | DK22: =IF(D22="",0,IF(ISNUMBER(VALUE(D22)),VALUE(D22),LEFT(D22,FIND(".",D22)-1))) -> 2 | DL22: =SUM(DM22:FJ22) -> 0 | DM22: =IF($K22<>1,IF(ISNUMBER(INDEX(Import.PLE,$K22,DM$16)),IF(INDEX(Import.PLE,$K22,DM$16)<=mediçao,BM22,0),0),PLE!$AA$28*BM22) -> 0 | DN22: =IF($K22<>1,IF(ISNUMBER(INDEX(Import.PLE,$K22,DN$16)),IF(INDEX(Import.PLE,$K22,DN$16)<=mediçao,BN22,0),0),PLE!$AA$28*BN22) -> 0 | DO22: =IF($K22<>1,IF(ISNUMBER(INDEX(Import.PLE,$K22,DO$16)),IF(INDEX(Import.PLE,$K22,DO$16)<=mediçao,BO22,0),0),PLE!$AA$28*BO22) -> 0 | DP22: =IF($K22<>1,IF(ISNUMBER(INDEX(Import.PLE,$K22,DP$16)),IF(INDEX(Import.PLE,$K22,DP$16)<=mediçao,BP22,0),0),PLE!$AA$28*BP22) -> 0 | DQ22: =IF($K22<>1,IF(ISNUMBER(INDEX(Import.PLE,$K22,DQ$16)),IF(INDEX(Import.PLE,$K22,DQ$16)<=mediçao,BQ22,0),0),PLE!$AA$28*BQ22) -> 0 | DR22: =IF($K22<>1,IF(ISNUMBER(INDEX(Import.PLE,$K22,DR$16)),IF(INDEX(Import.PLE,$K22,DR$16)<=mediçao,BR22,0),0),PLE!$AA$28*BR22) -> 0 | DS22: =IF($K22<>1,IF(ISNUMBER(INDEX(Import.PLE,$K22,DS$16)),IF(INDEX(Import.PLE,$K22,DS$16)<=mediçao,BS22,0),0),PLE!$AA$28*BS22) -> 0 | DT22: =IF($K22<>1,IF(ISNUMBER(INDEX(Import.PLE,$K22,DT$16)),IF(INDEX(Import.PLE,$K22,DT$16)<=mediçao,BT22,0),0),PLE!$AA$28*BT22) -> 0 | ... FJ22: =IF($K22<>1,IF(ISNUMBER(INDEX(Import.PLE,$K22,FJ$16)),IF(INDEX(Import.PLE,$K22,FJ$16)<=mediçao,DJ22,0),0),PLE!$AA$28*DJ22) -> 0
B23: =ROW(Nível)-ROW(LIorçamento)+1 -> 6 | C23: =IF(D23="","",IF(ISNUMBER(VALUE(D23)),"Meta",IF(AND(F23<>"",I23<>""),"Serviço","Nível"))) -> Meta | D23: 3 | E23: PAVIMENTAÇÃO | G23: =IF(Nível="Serviço",SUMIF($N$15:$BK$15,"<>"&"",N23:BK23),"") | H23: =IF(AND(ISNUMBER(G23),G23<>0),I23/G23,IF(G23=0,0,"")) | K23: =deactivatedados.form1 | BM23: =IF(N$15="",0,IF(ISNUMBER(PreçoUnit),PreçoUnit*INDEX(Import.PLQ,$B23,BM$16),0)) -> 0 | BN23: =IF(O$15="",0,IF(ISNUMBER(PreçoUnit),PreçoUnit*INDEX(Import.PLQ,$B23,BN$16),0)) -> 0 | BO23: =IF(P$15="",0,IF(ISNUMBER(PreçoUnit),PreçoUnit*INDEX(Import.PLQ,$B23,BO$16),0)) -> 0 | BP23: =IF(Q$15="",0,IF(ISNUMBER(PreçoUnit),PreçoUnit*INDEX(Import.PLQ,$B23,BP$16),0)) -> 0 | BQ23: =IF(R$15="",0,IF(ISNUMBER(PreçoUnit),PreçoUnit*INDEX(Import.PLQ,$B23,BQ$16),0)) -> 0 | BR23: =IF(S$15="",0,IF(ISNUMBER(PreçoUnit),PreçoUnit*INDEX(Import.PLQ,$B23,BR$16),0)) -> 0 | BS23: =IF(T$15="",0,IF(ISNUMBER(PreçoUnit),PreçoUnit*INDEX(Import.PLQ,$B23,BS$16),0)) -> 0 | BT23: =IF(U$15="",0,IF(ISNUMBER(PreçoUnit),PreçoUnit*INDEX(Import.PLQ,$B23,BT$16),0)) -> 0 | ... DJ23: =IF(BK$15="",0,IF(ISNUMBER(PreçoUnit),PreçoUnit*INDEX(Import.PLQ,$B23,DJ$16),0)) -> 0 | DK23: =IF(D23="",0,IF(ISNUMBER(VALUE(D23)),VALUE(D23),LEFT(D23,FIND(".",D23)-1))) -> 3 | DL23: =SUM(DM23:FJ23) -> 0 | DM23: =IF($K23<>1,IF(ISNUMBER(INDEX(Import.PLE,$K23,DM$16)),IF(INDEX(Import.PLE,$K23,DM$16)<=mediçao,BM23,0),0),PLE!$AA$28*BM23) -> 0 | DN23: =IF($K23<>1,IF(ISNUMBER(INDEX(Import.PLE,$K23,DN$16)),IF(INDEX(Import.PLE,$K23,DN$16)<=mediçao,BN23,0),0),PLE!$AA$28*BN23) -> 0 | DO23: =IF($K23<>1,IF(ISNUMBER(INDEX(Import.PLE,$K23,DO$16)),IF(INDEX(Import.PLE,$K23,DO$16)<=mediçao,BO23,0),0),PLE!$AA$28*BO23) -> 0 | DP23: =IF($K23<>1,IF(ISNUMBER(INDEX(Import.PLE,$K23,DP$16)),IF(INDEX(Import.PLE,$K23,DP$16)<=mediçao,BP23,0),0),PLE!$AA$28*BP23) -> 0 | DQ23: =IF($K23<>1,IF(ISNUMBER(INDEX(Import.PLE,$K23,DQ$16)),IF(INDEX(Import.PLE,$K23,DQ$16)<=mediçao,BQ23,0),0),PLE!$AA$28*BQ23) -> 0 | DR23: =IF($K23<>1,IF(ISNUMBER(INDEX(Import.PLE,$K23,DR$16)),IF(INDEX(Import.PLE,$K23,DR$16)<=mediçao,BR23,0),0),PLE!$AA$28*BR23) -> 0 | DS23: =IF($K23<>1,IF(ISNUMBER(INDEX(Import.PLE,$K23,DS$16)),IF(INDEX(Import.PLE,$K23,DS$16)<=mediçao,BS23,0),0),PLE!$AA$28*BS23) -> 0 | DT23: =IF($K23<>1,IF(ISNUMBER(INDEX(Import.PLE,$K23,DT$16)),IF(INDEX(Import.PLE,$K23,DT$16)<=mediçao,BT23,0),0),PLE!$AA$28*BT23) -> 0 | ... FJ23: =IF($K23<>1,IF(ISNUMBER(INDEX(Import.PLE,$K23,FJ$16)),IF(INDEX(Import.PLE,$K23,FJ$16)<=mediçao,DJ23,0),0),PLE!$AA$28*DJ23) -> 0
B24: =ROW(Nível)-ROW(LIorçamento)+1 -> 7 | C24: =IF(D24="","",IF(ISNUMBER(VALUE(D24)),"Meta",IF(AND(F24<>"",I24<>""),"Serviço","Nível"))) -> Serviço | D24: 3.1 | E24: Serviços topográficos para pavimentação (locação e nivelamento), inclusive nota de serviços, acompanhamento e greide | F24: m² | G24: =IF(Nível="Serviço",SUMIF($N$15:$BK$15,"<>"&"",N24:BK24),"") -> 5349.12 | H24: =IF(AND(ISNUMBER(G24),G24<>0),I24/G24,IF(G24=0,0,"")) -> 0.47999858 | I24: 2567.57 | K24: =deactivatedados.form1 -> 2 | L24: 2-PAVIMENTAÇÃO | N24: 1102.85 | O24: 452.76 | P24: 727.62 | Q24: 1032.9 | R24: 390.01 | S24: 733.74 | T24: 523.8 | U24: 385.44 | BM24: =IF(N$15="",0,IF(ISNUMBER(PreçoUnit),PreçoUnit*INDEX(Import.PLQ,$B24,BM$16),0)) -> 529.36643 | BN24: =IF(O$15="",0,IF(ISNUMBER(PreçoUnit),PreçoUnit*INDEX(Import.PLQ,$B24,BN$16),0)) -> 217.32416 | BO24: =IF(P$15="",0,IF(ISNUMBER(PreçoUnit),PreçoUnit*INDEX(Import.PLQ,$B24,BO$16),0)) -> 349.25657 | BP24: =IF(Q$15="",0,IF(ISNUMBER(PreçoUnit),PreçoUnit*INDEX(Import.PLQ,$B24,BP$16),0)) -> 495.79053 | BQ24: =IF(R$15="",0,IF(ISNUMBER(PreçoUnit),PreçoUnit*INDEX(Import.PLQ,$B24,BQ$16),0)) -> 187.20425 | BR24: =IF(S$15="",0,IF(ISNUMBER(PreçoUnit),PreçoUnit*INDEX(Import.PLQ,$B24,BR$16),0)) -> 352.19416 | BS24: =IF(T$15="",0,IF(ISNUMBER(PreçoUnit),PreçoUnit*INDEX(Import.PLQ,$B24,BS$16),0)) -> 251.42326 | BT24: =IF(U$15="",0,IF(ISNUMBER(PreçoUnit),PreçoUnit*INDEX(Import.PLQ,$B24,BT$16),0)) -> 185.01065 | ... DJ24: =IF(BK$15="",0,IF(ISNUMBER(PreçoUnit),PreçoUnit*INDEX(Import.PLQ,$B24,DJ$16),0)) -> 0 | DK24: =IF(D24="",0,IF(ISNUMBER(VALUE(D24)),VALUE(D24),LEFT(D24,FIND(".",D24)-1))) -> 3 | DL24: =SUM(DM24:FJ24) -> 0 | DM24: =IF($K24<>1,IF(ISNUMBER(INDEX(Import.PLE,$K24,DM$16)),IF(INDEX(Import.PLE,$K24,DM$16)<=mediçao,BM24,0),0),PLE!$AA$28*BM24) -> 0 | DN24: =IF($K24<>1,IF(ISNUMBER(INDEX(Import.PLE,$K24,DN$16)),IF(INDEX(Import.PLE,$K24,DN$16)<=mediçao,BN24,0),0),PLE!$AA$28*BN24) -> 0 | DO24: =IF($K24<>1,IF(ISNUMBER(INDEX(Import.PLE,$K24,DO$16)),IF(INDEX(Import.PLE,$K24,DO$16)<=mediçao,BO24,0),0),PLE!$AA$28*BO24) -> 0 | DP24: =IF($K24<>1,IF(ISNUMBER(INDEX(Import.PLE,$K24,DP$16)),IF(INDEX(Import.PLE,$K24,DP$16)<=mediçao,BP24,0),0),PLE!$AA$28*BP24) -> 0 | DQ24: =IF($K24<>1,IF(ISNUMBER(INDEX(Import.PLE,$K24,DQ$16)),IF(INDEX(Import.PLE,$K24,DQ$16)<=mediçao,BQ24,0),0),PLE!$AA$28*BQ24) -> 0 | DR24: =IF($K24<>1,IF(ISNUMBER(INDEX(Import.PLE,$K24,DR$16)),IF(INDEX(Import.PLE,$K24,DR$16)<=mediçao,BR24,0),0),PLE!$AA$28*BR24) -> 0 | DS24: =IF($K24<>1,IF(ISNUMBER(INDEX(Import.PLE,$K24,DS$16)),IF(INDEX(Import.PLE,$K24,DS$16)<=mediçao,BS24,0),0),PLE!$AA$28*BS24) -> 0 | DT24: =IF($K24<>1,IF(ISNUMBER(INDEX(Import.PLE,$K24,DT$16)),IF(INDEX(Import.PLE,$K24,DT$16)<=mediçao,BT24,0),0),PLE!$AA$28*BT24) -> 0 | ... FJ24: =IF($K24<>1,IF(ISNUMBER(INDEX(Import.PLE,$K24,FJ$16)),IF(INDEX(Import.PLE,$K24,FJ$16)<=mediçao,DJ24,0),0),PLE!$AA$28*DJ24) -> 0
B25: =ROW(Nível)-ROW(LIorçamento)+1 -> 8 | C25: =IF(D25="","",IF(ISNUMBER(VALUE(D25)),"Meta",IF(AND(F25<>"",I25<>""),"Serviço","Nível"))) -> Serviço | D25: 3.2 | E25: Assentamento de guia (meio-fio) em trecho reto, confeccionada em concreto pré-fabricado, dimensões 100x15x13x30 cm (comprimento x base inferior x base superior x altura), para vias urbanas (uso viário) | F25: m | G25: =IF(Nível="Serviço",SUMIF($N$15:$BK$15,"<>"&"",N25:BK25),"") -> 1740.41 | H25: =IF(AND(ISNUMBER(G25),G25<>0),I25/G25,IF(G25=0,0,"")) -> 54.370005 | I25: 94626.1 | K25: =deactivatedados.form1 -> 2 | L25: 2-PAVIMENTAÇÃO | N25: 353.89 | O25: 154.35 | P25: 215.58 | Q25: 348.78 | R25: 130.15 | S25: 241.91 | T25: 167.27 | U25: 128.48 | BM25: =IF(N$15="",0,IF(ISNUMBER(PreçoUnit),PreçoUnit*INDEX(Import.PLQ,$B25,BM$16),0)) -> 19241.001 | BN25: =IF(O$15="",0,IF(ISNUMBER(PreçoUnit),PreçoUnit*INDEX(Import.PLQ,$B25,BN$16),0)) -> 8392.0102 | BO25: =IF(P$15="",0,IF(ISNUMBER(PreçoUnit),PreçoUnit*INDEX(Import.PLQ,$B25,BO$16),0)) -> 11721.086 | BP25: =IF(Q$15="",0,IF(ISNUMBER(PreçoUnit),PreçoUnit*INDEX(Import.PLQ,$B25,BP$16),0)) -> 18963.17 | BQ25: =IF(R$15="",0,IF(ISNUMBER(PreçoUnit),PreçoUnit*INDEX(Import.PLQ,$B25,BQ$16),0)) -> 7076.2561 | BR25: =IF(S$15="",0,IF(ISNUMBER(PreçoUnit),PreçoUnit*INDEX(Import.PLQ,$B25,BR$16),0)) -> 13152.648 | BS25: =IF(T$15="",0,IF(ISNUMBER(PreçoUnit),PreçoUnit*INDEX(Import.PLQ,$B25,BS$16),0)) -> 9094.4707 | BT25: =IF(U$15="",0,IF(ISNUMBER(PreçoUnit),PreçoUnit*INDEX(Import.PLQ,$B25,BT$16),0)) -> 6985.4582 | ... DJ25: =IF(BK$15="",0,IF(ISNUMBER(PreçoUnit),PreçoUnit*INDEX(Import.PLQ,$B25,DJ$16),0)) -> 0 | DK25: =IF(D25="",0,IF(ISNUMBER(VALUE(D25)),VALUE(D25),LEFT(D25,FIND(".",D25)-1))) -> 3 | DL25: =SUM(DM25:FJ25) -> 0 | DM25: =IF($K25<>1,IF(ISNUMBER(INDEX(Import.PLE,$K25,DM$16)),IF(INDEX(Import.PLE,$K25,DM$16)<=mediçao,BM25,0),0),PLE!$AA$28*BM25) -> 0 | DN25: =IF($K25<>1,IF(ISNUMBER(INDEX(Import.PLE,$K25,DN$16)),IF(INDEX(Import.PLE,$K25,DN$16)<=mediçao,BN25,0),0),PLE!$AA$28*BN25) -> 0 | DO25: =IF($K25<>1,IF(ISNUMBER(INDEX(Import.PLE,$K25,DO$16)),IF(INDEX(Import.PLE,$K25,DO$16)<=mediçao,BO25,0),0),PLE!$AA$28*BO25) -> 0 | DP25: =IF($K25<>1,IF(ISNUMBER(INDEX(Import.PLE,$K25,DP$16)),IF(INDEX(Import.PLE,$K25,DP$16)<=mediçao,BP25,0),0),PLE!$AA$28*BP25) -> 0 | DQ25: =IF($K25<>1,IF(ISNUMBER(INDEX(Import.PLE,$K25,DQ$16)),IF(INDEX(Import.PLE,$K25,DQ$16)<=mediçao,BQ25,0),0),PLE!$AA$28*BQ25) -> 0 | DR25: =IF($K25<>1,IF(ISNUMBER(INDEX(Import.PLE,$K25,DR$16)),IF(INDEX(Import.PLE,$K25,DR$16)<=mediçao,BR25,0),0),PLE!$AA$28*BR25) -> 0 | DS25: =IF($K25<>1,IF(ISNUMBER(INDEX(Import.PLE,$K25,DS$16)),IF(INDEX(Import.PLE,$K25,DS$16)<=mediçao,BS25,0),0),PLE!$AA$28*BS25) -> 0 | DT25: =IF($K25<>1,IF(ISNUMBER(INDEX(Import.PLE,$K25,DT$16)),IF(INDEX(Import.PLE,$K25,DT$16)<=mediçao,BT25,0),0),PLE!$AA$28*BT25) -> 0 | ... FJ25: =IF($K25<>1,IF(ISNUMBER(INDEX(Import.PLE,$K25,FJ$16)),IF(INDEX(Import.PLE,$K25,FJ$16)<=mediçao,DJ25,0),0),PLE!$AA$28*DJ25) -> 0
B26: =ROW(Nível)-ROW(LIorçamento)+1 -> 9 | C26: =IF(D26="","",IF(ISNUMBER(VALUE(D26)),"Meta",IF(AND(F26<>"",I26<>""),"Serviço","Nível"))) -> Serviço | D26: 3.3 | E26: Revestimento em paralelepipedo inclusive colchão de areia rejuntado no traço 1:3 (Cimento e areia) | F26: m² | G26: =IF(Nível="Serviço",SUMIF($N$15:$BK$15,"<>"&"",N26:BK26),"") -> 5349.12 | H26: =IF(AND(ISNUMBER(G26),G26<>0),I26/G26,IF(G26=0,0,"")) -> 93.65 | I26: 500945.09 | K26: =deactivatedados.form1 -> 2 | L26: 2-PAVIMENTAÇÃO | N26: 1102.85 | O26: 452.76 | P26: 727.62 | Q26: 1032.9 | R26: 390.01 | S26: 733.74 | T26: 523.8 | U26: 385.44 | BM26: =IF(N$15="",0,IF(ISNUMBER(PreçoUnit),PreçoUnit*INDEX(Import.PLQ,$B26,BM$16),0)) -> 103281.9 | BN26: =IF(O$15="",0,IF(ISNUMBER(PreçoUnit),PreçoUnit*INDEX(Import.PLQ,$B26,BN$16),0)) -> 42400.974 | BO26: =IF(P$15="",0,IF(ISNUMBER(PreçoUnit),PreçoUnit*INDEX(Import.PLQ,$B26,BO$16),0)) -> 68141.613 | BP26: =IF(Q$15="",0,IF(ISNUMBER(PreçoUnit),PreçoUnit*INDEX(Import.PLQ,$B26,BP$16),0)) -> 96731.085 | BQ26: =IF(R$15="",0,IF(ISNUMBER(PreçoUnit),PreçoUnit*INDEX(Import.PLQ,$B26,BQ$16),0)) -> 36524.437 | BR26: =IF(S$15="",0,IF(ISNUMBER(PreçoUnit),PreçoUnit*INDEX(Import.PLQ,$B26,BR$16),0)) -> 68714.751 | BS26: =IF(T$15="",0,IF(ISNUMBER(PreçoUnit),PreçoUnit*INDEX(Import.PLQ,$B26,BS$16),0)) -> 49053.87 | BT26: =IF(U$15="",0,IF(ISNUMBER(PreçoUnit),PreçoUnit*INDEX(Import.PLQ,$B26,BT$16),0)) -> 36096.456 | ... DJ26: =IF(BK$15="",0,IF(ISNUMBER(PreçoUnit),PreçoUnit*INDEX(Import.PLQ,$B26,DJ$16),0)) -> 0 | DK26: =IF(D26="",0,IF(ISNUMBER(VALUE(D26)),VALUE(D26),LEFT(D26,FIND(".",D26)-1))) -> 3 | DL26: =SUM(DM26:FJ26) -> 0 | DM26: =IF($K26<>1,IF(ISNUMBER(INDEX(Import.PLE,$K26,DM$16)),IF(INDEX(Import.PLE,$K26,DM$16)<=mediçao,BM26,0),0),PLE!$AA$28*BM26) -> 0 | DN26: =IF($K26<>1,IF(ISNUMBER(INDEX(Import.PLE,$K26,DN$16)),IF(INDEX(Import.PLE,$K26,DN$16)<=mediçao,BN26,0),0),PLE!$AA$28*BN26) -> 0 | DO26: =IF($K26<>1,IF(ISNUMBER(INDEX(Import.PLE,$K26,DO$16)),IF(INDEX(Import.PLE,$K26,DO$16)<=mediçao,BO26,0),0),PLE!$AA$28*BO26) -> 0 | DP26: =IF($K26<>1,IF(ISNUMBER(INDEX(Import.PLE,$K26,DP$16)),IF(INDEX(Import.PLE,$K26,DP$16)<=mediçao,BP26,0),0),PLE!$AA$28*BP26) -> 0 | DQ26: =IF($K26<>1,IF(ISNUMBER(INDEX(Import.PLE,$K26,DQ$16)),IF(INDEX(Import.PLE,$K26,DQ$16)<=mediçao,BQ26,0),0),PLE!$AA$28*BQ26) -> 0 | DR26: =IF($K26<>1,IF(ISNUMBER(INDEX(Import.PLE,$K26,DR$16)),IF(INDEX(Import.PLE,$K26,DR$16)<=mediçao,BR26,0),0),PLE!$AA$28*BR26) -> 0 | DS26: =IF($K26<>1,IF(ISNUMBER(INDEX(Import.PLE,$K26,DS$16)),IF(INDEX(Import.PLE,$K26,DS$16)<=mediçao,BS26,0),0),PLE!$AA$28*BS26) -> 0 | DT26: =IF($K26<>1,IF(ISNUMBER(INDEX(Import.PLE,$K26,DT$16)),IF(INDEX(Import.PLE,$K26,DT$16)<=mediçao,BT26,0),0),PLE!$AA$28*BT26) -> 0 | ... FJ26: =IF($K26<>1,IF(ISNUMBER(INDEX(Import.PLE,$K26,FJ$16)),IF(INDEX(Import.PLE,$K26,FJ$16)<=mediçao,DJ26,0),0),PLE!$AA$28*DJ26) -> 0
B27: =ROW(Nível)-ROW(LIorçamento)+1 -> 10 | C27: =IF(D27="","",IF(ISNUMBER(VALUE(D27)),"Meta",IF(AND(F27<>"",I27<>""),"Serviço","Nível"))) -> Serviço | D27: 3.4 | E27: Fornecimento e aplicação de meio fio em pedra granitica.(Cordão) | F27: m | G27: =IF(Nível="Serviço",SUMIF($N$15:$BK$15,"<>"&"",N27:BK27),"") -> 50.8 | H27: =IF(AND(ISNUMBER(G27),G27<>0),I27/G27,IF(G27=0,0,"")) -> 36.560039 | I27: 1857.25 | K27: =deactivatedados.form1 -> 2 | L27: 2-PAVIMENTAÇÃO | N27: 8.8 | O27: 0 | P27: 12 | Q27: 6 | R27: 0 | S27: 6 | T27: 6 | U27: 12 | BM27: =IF(N$15="",0,IF(ISNUMBER(PreçoUnit),PreçoUnit*INDEX(Import.PLQ,$B27,BM$16),0)) -> 321.72835 | BN27: =IF(O$15="",0,IF(ISNUMBER(PreçoUnit),PreçoUnit*INDEX(Import.PLQ,$B27,BN$16),0)) -> 0 | BO27: =IF(P$15="",0,IF(ISNUMBER(PreçoUnit),PreçoUnit*INDEX(Import.PLQ,$B27,BO$16),0)) -> 438.72047 | BP27: =IF(Q$15="",0,IF(ISNUMBER(PreçoUnit),PreçoUnit*INDEX(Import.PLQ,$B27,BP$16),0)) -> 219.36024 | BQ27: =IF(R$15="",0,IF(ISNUMBER(PreçoUnit),PreçoUnit*INDEX(Import.PLQ,$B27,BQ$16),0)) -> 0 | BR27: =IF(S$15="",0,IF(ISNUMBER(PreçoUnit),PreçoUnit*INDEX(Import.PLQ,$B27,BR$16),0)) -> 219.36024 | BS27: =IF(T$15="",0,IF(ISNUMBER(PreçoUnit),PreçoUnit*INDEX(Import.PLQ,$B27,BS$16),0)) -> 219.36024 | BT27: =IF(U$15="",0,IF(ISNUMBER(PreçoUnit),PreçoUnit*INDEX(Import.PLQ,$B27,BT$16),0)) -> 438.72047 | ... DJ27: =IF(BK$15="",0,IF(ISNUMBER(PreçoUnit),PreçoUnit*INDEX(Import.PLQ,$B27,DJ$16),0)) -> 0 | DK27: =IF(D27="",0,IF(ISNUMBER(VALUE(D27)),VALUE(D27),LEFT(D27,FIND(".",D27)-1))) -> 3 | DL27: =SUM(DM27:FJ27) -> 0 | DM27: =IF($K27<>1,IF(ISNUMBER(INDEX(Import.PLE,$K27,DM$16)),IF(INDEX(Import.PLE,$K27,DM$16)<=mediçao,BM27,0),0),PLE!$AA$28*BM27) -> 0 | DN27: =IF($K27<>1,IF(ISNUMBER(INDEX(Import.PLE,$K27,DN$16)),IF(INDEX(Import.PLE,$K27,DN$16)<=mediçao,BN27,0),0),PLE!$AA$28*BN27) -> 0 | DO27: =IF($K27<>1,IF(ISNUMBER(INDEX(Import.PLE,$K27,DO$16)),IF(INDEX(Import.PLE,$K27,DO$16)<=mediçao,BO27,0),0),PLE!$AA$28*BO27) -> 0 | DP27: =IF($K27<>1,IF(ISNUMBER(INDEX(Import.PLE,$K27,DP$16)),IF(INDEX(Import.PLE,$K27,DP$16)<=mediçao,BP27,0),0),PLE!$AA$28*BP27) -> 0 | DQ27: =IF($K27<>1,IF(ISNUMBER(INDEX(Import.PLE,$K27,DQ$16)),IF(INDEX(Import.PLE,$K27,DQ$16)<=mediçao,BQ27,0),0),PLE!$AA$28*BQ27) -> 0 | DR27: =IF($K27<>1,IF(ISNUMBER(INDEX(Import.PLE,$K27,DR$16)),IF(INDEX(Import.PLE,$K27,DR$16)<=mediçao,BR27,0),0),PLE!$AA$28*BR27) -> 0 | DS27: =IF($K27<>1,IF(ISNUMBER(INDEX(Import.PLE,$K27,DS$16)),IF(INDEX(Import.PLE,$K27,DS$16)<=mediçao,BS27,0),0),PLE!$AA$28*BS27) -> 0 | DT27: =IF($K27<>1,IF(ISNUMBER(INDEX(Import.PLE,$K27,DT$16)),IF(INDEX(Import.PLE,$K27,DT$16)<=mediçao,BT27,0),0),PLE!$AA$28*BT27) -> 0 | ... FJ27: =IF($K27<>1,IF(ISNUMBER(INDEX(Import.PLE,$K27,FJ$16)),IF(INDEX(Import.PLE,$K27,FJ$16)<=mediçao,DJ27,0),0),PLE!$AA$28*DJ27) -> 0
B28: =ROW(Nível)-ROW(LIorçamento)+1 -> 11 | C28: =IF(D28="","",IF(ISNUMBER(VALUE(D28)),"Meta",IF(AND(F28<>"",I28<>""),"Serviço","Nível"))) -> Meta | D28: 4 | E28: SERVIÇOS COMPLEMENTARES | G28: =IF(Nível="Serviço",SUMIF($N$15:$BK$15,"<>"&"",N28:BK28),"") | H28: =IF(AND(ISNUMBER(G28),G28<>0),I28/G28,IF(G28=0,0,"")) | K28: =deactivatedados.form1 | BM28: =IF(N$15="",0,IF(ISNUMBER(PreçoUnit),PreçoUnit*INDEX(Import.PLQ,$B28,BM$16),0)) -> 0 | BN28: =IF(O$15="",0,IF(ISNUMBER(PreçoUnit),PreçoUnit*INDEX(Import.PLQ,$B28,BN$16),0)) -> 0 | BO28: =IF(P$15="",0,IF(ISNUMBER(PreçoUnit),PreçoUnit*INDEX(Import.PLQ,$B28,BO$16),0)) -> 0 | BP28: =IF(Q$15="",0,IF(ISNUMBER(PreçoUnit),PreçoUnit*INDEX(Import.PLQ,$B28,BP$16),0)) -> 0 | BQ28: =IF(R$15="",0,IF(ISNUMBER(PreçoUnit),PreçoUnit*INDEX(Import.PLQ,$B28,BQ$16),0)) -> 0 | BR28: =IF(S$15="",0,IF(ISNUMBER(PreçoUnit),PreçoUnit*INDEX(Import.PLQ,$B28,BR$16),0)) -> 0 | BS28: =IF(T$15="",0,IF(ISNUMBER(PreçoUnit),PreçoUnit*INDEX(Import.PLQ,$B28,BS$16),0)) -> 0 | BT28: =IF(U$15="",0,IF(ISNUMBER(PreçoUnit),PreçoUnit*INDEX(Import.PLQ,$B28,BT$16),0)) -> 0 | ... DJ28: =IF(BK$15="",0,IF(ISNUMBER(PreçoUnit),PreçoUnit*INDEX(Import.PLQ,$B28,DJ$16),0)) -> 0 | DK28: =IF(D28="",0,IF(ISNUMBER(VALUE(D28)),VALUE(D28),LEFT(D28,FIND(".",D28)-1))) -> 4 | DL28: =SUM(DM28:FJ28) -> 0 | DM28: =IF($K28<>1,IF(ISNUMBER(INDEX(Import.PLE,$K28,DM$16)),IF(INDEX(Import.PLE,$K28,DM$16)<=mediçao,BM28,0),0),PLE!$AA$28*BM28) -> 0 | DN28: =IF($K28<>1,IF(ISNUMBER(INDEX(Import.PLE,$K28,DN$16)),IF(INDEX(Import.PLE,$K28,DN$16)<=mediçao,BN28,0),0),PLE!$AA$28*BN28) -> 0 | DO28: =IF($K28<>1,IF(ISNUMBER(INDEX(Import.PLE,$K28,DO$16)),IF(INDEX(Import.PLE,$K28,DO$16)<=mediçao,BO28,0),0),PLE!$AA$28*BO28) -> 0 | DP28: =IF($K28<>1,IF(ISNUMBER(INDEX(Import.PLE,$K28,DP$16)),IF(INDEX(Import.PLE,$K28,DP$16)<=mediçao,BP28,0),0),PLE!$AA$28*BP28) -> 0 | DQ28: =IF($K28<>1,IF(ISNUMBER(INDEX(Import.PLE,$K28,DQ$16)),IF(INDEX(Import.PLE,$K28,DQ$16)<=mediçao,BQ28,0),0),PLE!$AA$28*BQ28) -> 0 | DR28: =IF($K28<>1,IF(ISNUMBER(INDEX(Import.PLE,$K28,DR$16)),IF(INDEX(Import.PLE,$K28,DR$16)<=mediçao,BR28,0),0),PLE!$AA$28*BR28) -> 0 | DS28: =IF($K28<>1,IF(ISNUMBER(INDEX(Import.PLE,$K28,DS$16)),IF(INDEX(Import.PLE,$K28,DS$16)<=mediçao,BS28,0),0),PLE!$AA$28*BS28) -> 0 | DT28: =IF($K28<>1,IF(ISNUMBER(INDEX(Import.PLE,$K28,DT$16)),IF(INDEX(Import.PLE,$K28,DT$16)<=mediçao,BT28,0),0),PLE!$AA$28*BT28) -> 0 | ... FJ28: =IF($K28<>1,IF(ISNUMBER(INDEX(Import.PLE,$K28,FJ$16)),IF(INDEX(Import.PLE,$K28,FJ$16)<=mediçao,DJ28,0),0),PLE!$AA$28*DJ28) -> 0
B29: =ROW(Nível)-ROW(LIorçamento)+1 -> 12 | C29: =IF(D29="","",IF(ISNUMBER(VALUE(D29)),"Meta",IF(AND(F29<>"",I29<>""),"Serviço","Nível"))) -> Serviço | D29: 4.1 | E29: Execução de passeio (calçada) em concreto moldado in loco, feito em obra, acabamento convencional, não armado, espessura 6 cm | F29: m³ | G29: =IF(Nível="Serviço",SUMIF($N$15:$BK$15,"<>"&"",N29:BK29),"") -> 100.67 | H29: =IF(AND(ISNUMBER(G29),G29<>0),I29/G29,IF(G29=0,0,"")) -> 864.34996 | I29: 87014.11 | K29: =deactivatedados.form1 -> 3 | L29: 3-CALÇADAS E RAMPAS | N29: 18.23 | O29: 8.89 | P29: 12.29 | Q29: 20.81 | R29: 7.84 | S29: 15.19 | T29: 10.1 | U29: 7.32 | BM29: =IF(N$15="",0,IF(ISNUMBER(PreçoUnit),PreçoUnit*INDEX(Import.PLQ,$B29,BM$16),0)) -> 15757.1 | BN29: =IF(O$15="",0,IF(ISNUMBER(PreçoUnit),PreçoUnit*INDEX(Import.PLQ,$B29,BN$16),0)) -> 7684.0711 | BO29: =IF(P$15="",0,IF(ISNUMBER(PreçoUnit),PreçoUnit*INDEX(Import.PLQ,$B29,BO$16),0)) -> 10622.861 | BP29: =IF(Q$15="",0,IF(ISNUMBER(PreçoUnit),PreçoUnit*INDEX(Import.PLQ,$B29,BP$16),0)) -> 17987.123 | BQ29: =IF(R$15="",0,IF(ISNUMBER(PreçoUnit),PreçoUnit*INDEX(Import.PLQ,$B29,BQ$16),0)) -> 6776.5036 | BR29: =IF(S$15="",0,IF(ISNUMBER(PreçoUnit),PreçoUnit*INDEX(Import.PLQ,$B29,BR$16),0)) -> 13129.476 | BS29: =IF(T$15="",0,IF(ISNUMBER(PreçoUnit),PreçoUnit*INDEX(Import.PLQ,$B29,BS$16),0)) -> 8729.9345 | BT29: =IF(U$15="",0,IF(ISNUMBER(PreçoUnit),PreçoUnit*INDEX(Import.PLQ,$B29,BT$16),0)) -> 6327.0417 | ... DJ29: =IF(BK$15="",0,IF(ISNUMBER(PreçoUnit),PreçoUnit*INDEX(Import.PLQ,$B29,DJ$16),0)) -> 0 | DK29: =IF(D29="",0,IF(ISNUMBER(VALUE(D29)),VALUE(D29),LEFT(D29,FIND(".",D29)-1))) -> 4 | DL29: =SUM(DM29:FJ29) -> 0 | DM29: =IF($K29<>1,IF(ISNUMBER(INDEX(Import.PLE,$K29,DM$16)),IF(INDEX(Import.PLE,$K29,DM$16)<=mediçao,BM29,0),0),PLE!$AA$28*BM29) -> 0 | DN29: =IF($K29<>1,IF(ISNUMBER(INDEX(Import.PLE,$K29,DN$16)),IF(INDEX(Import.PLE,$K29,DN$16)<=mediçao,BN29,0),0),PLE!$AA$28*BN29) -> 0 | DO29: =IF($K29<>1,IF(ISNUMBER(INDEX(Import.PLE,$K29,DO$16)),IF(INDEX(Import.PLE,$K29,DO$16)<=mediçao,BO29,0),0),PLE!$AA$28*BO29) -> 0 | DP29: =IF($K29<>1,IF(ISNUMBER(INDEX(Import.PLE,$K29,DP$16)),IF(INDEX(Import.PLE,$K29,DP$16)<=mediçao,BP29,0),0),PLE!$AA$28*BP29) -> 0 | DQ29: =IF($K29<>1,IF(ISNUMBER(INDEX(Import.PLE,$K29,DQ$16)),IF(INDEX(Import.PLE,$K29,DQ$16)<=mediçao,BQ29,0),0),PLE!$AA$28*BQ29) -> 0 | DR29: =IF($K29<>1,IF(ISNUMBER(INDEX(Import.PLE,$K29,DR$16)),IF(INDEX(Import.PLE,$K29,DR$16)<=mediçao,BR29,0),0),PLE!$AA$28*BR29) -> 0 | DS29: =IF($K29<>1,IF(ISNUMBER(INDEX(Import.PLE,$K29,DS$16)),IF(INDEX(Import.PLE,$K29,DS$16)<=mediçao,BS29,0),0),PLE!$AA$28*BS29) -> 0 | DT29: =IF($K29<>1,IF(ISNUMBER(INDEX(Import.PLE,$K29,DT$16)),IF(INDEX(Import.PLE,$K29,DT$16)<=mediçao,BT29,0),0),PLE!$AA$28*BT29) -> 0 | ... FJ29: =IF($K29<>1,IF(ISNUMBER(INDEX(Import.PLE,$K29,FJ$16)),IF(INDEX(Import.PLE,$K29,FJ$16)<=mediçao,DJ29,0),0),PLE!$AA$28*DJ29) -> 0
B30: =ROW(Nível)-ROW(LIorçamento)+1 -> 13 | C30: =IF(D30="","",IF(ISNUMBER(VALUE(D30)),"Meta",IF(AND(F30<>"",I30<>""),"Serviço","Nível"))) -> Serviço | D30: 4.2 | E30: Alvenaria de vedação de blocos cerâmicos furados na horizontal de 9x19x19cm (espessura 9cm)para execução de passeio e argamassa de assentamento com preparo em betoneira | F30: m² | G30: =IF(Nível="Serviço",SUMIF($N$15:$BK$15,"<>"&"",N30:BK30),"") -> 314.73 | H30: =IF(AND(ISNUMBER(G30),G30<>0),I30/G30,IF(G30=0,0,"")) -> 53.080005 | I30: 16705.87 | K30: =deactivatedados.form1 -> 3 | L30: 3-CALÇADAS E RAMPAS | N30: 54.52 | O30: 29.01 | P30: 42.33 | Q30: 67.53 | R30: 21.62 | S30: 39.7 | T30: 33.12 | U30: 26.9 | BM30: =IF(N$15="",0,IF(ISNUMBER(PreçoUnit),PreçoUnit*INDEX(Import.PLQ,$B30,BM$16),0)) -> 2893.9219 | BN30: =IF(O$15="",0,IF(ISNUMBER(PreçoUnit),PreçoUnit*INDEX(Import.PLQ,$B30,BN$16),0)) -> 1539.8509 | BO30: =IF(P$15="",0,IF(ISNUMBER(PreçoUnit),PreçoUnit*INDEX(Import.PLQ,$B30,BO$16),0)) -> 2246.8766 | BP30: =IF(Q$15="",0,IF(ISNUMBER(PreçoUnit),PreçoUnit*INDEX(Import.PLQ,$B30,BP$16),0)) -> 3584.4927 | BQ30: =IF(R$15="",0,IF(ISNUMBER(PreçoUnit),PreçoUnit*INDEX(Import.PLQ,$B30,BQ$16),0)) -> 1147.5897 | BR30: =IF(S$15="",0,IF(ISNUMBER(PreçoUnit),PreçoUnit*INDEX(Import.PLQ,$B30,BR$16),0)) -> 2107.2762 | BS30: =IF(T$15="",0,IF(ISNUMBER(PreçoUnit),PreçoUnit*INDEX(Import.PLQ,$B30,BS$16),0)) -> 1758.0098 | BT30: =IF(U$15="",0,IF(ISNUMBER(PreçoUnit),PreçoUnit*INDEX(Import.PLQ,$B30,BT$16),0)) -> 1427.8521 | ... DJ30: =IF(BK$15="",0,IF(ISNUMBER(PreçoUnit),PreçoUnit*INDEX(Import.PLQ,$B30,DJ$16),0)) -> 0 | DK30: =IF(D30="",0,IF(ISNUMBER(VALUE(D30)),VALUE(D30),LEFT(D30,FIND(".",D30)-1))) -> 4 | DL30: =SUM(DM30:FJ30) -> 0 | DM30: =IF($K30<>1,IF(ISNUMBER(INDEX(Import.PLE,$K30,DM$16)),IF(INDEX(Import.PLE,$K30,DM$16)<=mediçao,BM30,0),0),PLE!$AA$28*BM30) -> 0 | DN30: =IF($K30<>1,IF(ISNUMBER(INDEX(Import.PLE,$K30,DN$16)),IF(INDEX(Import.PLE,$K30,DN$16)<=mediçao,BN30,0),0),PLE!$AA$28*BN30) -> 0 | DO30: =IF($K30<>1,IF(ISNUMBER(INDEX(Import.PLE,$K30,DO$16)),IF(INDEX(Import.PLE,$K30,DO$16)<=mediçao,BO30,0),0),PLE!$AA$28*BO30) -> 0 | DP30: =IF($K30<>1,IF(ISNUMBER(INDEX(Import.PLE,$K30,DP$16)),IF(INDEX(Import.PLE,$K30,DP$16)<=mediçao,BP30,0),0),PLE!$AA$28*BP30) -> 0 | DQ30: =IF($K30<>1,IF(ISNUMBER(INDEX(Import.PLE,$K30,DQ$16)),IF(INDEX(Import.PLE,$K30,DQ$16)<=mediçao,BQ30,0),0),PLE!$AA$28*BQ30) -> 0 | DR30: =IF($K30<>1,IF(ISNUMBER(INDEX(Import.PLE,$K30,DR$16)),IF(INDEX(Import.PLE,$K30,DR$16)<=mediçao,BR30,0),0),PLE!$AA$28*BR30) -> 0 | DS30: =IF($K30<>1,IF(ISNUMBER(INDEX(Import.PLE,$K30,DS$16)),IF(INDEX(Import.PLE,$K30,DS$16)<=mediçao,BS30,0),0),PLE!$AA$28*BS30) -> 0 | DT30: =IF($K30<>1,IF(ISNUMBER(INDEX(Import.PLE,$K30,DT$16)),IF(INDEX(Import.PLE,$K30,DT$16)<=mediçao,BT30,0),0),PLE!$AA$28*BT30) -> 0 | ... FJ30: =IF($K30<>1,IF(ISNUMBER(INDEX(Import.PLE,$K30,FJ$16)),IF(INDEX(Import.PLE,$K30,FJ$16)<=mediçao,DJ30,0),0),PLE!$AA$28*DJ30) -> 0
B31: =ROW(Nível)-ROW(LIorçamento)+1 -> 14 | C31: =IF(D31="","",IF(ISNUMBER(VALUE(D31)),"Meta",IF(AND(F31<>"",I31<>""),"Serviço","Nível"))) -> Serviço | D31: 4.3 | E31: Execução de rampa em concreto moldado in loco, feito em obra, acabamento convencional, não armado, conforme ABNT NBR 9050/2004 | F31: m³ | G31: =IF(Nível="Serviço",SUMIF($N$15:$BK$15,"<>"&"",N31:BK31),"") -> 25.63 | H31: =IF(AND(ISNUMBER(G31),G31<>0),I31/G31,IF(G31=0,0,"")) -> 864.34998 | I31: 22153.29 | K31: =deactivatedados.form1 -> 3 | L31: 3-CALÇADAS E RAMPAS | N31: 5.26 | O31: 2.63 | P31: 3.94 | Q31: 5.26 | R31: 1.31 | S31: 1.97 | T31: 2.63 | U31: 2.63 | BM31: =IF(N$15="",0,IF(ISNUMBER(PreçoUnit),PreçoUnit*INDEX(Import.PLQ,$B31,BM$16),0)) -> 4546.4809 | BN31: =IF(O$15="",0,IF(ISNUMBER(PreçoUnit),PreçoUnit*INDEX(Import.PLQ,$B31,BN$16),0)) -> 2273.2404 | BO31: =IF(P$15="",0,IF(ISNUMBER(PreçoUnit),PreçoUnit*INDEX(Import.PLQ,$B31,BO$16),0)) -> 3405.5389 | BP31: =IF(Q$15="",0,IF(ISNUMBER(PreçoUnit),PreçoUnit*INDEX(Import.PLQ,$B31,BP$16),0)) -> 4546.4809 | BQ31: =IF(R$15="",0,IF(ISNUMBER(PreçoUnit),PreçoUnit*INDEX(Import.PLQ,$B31,BQ$16),0)) -> 1132.2985 | BR31: =IF(S$15="",0,IF(ISNUMBER(PreçoUnit),PreçoUnit*INDEX(Import.PLQ,$B31,BR$16),0)) -> 1702.7695 | BS31: =IF(T$15="",0,IF(ISNUMBER(PreçoUnit),PreçoUnit*INDEX(Import.PLQ,$B31,BS$16),0)) -> 2273.2404 | BT31: =IF(U$15="",0,IF(ISNUMBER(PreçoUnit),PreçoUnit*INDEX(Import.PLQ,$B31,BT$16),0)) -> 2273.2404 | ... DJ31: =IF(BK$15="",0,IF(ISNUMBER(PreçoUnit),PreçoUnit*INDEX(Import.PLQ,$B31,DJ$16),0)) -> 0 | DK31: =IF(D31="",0,IF(ISNUMBER(VALUE(D31)),VALUE(D31),LEFT(D31,FIND(".",D31)-1))) -> 4 | DL31: =SUM(DM31:FJ31) -> 0 | DM31: =IF($K31<>1,IF(ISNUMBER(INDEX(Import.PLE,$K31,DM$16)),IF(INDEX(Import.PLE,$K31,DM$16)<=mediçao,BM31,0),0),PLE!$AA$28*BM31) -> 0 | DN31: =IF($K31<>1,IF(ISNUMBER(INDEX(Import.PLE,$K31,DN$16)),IF(INDEX(Import.PLE,$K31,DN$16)<=mediçao,BN31,0),0),PLE!$AA$28*BN31) -> 0 | DO31: =IF($K31<>1,IF(ISNUMBER(INDEX(Import.PLE,$K31,DO$16)),IF(INDEX(Import.PLE,$K31,DO$16)<=mediçao,BO31,0),0),PLE!$AA$28*BO31) -> 0 | DP31: =IF($K31<>1,IF(ISNUMBER(INDEX(Import.PLE,$K31,DP$16)),IF(INDEX(Import.PLE,$K31,DP$16)<=mediçao,BP31,0),0),PLE!$AA$28*BP31) -> 0 | DQ31: =IF($K31<>1,IF(ISNUMBER(INDEX(Import.PLE,$K31,DQ$16)),IF(INDEX(Import.PLE,$K31,DQ$16)<=mediçao,BQ31,0),0),PLE!$AA$28*BQ31) -> 0 | DR31: =IF($K31<>1,IF(ISNUMBER(INDEX(Import.PLE,$K31,DR$16)),IF(INDEX(Import.PLE,$K31,DR$16)<=mediçao,BR31,0),0),PLE!$AA$28*BR31) -> 0 | DS31: =IF($K31<>1,IF(ISNUMBER(INDEX(Import.PLE,$K31,DS$16)),IF(INDEX(Import.PLE,$K31,DS$16)<=mediçao,BS31,0),0),PLE!$AA$28*BS31) -> 0 | DT31: =IF($K31<>1,IF(ISNUMBER(INDEX(Import.PLE,$K31,DT$16)),IF(INDEX(Import.PLE,$K31,DT$16)<=mediçao,BT31,0),0),PLE!$AA$28*BT31) -> 0 | ... FJ31: =IF($K31<>1,IF(ISNUMBER(INDEX(Import.PLE,$K31,FJ$16)),IF(INDEX(Import.PLE,$K31,FJ$16)<=mediçao,DJ31,0),0),PLE!$AA$28*DJ31) -> 0
B32: =ROW(Nível)-ROW(LIorçamento)+1 -> 15 | C32: =IF(D32="","",IF(ISNUMBER(VALUE(D32)),"Meta",IF(AND(F32<>"",I32<>""),"Serviço","Nível"))) -> Serviço | D32: 4.4 | E32: Piso tátil em rampas e calçadas para acessibilidade (rota acessível) | F32: m² | G32: =IF(Nível="Serviço",SUMIF($N$15:$BK$15,"<>"&"",N32:BK32),"") -> 307.65 | H32: =IF(AND(ISNUMBER(G32),G32<>0),I32/G32,IF(G32=0,0,"")) -> 121.78001 | I32: 37465.62 | K32: =deactivatedados.form1 -> 3 | L32: 3-CALÇADAS E RAMPAS | N32: 54.67 | O32: 27.88 | P32: 38.13 | Q32: 62.42 | R32: 24.61 | S32: 45.87 | T32: 30.77 | U32: 23.3 | BM32: =IF(N$15="",0,IF(ISNUMBER(PreçoUnit),PreçoUnit*INDEX(Import.PLQ,$B32,BM$16),0)) -> 6657.7131 | BN32: =IF(O$15="",0,IF(ISNUMBER(PreçoUnit),PreçoUnit*INDEX(Import.PLQ,$B32,BN$16),0)) -> 3395.2267 | BO32: =IF(P$15="",0,IF(ISNUMBER(PreçoUnit),PreçoUnit*INDEX(Import.PLQ,$B32,BO$16),0)) -> 4643.4718 | BP32: =IF(Q$15="",0,IF(ISNUMBER(PreçoUnit),PreçoUnit*INDEX(Import.PLQ,$B32,BP$16),0)) -> 7601.5082 | BQ32: =IF(R$15="",0,IF(ISNUMBER(PreçoUnit),PreçoUnit*INDEX(Import.PLQ,$B32,BQ$16),0)) -> 2997.006 | BR32: =IF(S$15="",0,IF(ISNUMBER(PreçoUnit),PreçoUnit*INDEX(Import.PLQ,$B32,BR$16),0)) -> 5586.049 | BS32: =IF(T$15="",0,IF(ISNUMBER(PreçoUnit),PreçoUnit*INDEX(Import.PLQ,$B32,BS$16),0)) -> 3747.1709 | BT32: =IF(U$15="",0,IF(ISNUMBER(PreçoUnit),PreçoUnit*INDEX(Import.PLQ,$B32,BT$16),0)) -> 2837.4742 | ... DJ32: =IF(BK$15="",0,IF(ISNUMBER(PreçoUnit),PreçoUnit*INDEX(Import.PLQ,$B32,DJ$16),0)) -> 0 | DK32: =IF(D32="",0,IF(ISNUMBER(VALUE(D32)),VALUE(D32),LEFT(D32,FIND(".",D32)-1))) -> 4 | DL32: =SUM(DM32:FJ32) -> 0 | DM32: =IF($K32<>1,IF(ISNUMBER(INDEX(Import.PLE,$K32,DM$16)),IF(INDEX(Import.PLE,$K32,DM$16)<=mediçao,BM32,0),0),PLE!$AA$28*BM32) -> 0 | DN32: =IF($K32<>1,IF(ISNUMBER(INDEX(Import.PLE,$K32,DN$16)),IF(INDEX(Import.PLE,$K32,DN$16)<=mediçao,BN32,0),0),PLE!$AA$28*BN32) -> 0 | DO32: =IF($K32<>1,IF(ISNUMBER(INDEX(Import.PLE,$K32,DO$16)),IF(INDEX(Import.PLE,$K32,DO$16)<=mediçao,BO32,0),0),PLE!$AA$28*BO32) -> 0 | DP32: =IF($K32<>1,IF(ISNUMBER(INDEX(Import.PLE,$K32,DP$16)),IF(INDEX(Import.PLE,$K32,DP$16)<=mediçao,BP32,0),0),PLE!$AA$28*BP32) -> 0 | DQ32: =IF($K32<>1,IF(ISNUMBER(INDEX(Import.PLE,$K32,DQ$16)),IF(INDEX(Import.PLE,$K32,DQ$16)<=mediçao,BQ32,0),0),PLE!$AA$28*BQ32) -> 0 | DR32: =IF($K32<>1,IF(ISNUMBER(INDEX(Import.PLE,$K32,DR$16)),IF(INDEX(Import.PLE,$K32,DR$16)<=mediçao,BR32,0),0),PLE!$AA$28*BR32) -> 0 | DS32: =IF($K32<>1,IF(ISNUMBER(INDEX(Import.PLE,$K32,DS$16)),IF(INDEX(Import.PLE,$K32,DS$16)<=mediçao,BS32,0),0),PLE!$AA$28*BS32) -> 0 | DT32: =IF($K32<>1,IF(ISNUMBER(INDEX(Import.PLE,$K32,DT$16)),IF(INDEX(Import.PLE,$K32,DT$16)<=mediçao,BT32,0),0),PLE!$AA$28*BT32) -> 0 | ... FJ32: =IF($K32<>1,IF(ISNUMBER(INDEX(Import.PLE,$K32,FJ$16)),IF(INDEX(Import.PLE,$K32,FJ$16)<=mediçao,DJ32,0),0),PLE!$AA$28*DJ32) -> 0
B33: =ROW(Nível)-ROW(LIorçamento)+1 -> 16 | C33: =IF(D33="","",IF(ISNUMBER(VALUE(D33)),"Meta",IF(AND(F33<>"",I33<>""),"Serviço","Nível"))) -> Serviço | D33: 4.5 | E33: Pintura acrílica em piso cimentado da rampa, 2 demãos | F33: m² | G33: =IF(Nível="Serviço",SUMIF($N$15:$BK$15,"<>"&"",N33:BK33),"") -> 485.94 | H33: =IF(AND(ISNUMBER(G33),G33<>0),I33/G33,IF(G33=0,0,"")) -> 19.189982 | I33: 9325.18 | K33: =deactivatedados.form1 -> 4 | L33: 4-SINALIZAÇÃO E SERVIÇOS FINAIS | N33: 99.68 | O33: 49.84 | P33: 74.76 | Q33: 99.68 | R33: 24.92 | S33: 37.38 | T33: 49.84 | U33: 49.84 | BM33: =IF(N$15="",0,IF(ISNUMBER(PreçoUnit),PreçoUnit*INDEX(Import.PLQ,$B33,BM$16),0)) -> 1912.8574 | BN33: =IF(O$15="",0,IF(ISNUMBER(PreçoUnit),PreçoUnit*INDEX(Import.PLQ,$B33,BN$16),0)) -> 956.42872 | BO33: =IF(P$15="",0,IF(ISNUMBER(PreçoUnit),PreçoUnit*INDEX(Import.PLQ,$B33,BO$16),0)) -> 1434.6431 | BP33: =IF(Q$15="",0,IF(ISNUMBER(PreçoUnit),PreçoUnit*INDEX(Import.PLQ,$B33,BP$16),0)) -> 1912.8574 | BQ33: =IF(R$15="",0,IF(ISNUMBER(PreçoUnit),PreçoUnit*INDEX(Import.PLQ,$B33,BQ$16),0)) -> 478.21436 | BR33: =IF(S$15="",0,IF(ISNUMBER(PreçoUnit),PreçoUnit*INDEX(Import.PLQ,$B33,BR$16),0)) -> 717.32154 | BS33: =IF(T$15="",0,IF(ISNUMBER(PreçoUnit),PreçoUnit*INDEX(Import.PLQ,$B33,BS$16),0)) -> 956.42872 | BT33: =IF(U$15="",0,IF(ISNUMBER(PreçoUnit),PreçoUnit*INDEX(Import.PLQ,$B33,BT$16),0)) -> 956.42872 | ... DJ33: =IF(BK$15="",0,IF(ISNUMBER(PreçoUnit),PreçoUnit*INDEX(Import.PLQ,$B33,DJ$16),0)) -> 0 | DK33: =IF(D33="",0,IF(ISNUMBER(VALUE(D33)),VALUE(D33),LEFT(D33,FIND(".",D33)-1))) -> 4 | DL33: =SUM(DM33:FJ33) -> 0 | DM33: =IF($K33<>1,IF(ISNUMBER(INDEX(Import.PLE,$K33,DM$16)),IF(INDEX(Import.PLE,$K33,DM$16)<=mediçao,BM33,0),0),PLE!$AA$28*BM33) -> 0 | DN33: =IF($K33<>1,IF(ISNUMBER(INDEX(Import.PLE,$K33,DN$16)),IF(INDEX(Import.PLE,$K33,DN$16)<=mediçao,BN33,0),0),PLE!$AA$28*BN33) -> 0 | DO33: =IF($K33<>1,IF(ISNUMBER(INDEX(Import.PLE,$K33,DO$16)),IF(INDEX(Import.PLE,$K33,DO$16)<=mediçao,BO33,0),0),PLE!$AA$28*BO33) -> 0 | DP33: =IF($K33<>1,IF(ISNUMBER(INDEX(Import.PLE,$K33,DP$16)),IF(INDEX(Import.PLE,$K33,DP$16)<=mediçao,BP33,0),0),PLE!$AA$28*BP33) -> 0 | DQ33: =IF($K33<>1,IF(ISNUMBER(INDEX(Import.PLE,$K33,DQ$16)),IF(INDEX(Import.PLE,$K33,DQ$16)<=mediçao,BQ33,0),0),PLE!$AA$28*BQ33) -> 0 | DR33: =IF($K33<>1,IF(ISNUMBER(INDEX(Import.PLE,$K33,DR$16)),IF(INDEX(Import.PLE,$K33,DR$16)<=mediçao,BR33,0),0),PLE!$AA$28*BR33) -> 0 | DS33: =IF($K33<>1,IF(ISNUMBER(INDEX(Import.PLE,$K33,DS$16)),IF(INDEX(Import.PLE,$K33,DS$16)<=mediçao,BS33,0),0),PLE!$AA$28*BS33) -> 0 | DT33: =IF($K33<>1,IF(ISNUMBER(INDEX(Import.PLE,$K33,DT$16)),IF(INDEX(Import.PLE,$K33,DT$16)<=mediçao,BT33,0),0),PLE!$AA$28*BT33) -> 0 | ... FJ33: =IF($K33<>1,IF(ISNUMBER(INDEX(Import.PLE,$K33,FJ$16)),IF(INDEX(Import.PLE,$K33,FJ$16)<=mediçao,DJ33,0),0),PLE!$AA$28*DJ33) -> 0
