Workbook
Name _______MDO1: [2]INSUMOS!$C$8
Name _______MDO2: [3]INSUMOS!$C$6
Name _______R: #REF!
Name ______MDO1: [2]INSUMOS!$C$8
Name ______MDO2: [3]INSUMOS!$C$6
Name ______R: #REF!
Name ______R: #REF!
Name ______rua1: #REF!
Name ______rua1: #REF!
Name _____MDO1: [2]INSUMOS!$C$8
Name _____MDO2: [3]INSUMOS!$C$6
Name _____R: #REF!
Name _____R: #REF!
Name _____rua1: #REF!
Name _____rua1: #REF!
Name ____MDO1: [2]INSUMOS!$C$8
Name ____MDO2: [3]INSUMOS!$C$6
Name ____R: #REF!
Name ____R: #REF!
Name ____rua1: #REF!
Name ____rua1: #REF!
Name ___MDO1: [2]INSUMOS!$C$8
Name ___MDO2: [3]INSUMOS!$C$6
Name ___R: #REF!
Name ___R: #REF!
Name ___rua1: #REF!
Name ___rua1: #REF!
Name __MDO1: [4]INSUMOS!$C$8
Name __MDO1: [4]INSUMOS!$C$8
Name __MDO2: [3]INSUMOS!$C$6
Name __R: #REF!
Name __R: #REF!
Name __rua1: #REF!
Name __rua1: #REF!
Name __xlnm.Print_Titles_2: #REF!
Name __xlnm.Print_Titles_2: #REF!
Name _MDO1: [4]INSUMOS!$C$8
Name _MDO1: [4]INSUMOS!$C$8
Name _MDO2: [3]INSUMOS!$C$6
Name _R: #REF!
Name _R: #REF!
Name _rua1: #REF!
Name _rua1: #REF!
Name A: #REF!
Name AA: [5]CUBACAO!#REF!
Name AA: [5]CUBACAO!#REF!
Name AAA: [5]CUBACAO!#REF!
Name AAA: [5]CUBACAO!#REF!
Name Ac: #REF!
Name Ac: #REF!
Name artFiscal: [6]DADOS!$D$23
Name ASDFASDFAS: #REF!
Name ASDFASDFAS: #REF!
Name BB: [5]CUBACAO!#REF!
Name BB: [5]CUBACAO!#REF!
Name BBB: [5]CUBACAO!#REF!
Name BBB: [5]CUBACAO!#REF!
Name bdi: [7]Orçamento!$J$10
Name bdi: [7]Orçamento!$J$10
Name BDIc: #REF!

Sheet BM-01
A1: ESTADO DA PARAÍBA
A2: PREFEITURA MUNICIPAL DE COREMAS | Q2: VALOR EDITAL | R2: R$ 1.252.370,60
A3: CONTRATO Nº 10004/2023 | Q3: VALOR C/DESC. | R3: =L213 -> 1039467.6
A4: OBRA: CONSTRUÇÃO DE UMA UNIDADE ESCOLAR DE 06 (SEIS) SALAS DE AULA PARA O MUNICÍPIO DE COREMAS-PB | J4: BDI = | K4: 0.25
A5: LOCAL: MUNICÍPIO DE COREMAS-PB | Q5: DESCONTO: | R5: 0.17
A6: BOLETIM DE MEDIÇÃO - BM-01
A7: ITEM | B7: CÓDIGO | C7: REFERÊNCIA | D7: DESCRIÇÃO | E7: ORIGEM | F7: UNID | G7: QUANTIDADES | K7: VALOR UNIT COM BDI | L7: VALORES TOTAIS
G8: LICITADA | H8: ACUMULADA ATÉ O PERÍODO | I8: MEDIDA NO PERÍODO | J8: ACUMULADA INCLUINDO O PERÍODO | L8: LICITADO | M8: ACUMULADO ATÉ O PERÍODO | N8: MEDIDO NO PERÍODO | O8: ACUMULADO INCLUINDO O PERÍODO
A9: 1 ETAPA 01: GERAL | L9: =SUM(L10,L16) -> 66229.186 | M9: =SUM(M10,M16) -> 0 | N9: =SUM(N10,N16) -> 7723.8406 | O9: =SUM(O10,O16) -> 7723.8406
A10: 1.1 1 ADMINISTRACAO LOCAL | L10: =SUM(L11:L15) -> 64365.338 | M10: =SUM(M11:M15) -> 0 | N10: =SUM(N11:N15) -> 7723.8406 | O10: =SUM(O11:O15) -> 7723.8406
A11: 1.1.1 | B11: 164471 | C11: O13221 | D11: ADMINSTRACAO LOCAL - PESSOAL | E11: SUPLAN | F11: UN | G11: 8 | I11: ='MEMORIAL DE CÁLCULOS'!J11 -> 0.96 | J11: =H11+I11 -> 0.96 | K11: 4208.9549 | L11: =G11*K11 -> 33671.639 | M11: =H11*K11 -> 0 | N11: =I11*K11 -> 4040.5967 | O11: =J11*K11 -> 4040.5967 | V11: 5071.03 | W11: =V11-V11*$R$5 -> 4208.9549
A12: 1.1.2 | B12: 164472 | C12: O13221 | D12: ADMINISTRACAO LOCAL - DESPESAS GERAIS MENSAIS | E12: SUPLAN | F12: UN | G12: 8 | I12: ='MEMORIAL DE CÁLCULOS'!J14 -> 0.96 | J12: =H12+I12 -> 0.96 | K12: 1588.6449 | L12: =G12*K12 -> 12709.159 | M12: =H12*K12 -> 0 | N12: =I12*K12 -> 1525.0991 | O12: =J12*K12 -> 1525.0991 | V12: 1914.03 | W12: =V12-V12*$R$5 -> 1588.6449
A13: 1.1.3 | B13: 164473 | C13: O13221 | D13: ADMINISTRACAO LOCAL - DESPESAS GERAIS FIXAS | E13: SUPLAN | F13: UN | G13: 1 | I13: ='MEMORIAL DE CÁLCULOS'!J17 -> 0.12 | J13: =H13+I13 -> 0.12 | K13: 2489.2862 | L13: =G13*K13 -> 2489.2862 | M13: =H13*K13 -> 0 | N13: =I13*K13 -> 298.71434 | O13: =J13*K13 -> 298.71434 | V13: 2999.14 | W13: =V13-V13*$R$5 -> 2489.2862
A14: 1.1.4 | B14: 164474 | C14: O13221 | D14: ADMINISTRACAO LOCAL - VECULOS E EQUIPAMENTOS | E14: SUPLAN | F14: UN | G14: 8 | I14: ='MEMORIAL DE CÁLCULOS'!J20 -> 0.96 | J14: =H14+I14 -> 0.96 | K14: 1279.8185 | L14: =G14*K14 -> 10238.548 | M14: =H14*K14 -> 0 | N14: =I14*K14 -> 1228.6258 | O14: =J14*K14 -> 1228.6258 | V14: 1541.95 | W14: =V14-V14*$R$5 -> 1279.8185
A15: 1.1.5 | B15: 164475 | C15: O13221 | D15: ADMINISTRACAO LOCAL - MOVEIS E UTENSILIOS | E15: SUPLAN | F15: UN | G15: 1 | I15: ='MEMORIAL DE CÁLCULOS'!J23 -> 0.12 | J15: =H15+I15 -> 0.12 | K15: 5256.7054 | L15: =G15*K15 -> 5256.7054 | M15: =H15*K15 -> 0 | N15: =I15*K15 -> 630.80465 | O15: =J15*K15 -> 630.80465 | V15: 6333.38 | W15: =V15-V15*$R$5 -> 5256.7054
A16: 1.2 DIVERSOS | L16: =SUM(L17) -> 1863.848 | M16: =SUM(M17) -> 0 | N16: =SUM(N17) -> 0 | O16: =SUM(O17) -> 0
A17: 1.2.1 | B17: 164476 | D17: "AS BUILT" DO PROJETO ARQUITETONICO E DOS PROJETOS DE ENGENHARIA DE ESTRUTURAS E DE INSTALACOES ELETRICAS, INSTALACOES HIDRAULICAS E INSTALACOES SANITARIAS - ESCOLAS | E17: SINAPI | F17: UN | G17: 1 | J17: =H17+I17 -> 0 | K17: 1863.848 | L17: =G17*K17 -> 1863.848 | M17: =H17*K17 -> 0 | N17: =I17*K17 -> 0 | O17: =J17*K17 -> 0 | V17: 2245.6 | W17: =V17-V17*$R$5 -> 1863.848
A18: 2 ETAPA 02: CONSTRUCAO DA ESCOLA | L18: =SUM(L19,L28,L32,L38,L47,L52,L63,L72,L80,L91,L102,L133,L141,L165,L176,) -> 930676.59 | M18: =SUM(M19,M28,M32,M38,M47,M52,M63,M72,M80,M91,M102,M133,M141,M165,M176,) -> 0 | N18: =SUM(N19,N28,N32,N38,N47,N52,N63,N72,N80,N91,N102,N133,N141,N165,N176,) -> 121891.57 | O18: =SUM(O19,O28,O32,O38,O47,O52,O63,O72,O80,O91,O102,O133,O141,O165,O176,) -> 121891.57
A19: 2.1 1 SERVICOS PRELIMINARES | L19: =SUM(L20:L27) -> 20901.206 | M19: =SUM(M20:M27) -> 0 | N19: =SUM(N20:N27) -> 9189.5164 | O19: =SUM(O20:O27) -> 9189.5164
A20: 2.1.1 | B20: 132583 | C20: 74209/001 | D20: PLACA DE OBRA EM CHAPA DE ACO GALVANIZADO | E20: SINAPI | F20: M2 | G20: 10 | I20: ='MEMORIAL DE CÁLCULOS'!J28 -> 10 | J20: =H20+I20 -> 10 | K20: 342.8979 | L20: =G20*K20 -> 3428.979 | M20: =H20*K20 -> 0 | N20: =I20*K20 -> 3428.979 | O20: =J20*K20 -> 3428.979 | V20: 413.13 | W20: =V20-V20*$R$5 -> 342.8979
A21: 2.1.2 | B21: 163387 | C21: 74077/3 | D21: LOCACAO CONVENCIONAL DE OBRA, ATRAVES DE GABARITO DE TABUAS CORRIDAS PONTALETADAS, COM REAPROVEITAMENTO DE 3 VEZES - | E21: SINAPI | F21: M2 | G21: 771.45 | I21: ='MEMORIAL DE CÁLCULOS'!J31 -> 771.45 | J21: =H21+I21 -> 771.45 | K21: 4.9551 | L21: =G21*K21 -> 3822.6119 | M21: =H21*K21 -> 0 | N21: =I21*K21 -> 3822.6119 | O21: =J21*K21 -> 3822.6119 | V21: 5.97 | W21: =V21-V21*$R$5 -> 4.9551
A22: 2.1.3 | B22: 137043 | C22: 73822/002 | D22: LIMPEZA MECANIZADA DE TERRENO COM REMOCAO DE CAMADA VEGETAL, UTILIZAND O MOTONIVELADORA | E22: SINAPI | F22: M2 | G22: 2000 | I22: ='MEMORIAL DE CÁLCULOS'!J34 -> 2000 | J22: =H22+I22 -> 2000 | K22: 0.2739 | L22: =G22*K22 -> 547.8 | M22: =H22*K22 -> 0 | N22: =I22*K22 -> 547.8 | O22: =J22*K22 -> 547.8 | V22: 0.33 | W22: =V22-V22*$R$5 -> 0.2739
A23: 2.1.4 | B23: 163443 | C23: C2851 | D23: INSTALACOES PROVISORIAS DE AGUA, INCLUSIVE CAIXA DAGUA DE 1000L | E23: SINAPI | F23: UN | G23: 1 | I23: ='MEMORIAL DE CÁLCULOS'!J37 -> 1 | J23: =H23+I23 -> 1 | K23: 1390.1255 | L23: =G23*K23 -> 1390.1255 | M23: =H23*K23 -> 0 | N23: =I23*K23 -> 1390.1255 | O23: =J23*K23 -> 1390.1255 | V23: 1674.85 | W23: =V23-V23*$R$5 -> 1390.1255
A24: 2.1.5 | B24: 163442 | C24: 11122/ORS | D24: ENTRADA DE ENERGIA ELETRICA MONOFASICA COM POSTE DE CONCRETO, INCLUSIVE CABEAMENTO, CAIXA DE PROTECAO PARA MEDIDOR E | E24: SINAPI | F24: UN | G24: 1 | J24: =H24+I24 -> 0 | K24: 1506.3255 | L24: =G24*K24 -> 1506.3255 | M24: =H24*K24 -> 0 | N24: =I24*K24 -> 0 | O24: =J24*K24 -> 0 | V24: 1814.85 | W24: =V24-V24*$R$5 -> 1506.3255
A25: 2.1.6 | B25: 135723 | C25: 73658 | D25: LIGACAO DOMICILIAR DE ESGOTO DN 100MM, DA CASA ATE A CAIXA, COMPOSTO P OR 10,0M TUBO DE PVC ESGOTO PREDIAL DN 100MM E CAIXA DE ALVENARIA COM TAMPA DE CONCRETO - FORNECIMENTO E | E25: SINAPI | F25: UN | G25: 1 | J25: =H25+I25 -> 0 | K25: 442.5062 | L25: =G25*K25 -> 442.5062 | M25: =H25*K25 -> 0 | N25: =I25*K25 -> 0 | O25: =J25*K25 -> 0 | V25: 533.14 | W25: =V25-V25*$R$5 -> 442.5062
A26: 2.1.7 | B26: 162175 | D26: LOCACAO DE CONTAINER 2,30 X 4,30 M, ALT. 2,50 M, P/ SANITARIO, C/ 5 BACIAS, 1 LAVATORIO E 4 MICTORIOS, INCLUSIVE TRANSP/CARGA/DESCARGA | E26: SUPLAN | F26: MÊS | G26: 8 | J26: =H26+I26 -> 0 | K26: 654.9198 | L26: =G26*K26 -> 5239.3584 | M26: =H26*K26 -> 0 | N26: =I26*K26 -> 0 | O26: =J26*K26 -> 0 | V26: 789.06 | W26: =V26-V26*$R$5 -> 654.9198
A27: 2.1.8 | B27: 163536 | D27: ALUGUEL CONTAINER/ESCRIT INCL INST ELET LARG=2,20 COMP=6,20M ALT=2,50M CHAPA ACO C/NERV TRAPEZ FORRO C/ISOLTERMO/ACUSTICO CHASSIS REFORC P I S O C O M P E N S N A V A L I N C T R A N S P / C A R G A / D E S C A R G A | E27: SINAPI | F27: MÊS | G27: 8 | J27: =H27+I27 -> 0 | K27: 565.4375 | L27: =G27*K27 -> 4523.5 | M27: =H27*K27 -> 0 | N27: =I27*K27 -> 0 | O27: =J27*K27 -> 0 | V27: 681.25 | W27: =V27-V27*$R$5 -> 565.4375
A28: 2.2 2 MOVIMENTO DE TERRA | L28: =SUM(L29:L31) -> 43621.441 | M28: =SUM(M29:M31) -> 0 | N28: =SUM(N29:N31) -> 42875.185 | O28: =SUM(O29:O31) -> 42875.185
A29: 2.2.1 | B29: 160239 | D29: ESCAVACAO MANUAL DE VALA EM MATERIAL DE QUALQUER CATEGORIA, EXCETO ROCHA COM PROFUNDIDADE ATE 2M. | E29: SINAPI | F29: M3 | G29: 157.35 | I29: ='MEMORIAL DE CÁLCULOS'!J41 -> 157.35 | J29: =H29+I29 -> 157.35 | K29: 63.1132 | L29: =G29*K29 -> 9930.862 | M29: =H29*K29 -> 0 | N29: =I29*K29 -> 9930.862 | O29: =J29*K29 -> 9930.862 | V29: 76.04 | W29: =V29-V29*$R$5 -> 63.1132
A30: 2.2.2 | B30: 164368 | C30: 24824/SIN | D30: ATERRO DO CAIXAO SEM AQUISICAO DO MATERIAL (REATERRO MANUAL) | E30: SINAPI | F30: M3 | G30: 157.35 | I30: ='MEMORIAL DE CÁLCULOS'!J80 -> 137.8 | J30: =H30+I30 -> 137.8 | K30: 38.1717 | L30: =G30*K30 -> 6006.317 | M30: =H30*K30 -> 0 | N30: =I30*K30 -> 5260.0603 | O30: =J30*K30 -> 5260.0603 | V30: 45.99 | W30: =V30-V30*$R$5 -> 38.1717
A31: 2.2.3 | B31: 153622 | D31: ATERRO DO CAIXAO COM AQUISICAO DO MATERIAL/AREIA, APILOADO EM CAMADAS DE 0,20M | E31: SINAPI | F31: M3 | G31: 195.41 | I31: ='MEMORIAL DE CÁLCULOS'!J83 -> 195.41 | J31: =H31+I31 -> 195.41 | K31: 141.6727 | L31: =G31*K31 -> 27684.262 | M31: =H31*K31 -> 0 | N31: =I31*K31 -> 27684.262 | O31: =J31*K31 -> 27684.262 | V31: 170.69 | W31: =V31-V31*$R$5 -> 141.6727
A32: 2.3 3 INFRAESTRUTURA | L32: =SUM(L33:L37) -> 69826.867 | M32: =SUM(M33:M37) -> 0 | N32: =SUM(N33:N37) -> 69826.867 | O32: =SUM(O33:O37) -> 69826.867
A33: 2.3.1 | B33: 146934 | C33: 95467 | D33: EMBASAMENTO C/PEDRA ARGAMASSADA UTILIZANDO ARG.CIM/AREIA 1:4 | E33: SINAPI | F33: M3 | G33: 105.04 | I33: ='MEMORIAL DE CÁLCULOS'!J88 -> 105.04 | J33: =H33+I33 -> 105.04 | K33: 316.5952 | L33: =G33*K33 -> 33255.16 | M33: =H33*K33 -> 0 | N33: =I33*K33 -> 33255.16 | O33: =J33*K33 -> 33255.16 | V33: 381.44 | W33: =V33-V33*$R$5 -> 316.5952
A34: 2.3.2 | B34: 160126 | D34: ALVENARIA DE 1 VEZ VEDACAO COM BLOCOS CERAMICO FURADOS 9 X 19 X 19 CM FUROS HORIZONTAIS, ESPESSURA DA PAREDE 19 CM, JUNTAS DE 10 MM COM ARGAMASSA TRACO 1:2:8 (CIMENTO, CAL E AREIA MEDIA) | E34: SINAPI | F34: M2 | G34: 35.13 | I34: ='MEMORIAL DE CÁLCULOS'!J92 -> 35.13 | J34: =H34+I34 -> 35.13 | K34: 45.4342 | L34: =G34*K34 -> 1596.1034 | M34: =H34*K34 -> 0 | N34: =I34*K34 -> 1596.1034 | O34: =J34*K34 -> 1596.1034 | V34: 54.74 | W34: =V34-V34*$R$5 -> 45.4342
A35: 2.3.3 | B35: 154476 | C35: 96616 | D35: LASTRO DE CONCRETO MAGRO, APLICADO EM BLOCOS DE COROAMENTO OU SAPATAS.AF_08/2017 | E35: SINAPI | F35: M3 | G35: 6.13 | I35: ='MEMORIAL DE CÁLCULOS'!J96 -> 6.13 | J35: =H35+I35 -> 6.13 | K35: 463.804 | L35: =G35*K35 -> 2843.1185 | M35: =H35*K35 -> 0 | N35: =I35*K35 -> 2843.1185 | O35: =J35*K35 -> 2843.1185 | V35: 558.8 | W35: =V35-V35*$R$5 -> 463.804
A36: 2.3.4 | B36: 161024 | D36: CONCRETO ARMADO (PREPARO E LANCAMENTO)PARA SAPATAS COM FCK >= 25MPA, COM FORMA DE TABUA, COM APROVEI TAMENTO DE 2 VEZES, COM BETONEIRA - | E36: SINAPI | F36: M3 | G36: 19.55 | I36: ='MEMORIAL DE CÁLCULOS'!J133 -> 19.55 | J36: =H36+I36 -> 19.55 | K36: 1008.533 | L36: =G36*K36 -> 19716.82 | M36: =H36*K36 -> 0 | N36: =I36*K36 -> 19716.82 | O36: =J36*K36 -> 19716.82 | V36: 1215.1 | W36: =V36-V36*$R$5 -> 1008.533
A37: 2.3.5 | B37: 161026 | D37: CONCRETO ARMADO (PREPARO E LANCAMENTO) PARA RADIER COM FCK>=25MPA, COM TABUA DE MADEIRA, COM APROVEITAMENTO DE 3 VEZES COM BETONEIRA - | E37: SINAPI | F37: M3 | G37: 12.33 | I37: ='MEMORIAL DE CÁLCULOS'!J136 -> 12.33 | J37: =H37+I37 -> 12.33 | K37: 1006.9477 | L37: =G37*K37 -> 12415.665 | M37: =H37*K37 -> 0 | N37: =I37*K37 -> 12415.665 | O37: =J37*K37 -> 12415.665 | V37: 1213.19 | W37: =V37-V37*$R$5 -> 1006.9477
A38: 2.4 4 SUPER-ESTRUTURA | L38: =SUM(L39:L46) -> 187786.33 | M38: =SUM(M39:M46) -> 0 | N38: =SUM(N39:N46) -> 0 | O38: =SUM(O39:O46) -> 0
A39: 2.4.1 | B39: 161030 | D39: CONCRETO ARMADO (PREPARO E LANCAMENTO) PARA VIGA COM FCK>=30MPA, COM FORMA EM CHAPA DE MADEIRA COM- P E N S A D A R E S I N A D A , C O M APROVEITAMENTO DE 3 VEZES COM BETONEIRA - | E39: SINAPI | F39: M3 | G39: 18.92 | J39: =H39+I39 -> 0 | K39: 2838.0273 | L39: =G39*K39 -> 53695.477 | M39: =H39*K39 -> 0 | N39: =I39*K39 -> 0 | O39: =J39*K39 -> 0 | V39: 3419.31 | W39: =V39-V39*$R$5 -> 2838.0273
A40: 2.4.2 | B40: 161031 | D40: CONCRETO ARMADO (PREPARO E LANCAMENTO) P/ PILARES COM FCK>=30MPA, COM FORMA EM CHAPA DE MADEIRA COM- P E N S A D A R E S I N A D A , C O M APROVEITAMENTO DE 3 VEZES, COM BETONEIRA - | E40: SUPLAN | F40: M3 | G40: 18.39 | J40: =H40+I40 -> 0 | K40: 2812.9032 | L40: =G40*K40 -> 51729.29 | M40: =H40*K40 -> 0 | N40: =I40*K40 -> 0 | O40: =J40*K40 -> 0 | V40: 3389.04 | W40: =V40-V40*$R$5 -> 2812.9032
...

Sheet MEMORIAL DE CÁLCULOS
A1: =[13]ORÇAMENTO!A1:J1 -> ESTADO DA PARAÍBA
A2: ESTADO DA PARAÍBA
A3: PREFEITURA MUNICIPAL DE COREMAS
A4: ='BM-01'!A3 -> CONTRATO Nº 10004/2023
A5: ='BM-01'!A4 -> OBRA: CONSTRUÇÃO DE UMA UNIDADE ESCOLAR DE 06 (SEIS) SALAS DE AULA PARA O MUNICÍPIO DE COREMAS-PB
A6: MEMORIAL DE CÁLCULOS
A7: ITEM | B7: DESCRIÇÃO | C7: DADOS | G7: Descontos | I7: RESULTADO | K7: UN.
C8: Quantid. | D8: Comprim. (m) | E8: Largura (m) | F8: Altura (m) | G8: Descrição | H8: Valor | I8: PARCIAL | J8: GERAL
A9: 1 | B9: ETAPA 01: GERAL
A10: 1.1 | B10: ADMINISTRAÇÃO LOCAL
A11: ='BM-01'!A11 -> 1.1.1 | B11: ='BM-01'!D11 -> ADMINSTRACAO LOCAL - PESSOAL | J11: =ROUND(SUM(J12:J12),2) -> 0.96 | K11: ='BM-01'!F11 -> UN
B12: Proporcional ao valor da medição | C12: 0.96 | J12: =C12 -> 0.96
A14: ='BM-01'!A12 -> 1.1.2 | B14: ='BM-01'!D12 -> ADMINISTRACAO LOCAL - DESPESAS GERAIS MENSAIS | J14: =ROUND(SUM(J15:J15),2) -> 0.96 | K14: ='BM-01'!F12 -> UN
B15: Proporcional ao valor da medição | C15: 0.96 | J15: =C15 -> 0.96
A17: ='BM-01'!A13 -> 1.1.3 | B17: ='BM-01'!D13 -> ADMINISTRACAO LOCAL - DESPESAS GERAIS FIXAS | J17: =ROUND(SUM(J18:J18),2) -> 0.12 | K17: ='BM-01'!F13 -> UN
B18: Proporcional ao valor da medição | C18: 0.12 | J18: =C18 -> 0.12
A20: ='BM-01'!A14 -> 1.1.4 | B20: ='BM-01'!D14 -> ADMINISTRACAO LOCAL - VECULOS E EQUIPAMENTOS | J20: =ROUND(SUM(J21:J21),2) -> 0.96 | K20: ='BM-01'!F14 -> UN
B21: Proporcional ao valor da medição | C21: 0.96 | J21: =C21 -> 0.96
A23: ='BM-01'!A15 -> 1.1.5 | B23: ='BM-01'!D15 -> ADMINISTRACAO LOCAL - MOVEIS E UTENSILIOS | J23: =ROUND(SUM(J24:J24),2) -> 0.12 | K23: ='BM-01'!F15 -> UN
B24: Proporcional ao valor da medição | C24: 0.12 | J24: =C24 -> 0.12
A26: 2 | B26: ETAPA 02: CONSTRUÇÃO DA ESCOLA
A27: 2.1 | B27: SERVIÇOS PRELIMINARES
A28: ='BM-01'!A20 -> 2.1.1 | B28: ='BM-01'!D20 -> PLACA DE OBRA EM CHAPA DE ACO GALVANIZADO | J28: =ROUND(SUM(J29:J29),2) -> 10 | K28: ='BM-01'!F20 -> M2
B29: Placa da obra | C29: 1 | D29: 4 | F29: 2.5 | I29: =D29*F29 -> 10 | J29: =C29*I29 -> 10
A31: ='BM-01'!A21 -> 2.1.2 | B31: ='BM-01'!D21 -> LOCACAO CONVENCIONAL DE OBRA, ATRAVES DE GABARITO DE TABUAS CORRIDAS PONTALETADAS, COM REAPROVEITAMENTO DE 3 VEZES - | J31: =ROUND(SUM(J32:J32),2) -> 771.45 | K31: ='BM-01'!F21 -> M2
B32: Área da construção com offset de 0,50m (Auxílio CAD) | C32: 771.45 | J32: =C32 -> 771.45
A34: ='BM-01'!A22 -> 2.1.3 | B34: ='BM-01'!D22 -> LIMPEZA MECANIZADA DE TERRENO COM REMOCAO DE CAMADA VEGETAL, UTILIZAND O MOTONIVELADORA | J34: =ROUND(SUM(J35:J35),2) -> 2000 | K34: ='BM-01'!F22 -> M2
B35: Área de limpeza | C35: =2000 -> 2000 | J35: =C35 -> 2000
A37: ='BM-01'!A23 -> 2.1.4 | B37: ='BM-01'!D23 -> INSTALACOES PROVISORIAS DE AGUA, INCLUSIVE CAIXA DAGUA DE 1000L | J37: =ROUND(SUM(J38:J38),2) -> 1 | K37: ='BM-01'!F23 -> UN
B38: Reservatório provisório construído | C38: 1 | J38: =C38 -> 1
A40: 2.2 | B40: MOVIMENTO DE TERRA
A41: ='BM-01'!A29 -> 2.2.1 | B41: ='BM-01'!D29 -> ESCAVACAO MANUAL DE VALA EM MATERIAL DE QUALQUER CATEGORIA, EXCETO ROCHA COM PROFUNDIDADE ATE 2M. | J41: =ROUND(SUM(J42:J43),2) -> 157.35 | K41: ='BM-01'!F29 -> M3
B42: Escavações para alvenaria de pedra (Item 2.3.1) | C42: =J88 -> 105.04 | J42: =C42 -> 105.04 | L42: 2.6
B43: Escavações de sapatas = Dimensões mais folga x profundidade média (medido cerca de 40% do total devido ao quantitativo insuficiente na planilha): | J43: =0.4352*(SUM(J44:J78)) -> 52.314304 | L43: 2.85
B44: S41=S48=S50=S66=S73 | C44: 5 | D44: 1.1 | E44: 0.95 | F44: 1 | I44: =D44*E44*F44 -> 1.045 | J44: =C44*I44 -> 5.225 | L44: 3.15
B45: S28=S37=S40 | C45: 3 | D45: 1.1 | E45: 1.1 | F45: 1 | I45: =D45*E45*F45 -> 1.21 | J45: =C45*I45 -> 3.63
B46: S1=S4=S6=S8=S10=S52 | C46: 6 | D46: 1.2 | E46: 1.05 | F46: 1 | I46: =D46*E46*F46 -> 1.26 | J46: =C46*I46 -> 7.56
B47: S13 | C47: 1 | D47: 1.25 | E47: 1.05 | F47: 1 | I47: =D47*E47*F47 -> 1.3125 | J47: =C47*I47 -> 1.3125
B48: S31=S33=S35 | C48: 3 | D48: 1.15 | E48: 1.5 | F48: 1 | I48: =D48*E48*F48 -> 1.725 | J48: =C48*I48 -> 5.175
B49: S32=S34=S36=S38=S43 | C49: 5 | D49: 0.9 | E49: 0.9 | F49: 1 | I49: =D49*E49*F49 -> 0.81 | J49: =C49*I49 -> 4.05
...
