Workbook

Sheet ADITIVO
E1: PREFEITURA MUNICIPAL DE COREMAS
E2: OBRA: REFORMA DA ESCOLA DO LOGRADOURO - ADITIVO | L2: Data Base: | M2: Outubro/2019
E3: MUNICÍPIO: COREMAS-PB | L3: BDI: | M3: 0.19211564
E4: ENDEREÇO: ZONA URBANA | L4: Encargos | M4: Não Desonerados
B6: PLANILHA ORÇAMENTÁRIA | L6: BDI = 19,21% Não Desonerado117,54% hora 73,43%mês
B8: ITEM | C8: CÓDIGO | D8: FONTE | E8: DESCRIÇÃO DOS SERVIÇOS | F8: UNID. | G8: QUANTIDADE | J8: V.Unit.(R$) | K8: V.Unit. com BDI (R$) | L8: VALOR TOTAL R$
G9: LICITADA | H9: ACRESCIDO/SUPRIMIDO | I9: TOTAL 1° REPROGRAMAÇÃO | L9: LICITADA | M9: ACRESCIDO/SUPRIMIDO | N9: TOTAL 1° REPROGRAMAÇÃO
E10: REFORMA DA ESCOLA LOGRADOURO
B11: 1.0 | E11: DEMOLIÇÕES E RETIRADAS
B12: 1.1 | C12: 97622 | D12: SINAPI | E12: Demolição de alvenaria de bloco furado, de forma manual, sem reaproveitamento. af_12/2017 | F12: m² | G12: 39.72 | H12: 0 | I12: =G12+H12 -> 39.72 | J12: 1.03 | K12: =ROUND(J12*(1+$M$3),2) -> 1.23 | L12: =ROUND(G12*$K12,2) -> 48.86 | M12: =ROUND(H12*$K12,2) -> 0 | N12: =ROUND(I12*$K12,2) -> 48.86
B13: 1.2 | C13: 97644 | D13: SINAPI | E13: Remoção de portas, de forma manual, sem reaproveitamento. af_12/2017 | F13: m² | G13: 4.83 | I13: =G13+H13 -> 4.83 | J13: 5.49 | K13: =ROUND(J13*(1+$M$3),2) -> 6.54 | L13: =ROUND(G13*$K13,2) -> 31.59 | M13: =ROUND(H13*$K13,2) -> 0 | N13: =ROUND(I13*$K13,2) -> 31.59
B14: 1.3 | C14: 97663 | D14: SINAPI | E14: Remoção de louças, de forma manual, sem reaproveitamento. | F14: un | G14: 7 | I14: =G14+H14 -> 7 | J14: 7.25 | K14: =ROUND(J14*(1+$M$3),2) -> 8.64 | L14: =ROUND(G14*$K14,2) -> 60.48 | M14: =ROUND(H14*$K14,2) -> 0 | N14: =ROUND(I14*$K14,2) -> 60.48
B15: 1.4 | D15: CPU | E15: Demolição de piso cimentado | F15: m² | G15: 42.825 | I15: =G15+H15 -> 42.825 | J15: 18.99 | K15: =ROUND(J15*(1+$M$3),2) -> 22.64 | L15: =ROUND(G15*$K15,2) -> 969.56 | M15: =ROUND(H15*$K15,2) -> 0 | N15: =ROUND(I15*$K15,2) -> 969.56
B16: 1.5 | C16: 97636 | D16: SINAPI | E16: Demolição de revestimento cerâmico, de forma manual, sem reaproveitamento. af_12/2017 - Cozinha e WC | F16: m² | G16: 143.585 | I16: =G16+H16 -> 143.585 | J16: 8.24 | K16: =ROUND(J16*(1+$M$3),2) -> 9.82 | L16: =ROUND(G16*$K16,2) -> 1410 | M16: =ROUND(H16*$K16,2) -> 0 | N16: =ROUND(I16*$K16,2) -> 1410
B17: 1.6 | C17: 72897 | D17: SINAPI | E17: Carga manual de entulho em caminhão basculante 6 m³. | F17: m³ | G17: 12.4072 | I17: =G17+H17 -> 12.4072 | J17: 16.56 | K17: =ROUND(J17*(1+$M$3),2) -> 19.74 | L17: =ROUND(G17*$K17,2) -> 244.92 | M17: =ROUND(H17*$K17,2) -> 0 | N17: =ROUND(I17*$K17,2) -> 244.92
B18: 1.7 | C18: 97914 | D18: SINAPI | E18: Transporte com caminhão basculante de 6 m3, em via urbana pavimentada dmt até 30 km (unidade: m3xkm). af_01/2018 - material excedente(bota-fora) | F18: m3 x km | G18: 16.133 | I18: =G18+H18 -> 16.133 | J18: 1.09 | K18: =ROUND(J18*(1+$M$3),2) -> 1.3 | L18: =ROUND(G18*$K18,2) -> 20.97 | M18: =ROUND(H18*$K18,2) -> 0 | N18: =ROUND(I18*$K18,2) -> 20.97
B19: Subtotal 1.0 | L19: =SUM(L12:L18) -> 2786.38 | M19: =SUM(M12:M18) -> 0 | N19: =SUM(N12:N18) -> 2786.38
B20: 2.0 | E20: REVESTIMENTOS - PISOS E PAREDES
B21: 2.1 | C21: 94990 | D21: SINAPI | E21: Execução de passeio (calçada) ou piso de concreto com concreto, espessura de 5 cm moldado in loco, feito em obra, acabamento convencional, não armado. af_07/2016 | F21: m³ | G21: 2.14125 | I21: =G21+H21 -> 2.14125 | J21: 481.46 | K21: =ROUND(J21*(1+$M$3),2) -> 573.96 | L21: =ROUND(G21*$K21,2) -> 1228.99 | M21: =ROUND(H21*$K21,2) -> 0 | N21: =ROUND(I21*$K21,2) -> 1228.99
B22: 2.2 | C22: 87894 | D22: SINAPI | E22: Chapisco aplicado em alvenaria (sem presença de vãos) e estruturas de concreto de fachada, com colher de pedreiro. argamassa traço 1:3 com preparo em betoneira 400l. af_06/2014 | F22: m² | G22: 5.4 | I22: =G22+H22 -> 5.4 | J22: 4.05 | K22: =ROUND(J22*(1+$M$3),2) -> 4.83 | L22: =ROUND(G22*$K22,2) -> 26.08 | M22: =ROUND(H22*$K22,2) -> 0 | N22: =ROUND(I22*$K22,2) -> 26.08
B23: 2.3 | C23: 87777 | D23: SINAPI | E23: Emboço ou massa única em argamassa traço 1:2:8, preparo manual, aplicada manualmente em panos de fachada com presença de vãos, espessura de 25 mm. af_06/2014 | F23: m² | G23: 5.4 | I23: =G23+H23 -> 5.4 | J23: 36.51 | K23: =ROUND(J23*(1+$M$3),2) -> 43.52 | L23: =ROUND(G23*$K23,2) -> 235.01 | M23: =ROUND(H23*$K23,2) -> 0 | N23: =ROUND(I23*$K23,2) -> 235.01
B24: 2.4 | C24: 88497 | D24: SINAPI | E24: Aplicação e lixamento de massa látex em paredes, duas demãos | F24: m² | G24: 809.27 | I24: =G24+H24 -> 809.27 | J24: 9.6 | K24: =ROUND(J24*(1+$M$3),2) -> 11.44 | L24: =ROUND(G24*$K24,2) -> 9258.05 | M24: =ROUND(H24*$K24,2) -> 0 | N24: =ROUND(I24*$K24,2) -> 9258.05
B25: 2.5 | C25: 88485 | D25: SINAPI | E25: Aplicação de fundo selador acrílico em paredes, uma demão. af_06/2014 | F25: m² | G25: 809.27 | I25: =G25+H25 -> 809.27 | J25: 1.7 | K25: =ROUND(J25*(1+$M$3),2) -> 2.03 | L25: =ROUND(G25*$K25,2) -> 1642.82 | M25: =ROUND(H25*$K25,2) -> 0 | N25: =ROUND(I25*$K25,2) -> 1642.82
B26: 2.6 | C26: 88489 | D26: SINAPI | E26: Aplicação manual de pintura com tinta látex acrílica em paredes, duas demãos. af_06/2014 | F26: m² | G26: 809.27 | I26: =G26+H26 -> 809.27 | J26: 11.22 | K26: =ROUND(J26*(1+$M$3),2) -> 13.38 | L26: =ROUND(G26*$K26,2) -> 10828.03 | M26: =ROUND(H26*$K26,2) -> 0 | N26: =ROUND(I26*$K26,2) -> 10828.03
B27: 2.7 | C27: 87272 | D27: SINAPI | E27: Revestimento cerâmico para paredes internas com placas tipo esmaltadaextra de dimensões 33x45 cm aplicadas em ambientes de área menor que 5 m² na altura inteira das paredes. af_06/2014 - WCs | F27: m² | G27: 238.47 | I27: =G27+H27 -> 238.47 | J27: 53.57 | K27: =ROUND(J27*(1+$M$3),2) -> 63.86 | L27: =ROUND(G27*$K27,2) -> 15228.69 | M27: =ROUND(H27*$K27,2) -> 0 | N27: =ROUND(I27*$K27,2) -> 15228.69 | P27: =800.8+142.1+936.6 -> 1879.5
B28: 2.8 | C28: 87273 | D28: SINAPI | E28: Revestimento cerâmico para paredes internas com placas tipo esmaltadaextra de dimensões 33x45 cm aplicadas em ambientes de área maior que 5 m² na altura inteira das paredes. af_06/2014 - Cozinha/Serviço | F28: m² | G28: 4.272 | H28: 35.46941 | I28: =G28+H28 -> 39.74141 | J28: 45.66 | K28: =ROUND(J28*(1+$M$3),2) -> 54.43 | L28: =ROUND(G28*$K28,2) -> 232.52 | M28: =ROUND(H28*$K28,2) -> 1930.6 | N28: =ROUND(I28*$K28,2) -> 2163.12 | P28: =P27/K28 -> 34.53059
B29: 2.9 | C29: 87246 | D29: SINAPI | E29: Revestimento cerâmico para piso com placas tipo grês de dimensões 35x35 cm aplicada em ambientes de área maior que 10 m² | F29: m2 | G29: 298.35 | I29: =G29+H29 -> 298.35 | J29: 43.73 | K29: =ROUND(J29*(1+$M$3),2) -> 52.13 | L29: =ROUND(G29*$K29,2) -> 15552.99 | M29: =ROUND(H29*$K29,2) -> 0 | N29: =ROUND(I29*$K29,2) -> 15552.99
B30: 2.10 | C30: 92402 | D30: SINAPI | E30: Execução de passeio em piso intertravado, com bloco 16 faces (na coloração natural) de (22 x 11) cm, espessura de 6cm. AF_12/2015.- PASSEIO EXTERNO | F30: m² | G30: 0 | H30: ='Memória de Cálculo'!D7 -> 105.19 | I30: =G30+H30 -> 105.19 | J30: 44.85 | K30: =ROUND(J30*(1+$M$3),2) -> 53.47 | L30: =ROUND(G30*$K30,2) -> 0 | M30: =ROUND(H30*$K30,2) -> 5624.51 | N30: =ROUND(I30*$K30,2) -> 5624.51 | Q30: 3810.1
B31: Subtotal 2.0 | L31: =SUM(L21:L30) -> 54233.18 | M31: =SUM(M21:M30) -> 7555.11 | N31: =SUM(N21:N30) -> 61788.29
B32: 3.0 | E32: COBERTA
B33: 3.1 | C33: 88496 | D33: SINAPI | E33: Aplicação e lixamento de massa látex em teto, duas demãos. | F33: m² | G33: 293.1055 | I33: =G33+H33 -> 293.1055 | J33: 17.55 | K33: =ROUND(J33*(1+$M$3),2) -> 20.92 | L33: =ROUND(G33*$K33,2) -> 6131.77 | M33: =ROUND(H33*$K33,2) -> 0 | N33: =ROUND(I33*$K33,2) -> 6131.77
B34: 3.2 | C34: 88482 | D34: SINAPI | E34: Aplicação de fundo selador látex pva em teto, uma demão. af_06/2014 | F34: m² | G34: 293.1055 | I34: =G34+H34 -> 293.1055 | J34: 2.4 | K34: =ROUND(J34*(1+$M$3),2) -> 2.86 | L34: =ROUND(G34*$K34,2) -> 838.28 | M34: =ROUND(H34*$K34,2) -> 0 | N34: =ROUND(I34*$K34,2) -> 838.28
B35: 3.3 | C35: 88486 | D35: SINAPI | E35: Aplicação manual de pintura com tinta látex pva em teto, duas demãos.af_06/2014 | F35: m² | G35: 293.1055 | I35: =G35+H35 -> 293.1055 | J35: 9.88 | K35: =ROUND(J35*(1+$M$3),2) -> 11.78 | L35: =ROUND(G35*$K35,2) -> 3452.78 | M35: =ROUND(H35*$K35,2) -> 0 | N35: =ROUND(I35*$K35,2) -> 3452.78
B36: 3.4 | C36: 92542 | D36: SINAPI | E36: Trama de madeira composta por ripas, caibros e terças para telhados demais que 2 águas para telha cerâmica capa-canal, incluso transporte v ertical. af_07/2019 | F36: m² | G36: 298.35 | I36: =G36+H36 -> 298.35 | J36: 57.97 | K36: =ROUND(J36*(1+$M$3),2) -> 69.11 | L36: =ROUND(G36*$K36,2) -> 20618.97 | M36: =ROUND(H36*$K36,2) -> 0 | N36: =ROUND(I36*$K36,2) -> 20618.97
B37: 3.4 | C37: 94445 | D37: SINAPI | E37: Telhamento com telha cerâmica capa-canal, tipo plan, com até 2 águas,incluso transporte vertical. af_07/2019 | F37: m² | G37: 298.35 | I37: =G37+H37 -> 298.35 | J37: 23.34 | K37: =ROUND(J37*(1+$M$3),2) -> 27.82 | L37: =ROUND(G37*$K37,2) -> 8300.1 | M37: =ROUND(H37*$K37,2) -> 0 | N37: =ROUND(I37*$K37,2) -> 8300.1
B38: Subtotal 3.0 | L38: =SUM(L33:L37) -> 39341.9 | M38: =SUM(M33:M37) -> 0 | N38: =SUM(N33:N37) -> 39341.9
B39: 4.0 | E39: ESQUADRIAS
B40: 4.1 | C40: 73739/001 | D40: SINAPI | E40: Pintura esmalte acetinado em madeira, duas demaos | F40: m² | G40: 11.76 | I40: =G40+H40 -> 11.76 | J40: 13.29 | K40: =ROUND(J40*(1+$M$3),2) -> 15.84 | L40: =ROUND(G40*$K40,2) -> 186.28 | M40: =ROUND(H40*$K40,2) -> 0 | N40: =ROUND(I40*$K40,2) -> 186.28
B41: 4.2 | C41: 73924/002 | D41: SINAPI | E41: Pintura esmalte acetinado, duas demaos, sobre superficie metalica | F41: m² | G41: 37.31 | I41: =G41+H41 -> 37.31 | J41: 20.31 | K41: =ROUND(J41*(1+$M$3),2) -> 24.21 | L41: =ROUND(G41*$K41,2) -> 903.28 | M41: =ROUND(H41*$K41,2) -> 0 | N41: =ROUND(I41*$K41,2) -> 903.28
B42: Subtotal 4.0 | L42: =SUM(L40:L41) -> 1089.56 | M42: =SUM(M40:M41) -> 0 | N42: =SUM(N40:N41) -> 1089.56
...

Sheet cronograma
A2: =[1]ORÇAMENTO!E1 -> PREFEITURA MUNICIPAL DE COREMAS
A3: =[1]ORÇAMENTO!E2 -> OBRA: REFORMA DA ESCOLA DO LOGRADOURO
A4: =[1]ORÇAMENTO!E3 -> MUNICÍPIO: COREMAS-PB
A5: =[1]ORÇAMENTO!E4 -> ENDEREÇO: ZONA URBANA
A7: CRONOGRAMA FÍSICOFINANCEIRO - CFF
A9: ITEM | B9: DESCRIÇÃO DOS SERVIÇOS | C9: TOTAL | E9: MÊS 1 | F9: MÊS 2 | G9: MÊS 3 | H9: 2786.38
H10: 61788.29
B11: REFORMA DA ESCOLA DO LOGRADOURO | H11: 39341.9
A12: 1 | B12: DEMOLIÇÕES E RETIRADAS | C12: =H9 -> 2786.38 | D12: % | E12: 1 | H12: 1089.56
D13: DIAS | H13: 2252.27
D14: R$ | E14: =C12 -> 2786.38 | H14: 1933.39
A15: 2 | B15: REVESTIMENTOS - PISOS E PAREDES | C15: =H10 -> 61788.29 | D15: % | E15: 0.6 | F15: 0.4 | H15: 5501.4
D16: DIAS | H16: 3003.28
D17: R$ | E17: =C15*E15 -> 37072.974 | F17: =C15-E17 -> 24715.316 | H17: 13631.59
A18: 3 | B18: COBERTA | C18: =H11 -> 39341.9 | D18: % | E18: 0.6 | F18: 0.4 | H18: 17399.3
D19: DIAS | H19: 18684.6
D20: R$ | E20: =C18*E18 -> 23605.14 | F20: =C18-E20 -> 15736.76 | H20: 9699.71
A21: 4 | B21: ESQUADRIAS | C21: =H12 -> 1089.56 | D21: % | F21: 1 | H21: 11258.43
D22: DIAS | H22: 5310.86
D23: R$ | F23: =C21 -> 1089.56 | H23: 1348.59
A24: 5 | B24: INSTALAÇÕES HIDROSANITÁRIAS | C24: =H13 -> 2252.27 | D24: % | F24: 1 | H24: 3448.64
D25: DIAS | H25: 8319.31
D26: R$ | F26: =C24 -> 2252.27 | H26: 75518.72
A27: 6 | B27: SERVIÇOS FINAIS | C27: =H14 -> 1933.39 | D27: % | F27: 1 | H27: 4310.77
D28: DIAS | H28: 812.03
D29: R$ | F29: =C27 -> 1933.39 | H29: 220.13
B30: AMPLIAÇÃO DA ESCOLA DO LOGRADOURO | H30: 2694.36
A31: 7 | B31: SERVIÇOS PRELIMINARES | C31: =H15 -> 5501.4 | D31: % | E31: 1 | H31: 33913.07
D32: DIAS | H32: 10328.58
D33: R$ | E33: =C31 -> 5501.4 | H33: 18745.34
A34: 8 | B34: MOVIMENTO DE TERRA | C34: =H16 -> 3003.28 | D34: % | E34: 1 | H34: 53.52
D35: DIAS | H35: 355.36
D36: R$ | E36: =C34 -> 3003.28 | H36: 3341.62
A37: 9 | B37: INFRAESTRUTURA | C37: =H17 -> 13631.59 | D37: % | E37: 0.8 | F37: 0.2 | H37: 4402.09
D38: DIAS | H38: 7610.59
D39: R$ | E39: =C37*E37 -> 10905.272 | F39: =C37-E39 -> 2726.318
A40: 10 | B40: PAREDES E PAINÉIS | C40: =[1]ORÇAMENTO!J73 -> 17399.3 | D40: % | E40: 0.3 | F40: 0.7
D41: DIAS
D42: R$ | E42: =C40*E40 -> 5219.79 | F42: =C40-E42 -> 12179.51
A43: 11 | B43: COBERTA | C43: =[1]ORÇAMENTO!J82 -> 18684.6 | D43: % | F43: 0.7 | G43: 0.3
...

Sheet Memória de Cálculo
B1: OBRA: REFORMA DA ESCOLA LOGRADOURO - ADITIVO
B2: MUNICÍPIO: COREMAS - PB
B3: ENDEREÇO: ZONA URBANA
A4: Item | B4: Descrição | C4: Und | D4: Quant. | E4: Memória de Cálculo
A5: 2.0 | B5: REVESTIMENTO - PISO E PAREDE
A6: 2.8 | B6: REVESTIMENTO CERÂMICO PARA PAREDES INTERNAS COM PLACAS TIPO ESMALTADAEXTRA DE DIMENSÕES 33X45 CM APLICADAS EM AMBIENTES DE ÁREA MAIOR QUE 5 M² NA ALTURA INTEIRA DAS PAREDES. AF_06/2014 - COZINHA/SERVIÇO | C6: m² | D6: 35.47 | E6: 35.47
A7: 2.10 | B7: EXECUÇÃO DE PASSEIO EM PISO INTERTRAVADO, COM BLOCO 16 FACES (NA COLORAÇÃO NATURAL) DE (22 X 11) CM, ESPESSURA DE 6CM. AF_12/2015. - PASSEIO EXTERNO e ACESSO LATERAL | C7: m² | D7: =TRUNC((24.61*1.2) + (25.22*3),2) -> 105.19 | E7: (24,61 x 1,20) + (25,22 X 3,00)
A8: 12 | B8: ESQUADRIAS
A9: 12.8 | B9: JANELA DE FERRO | C9: m² | D9: =(1.4*1)*2+(1.4*1)*1 -> 4.2 | E9: (1,40 x 1,00) x 2 + (1,40 x 1,00) x 1
A10: 12.9 | B10: PORTÃO DE METALON E BARRA CHATA DE FERRO C/FECHADURA E DOBRADIÇA, INCLUS. PINTURA ESMALTE SINTÉTICO | C10: m² | D10: =(2.4*2.4)+(3*2.4) -> 12.96 | E10: (2,40 x 2,40) + (3,00 x 2,40)
A11: 18 | B11: QUADRA
A12: 18.11 | B12: ALAMBRADO PARA QUADRA POLIESPORTIVA, ESTRUTURADO POR TUBOS DE ACO GALVANIZADO, COM COSTURA, DIN 2440, DIAMETRO 2", COM TELA DE ARAME GALVANIZADO, FIO 14 BWG E MALHA QUADRADA 5X5CM | C12: m² | D12: =TRUNC(188.2+((18.8+9.83)*3.5*2),2) -> 388.61 | E12: 188,20 + (18,80 + 9,83) x 3,50 x 2
A13: 18.12 | B13: FORNECIMENTO/INSTALACAO LONA PLASTICA PRETA, PARA IMPERMEABILIZACAO, ESPESSURA 150 MICRAS. | C13: m² | D13: 188.2 | E13: 188.2
A14: 18.13 | B14: PINTURA ACRILICA DE FAIXAS DE DEMARCACAO EM QUADRA , 5 CM DE LARGURA | D14: =796.09*0.05 -> 39.8045 | E14: 796,09 X 0,05
A15: 18.14 | B15: CONJUNTO PARA FUTSAL COM TRAVES OFICIAIS DE 3,00 X 2,00 M EM TUBO DE ACO GALVANIZADO 3" COM REQUADRO EM TUBO DE 1", PINTURA EM PRIMER COM TINTA ESMALTE SINTETICO E REDES DE POLIETILENO FIO 4 MM | D15: 1 | E15: 1
A16: 19 | B16: JADINAGEM
A17: 19.2 | B17: ESPALHAMETO MANUAL DE TERRA VEGETAL PARA PLANTIO DE GRAMA TIPO ESMERALDA. | C17: m³ | D17: =D18*0.1 -> 11.221 | E17: Área x Espessura = 112,21 x 0,10
A18: 19.3 | B18: PLANTIO DE GRAMA TIPO ESMERALDA, INCLUSIVE PREPARO DO SOLO. | C18: m² | D18: =44.58+67.63 -> 112.21 | E18: Área obtida no AutoCAD = Pátio 1 + Pátio 2 = 44,58 + 67,33
B19: MURO DE ARRIMO
A20: 21 | B20: SERVIÇOS PRELIMINARES
A21: 21.1 | B21: LOCACAO CONVENCIONAL DE OBRA, UTILIZANDO GABARITO DE TÁBUAS CORRIDAS PONTALETADAS A CADA 2,00M - 2 UTILIZAÇÕES. AF_10/2018 | C21: m² | D21: =TRUNC(((13.5 + 15.35 + 4.86) * 0.75) + ((6.34+5.26) * 1) + ((6.57 + 2.13) * 1.25),2) -> 47.75 | E21: [(13,50 + 15,35 + 4,86) x 0,75] + [(6,34 + 5,26) x 1,00] + [(6,57 + 2,13) x 1,25]
A22: 22.0 | B22: MOVIMENTO DE TERRA
A23: 22.1 | B23: ESCAVAÇÃO MANUAL DE VALA COM PROFUNDIDADE MENOR OU IGUAL A 1,30 M. AF_03/2016 | C23: m³ | D23: =TRUNC(((13.5 + 15.35 + 4.86) * 1.75)* 0.33 + ((6.34+5.26) * 2) * 0.25 + ((6.57 + 2.13)* 2.25)* 0.57,2) -> 36.42 | E23: [(13,50 + 15,35 + 4,86) x 1,75] x 0,33 + [(6,34+5,26) x 2,00] x 0,25 + [(6,57 + 2,13) x 2,25] x 0,57
A24: 22.2 | B24: REATERRO MANUAL DE VALAS COM COMPACTAÇÃO MECANIZADA. AF_04/2016 | C24: m³ | D24: =TRUNC((((13.5 + 15.35 + 4.86) * 1.75)* 0.33 + ((6.34+5.26) * 2) * 0.25 + ((6.57 + 2.13) * 2.25)* 0.57) - (13.5 + 15.35 + 4.86) * 0.75 * 0.33 - (5.26 * 1 * 0.25) -(6.57 + 2.13) *1.25* 0.57,2) -> 20.56 | E24: {[(13,50 + 15,35 + 4,86) x 1,75] x 0,33 + [(6,34+5,26) x 2,00] x 0,25 + [(6,57 + 2,13) x 2,25] x 0,57} - (13,50 + 15,35 + 4,86) x 0,75 x 0,33 + (5,26 x 1,00 x 0,25) + (6,57 + 2,13) x 1,25 x 0,57
A25: 23.0 | B25: INFRAESTRUTURA - MURO DE ARRIMO
A26: 23.1 | B26: CONCRETO MAGRO PARA LASTRO, TRAÇO 1:4,5:4,5 (CIMENTO/ AREIA MÉDIA/ BRITA 1) - PREPARO MECÂNICO COM BETONEIRA 400 L. AF_07/2016 | C26: m³ | D26: =TRUNC((((13.5+15.35+4.86)*0.85)+((6.34+5.26)*1.1)+((6.57+2.13)*1.35))*0.05,2) -> 2.65 | E26: {[(13,50 + 15,35 + 4,86) x 0,85] +[(6,34+5,26) x 1,10] + [(6,57 + 2,13) x 1,35]} x 0,05
A27: 23.2 | B27: LANÇAMENTO COM USO DE BALDES, ADENSAMENTO E ACABAMENTO DE CONCRETO EM ESTRUTURAS. AF_12/2015 | C27: m³ | D27: =TRUNC((((13.5+15.35+4.86)*0.85)+((6.34+5.26)*1.1)+((6.57+2.13)*1.35))*0.05,2) -> 2.65 | E27: {[(13,50 + 15,35 + 4,86) x 0,85] + [(6,34+5,26) x 1,10] + [(6,57 + 2,13) x 1,35]} x 0,05
A28: 23.3 | B28: EMBASAMENTO C/PEDRA ARGAMASSADA UTILIZANDO ARG.CIM/AREIA 1:4 | C28: m³ | D28: =TRUNC((0.68*13.5)+(0.68*15.35)+(1.18*6.34)+(1.93*6.57)+(1.93*2.13)+(1.18*5.26)+(0.67*4.86),2) -> 53.35 | E28: (0,68 x 13,50) + (0,68 x 15,35) + (1,18 x 6,34) + (1,93 x 6,57) + (1,93 x 2,13) + (1,18 x 5,26) + (0,67 x 4,86)
A29: 23.4 | B29: FABRICAÇÃO, MONTAGEM E DESMONTAGEM, EM MADEIRA SERRADA, E=25 MM, 4 UTILIZAÇÕES. AF_06/2017 | C29: m² | D29: =TRUNC((2.4*13.5)+(2.4*15.35)+(3.4*6.34)+(4.6*6.57)+(4.6*2.13)+(3.4*5.26)+(2.4*4.86),2) -> 160.36 | E29: (2,40 x 13,50) + (2,40 x 15,35) + (3,40 x 6,34) + (4,60 x 6,57) + (4,60 x 2,13) + (3,40 x 5,26) + (2,40 x 4,86)
A30: 23.5 | B30: IMPERMEABILIZACAO DE ESTRUTURAS ENTERRADAS, COM TINTA ASFALTICA, DUAS DEMAOS. | C30: m² | D30: =TRUNC((2.4*13.5)+(2.4*15.35)+(3.4*6.34)+(4.6*6.57)+(4.6*2.13)+(3.4*5.26)+(2.4*4.86),2) -> 160.36 | E30: (2,40 x 13,50) + (2,40 x 15,35) + (3,40 x 6,34) + (4,60 x 6,57) + (4,60 x 2,13) + (3,40 x 5,26) + (2,40 x 4,86)
A31: 23.6 | B31: EXECUCAO DE DRENO COM TUBOS DE PVC CORRUGADO FLÉXIVEL DE 50 MM | C31: M | D31: =(0.5*6)+(0.5*8)+((0.5*3)+(0.75*2))+((0.5*3)+(0.75*3))+((0.5*1)+(0.75*1))+((0.5*3)+(0.75*1))+(0.5*2) -> 18.25 | E31: (0,50 x 6) + (0,50 x 8) + [(0,50 x 3) + (0,75 x 2)] + [(0,50 x 3) + (0,75 x 3)] + [(0,50 x 1) + (0,75 x 1)] + [(0,50 x 3) + (0,75 x 1)] + (0,50 x 2)
A32: 24.0 | B32: SUPERESTRUTURA - PILARES E VIGAS
B33: PILARES
A34: 24.1 | B34: FABRICAÇÃO, MONTAGEM E DESMONTAGEM, EM MADEIRA SERRADA, E=25 MM, 4 UTILIZAÇÕES. AF_06/2017 | C34: m² | D34: =TRUNC((0.19+0.19+0.19+0.19)*1.83*18,2) -> 25.03 | E34: (0,19 + 0,19 + 0,19 + 0,19) x 1,83 x 18
A35: 24.2 | B35: ARMAÇÃO DE PILAR UTILIZANDO AÇO CA-60 DE 5 MM - MONTAGEM. AF_06/2017 | C35: KG | D35: =E35 -> 44 | E35: 44
A36: 24.3 | B36: ARMAÇÃO DE PILAR UTILIZANDO AÇO CA-50 DE 10 MM - MONTAGEM. AF_06/2017 | C36: KG | D36: =E36 -> 130 | E36: 130
A37: 24.4 | B37: CONCRETO FCK = 25MPA, TRAÇO 1:2,3:2,7 (CIMENTO/ AREIA MÉDIA/ BRITA 1) - PREPARO MECÂNICO COM BETONEIRA 400 L. AF_07/2016 | C37: m³ | D37: =TRUNC((0.19*0.19*1.83)*18,2) -> 1.18 | E37: (0,19 x 0,19 x 1,83) x 18
A38: 24.5 | B38: LANÇAMENTO COM USO DE BALDES, ADENSAMENTO E ACABAMENTO DE CONCRETO EM ESTRUTURAS. AF_12/2015 | C38: m³ | D38: =TRUNC((0.19*0.19*1.83)*18,2) -> 1.18 | E38: (0,19 x 0,19 x 1,83) x 18
B39: VIGAS BALDRAME E DE TOPO
A40: 24.6 | B40: FABRICAÇÃO, MONTAGEM E DESMONTAGEM, EM MADEIRA SERRADA, E=25 MM, 4 UTILIZAÇÕES. AF_06/2017 | C40: m² | D40: =TRUNC(((0.15+0.15)*(13.5+29.01+13.5))+((0.12+0.15+0.12)*(13.5+29.01+13.5)),2) -> 38.64 | E40: [(0,15 + 0,15) x (13,50 + 29,01 + 13,50)] + [(0,12 + 0,15 + 0,12) x (13,50 + 29,01 + 13,50)]
...

Sheet CFF
B1: OBRA: REFORMA DA ESCOLA LOGRADOURO - ADITIVO
B2: MUNICÍPIO: COREMAS - PB
B3: ENDEREÇO: ZONA URBANA
A4: Cronograma Físico e Financeiro
A5: Item | B5: Descrição | C5: Total Por Etapa | D5: 30 DIAS | E5: 60 DIAS
A6: 1.0 | B6: REFORMA | C6: 100,00% 108.102,23 | D6: 100,00% 108.102,23
A7: 2.0 | B7: AMPLIAÇÃO | C7: 100,00% 172.936,37 | D7: 100,00% 172.936,37
A8: 3.0 | B8: MURO DE ARRIMO | C8: 100,00% 65.901,48 | D8: 40,00% 26.360,59 | E8: 60,00% 39.540,89
A9: 4.0 | B9: MURO LATERAL DIREITA | C9: 100,00% 17.763,18 | D9: 40,00% 7.105,27 | E9: 60,00% 10.657,91
A10: Porcentagem | C10: 369103.68 | D10: =D11/C10 -> 0.8639981 | E10: =E11/C10 -> 0.1360019
A11: Custo | D11: =C10-E11 -> 318904.88 | E11: =39540.89+10657.91 -> 50198.8 | G11: =SUM(G10:G10) -> 0 | H11: =SUM(H10:H10) -> 0
A12: Porcentagem Acumulado | D12: =D13/C10 -> 0.8639981 | E12: 100,0%
A13: Custo Acumulado | D13: =D11 -> 318904.88 | E13: =D13+E11 -> 369103.68

Sheet Resumo_Valor_Desconto
C1: OBRA: REFORMA DA ESCOLA LOGRADOURO - ADITIVO | E1: VALOR | H1: DESCONTO
C2: MUNICÍPIO: COREMAS - PB | E2: ORÇADO | G2: 287139.68 | H2: =1-(G3/G2) -> 0.050187734
C3: ENDEREÇO: ZONA URBANA | E3: LICITAÇÃO | G3: 272728.79
A4: Planilha de Preços Com Desconto
A5: Item | B5: Código | C5: Banco | D5: Descrição | E5: Und | F5: Valor Unit SINAPI 10/2019 | G5: Desconto | H5: Valor Unit sem BDI
A6: 1 | B6: 93382 | C6: SINAPI | D6: REATERRO MANUAL DE VALAS COM COMPACTAÇÃO MECANIZADA. AF_04/2016 | E6: m³ | F6: 19.92 | G6: =(F6*$H$2) -> 0.99973967 | H6: =F6-G6 -> 18.92026
A7: 2 | B7: 96534 | C7: SINAPI | D7: FABRICAÇÃO, MONTAGEM E DESMONTAGEM, EM MADEIRA SERRADA, E=25 MM, 4 UTILIZAÇÕES. AF_06/2017 | E7: m² | F7: 52.36 | G7: =(F7*$H$2) -> 2.6278298 | H7: =F7-G7 -> 49.73217
A8: 3 | B8: 00000057 | C8: Próprio | D8: EXECUCAO DE DRENO COM TUBOS DE PVC CORRUGADO FLEXIVEL PERFURADO - DN 50 | E8: M | F8: 22.71 | G8: =(F8*$H$2) -> 1.1397634 | H8: =F8-G8 -> 21.570237
A9: 4 | B9: 96543 | C9: SINAPI | D9: ARMAÇÃO DE PILAR UTILIZANDO AÇO CA-60 DE 5 MM - MONTAGEM. AF_06/2017 | E9: KG | F9: 10.92 | G9: =(F9*$H$2) -> 0.54805006 | H9: =F9-G9 -> 10.37195
A10: 5 | B10: 96546 | C10: SINAPI | D10: ARMAÇÃO DE PILAR UTILIZANDO AÇO CA-50 DE 10 MM - MONTAGEM. AF_06/2017 | E10: KG | F10: 7.48 | G10: =(F10*$H$2) -> 0.37540425 | H10: =F10-G10 -> 7.1045957
A11: 6 | B11: 94965 | C11: SINAPI | D11: CONCRETO FCK = 25MPA, TRAÇO 1:2,3:2,7 (CIMENTO/ AREIA MÉDIA/ BRITA 1) - PREPARO MECÂNICO COM BETONEIRA 400 L. AF_07/2016 | E11: m³ | F11: 302.53 | G11: =(F11*$H$2) -> 15.183295 | H11: =F11-G11 -> 287.3467
A12: 7 | B12: 96543 | C12: SINAPI | D12: ARMAÇÃO DE BLOCO, VIGA UTILIZANDO AÇO CA-60 DE 5 MM - MONTAGEM. AF_06/2017 | E12: KG | F12: 10.92 | G12: =(F12*$H$2) -> 0.54805006 | H12: =F12-G12 -> 10.37195
A13: 8 | B13: 96544 | C13: SINAPI | D13: ARMAÇÃO DE BLOCO, VIGA UTILIZANDO AÇO CA-50 DE 6,3 MM - MONTAGEM. AF_06/2017 | E13: KG | F13: 9.5 | G13: =(F13*$H$2) -> 0.47678348 | H13: =F13-G13 -> 9.0232165
A14: 9 | B14: 96545 | C14: SINAPI | D14: ARMAÇÃO DE BLOCO, VIGA UTILIZANDO AÇO CA-50 DE 8 MM - MONTAGEM. AF_06/2017 | E14: KG | F14: 9.15 | G14: =(F14*$H$2) -> 0.45921777 | H14: =F14-G14 -> 8.6907822
A15: 10 | B15: 96546 | C15: SINAPI | D15: ARMAÇÃO DE BLOCO, VIGA UTILIZANDO AÇO CA-50 DE 10 MM - MONTAGEM. AF_06/2017 | E15: KG | F15: 7.48 | G15: =(F15*$H$2) -> 0.37540425 | H15: =F15-G15 -> 7.1045957
A16: 11 | B16: 94965 | C16: SINAPI | D16: CONCRETO FCK = 25MPA, TRAÇO 1:2,3:2,7 (CIMENTO/ AREIA MÉDIA/ BRITA 1) - PREPARO MECÂNICO COM BETONEIRA 400 L. AF_07/2016 | E16: m³ | F16: 302.53 | G16: =(F16*$H$2) -> 15.183295 | H16: =F16-G16 -> 287.3467
A17: 12 | B17: 87894 | C17: SINAPI | D17: CHAPISCO APLICADO EM ALVENARIA (SEM PRESENÇA DE VÃOS) E ESTRUTURAS DE CONCRETO DE FACHADA, COM COLHER DE PEDREIRO. ARGAMASSA TRAÇO 1:3 COM PREPARO EM BETONEIRA 400L. AF_06/2014 | E17: m² | F17: 4.05 | G17: =(F17*$H$2) -> 0.20326032 | H17: =F17-G17 -> 3.8467397
A18: 13 | B18: 87530 | C18: SINAPI | D18: MASSA ÚNICA, PARA RECEBIMENTO DE PINTURA, EM ARGAMASSA TRAÇO 1:2:8, PREPARO MANUAL, APLICADA MANUALMENTE EM FACES INTERNAS DE PAREDES, ESPESSURA DE 20MM, COM EXECUÇÃO DE TALISCAS. AF_06/2014 | E18: m² | F18: 24.49 | G18: =(F18*$H$2) -> 1.2290976 | H18: =F18-G18 -> 23.260902
A19: 14 | B19: C1518 | C19: SEINFRA | D19: JANELA DE FERRO | E19: m² | F19: 264.18 | G19: =(F19*$H$2) -> 13.258596 | H19: =F19-G19 -> 250.9214
A20: 15 | B20: C3659 | C20: SEINFRA | D20: PORTÃO DE METALON E BARRA CHATA DE FERRO C/FECHADURA E DOBRADIÇA, INCLUS. PINTURA ESMALTE SINTÉTICO | E20: m² | F20: 383.41 | G20: =(F20*$H$2) -> 19.242479 | H20: =F20-G20 -> 364.16752
A21: 16 | C21: CPU | D21: ESPALHAMETO MANUAL DE TERRA VEGETAL PARA PLANTIO DE GRAMA TIPO ESMERALDA. | E21: m² | F21: ='COMPOS_NÃO_DESONER.'!F12 -> 159.54 | G21: =(F21*$H$2) -> 8.0069511 | H21: =F21-G21 -> 151.53305
A22: 17 | B22: 85180 | C22: SINAPI | D22: PLANTIO DE GRAMA TIPO ESMERALDA, INCLUSIVE PREPARO DO SOLO. | E22: m² | F22: 15.5 | G22: =(F22*$H$2) -> 0.77790988 | H22: =F22-G22 -> 14.72209
A23: 18 | B23: 74244/001 | C23: SINAPI | D23: ALAMBRADO PARA QUADRA POLIESPORTIVA, ESTRUTURADO POR TUBOS DE ACO GALVANIZADO, COM COSTURA, DIN 2440, DIAMETRO 2", COM TELA DE ARAME GALVANIZADO, FIO 14 BWG E MALHA QUADRADA 5X5CM | E23: m² | F23: 114.78 | G23: =(F23*$H$2) -> 5.7605482 | H23: =F23-G23 -> 109.01945
A24: 19 | C24: CPU | D24: PORTÃO METÁLICO 1 FOLHAS DE ABRIR COM ESTRUTURA EM TUBOS DE AÇO E TELA GALVANIZADA | E24: und | G24: =(F24*$H$2) -> 0 | H24: =F24-G24 -> 0
A25: 19 | B25: 68053 | C25: SINAPI | D25: FORNECIMENTO/INSTALACAO LONA PLASTICA PRETA, PARA IMPERMEABILIZACAO, ESPESSURA 150 MICRAS. | F25: 4.79 | G25: =(F25*$H$2) -> 0.24039925 | H25: =F25-G25 -> 4.5496008
A26: 19 | B26: 41595 | C26: SINAPI | D26: PINTURA ACRILICA DE FAIXAS DE DEMARCACAO EM QUADRA , 5 CM DE LARGURA | E26: m² | F26: 9.23 | G26: =(F26*$H$2) -> 0.46323279 | H26: =F26-G26 -> 8.7667672
A27: 19 | B27: I 25398 | C27: SINAPI | D27: CONJUNTO PARA FUTSAL COM TRAVES OFICIAIS DE 3,00 X 2,00 M EM TUBO DE ACO GALVANIZADO 3" COM REQUADRO EM TUBO DE 1", PINTURA EM PRIMER COM TINTA ESMALTE SINTETICO E REDES DE POLIETILENO FIO 4 MM | E27: und | F27: 2497.16 | G27: =(F27*$H$2) -> 125.3268 | H27: =F27-G27 -> 2371.8332

Sheet COMPOS_NÃO_DESONER.
B1: PREFEITURA MUNICIPAL DE COREMAS
B2: OBRA: REFORMA DA ESCOLA LOGRADOURO - ADITIVO | D2: Data Base: | F2: Outubro/2019
B3: MUNICÍPIO: COREMAS | D3: BDI: | F3: 0.1921
B4: ENDEREÇO: ZONA URBANA | D4: Encargos | F4: Não Desonerados
A6: COMPOSIÇÕES DE CUSTO NÃO DESONERADAS
A8: 04358/ORSE | B8: Espalhamento manual de terra vegetal para o plantio de grama tipo esmeralda. | C8: m³
A9: Cód. SINAPI | B9: Descrição do Insumo | C9: Unid. | D9: Coef. | E9: Valor Unit. | F9: Valor Total
A10: 7253 Insumos | B10: Terra vegetal (granel) | C10: m³ | D10: 1.3 | E10: 96.42 | F10: =TRUNC(D10*E10,2) -> 125.34
A11: 88316 Composicao | B11: Servente com encargos complementares | C11: h | D11: 2.5 | E11: 13.68 | F11: =TRUNC(D11*E11,2) -> 34.2
A12: Valor Total Unitário | F12: =SUM(F10:F11) -> 159.54
