Workbook
Name JR_PAGE_ANCHOR_0_1: 'MEMORIAL DE CALCULO'!#REF!
Name JR_PAGE_ANCHOR_0_1: 'PLANILHA DE MEDIÇÃO'!#REF!

Sheet PLANILHA DE MEDIÇÃO
B1: CONTRATAÇÃO DE UMA EMPRESA ESPECIALIZADA PARA CONSTRUÇÃO DE 01 (UM) CENTRO ESPECIALIZADO EM ATENÇÃO A SAÚDE MENTAL PARA ATENDER AS NECESSIDADES DA SECRETARIA MUNICIPAL DE SAÚDE EM COREMAS/PB | E1: BANCO DE DADOS: SINAPI - 05/2024-Paraiba ORSE - 0412024- Sergipe | G1: B.D.I. = 22,47% ENCARGOS SOCIAIS: Nao Desonerado: embutido nos presos unitário dos insumos de mão de obra, de acordo com as bases. | I1: DATA DE INÍCIO DO CONTRATO: 15/10/2024. VIGÊNCIA: 12 MESES
A2: DADOS DO CONTRATANTE: Prefeitura Municipal de Coremas. CNPJ: 08.939.936/0001-94 POCESSO LICITATÓRIO: Processo Administrativo N°. 176/2024 e Concorrência Eletrônica N°. 0004/2024 CONTRATO N°. 328/2024 VALOR DA OBRA/CONTRATO: 1.150.000,00 (Um milhão, cento e cinquenta mil reais). | E2: NÚMERO DA MEDIÇÃO: 7ª MEDIÇÃO. | G2: REFERÊNCIA/PERÍODO DA MEDIÇÃO: De 26/06/2025 a 11/08/2025 | I2: VALOR MEDIDO NO PERÍODO: R$ 330.767,00
A3: DADOS DO CONTRATADO: CL CONSTRUÇÕES E SERVIÇOS LTDA CNPJ: 09.335.002/0001-06 ENDEREÇO: Rua Cel. João Severino, SN - Sala D - Centro - Itaporanga - PB. | E3: FONTE DOS RECURSOS: Próprio (Diversos) do Município, prevista no orçamento da União, para o exercício de 2024. | J3: TOTAL DA MEDIÇÃO 01 = | L3: =L127 -> 143165.41 | M3: TOTAL DA MEDIÇÃO 02 = | O3: =O127 -> 90821.55 | P3: TOTAL DA MEDIÇÃO 03 = | R3: =R127 -> 66728 | V3: TOTAL DA MEDIÇÃO 05 = | X3: =X127 -> 41614.02 | Y3: TOTAL DA MEDIÇÃO 06 = | AA3: =AA127 -> 330767 | AB3: TOTAL DA MEDIÇÃO 07 = | AD3: =AD127 -> 167779
J4: MEDIÇÕES | M4: MEDIÇÕES | P4: MEDIÇÕES | V4: MEDIÇÕES | Y4: MEDIÇÕES | AB4: MEDIÇÕES | AE4: AVANÇO
A5: ITEM | B5: CÓDIGO | C5: DESCRIÇÃO | D5: FONTE | E5: UND | F5: QUANTIDADE | G5: PREÇO UNITÁRIO R$ | H5: PREÇO TOTAL R$ | J5: AVANÇO PERCENTUAL NO PERÍODO | K5: QUANTIDADE MEDIDA NO PERÍODO | L5: VALOR MEDIDO NO PERÍODO | M5: AVANÇO PERCENTUAL NO PERÍODO | N5: QUANTIDADE MEDIDA NO PERÍODO | O5: VALOR MEDIDO NO PERÍODO | P5: AVANÇO PERCENTUAL NO PERÍODO | Q5: QUANTIDADE MEDIDA NO PERÍODO | R5: VALOR MEDIDO NO PERÍODO | S5: AVANÇO PERCENTUAL NO PERÍODO | T5: QUANTIDADE MEDIDA NO PERÍODO | U5: VALOR MEDIDO NO PERÍODO | V5: AVANÇO PERCENTUAL NO PERÍODO | W5: QUANTIDADE MEDIDA NO PERÍODO | X5: VALOR MEDIDO NO PERÍODO | Y5: AVANÇO PERCENTUAL NO PERÍODO | Z5: QUANTIDADE MEDIDA NO PERÍODO | AA5: VALOR MEDIDO NO PERÍODO | AB5: AVANÇO PERCENTUAL NO PERÍODO | AC5: QUANTIDADE MEDIDA NO PERÍODO | AD5: VALOR MEDIDO NO PERÍODO | AE5: % ACUMULADO | AF5: QUANT. ACUMULADA | AG5: TOTAL ACUMULADO | AH5: STATUS DO ÍTEM | AI5: QUANTIDADE A SER ACRESCENTADA NO ADITIVO
A6: 1 | B6: SERVIÇOS PRELIMINARES | H6: =SUM(H7:H8) -> 4383.8738 | J6: MEDIÇÃO 01 | M6: MEDIÇÃO 02 | P6: MEDIÇÃO 03 | S6: MEDIÇÃO 04 | V6: MEDIÇÃO 05 | Y6: MEDIÇÃO 06 | AB6: MEDIÇÃO 07
A7: 1.1 | B7: 51 | C7: Placa de obra em chapa aco galvanizado, instalada - Rev 02_O1/2022 | D7: ORSE | E7: M2 | F7: 6 | G7: 350.91 | H7: =F7*G7 -> 2105.46 | J7: 1 | K7: =TRUNC(J7*F7,2) -> 6 | L7: =TRUNC(K7*G7)+0.46 -> 2105.46 | M7: 0 | N7: =TRUNC(M7*F7,2) -> 0 | O7: =TRUNC(N7*G7)+0 -> 0 | P7: 0 | Q7: =TRUNC(P7*F7,2) -> 0 | R7: =TRUNC(Q7*G7) -> 0 | U7: =TRUNC(G7*T7)+0 -> 0 | V7: 0 | W7: =TRUNC(V7*F7,2) -> 0 | X7: =TRUNC(W7*G7)+0 -> 0 | Y7: =Z7/F7 -> 0 | AA7: =TRUNC(Z7*G7)+0 -> 0 | AB7: =AC7/F7 -> 0 | AD7: =TRUNC(AC7*G7) -> 0 | AE7: =SUM(J7,M7,P7,V7,Y7,AB7) -> 1 | AF7: =SUM(K7,N7,Q7,W7,Z7,T7,AC7) -> 6 | AG7: =SUM(L7,O7,R7,X7,AA7,U7,AD7) -> 2105.46 | AH7: =IF(AE7=100%,"ITEM FINALIZADO",AE7) -> ITEM FINALIZADO
A8: 1.2 | B8: 98524 | C8: LIMPEZA MANUAL DE VEGETAÇÃO EM TERRENO COM EXADA AF 03/2024 | D8: SINAPI | E8: M2 | F8: 488.93 | G8: 4.66 | H8: =F8*G8 -> 2278.4138 | J8: 1 | K8: =TRUNC(J8*F8,2) -> 488.93 | L8: =TRUNC(K8*G8)+0.41 -> 2278.41 | U8: =TRUNC(G8*T8)+0 -> 0 | W8: =TRUNC(V8*F8,2) -> 0 | X8: =TRUNC(W8*G8)+0 -> 0 | Y8: =Z8/F8 -> 0 | AA8: =TRUNC(Z8*G8)+0 -> 0 | AB8: =AC8/F8 -> 0 | AD8: =TRUNC(AC8*G8) -> 0 | AE8: =SUM(J8,M8,P8,V8,Y8,AB8) -> 1 | AF8: =SUM(K8,N8,Q8,W8,Z8,T8,AC8) -> 488.93 | AG8: =SUM(L8,O8,R8,X8,AA8,U8,AD8) -> 2278.41 | AH8: =IF(AE8=100%,"ITEM FINALIZADO",AE8) -> ITEM FINALIZADO
A9: 2 | B9: MOVIMENTO DE TERRA | H9: =SUM(H10:H12) -> 31651.318
A10: 2.1 | B10: 99059 | C10: LOCAÇÃO CONVENCIONAL DE OBRA, UTILIZANDO DE GABARITO DE TÁBUAS CORRIDAS PONTALETADAS A CADA 2,00M - 2 UTILIZAÇÕES. AF_03/2024 | D10: SINAPI | E10: M | F10: 335.2 | G10: 61.14 | H10: =(F10*G10)-0.01 -> 20494.118 | J10: 1 | K10: =TRUNC(J10*F10,2) -> 335.2 | L10: =TRUNC(K10*G10)+0.12 -> 20494.12 | U10: =TRUNC(G10*T10)+0 -> 0 | W10: =TRUNC(V10*F10,2) -> 0 | X10: =TRUNC(W10*G10)+0 -> 0 | Y10: =Z10/F10 -> 0 | AA10: =TRUNC(Z10*G10)+0 -> 0 | AB10: =AC10/F10 -> 0 | AD10: =TRUNC(AC10*G10) -> 0 | AE10: =SUM(J10,M10,P10,V10,Y10,AB10) -> 1 | AF10: =SUM(K10,N10,Q10,W10,Z10,T10,AC10) -> 335.2 | AG10: =SUM(L10,O10,R10,X10,AA10,U10,AD10) -> 20494.12 | AH10: =IF(AE10=100%,"ITEM FINALIZADO",AE10) -> ITEM FINALIZADO
A11: 2.2 | B11: 93358 | C11: ESCAVAÇÃO MANUAL DE VALA COM PROFUNDIDADE MENOR OU IGUAL A 1,30M AF 02/2021 | D11: SINAPI | E11: M3 | F11: 81.25 | G11: 86.72 | H11: =F11*G11 -> 7046 | J11: 1 | K11: =TRUNC(J11*F11,2) -> 81.25 | L11: =TRUNC(K11*G11)+0 -> 7046 | U11: =TRUNC(G11*T11)+0 -> 0 | W11: =TRUNC(V11*F11,2) -> 0 | X11: =TRUNC(W11*G11)+0 -> 0 | Y11: =Z11/F11 -> 0 | AA11: =TRUNC(Z11*G11)+0 -> 0 | AB11: =AC11/F11 -> 0 | AD11: =TRUNC(AC11*G11) -> 0 | AE11: =SUM(J11,M11,P11,V11,Y11,AB11) -> 1 | AF11: =SUM(K11,N11,Q11,W11,Z11,T11,AC11) -> 81.25 | AG11: =SUM(L11,O11,R11,X11,AA11,U11,AD11) -> 7046 | AH11: =IF(AE11=100%,"ITEM FINALIZADO",AE11) -> ITEM FINALIZADO
A12: 2.3 | B12: 94319 | C12: ATERRO MANUAL DE VALAS COM SOLO ARGILO-ARENOSO. AF_08/2023 | D12: SINAPI | E12: M3 | F12: 57.1 | G12: 72 | H12: =(F12*G12) -> 4111.2 | J12: 1 | K12: =TRUNC(J12*F12,2) -> 57.1 | L12: =TRUNC(K12*G12)+0.2 -> 4111.2 | U12: =TRUNC(G12*T12)+0 -> 0 | W12: =TRUNC(V12*F12,2) -> 0 | X12: =TRUNC(W12*G12)+0 -> 0 | Y12: =Z12/F12 -> 0 | AA12: =TRUNC(Z12*G12)+0 -> 0 | AB12: =AC12/F12 -> 0 | AD12: =TRUNC(AC12*G12) -> 0 | AE12: =SUM(J12,M12,P12,V12,Y12,AB12) -> 1 | AF12: =SUM(K12,N12,Q12,W12,Z12,T12,AC12) -> 57.1 | AG12: =SUM(L12,O12,R12,X12,AA12,U12,AD12) -> 4111.2 | AH12: =IF(AE12=100%,"ITEM FINALIZADO",AE12) -> ITEM FINALIZADO
A13: 3 | B13: ESTRUTURA | H13: =SUM(H15,H22) -> 200390.71
A14: 3.1 | B14: INFRAESTUTURA | H14: =H15 -> 79073.708
A15: 3.1.1 | B15: FUNDAÇÃO | H15: =SUM(H16:H21) -> 79073.708
A16: 3.1.1.1 | B16: 102486 | C16: CONCRETO FCK = 15MPA, TRACO 13,4.3,4 (EM MASSA SECA DE CIMENTO / AREIA MÉDIA/ SEIXO ROLADO) - PREPARO MANUAL. AF_05/2021 | D16: SINAPI | E16: M3 | F16: 10.59 | G16: 569.3 | H16: =(F16*G16)-0.01 -> 6028.877 | J16: 0.8 | K16: =TRUNC(J16*F16,2) -> 8.47 | L16: =TRUNC(K16*G16)+0.1 -> 4821.1 | M16: 0.2 | N16: =TRUNC(M16*F16,2)+0.01 -> 2.12 | O16: =TRUNC(N16*G16)+1.78 -> 1207.78 | U16: =TRUNC(G16*T16)+0 -> 0 | W16: =TRUNC(V16*F16,2) -> 0 | X16: =TRUNC(W16*G16)+0 -> 0 | Y16: =Z16/F16 -> 0 | AA16: =TRUNC(Z16*G16)+0 -> 0 | AB16: =AC16/F16 -> 0 | AD16: =TRUNC(AC16*G16) -> 0 | AE16: =SUM(J16,M16,P16,V16,Y16,AB16) -> 1 | AF16: =SUM(K16,N16,Q16,W16,Z16,T16,AC16) -> 10.59 | AG16: =SUM(L16,O16,R16,X16,AA16,U16,AD16) -> 6028.88 | AH16: =IF(AE16=100%,"ITEM FINALIZADO",AE16) -> ITEM FINALIZADO
A17: 3.1.1.2 | B17: 94965 | C17: CONCRETO FCK = 25MPA, TRACO 12,3:2,7 (EM MASSA SECA DE CIMENTO/ AREIA MEDIA/ BRITA 1) - PREPARO MECANICO COM BETONEIRA 400 L. AF 05/2021 | D17: SINAPI | E17: M3 | F17: 30.05 | G17: 433.53 | H17: =(F17*G17)-0.01 -> 13027.566 | J17: 0.8 | K17: =TRUNC(J17*F17,2) -> 24.04 | L17: =TRUNC(K17*G17)+0.05 -> 10422.05 | M17: 0.2 | N17: =TRUNC(M17*F17,2) -> 6.01 | O17: =TRUNC(N17*G17)+0.52 -> 2605.52 | U17: =TRUNC(G17*T17)+0 -> 0 | W17: =TRUNC(V17*F17,2) -> 0 | X17: =TRUNC(W17*G17)+0 -> 0 | Y17: =Z17/F17 -> 0 | AA17: =TRUNC(Z17*G17)+0 -> 0 | AB17: =AC17/F17 -> 0 | AD17: =TRUNC(AC17*G17) -> 0 | AE17: =SUM(J17,M17,P17,V17,Y17,AB17) -> 1 | AF17: =SUM(K17,N17,Q17,W17,Z17,T17,AC17) -> 30.05 | AG17: =SUM(L17,O17,R17,X17,AA17,U17,AD17) -> 13027.57 | AH17: =IF(AE17=100%,"ITEM FINALIZADO",AE17) -> ITEM FINALIZADO
A18: 3.1.1.3 | B18: 96544 | C18: ARMAÇÃO DE BLOCO UTILIZANDO AÇO CA-50 DE 6,3 MM - MONTAGEM. AF 01/2024 | D18: SINAPI | E18: KG | F18: 33.4 | G18: 16.48 | H18: =(F18*G18) -> 550.432 | J18: 0.8 | K18: =TRUNC(J18*F18,2) -> 26.72 | L18: =TRUNC(K18*G18)+0.34 -> 440.34 | M18: 0.2 | N18: =TRUNC(M18*F18,2) -> 6.68 | O18: =TRUNC(N18*G18)+0.09 -> 110.09 | U18: =TRUNC(G18*T18)+0 -> 0 | W18: =TRUNC(V18*F18,2) -> 0 | X18: =TRUNC(W18*G18)+0 -> 0 | Y18: =Z18/F18 -> 0 | AA18: =TRUNC(Z18*G18)+0 -> 0 | AB18: =AC18/F18 -> 0 | AD18: =TRUNC(AC18*G18) -> 0 | AE18: =SUM(J18,M18,P18,V18,Y18,AB18) -> 1 | AF18: =SUM(K18,N18,Q18,W18,Z18,T18,AC18) -> 33.4 | AG18: =SUM(L18,O18,R18,X18,AA18,U18,AD18) -> 550.43 | AH18: =IF(AE18=100%,"ITEM FINALIZADO",AE18) -> ITEM FINALIZADO
A19: 3.1.1.4 | B19: 98545 | C19: ARMAÇÃO DE BLOCO UTILZANDO AÇO CASO DE 8 MM - MONTAGEM. AF 01/2024 | D19: SINAPI | E19: KG | F19: 2842 | G19: 14.61 | H19: =(F19*G19) -> 41521.62 | J19: 0.8 | K19: =TRUNC(J19*F19,2) -> 2273.6 | L19: =TRUNC(K19*G19)+0.3 -> 33217.3 | M19: 0.2 | N19: =TRUNC(M19*F19,2) -> 568.4 | O19: =TRUNC(N19*G19)+0.32 -> 8304.32 | U19: =TRUNC(G19*T19)+0 -> 0 | W19: =TRUNC(V19*F19,2) -> 0 | X19: =TRUNC(W19*G19)+0 -> 0 | Y19: =Z19/F19 -> 0 | AA19: =TRUNC(Z19*G19)+0 -> 0 | AB19: =AC19/F19 -> 0 | AD19: =TRUNC(AC19*G19) -> 0 | AE19: =SUM(J19,M19,P19,V19,Y19,AB19) -> 1 | AF19: =SUM(K19,N19,Q19,W19,Z19,T19,AC19) -> 2842 | AG19: =SUM(L19,O19,R19,X19,AA19,U19,AD19) -> 41521.62 | AH19: =IF(AE19=100%,"ITEM FINALIZADO",AE19) -> ITEM FINALIZADO
A20: 3.1.1.5 | B20: 96543 | C20: ARMAÇÃO DE BLOCO UTILIZANDO AÇO CA-60 DE 5 MM - MONTAGEM. AF 01/2024 | D20: SINAPI | E20: KG | F20: 580.1 | G20: 18.71 | H20: =(F20*G20) -> 10853.671 | J20: 0.8 | K20: =TRUNC(J20*F20,2) -> 464.08 | L20: =TRUNC(K20*G20)+0.94 -> 8682.94 | M20: 0.2 | N20: =TRUNC(M20*F20,2) -> 116.02 | O20: =TRUNC(N20*G20)+0.73 -> 2170.73 | U20: =TRUNC(G20*T20)+0 -> 0 | W20: =TRUNC(V20*F20,2) -> 0 | X20: =TRUNC(W20*G20)+0 -> 0 | Y20: =Z20/F20 -> 0 | AA20: =TRUNC(Z20*G20)+0 -> 0 | AB20: =AC20/F20 -> 0 | AD20: =TRUNC(AC20*G20) -> 0 | AE20: =SUM(J20,M20,P20,V20,Y20,AB20) -> 1 | AF20: =SUM(K20,N20,Q20,W20,Z20,T20,AC20) -> 580.1 | AG20: =SUM(L20,O20,R20,X20,AA20,U20,AD20) -> 10853.67 | AH20: =IF(AE20=100%,"ITEM FINALIZADO",AE20) -> ITEM FINALIZADO
A21: 3.1.1.6 | B21: 98557 | C21: IMPERMEABILIZAÇÃO DE SUPERFÍCIE COM EMULSÃO ASFÁLTICA, 2 DEMÃOS. AF 09/2023 | D21: SINAPI | E21: M2 | F21: 154.03 | G21: 46.04 | H21: =(F21*G21) -> 7091.5412 | J21: 0.2 | K21: =TRUNC(J21*F21,2) -> 30.8 | L21: =TRUNC(K21*G21)+0.23 -> 1418.23 | M21: 0.8 | N21: =TRUNC(M21*F21,2) -> 123.22 | O21: =TRUNC(N21*G21)+0.31 -> 5673.31 | U21: =TRUNC(G21*T21)+0 -> 0 | W21: =TRUNC(V21*F21,2) -> 0 | X21: =TRUNC(W21*G21)+0 -> 0 | Y21: =Z21/F21 -> 0 | AA21: =TRUNC(Z21*G21)+0 -> 0 | AB21: =AC21/F21 -> 0 | AD21: =TRUNC(AC21*G21) -> 0 | AE21: =SUM(J21,M21,P21,V21,Y21,AB21) -> 1 | AF21: =SUM(K21,N21,Q21,W21,Z21,T21,AC21) -> 154.02 | AG21: =SUM(L21,O21,R21,X21,AA21,U21,AD21) -> 7091.54 | AH21: =IF(AE21=100%,"ITEM FINALIZADO",AE21) -> ITEM FINALIZADO
A22: 3.2 | B22: SUPERESTRUTURA | H22: =SUM(H23,H30,H38)+0.01 -> 121317
A23: 3.2.1 | B23: PILARES | H23: =SUM(H24:H29) -> 46405.309
A24: 3.2.1.1 | B24: 102476 | C24: CONCRETO FCK = 25MPA, TRACO 1:2,2:2,5 (EM MASSA SECA DE CIMENTO/ AREIA MEDIA/ SEIXO ROLADO) - PREPARO MECANICO COM BETONEIRA 400 L. AF 05/2021 | D24: SINAPI | E24: M3 | F24: 15.1 | G24: 557.58 | H24: =(F24*G24)-0.01 -> 8419.448 | J24: 0.5 | K24: =TRUNC(J24*F24,2) -> 7.55 | L24: =TRUNC(K24*G24)+0.73 -> 4209.73 | M24: 0.4 | N24: =TRUNC(M24*F24,2) -> 6.04 | O24: =TRUNC(N24*G24)+0.78 -> 3367.78 | P24: 0.1 | Q24: =TRUNC(P24*F24,2) -> 1.51 | R24: =TRUNC(Q24*G24) -> 841 | U24: =TRUNC(G24*T24)+0 -> 0 | W24: =TRUNC(V24*F24,2) -> 0 | X24: =TRUNC(W24*G24)+0 -> 0 | Y24: =Z24/F24 -> 0 | AA24: =TRUNC(Z24*G24)+0 -> 0 | AB24: =AC24/F24 -> 0 | AD24: =TRUNC(AC24*G24) -> 0 | AE24: =SUM(J24,M24,P24,V24,Y24,AB24) -> 1 | AF24: =SUM(K24,N24,Q24,W24,Z24,T24,AC24) -> 15.1 | AG24: =SUM(L24,O24,R24,X24,AA24,U24,AD24) -> 8418.51 | AH24: =IF(AE24=100%,"ITEM FINALIZADO",AE24) -> ITEM FINALIZADO
A25: 3.2.1.2 | B25: 96546 | C25: ARMAÇÃO DE BLOCO UTILIZANDO AÇO CA-SO DE 10 MM - MONTAGEM. AF 01/2024 | D25: SINAPI | E25: KG | F25: 90.3 | G25: 12.61 | H25: =(F25*G25) -> 1138.683 | J25: 0.5 | K25: =TRUNC(J25*F25,2) -> 45.15 | L25: =TRUNC(K25*G25)+0.34 -> 569.34 | M25: 0.4 | N25: =TRUNC(M25*F25,2) -> 36.12 | O25: =TRUNC(N25*G25)+0.47 -> 455.47 | P25: 0.1 | Q25: =TRUNC(P25*F25,2) -> 9.03 | R25: =TRUNC(Q25*G25) -> 113 | U25: =TRUNC(G25*T25)+0 -> 0 | W25: =TRUNC(V25*F25,2) -> 0 | X25: =TRUNC(W25*G25)+0 -> 0 | Y25: =Z25/F25 -> 0 | AA25: =TRUNC(Z25*G25)+0 -> 0 | AB25: =AC25/F25 -> 0 | AD25: =TRUNC(AC25*G25) -> 0 | AE25: =SUM(J25,M25,P25,V25,Y25,AB25) -> 1 | AF25: =SUM(K25,N25,Q25,W25,Z25,T25,AC25) -> 90.3 | AG25: =SUM(L25,O25,R25,X25,AA25,U25,AD25) -> 1137.81 | AH25: =IF(AE25=100%,"ITEM FINALIZADO",AE25) -> ITEM FINALIZADO
A26: 3.2.1.3 | B26: 98543 | C26: ARMAÇÃO DE BLOCO UTILIZANDO AÇO CA-CO DE 5 MM - MONTAGEM. AF 01/2024 | D26: SINAPI | E26: KG | F26: 466.7 | G26: 18.71 | H26: =(F26*G26)-0.01 -> 8731.947 | J26: 1 | K26: =TRUNC(J26*F26,2) -> 466.7 | L26: =TRUNC(K26*G26)+0.95 -> 8731.95 | Q26: =TRUNC(P26*F26,2) -> 0 | R26: =TRUNC(Q26*G26) -> 0 | U26: =TRUNC(G26*T26)+0 -> 0 | W26: =TRUNC(V26*F26,2) -> 0 | X26: =TRUNC(W26*G26)+0 -> 0 | Y26: =Z26/F26 -> 0 | AA26: =TRUNC(Z26*G26)+0 -> 0 | AB26: =AC26/F26 -> 0 | AD26: =TRUNC(AC26*G26) -> 0 | AE26: =SUM(J26,M26,P26,V26,Y26,AB26) -> 1 | AF26: =SUM(K26,N26,Q26,W26,Z26,T26,AC26) -> 466.7 | AG26: =SUM(L26,O26,R26,X26,AA26,U26,AD26) -> 8731.95 | AH26: =IF(AE26=100%,"ITEM FINALIZADO",AE26) -> ITEM FINALIZADO
A27: 3.2.1.4 | B27: 96545 | C27: ARMAÇÃO DE BLOCO UTILZANDO AÇO CA-50 DES MM - MONTAGEM, AF 01/2024 | D27: SINAPI | E27: KG | F27: 636.3 | G27: 14.61 | H27: =(F27*G27) -> 9296.343 | J27: 1 | K27: =TRUNC(J27*F27,2) -> 636.3 | L27: =TRUNC(K27*G27)+0.34 -> 9296.34 | Q27: =TRUNC(P27*F27,2) -> 0 | R27: =TRUNC(Q27*G27) -> 0 | U27: =TRUNC(G27*T27)+0 -> 0 | W27: =TRUNC(V27*F27,2) -> 0 | X27: =TRUNC(W27*G27)+0 -> 0 | Y27: =Z27/F27 -> 0 | AA27: =TRUNC(Z27*G27)+0 -> 0 | AB27: =AC27/F27 -> 0 | AD27: =TRUNC(AC27*G27) -> 0 | AE27: =SUM(J27,M27,P27,V27,Y27,AB27) -> 1 | AF27: =SUM(K27,N27,Q27,W27,Z27,T27,AC27) -> 636.3 | AG27: =SUM(L27,O27,R27,X27,AA27,U27,AD27) -> 9296.34 | AH27: =IF(AE27=100%,"ITEM FINALIZADO",AE27) -> ITEM FINALIZADO
A28: 3.2.1.5 | B28: 96547 | C28: ARMAÇÃO DE BLOCO, VIGA BALDRAME OU SAPATA UTILIZANDO AÇO CA- 50 DE 12,5 MM - MONTAGEM. AF 06/2017 | D28: SINAPI | E28: KG | F28: 17.11 | G28: 9.6 | H28: =(F28*G28)-0.01 -> 164.246 | J28: 1 | K28: =TRUNC(J28*F28,2) -> 17.11 | L28: =TRUNC(K28*G28)+0.25 -> 164.25 | Q28: =TRUNC(P28*F28,2) -> 0 | R28: =TRUNC(Q28*G28) -> 0 | U28: =TRUNC(G28*T28)+0 -> 0 | W28: =TRUNC(V28*F28,2) -> 0 | X28: =TRUNC(W28*G28)+0 -> 0 | Y28: =Z28/F28 -> 0 | AA28: =TRUNC(Z28*G28)+0 -> 0 | AB28: =AC28/F28 -> 0 | AD28: =TRUNC(AC28*G28) -> 0 | AE28: =SUM(J28,M28,P28,V28,Y28,AB28) -> 1 | AF28: =SUM(K28,N28,Q28,W28,Z28,T28,AC28) -> 17.11 | AG28: =SUM(L28,O28,R28,X28,AA28,U28,AD28) -> 164.25 | AH28: =IF(AE28=100%,"ITEM FINALIZADO",AE28) -> ITEM FINALIZADO
A29: 3.2.1.6 | B29: 103795 | C29: FABRICAÇÃO, MONTAGEM E DESMONTAGEM DE FÔRMA PARA ESCADA HIDRAULICA, EM CHAPA DE MADEIRA COMPENSADA RESINADA, E = 17 MM, 3 UTILIZAÇÕES. AF 08/2022 | D29: SINAPI | E29: M2 | F29: 227.69 | G29: 81.93 | H29: =(F29*G29) -> 18654.642 | J29: 0.5 | K29: =TRUNC(J29*F29,2) -> 113.84 | L29: =TRUNC(K29*G29)+1.32 -> 9327.32 | M29: 0.5 | N29: =TRUNC(M29*F29,2) -> 113.84 | O29: =TRUNC(N29*G29)+1.32 -> 9327.32 | P29: 0.1 | Q29: =TRUNC(P29*F29,2) -> 22.76 | R29: =TRUNC(Q29*G29) -> 1864 | T29: -22.76 | U29: =TRUNC(G29*T29)+0 -> -1864 | V29: -0.1 | W29: =TRUNC(V29*F29,2) -> -22.76 | Y29: =Z29/F29 -> 0 | AA29: =TRUNC(Z29*G29)+0 -> 0 | AB29: =AC29/F29 -> 0 | AD29: =TRUNC(AC29*G29) -> 0 | AE29: =SUM(J29,M29,P29,V29,Y29,AB29) -> 1 | AF29: =SUM(K29,N29,Q29,W29,Z29,T29,AC29) -> 204.92 | AG29: =SUM(L29,O29,R29,X29,AA29,U29,AD29) -> 18654.64 | AH29: =IF(AE29=100%,"ITEM FINALIZADO",AE29) -> ITEM FINALIZADO
A30: 3.2.2 | B30: VIGAS | H30: =SUM(H31:H37) -> 32909.86 | AH30: =SUM(AH31) -> 0
A31: 3.2.2.1 | B31: 102476 | C31: CONCRETO FCK = 25MPA, TRAGO 12,2:2,5 (EM MASSA SECA DE CIMENTO/ AREIA MEDIA/ SEIXO ROLADO) - PREPARO MECANICO COM BETONEIRA 400 L. AF 05/2021 | D31: SINAPI | E31: M3 | F31: 15.81 | G31: 557.58 | H31: =(F31*G31)-0.01 -> 8815.3298 | M31: 0.4 | N31: =TRUNC(M31*F31,2) -> 6.32 | O31: =TRUNC(N31*G31)+3.13 -> 3526.13 | P31: 0.6 | Q31: =TRUNC(P31*F31,2) -> 9.48 | R31: =TRUNC(Q31*G31) -> 5285 | U31: =TRUNC(G31*T31)+0 -> 0 | W31: =TRUNC(V31*F31,2) -> 0 | X31: =TRUNC(W31*G31)+0 -> 0 | Y31: =Z31/F31 -> 0 | AA31: =TRUNC(Z31*G31)+0 -> 0 | AB31: =AC31/F31 -> 0 | AD31: =TRUNC(AC31*G31) -> 0 | AE31: =SUM(J31,M31,P31,V31,Y31,AB31) -> 1 | AF31: =SUM(K31,N31,Q31,W31,Z31,T31,AC31) -> 15.8 | AG31: =SUM(L31,O31,R31,X31,AA31,U31,AD31) -> 8811.13 | AH31: =IF(AE31=100%,"ITEM FINALIZADO",AE31) -> ITEM FINALIZADO
A32: 3.2.2.2 | B32: 92760 | C32: ARMAÇÃO DE PILAR OU VIGA DE ESTRUTURA CONVENCIONAL DE CONCRETO ARMADO UTILIZANDO AÇO CA-50 06 8,3 MM - MONTAGEM. AF 06/2022 | D32: SINAPI | E32: KG | F32: 39.6 | G32: 11.8 | H32: =(F32*G32) -> 467.28 | M32: 0.8 | N32: =TRUNC(M32*F32,2) -> 31.68 | O32: =TRUNC(N32*G32)+0.82 -> 373.82 | P32: 0.2 | Q32: =TRUNC(P32*F32,2) -> 7.92 | R32: =TRUNC(Q32*G32) -> 93 | U32: =TRUNC(G32*T32)+0 -> 0 | W32: =TRUNC(V32*F32,2) -> 0 | X32: =TRUNC(W32*G32)+0 -> 0 | Y32: =Z32/F32 -> 0 | AA32: =TRUNC(Z32*G32)+0 -> 0 | AB32: =AC32/F32 -> 0 | AD32: =TRUNC(AC32*G32) -> 0 | AE32: =SUM(J32,M32,P32,V32,Y32,AB32) -> 1 | AF32: =SUM(K32,N32,Q32,W32,Z32,T32,AC32) -> 39.6 | AG32: =SUM(L32,O32,R32,X32,AA32,U32,AD32) -> 466.82 | AH32: =IF(AE32=100%,"ITEM FINALIZADO",AE32) -> ITEM FINALIZADO
A33: 3.2.2.3 | B33: 92761 | C33: ARMAÇÃO DE PILAR OU VIGA DE ESTRUTURA CONVENCIONAL DE CONCRETO ARMADO UTILIZANDO AÇO CA-50 DE 8,0 MM - MONTAGEM. AF 06/2022 | D33: SINAPI | E33: KG | F33: 80 | G33: 10.88 | H33: =(F33*G33) -> 870.4 | M33: 0.8 | N33: =TRUNC(M33*F33,2) -> 64 | O33: =TRUNC(N33*G33)+0.32 -> 696.32 | P33: 0.2 | Q33: =TRUNC(P33*F33,2) -> 16 | R33: =TRUNC(Q33*G33) -> 174 | U33: =TRUNC(G33*T33)+0 -> 0 | W33: =TRUNC(V33*F33,2) -> 0 | X33: =TRUNC(W33*G33)+0 -> 0 | Y33: =Z33/F33 -> 0 | AA33: =TRUNC(Z33*G33)+0 -> 0 | AB33: =AC33/F33 -> 0 | AD33: =TRUNC(AC33*G33) -> 0 | AE33: =SUM(J33,M33,P33,V33,Y33,AB33) -> 1 | AF33: =SUM(K33,N33,Q33,W33,Z33,T33,AC33) -> 80 | AG33: =SUM(L33,O33,R33,X33,AA33,U33,AD33) -> 870.32 | AH33: =IF(AE33=100%,"ITEM FINALIZADO",AE33) -> ITEM FINALIZADO
A34: 3.2.2.4 | B34: 92762 | C34: ARMAÇÃO DE PILAR OU VIGA DE ESTRUTURA CONVENCIONAL DE CONCRETO ARMADO UTILIZANDO AÇO CA-50 DE 10,0 MM - MONTAGEM. AF 06/2022 | D34: SINAPI | E34: KG | F34: 337.7 | G34: 9.61 | H34: =(F34*G34)-0.01 -> 3245.287 | M34: 0.8 | N34: =TRUNC(M34*F34,2) -> 270.16 | O34: =TRUNC(N34*G34)+0.23 -> 2596.23 | P34: 0.2 | Q34: =TRUNC(P34*F34,2) -> 67.54 | R34: =TRUNC(Q34*G34) -> 649 | U34: =TRUNC(G34*T34)+0 -> 0 | W34: =TRUNC(V34*F34,2) -> 0 | X34: =TRUNC(W34*G34)+0 -> 0 | Y34: =Z34/F34 -> 0 | AA34: =TRUNC(Z34*G34)+0 -> 0 | AB34: =AC34/F34 -> 0 | AD34: =TRUNC(AC34*G34) -> 0 | AE34: =SUM(J34,M34,P34,V34,Y34,AB34) -> 1 | AF34: =SUM(K34,N34,Q34,W34,Z34,T34,AC34) -> 337.7 | AG34: =SUM(L34,O34,R34,X34,AA34,U34,AD34) -> 3245.23 | AH34: =IF(AE34=100%,"ITEM FINALIZADO",AE34) -> ITEM FINALIZADO
A35: 3.2.2.5 | B35: 92763 | C35: ARMAÇÃO DE PILAR OU VIGA DE ESTRUTURA CONVENCIONAL DE CONCRETO ARMADO UTILZANDO AÇO CA-50 DE 12,5 MM - MONTAGEM. AF 06/2022 | D35: SINAPI | E35: KG | F35: 189.7 | G35: 8.02 | H35: =(F35*G35) -> 1521.394 | M35: 0.8 | N35: =TRUNC(M35*F35,2) -> 151.76 | O35: =TRUNC(N35*G35)+0.11 -> 1217.11 | P35: 0.2 | Q35: =TRUNC(P35*F35,2) -> 37.94 | R35: =TRUNC(Q35*G35) -> 304 | U35: =TRUNC(G35*T35)+0 -> 0 | W35: =TRUNC(V35*F35,2) -> 0 | X35: =TRUNC(W35*G35)+0 -> 0 | Y35: =Z35/F35 -> 0 | AA35: =TRUNC(Z35*G35)+0 -> 0 | AB35: =AC35/F35 -> 0 | AD35: =TRUNC(AC35*G35) -> 0 | AE35: =SUM(J35,M35,P35,V35,Y35,AB35) -> 1 | AF35: =SUM(K35,N35,Q35,W35,Z35,T35,AC35) -> 189.7 | AG35: =SUM(L35,O35,R35,X35,AA35,U35,AD35) -> 1521.11 | AH35: =IF(AE35=100%,"ITEM FINALIZADO",AE35) -> ITEM FINALIZADO
A36: 3.2.2.6 | B36: 92759 | C36: ARMAÇÃO DE PILAR OU VIGA DE ESTRUTURA CONVENCIONAL DE CONCRETO ARMADO UTILIZANDO AÇO CA-CO DE 5,0 MM - MONTAGEM. AF 06/2022 | D36: SINAPI | E36: KG | F36: 179.1 | G36: 12.82 | H36: =(F36*G36) -> 2296.062 | M36: 0.8 | N36: =TRUNC(M36*F36,2) -> 143.28 | O36: =TRUNC(N36*G36)+0.85 -> 1836.85 | P36: 0.2 | Q36: =TRUNC(P36*F36,2) -> 35.82 | R36: =TRUNC(Q36*G36) -> 459 | U36: =TRUNC(G36*T36)+0 -> 0 | W36: =TRUNC(V36*F36,2) -> 0 | X36: =TRUNC(W36*G36)+0 -> 0 | Y36: =Z36/F36 -> 0 | AA36: =TRUNC(Z36*G36)+0 -> 0 | AB36: =AC36/F36 -> 0 | AD36: =TRUNC(AC36*G36) -> 0 | AE36: =SUM(J36,M36,P36,V36,Y36,AB36) -> 1 | AF36: =SUM(K36,N36,Q36,W36,Z36,T36,AC36) -> 179.1 | AG36: =SUM(L36,O36,R36,X36,AA36,U36,AD36) -> 2295.85 | AH36: =IF(AE36=100%,"ITEM FINALIZADO",AE36) -> ITEM FINALIZADO
A37: 3.2.2.7 | B37: 92265 | C37: FABRICAÇÃO DE FORMA PARA VIGAS, EM CHAPA DE MADEIRA COMPENSADA RESINADA, E = 17 MM. AF 09/2020 | D37: SINAPI | E37: M2 | F37: 154.03 | G37: 101.89 | H37: =(F37*G37)-0.01 -> 15694.107 | M37: 1 | N37: =TRUNC(M37*F37,2) -> 154.03 | O37: =TRUNC(N37*G37)+0.11 -> 15694.11 | U37: =TRUNC(G37*T37)+0 -> 0 | W37: =TRUNC(V37*F37,2) -> 0 | X37: =TRUNC(W37*G37)+0 -> 0 | Y37: =Z37/F37 -> 0 | AA37: =TRUNC(Z37*G37)+0 -> 0 | AB37: =AC37/F37 -> 0 | AD37: =TRUNC(AC37*G37) -> 0 | AE37: =SUM(J37,M37,P37,V37,Y37,AB37) -> 1 | AF37: =SUM(K37,N37,Q37,W37,Z37,T37,AC37) -> 154.03 | AG37: =SUM(L37,O37,R37,X37,AA37,U37,AD37) -> 15694.11 | AH37: =IF(AE37=100%,"ITEM FINALIZADO",AE37) -> ITEM FINALIZADO
A38: 3.2.3 | B38: LAJE | H38: =SUM(H39:H44) -> 42001.827 | AH38: =SUM(AH39) -> 0
A39: 3.2.3.1 | B39: 94965 | C39: CONCRETO FCK = 25MPA, TRACO 1:2,3:2,7 (EM MASSA SECA DE CIMENTO/AREIA MEDIA/ BRITA 1) - PREPARO MECANICO COM BETONEIRA 400 L. AF 05/2021 | D39: SINAPI | E39: M3 | F39: 46.31 | G39: 433.53 | H39: =(F39*G39) -> 20076.774 | U39: =TRUNC(G39*T39)+0 -> 0 | V39: 0 | W39: =TRUNC(V39*F39,2) -> 0 | X39: =TRUNC(W39*G39)+0 -> 0 | Y39: =Z39/F39 -> 0 | AA39: =TRUNC(Z39*G39)+0 -> 0 | AB39: =AC39/F39 -> 0 | AD39: =TRUNC(AC39*G39) -> 0 | AE39: =SUM(J39,M39,P39,V39,Y39,AB39) -> 0 | AF39: =SUM(K39,N39,Q39,W39,Z39,T39,AC39) -> 0 | AG39: =SUM(L39,O39,R39,X39,AA39,U39,AD39) -> 0 | AH39: =IF(AE39=100%,"ITEM FINALIZADO",AE39) -> 0
A40: 3.2.3.2 | B40: 92267 | C40: FABRICAÇÃO DE FÔRMA PARA LAJES, EM CHAPA DE MADEIRA COMPENSADA RESINADA, E = 17 MM. AF 09/2020 | D40: SINAPI | E40: M2 | F40: 312.27 | G40: 26.89 | H40: =(F40*G40) -> 8396.9403 | U40: =TRUNC(G40*T40)+0 -> 0 | V40: 0 | W40: =TRUNC(V40*F40,2) -> 0 | X40: =TRUNC(W40*G40)+0 -> 0 | Y40: =Z40/F40 -> 0 | AA40: =TRUNC(Z40*G40)+0 -> 0 | AB40: =AC40/F40 -> 0 | AD40: =TRUNC(AC40*G40) -> 0 | AE40: =SUM(J40,M40,P40,V40,Y40,AB40) -> 0 | AF40: =SUM(K40,N40,Q40,W40,Z40,T40,AC40) -> 0 | AG40: =SUM(L40,O40,R40,X40,AA40,U40,AD40) -> 0 | AH40: =IF(AE40=100%,"ITEM FINALIZADO",AE40) -> 0
...

Sheet MEMORIAL DE CALCULO
B1: CONTRATAÇÃO DE UMA EMPRESA ESPECIALIZADA PARA CONSTRUÇÃO DE 01 (UM) CENTRO ESPECIALIZADO EM ATENÇÃO A SAÚDE MENTAL PARA ATENDER AS NECESSIDADES DA SECRETARIA MUNICIPAL DE SAÚDE EM COREMAS/PB | E1: BANCO DE DADOS: SINAPI - 05/2024-Paraiba ORSE - 0412024- Sergipe | V1: B.D.I. = 22,47% ENCARGOS SOCIAIS: Nao Desonerado: embutido nos presos unitário dos insumos de mão de obra, de acordo com as bases. | AW1: DATA DE INÍCIO DO CONTRATO: 15/10/2024. VIGÊNCIA: 12 MESES
A2: DADOS DO CONTRATANTE: Prefeitura Municipal de Coremas. CNPJ: 08.939.936/0001-94 POCESSO LICITATÓRIO: Processo Administrativo N°. 176/2024 e Concorrência Eletrônica N°. 0004/2024 CONTRATO N°. 328/2024 VALOR DA OBRA/CONTRATO: 1.150.000,00 (Um milhão, cento e cinquenta mil reais). | E2: NÚMERO DA MEDIÇÃO: 7ª MEDIÇÃO. | V2: REFERÊNCIA/PERÍODO DA MEDIÇÃO: 26/06/2025 a 11/08/2025 | AW2: ='PLANILHA DE MEDIÇÃO'!I2 -> VALOR MEDIDO NO PERÍODO: R$ 330.767,00
A3: DADOS DO CONTRATADO: CL CONSTRUÇÕES E SERVIÇOS LTDA CNPJ: 09.335.002/0001-06 ENDEREÇO: Rua Cel. João Severino, SN - Sala D - Centro - Itaporanga - PB. | E3: FONTE DOS RECURSOS: Próprio (Diversos) do Município, prevista no orçamento da União, para o exercício de 2024. | AX3: TOTAL DA MEDIÇÃO 01 = | AZ3: =#REF! -> #REF! | BA3: TOTAL DA MEDIÇÃO 02 = | BC3: =#REF! -> #REF! | BD3: TOTAL DA MEDIÇÃO 03 = | BF3: =#REF! -> #REF! | BJ3: TOTAL DA MEDIÇÃO 05 = | BL3: =#REF! -> #REF!
A4: MEMORIAL DE CALCULO 07 | AX4: MEDIÇÕES | BA4: MEDIÇÕES | BD4: MEDIÇÕES | BJ4: MEDIÇÕES
A5: ITEM | B5: CÓDIGO | C5: DESCRIÇÃO | D5: CALCULOS | AX5: AVANÇO PERCENTUAL NO PERÍODO | AY5: QUANTIDADE MEDIDA NO PERÍODO | AZ5: VALOR MEDIDO NO PERÍODO | BA5: AVANÇO PERCENTUAL NO PERÍODO | BB5: QUANTIDADE MEDIDA NO PERÍODO | BC5: VALOR MEDIDO NO PERÍODO | BD5: AVANÇO PERCENTUAL NO PERÍODO | BE5: QUANTIDADE MEDIDA NO PERÍODO | BF5: VALOR MEDIDO NO PERÍODO | BG5: AVANÇO PERCENTUAL NO PERÍODO | BH5: QUANTIDADE MEDIDA NO PERÍODO | BI5: VALOR MEDIDO NO PERÍODO | BJ5: AVANÇO PERCENTUAL NO PERÍODO | BK5: QUANTIDADE MEDIDA NO PERÍODO | BL5: VALOR MEDIDO NO PERÍODO
A6: 1 | B6: SERVIÇOS PRELIMINARES | AX6: MEDIÇÃO 01 | BA6: MEDIÇÃO 02 | BD6: MEDIÇÃO 03 | BG6: MEDIÇÃO 04 | BJ6: MEDIÇÃO 05
A7: 1.1 | B7: 51 | C7: Placa de obra em chapa aco galvanizado, instalada - Rev 02_O1/2022 | AX7: 1 | AY7: =TRUNC(AX7*U7,2) -> 0 | AZ7: =TRUNC(AY7*V7)+0.46 -> 0.46 | BA7: 0 | BB7: =TRUNC(BA7*U7,2) -> 0 | BC7: =TRUNC(BB7*V7)+0 -> 0 | BD7: 0 | BE7: =TRUNC(BD7*U7,2) -> 0 | BF7: =TRUNC(BE7*V7) -> 0 | BI7: =TRUNC(V7*BH7)+0 -> 0 | BJ7: 0 | BK7: =TRUNC(BJ7*U7,2) -> 0 | BL7: =TRUNC(BK7*V7)+0 -> 0
A8: 1.2 | B8: 98524 | C8: LIMPEZA MANUAL DE VEGETAÇÃO EM TERRENO COM EXADA AF 03/2024 | AX8: 1 | AY8: =TRUNC(AX8*U8,2) -> 0 | AZ8: =TRUNC(AY8*V8)+0.41 -> 0.41 | BI8: =TRUNC(V8*BH8)+0 -> 0 | BK8: =TRUNC(BJ8*U8,2) -> 0 | BL8: =TRUNC(BK8*V8)+0 -> 0
A9: 2 | B9: MOVIMENTO DE TERRA
A10: 2.1 | B10: 99059 | C10: LOCAÇÃO CONVENCIONAL DE OBRA, UTILIZANDO DE GABARITO DE TÁBUAS CORRIDAS PONTALETADAS A CADA 2,00M - 2 UTILIZAÇÕES. AF_03/2024 | AX10: 1 | AY10: =TRUNC(AX10*U10,2) -> 0 | AZ10: =TRUNC(AY10*V10)+0.12 -> 0.12 | BI10: =TRUNC(V10*BH10)+0 -> 0 | BK10: =TRUNC(BJ10*U10,2) -> 0 | BL10: =TRUNC(BK10*V10)+0 -> 0
A11: 2.2 | B11: 93358 | C11: ESCAVAÇÃO MANUAL DE VALA COM PROFUNDIDADE MENOR OU IGUAL A 1,30M AF 02/2021 | AX11: 1 | AY11: =TRUNC(AX11*U11,2) -> 0 | AZ11: =TRUNC(AY11*V11)+0 -> 0 | BI11: =TRUNC(V11*BH11)+0 -> 0 | BK11: =TRUNC(BJ11*U11,2) -> 0 | BL11: =TRUNC(BK11*V11)+0 -> 0
A12: 2.3 | B12: 94319 | C12: ATERRO MANUAL DE VALAS COM SOLO ARGILO-ARENOSO. AF_08/2023 | AX12: 1 | AY12: =TRUNC(AX12*U12,2) -> 0 | AZ12: =TRUNC(AY12*V12)+0.2 -> 0.2 | BI12: =TRUNC(V12*BH12)+0 -> 0 | BK12: =TRUNC(BJ12*U12,2) -> 0 | BL12: =TRUNC(BK12*V12)+0 -> 0
A13: 3 | B13: ESTRUTURA
A14: 3.1 | B14: INFRAESTUTURA
A15: 3.1.1 | B15: FUNDAÇÃO
A16: 3.1.1.1 | B16: 102486 | C16: CONCRETO FCK = 15MPA, TRACO 13,4.3,4 (EM MASSA SECA DE CIMENTO / AREIA MÉDIA/ SEIXO ROLADO) - PREPARO MANUAL. AF_05/2021 | AX16: 0.8 | AY16: =TRUNC(AX16*U16,2) -> 0 | AZ16: =TRUNC(AY16*V16)+0.1 -> 0.1 | BA16: 0.2 | BB16: =TRUNC(BA16*U16,2)+0.01 -> 0.01 | BC16: =TRUNC(BB16*V16)+1.78 -> 1.78 | BI16: =TRUNC(V16*BH16)+0 -> 0 | BK16: =TRUNC(BJ16*U16,2) -> 0 | BL16: =TRUNC(BK16*V16)+0 -> 0
A17: 3.1.1.2 | B17: 94965 | C17: CONCRETO FCK = 25MPA, TRACO 12,3:2,7 (EM MASSA SECA DE CIMENTO/ AREIA MEDIA/ BRITA 1) - PREPARO MECANICO COM BETONEIRA 400 L. AF 05/2021 | AX17: 0.8 | AY17: =TRUNC(AX17*U17,2) -> 0 | AZ17: =TRUNC(AY17*V17)+0.05 -> 0.05 | BA17: 0.2 | BB17: =TRUNC(BA17*U17,2) -> 0 | BC17: =TRUNC(BB17*V17)+0.52 -> 0.52 | BI17: =TRUNC(V17*BH17)+0 -> 0 | BK17: =TRUNC(BJ17*U17,2) -> 0 | BL17: =TRUNC(BK17*V17)+0 -> 0
A18: 3.1.1.3 | B18: 96544 | C18: ARMAÇÃO DE BLOCO UTILIZANDO AÇO CA-50 DE 6,3 MM - MONTAGEM. AF 01/2024 | AX18: 0.8 | AY18: =TRUNC(AX18*U18,2) -> 0 | AZ18: =TRUNC(AY18*V18)+0.34 -> 0.34 | BA18: 0.2 | BB18: =TRUNC(BA18*U18,2) -> 0 | BC18: =TRUNC(BB18*V18)+0.09 -> 0.09 | BI18: =TRUNC(V18*BH18)+0 -> 0 | BK18: =TRUNC(BJ18*U18,2) -> 0 | BL18: =TRUNC(BK18*V18)+0 -> 0
A19: 3.1.1.4 | B19: 98545 | C19: ARMAÇÃO DE BLOCO UTILZANDO AÇO CASO DE 8 MM - MONTAGEM. AF 01/2024 | AX19: 0.8 | AY19: =TRUNC(AX19*U19,2) -> 0 | AZ19: =TRUNC(AY19*V19)+0.3 -> 0.3 | BA19: 0.2 | BB19: =TRUNC(BA19*U19,2) -> 0 | BC19: =TRUNC(BB19*V19)+0.32 -> 0.32 | BI19: =TRUNC(V19*BH19)+0 -> 0 | BK19: =TRUNC(BJ19*U19,2) -> 0 | BL19: =TRUNC(BK19*V19)+0 -> 0
A20: 3.1.1.5 | B20: 96543 | C20: ARMAÇÃO DE BLOCO UTILIZANDO AÇO CA-60 DE 5 MM - MONTAGEM. AF 01/2024 | AX20: 0.8 | AY20: =TRUNC(AX20*U20,2) -> 0 | AZ20: =TRUNC(AY20*V20)+0.94 -> 0.94 | BA20: 0.2 | BB20: =TRUNC(BA20*U20,2) -> 0 | BC20: =TRUNC(BB20*V20)+0.73 -> 0.73 | BI20: =TRUNC(V20*BH20)+0 -> 0 | BK20: =TRUNC(BJ20*U20,2) -> 0 | BL20: =TRUNC(BK20*V20)+0 -> 0
A21: 3.1.1.6 | B21: 98557 | C21: IMPERMEABILIZAÇÃO DE SUPERFÍCIE COM EMULSÃO ASFÁLTICA, 2 DEMÃOS. AF 09/2023 | AX21: 0.2 | AY21: =TRUNC(AX21*U21,2) -> 0 | AZ21: =TRUNC(AY21*V21)+0.23 -> 0.23 | BA21: 0.8 | BB21: =TRUNC(BA21*U21,2) -> 0 | BC21: =TRUNC(BB21*V21)+0.31 -> 0.31 | BI21: =TRUNC(V21*BH21)+0 -> 0 | BK21: =TRUNC(BJ21*U21,2) -> 0 | BL21: =TRUNC(BK21*V21)+0 -> 0
A22: 3.2 | B22: SUPERESTRUTURA
A23: 3.2.1 | B23: PILARES
A24: 3.2.1.1 | B24: 102476 | C24: CONCRETO FCK = 25MPA, TRACO 1:2,2:2,5 (EM MASSA SECA DE CIMENTO/ AREIA MEDIA/ SEIXO ROLADO) - PREPARO MECANICO COM BETONEIRA 400 L. AF 05/2021 | AX24: 0.5 | AY24: =TRUNC(AX24*U24,2) -> 0 | AZ24: =TRUNC(AY24*V24)+0.73 -> 0.73 | BA24: 0.4 | BB24: =TRUNC(BA24*U24,2) -> 0 | BC24: =TRUNC(BB24*V24)+0.78 -> 0.78 | BD24: 0.1 | BE24: =TRUNC(BD24*U24,2) -> 0 | BF24: =TRUNC(BE24*V24) -> 0 | BI24: =TRUNC(V24*BH24)+0 -> 0 | BK24: =TRUNC(BJ24*U24,2) -> 0 | BL24: =TRUNC(BK24*V24)+0 -> 0
A25: 3.2.1.2 | B25: 96546 | C25: ARMAÇÃO DE BLOCO UTILIZANDO AÇO CA-SO DE 10 MM - MONTAGEM. AF 01/2024 | AX25: 0.5 | AY25: =TRUNC(AX25*U25,2) -> 0 | AZ25: =TRUNC(AY25*V25)+0.34 -> 0.34 | BA25: 0.4 | BB25: =TRUNC(BA25*U25,2) -> 0 | BC25: =TRUNC(BB25*V25)+0.47 -> 0.47 | BD25: 0.1 | BE25: =TRUNC(BD25*U25,2) -> 0 | BF25: =TRUNC(BE25*V25) -> 0 | BI25: =TRUNC(V25*BH25)+0 -> 0 | BK25: =TRUNC(BJ25*U25,2) -> 0 | BL25: =TRUNC(BK25*V25)+0 -> 0
A26: 3.2.1.3 | B26: 98543 | C26: ARMAÇÃO DE BLOCO UTILIZANDO AÇO CA-CO DE 5 MM - MONTAGEM. AF 01/2024 | AX26: 1 | AY26: =TRUNC(AX26*U26,2) -> 0 | AZ26: =TRUNC(AY26*V26)+0.95 -> 0.95 | BE26: =TRUNC(BD26*U26,2) -> 0 | BF26: =TRUNC(BE26*V26) -> 0 | BI26: =TRUNC(V26*BH26)+0 -> 0 | BK26: =TRUNC(BJ26*U26,2) -> 0 | BL26: =TRUNC(BK26*V26)+0 -> 0
A27: 3.2.1.4 | B27: 96545 | C27: ARMAÇÃO DE BLOCO UTILZANDO AÇO CA-50 DES MM - MONTAGEM, AF 01/2024 | AX27: 1 | AY27: =TRUNC(AX27*U27,2) -> 0 | AZ27: =TRUNC(AY27*V27)+0.34 -> 0.34 | BE27: =TRUNC(BD27*U27,2) -> 0 | BF27: =TRUNC(BE27*V27) -> 0 | BI27: =TRUNC(V27*BH27)+0 -> 0 | BK27: =TRUNC(BJ27*U27,2) -> 0 | BL27: =TRUNC(BK27*V27)+0 -> 0
A28: 3.2.1.5 | B28: 96547 | C28: ARMAÇÃO DE BLOCO, VIGA BALDRAME OU SAPATA UTILIZANDO AÇO CA- 50 DE 12,5 MM - MONTAGEM. AF 06/2017 | AX28: 1 | AY28: =TRUNC(AX28*U28,2) -> 0 | AZ28: =TRUNC(AY28*V28)+0.25 -> 0.25 | BE28: =TRUNC(BD28*U28,2) -> 0 | BF28: =TRUNC(BE28*V28) -> 0 | BI28: =TRUNC(V28*BH28)+0 -> 0 | BK28: =TRUNC(BJ28*U28,2) -> 0 | BL28: =TRUNC(BK28*V28)+0 -> 0
A29: 3.2.1.6 | B29: 103795 | C29: FABRICAÇÃO, MONTAGEM E DESMONTAGEM DE FÔRMA PARA ESCADA HIDRAULICA, EM CHAPA DE MADEIRA COMPENSADA RESINADA, E = 17 MM, 3 UTILIZAÇÕES. AF 08/2022 | AX29: 0.5 | AY29: =TRUNC(AX29*U29,2) -> 0 | AZ29: =TRUNC(AY29*V29)+1.32 -> 1.32 | BA29: 0.5 | BB29: =TRUNC(BA29*U29,2) -> 0 | BC29: =TRUNC(BB29*V29)+1.32 -> 1.32 | BD29: 0.1 | BE29: =TRUNC(BD29*U29,2) -> 0 | BF29: =TRUNC(BE29*V29) -> 0 | BH29: -22.76 | BI29: =TRUNC(V29*BH29)+0 -> 0 | BJ29: -0.1 | BK29: =TRUNC(BJ29*U29,2) -> 0
A30: 3.2.2 | B30: VIGAS
A31: 3.2.2.1 | B31: 102476 | C31: CONCRETO FCK = 25MPA, TRAGO 12,2:2,5 (EM MASSA SECA DE CIMENTO/ AREIA MEDIA/ SEIXO ROLADO) - PREPARO MECANICO COM BETONEIRA 400 L. AF 05/2021 | BA31: 0.4 | BB31: =TRUNC(BA31*U31,2) -> 0 | BC31: =TRUNC(BB31*V31)+3.13 -> 3.13 | BD31: 0.6 | BE31: =TRUNC(BD31*U31,2) -> 0 | BF31: =TRUNC(BE31*V31) -> 0 | BI31: =TRUNC(V31*BH31)+0 -> 0 | BK31: =TRUNC(BJ31*U31,2) -> 0 | BL31: =TRUNC(BK31*V31)+0 -> 0
A32: 3.2.2.2 | B32: 92760 | C32: ARMAÇÃO DE PILAR OU VIGA DE ESTRUTURA CONVENCIONAL DE CONCRETO ARMADO UTILIZANDO AÇO CA-50 06 8,3 MM - MONTAGEM. AF 06/2022 | BA32: 0.8 | BB32: =TRUNC(BA32*U32,2) -> 0 | BC32: =TRUNC(BB32*V32)+0.82 -> 0.82 | BD32: 0.2 | BE32: =TRUNC(BD32*U32,2) -> 0 | BF32: =TRUNC(BE32*V32) -> 0 | BI32: =TRUNC(V32*BH32)+0 -> 0 | BK32: =TRUNC(BJ32*U32,2) -> 0 | BL32: =TRUNC(BK32*V32)+0 -> 0
A33: 3.2.2.3 | B33: 92761 | C33: ARMAÇÃO DE PILAR OU VIGA DE ESTRUTURA CONVENCIONAL DE CONCRETO ARMADO UTILIZANDO AÇO CA-50 DE 8,0 MM - MONTAGEM. AF 06/2022 | BA33: 0.8 | BB33: =TRUNC(BA33*U33,2) -> 0 | BC33: =TRUNC(BB33*V33)+0.32 -> 0.32 | BD33: 0.2 | BE33: =TRUNC(BD33*U33,2) -> 0 | BF33: =TRUNC(BE33*V33) -> 0 | BI33: =TRUNC(V33*BH33)+0 -> 0 | BK33: =TRUNC(BJ33*U33,2) -> 0 | BL33: =TRUNC(BK33*V33)+0 -> 0
A34: 3.2.2.4 | B34: 92762 | C34: ARMAÇÃO DE PILAR OU VIGA DE ESTRUTURA CONVENCIONAL DE CONCRETO ARMADO UTILIZANDO AÇO CA-50 DE 10,0 MM - MONTAGEM. AF 06/2022 | BA34: 0.8 | BB34: =TRUNC(BA34*U34,2) -> 0 | BC34: =TRUNC(BB34*V34)+0.23 -> 0.23 | BD34: 0.2 | BE34: =TRUNC(BD34*U34,2) -> 0 | BF34: =TRUNC(BE34*V34) -> 0 | BI34: =TRUNC(V34*BH34)+0 -> 0 | BK34: =TRUNC(BJ34*U34,2) -> 0 | BL34: =TRUNC(BK34*V34)+0 -> 0
A35: 3.2.2.5 | B35: 92763 | C35: ARMAÇÃO DE PILAR OU VIGA DE ESTRUTURA CONVENCIONAL DE CONCRETO ARMADO UTILZANDO AÇO CA-50 DE 12,5 MM - MONTAGEM. AF 06/2022 | BA35: 0.8 | BB35: =TRUNC(BA35*U35,2) -> 0 | BC35: =TRUNC(BB35*V35)+0.11 -> 0.11 | BD35: 0.2 | BE35: =TRUNC(BD35*U35,2) -> 0 | BF35: =TRUNC(BE35*V35) -> 0 | BI35: =TRUNC(V35*BH35)+0 -> 0 | BK35: =TRUNC(BJ35*U35,2) -> 0 | BL35: =TRUNC(BK35*V35)+0 -> 0
A36: 3.2.2.6 | B36: 92759 | C36: ARMAÇÃO DE PILAR OU VIGA DE ESTRUTURA CONVENCIONAL DE CONCRETO ARMADO UTILIZANDO AÇO CA-CO DE 5,0 MM - MONTAGEM. AF 06/2022 | BA36: 0.8 | BB36: =TRUNC(BA36*U36,2) -> 0 | BC36: =TRUNC(BB36*V36)+0.85 -> 0.85 | BD36: 0.2 | BE36: =TRUNC(BD36*U36,2) -> 0 | BF36: =TRUNC(BE36*V36) -> 0 | BI36: =TRUNC(V36*BH36)+0 -> 0 | BK36: =TRUNC(BJ36*U36,2) -> 0 | BL36: =TRUNC(BK36*V36)+0 -> 0
A37: 3.2.2.7 | B37: 92265 | C37: FABRICAÇÃO DE FORMA PARA VIGAS, EM CHAPA DE MADEIRA COMPENSADA RESINADA, E = 17 MM. AF 09/2020 | BA37: 1 | BB37: =TRUNC(BA37*U37,2) -> 0 | BC37: =TRUNC(BB37*V37)+0.11 -> 0.11 | BI37: =TRUNC(V37*BH37)+0 -> 0 | BK37: =TRUNC(BJ37*U37,2) -> 0 | BL37: =TRUNC(BK37*V37)+0 -> 0
A38: 3.2.3 | B38: LAJE
A39: 3.2.3.1 | B39: 94965 | C39: CONCRETO FCK = 25MPA, TRACO 1:2,3:2,7 (EM MASSA SECA DE CIMENTO/AREIA MEDIA/ BRITA 1) - PREPARO MECANICO COM BETONEIRA 400 L. AF 05/2021 | BI39: =TRUNC(V39*BH39)+0 -> 0 | BJ39: 0 | BK39: =TRUNC(BJ39*U39,2) -> 0 | BL39: =TRUNC(BK39*V39)+0 -> 0
A40: 3.2.3.2 | B40: 92267 | C40: FABRICAÇÃO DE FÔRMA PARA LAJES, EM CHAPA DE MADEIRA COMPENSADA RESINADA, E = 17 MM. AF 09/2020 | BI40: =TRUNC(V40*BH40)+0 -> 0 | BJ40: 0 | BK40: =TRUNC(BJ40*U40,2) -> 0 | BL40: =TRUNC(BK40*V40)+0 -> 0
...
