Workbook
Name JR_PAGE_ANCHOR_0_1: 'MEMORIAL DE CALCULO'!#REF!
Name JR_PAGE_ANCHOR_0_1: 'PLANILHA DE MEDIÇÃO'!#REF!

Sheet PLANILHA DE MEDIÇÃO
B1: CONTRATAÇÃO DE UMA EMPRESA ESPECIALIZADA PARA CONSTRUÇÃO DE 01 (UM) CENTRO ESPECIALIZADO EM ATENÇÃO A SAÚDE MENTAL PARA ATENDER AS NECESSIDADES DA SECRETARIA MUNICIPAL DE SAÚDE EM COREMAS/PB | E1: BANCO DE DADOS: SINAPI - 05/2024-Paraiba ORSE - 0412024- Sergipe | G1: B.D.I. = 22,47% ENCARGOS SOCIAIS: Nao Desonerado: embutido nos presos unitário dos insumos de mão de obra, de acordo com as bases. | I1: DATA DE INÍCIO DO CONTRATO: 15/10/2024. VIGÊNCIA: 12 MESES
A2: DADOS DO CONTRATANTE: Prefeitura Municipal de Coremas. CNPJ: 08.939.936/0001-94 POCESSO LICITATÓRIO: Processo Administrativo N°. 176/2024 e Concorrência Eletrônica N°. 0004/2024 CONTRATO N°. 328/2024 VALOR DA OBRA/CONTRATO: 1.150.000,00 (Um milhão, cento e cinquenta mil reais). | E2: NÚMERO DA MEDIÇÃO: 8ª MEDIÇÃO. | G2: REFERÊNCIA/PERÍODO DA MEDIÇÃO: De 11/08/2025 A 11/09/2025 | I2: VALOR MEDIDO NO PERÍODO: R$ 330.767,00
A3: DADOS DO CONTRATADO: CL CONSTRUÇÕES E SERVIÇOS LTDA CNPJ: 09.335.002/0001-06 ENDEREÇO: Rua Cel. João Severino, SN - Sala D - Centro - Itaporanga - PB. | E3: FONTE DOS RECURSOS: Próprio (Diversos) do Município, prevista no orçamento da União, para o exercício de 2024. | J3: TOTAL DA MEDIÇÃO 01 = | L3: =L127 -> 143165.41 | M3: TOTAL DA MEDIÇÃO 02 = | O3: =O127 -> 90821.55 | P3: TOTAL DA MEDIÇÃO 03 = | R3: =R127 -> 66728 | V3: TOTAL DA MEDIÇÃO 05 = | X3: =X127 -> 41614.02 | Y3: TOTAL DA MEDIÇÃO 06 = | AA3: =AA127 -> 330767 | AB3: TOTAL DA MEDIÇÃO 07 = | AD3: =AD127 -> 167779 | AE3: TOTAL DA MEDIÇÃO 08= | AG3: =AG127 -> 80725
J4: MEDIÇÕES | M4: MEDIÇÕES | P4: MEDIÇÕES | V4: MEDIÇÕES | Y4: MEDIÇÕES | AB4: MEDIÇÕES | AH4: AVANÇO
A5: ITEM | B5: CÓDIGO | C5: DESCRIÇÃO | D5: FONTE | E5: UND | F5: QUANTIDADE | G5: PREÇO UNITÁRIO R$ | H5: PREÇO TOTAL R$ | J5: AVANÇO PERCENTUAL NO PERÍODO | K5: QUANTIDADE MEDIDA NO PERÍODO | L5: VALOR MEDIDO NO PERÍODO | M5: AVANÇO PERCENTUAL NO PERÍODO | N5: QUANTIDADE MEDIDA NO PERÍODO | O5: VALOR MEDIDO NO PERÍODO | P5: AVANÇO PERCENTUAL NO PERÍODO | Q5: QUANTIDADE MEDIDA NO PERÍODO | R5: VALOR MEDIDO NO PERÍODO | S5: AVANÇO PERCENTUAL NO PERÍODO | T5: QUANTIDADE MEDIDA NO PERÍODO | U5: VALOR MEDIDO NO PERÍODO | V5: AVANÇO PERCENTUAL NO PERÍODO | W5: QUANTIDADE MEDIDA NO PERÍODO | X5: VALOR MEDIDO NO PERÍODO | Y5: AVANÇO PERCENTUAL NO PERÍODO | Z5: QUANTIDADE MEDIDA NO PERÍODO | AA5: VALOR MEDIDO NO PERÍODO | AB5: AVANÇO PERCENTUAL NO PERÍODO | AC5: QUANTIDADE MEDIDA NO PERÍODO | AD5: VALOR MEDIDO NO PERÍODO | AE5: AVANÇO PERCENTUAL NO PERÍODO | AF5: QUANTIDADE MEDIDA NO PERÍODO | AG5: VALOR MEDIDO NO PERÍODO | AH5: % ACUMULADO | AI5: QUANT. ACUMULADA | AJ5: TOTAL ACUMULADO | AK5: STATUS DO ÍTEM | AL5: QUANTIDADE A SER ACRESCENTADA NO ADITIVO
A6: 1 | B6: SERVIÇOS PRELIMINARES | H6: =SUM(H7:H8) -> 4383.8738 | J6: MEDIÇÃO 01 | M6: MEDIÇÃO 02 | P6: MEDIÇÃO 03 | S6: MEDIÇÃO 04 | V6: MEDIÇÃO 05 | Y6: MEDIÇÃO 06 | AB6: MEDIÇÃO 07 | AE6: MEDIÇÃO 08
A7: 1.1 | B7: 51 | C7: Placa de obra em chapa aco galvanizado, instalada - Rev 02_O1/2022 | D7: ORSE | E7: M2 | F7: 6 | G7: 350.91 | H7: =F7*G7 -> 2105.46 | J7: 1 | K7: =TRUNC(J7*F7,2) -> 6 | L7: =TRUNC(K7*G7)+0.46 -> 2105.46 | M7: 0 | N7: =TRUNC(M7*F7,2) -> 0 | O7: =TRUNC(N7*G7)+0 -> 0 | P7: 0 | Q7: =TRUNC(P7*F7,2) -> 0 | R7: =TRUNC(Q7*G7) -> 0 | U7: =TRUNC(G7*T7)+0 -> 0 | V7: 0 | W7: =TRUNC(V7*F7,2) -> 0 | X7: =TRUNC(W7*G7)+0 -> 0 | Y7: =Z7/F7 -> 0 | AA7: =TRUNC(Z7*G7)+0 -> 0 | AB7: =AC7/F7 -> 0 | AD7: =TRUNC(AC7*G7) -> 0 | AE7: =AF7/F7 -> 0 | AG7: =TRUNC(AF7*G7) -> 0 | AH7: =SUM(J7,M7,P7,V7,Y7,AB7,AE7) -> 1 | AI7: =SUM(K7,N7,Q7,W7,Z7,T7,AC7) -> 6 | AJ7: =SUM(L7,O7,R7,X7,AA7,U7,AD7,AG7) -> 2105.46 | AK7: =IF(AH7=100%,"ITEM FINALIZADO",AH7) -> ITEM FINALIZADO
A8: 1.2 | B8: 98524 | C8: LIMPEZA MANUAL DE VEGETAÇÃO EM TERRENO COM EXADA AF 03/2024 | D8: SINAPI | E8: M2 | F8: 488.93 | G8: 4.66 | H8: =F8*G8 -> 2278.4138 | J8: 1 | K8: =TRUNC(J8*F8,2) -> 488.93 | L8: =TRUNC(K8*G8)+0.41 -> 2278.41 | U8: =TRUNC(G8*T8)+0 -> 0 | W8: =TRUNC(V8*F8,2) -> 0 | X8: =TRUNC(W8*G8)+0 -> 0 | Y8: =Z8/F8 -> 0 | AA8: =TRUNC(Z8*G8)+0 -> 0 | AB8: =AC8/F8 -> 0 | AD8: =TRUNC(AC8*G8) -> 0 | AE8: =AF8/F8 -> 0 | AG8: =TRUNC(AF8*G8) -> 0 | AH8: =SUM(J8,M8,P8,V8,Y8,AB8,AE8) -> 1 | AI8: =SUM(K8,N8,Q8,W8,Z8,T8,AC8) -> 488.93 | AJ8: =SUM(L8,O8,R8,X8,AA8,U8,AD8,AG8) -> 2278.41 | AK8: =IF(AH8=100%,"ITEM FINALIZADO",AH8) -> ITEM FINALIZADO
A9: 2 | B9: MOVIMENTO DE TERRA | H9: =SUM(H10:H12) -> 31651.318
A10: 2.1 | B10: 99059 | C10: LOCAÇÃO CONVENCIONAL DE OBRA, UTILIZANDO DE GABARITO DE TÁBUAS CORRIDAS PONTALETADAS A CADA 2,00M - 2 UTILIZAÇÕES. AF_03/2024 | D10: SINAPI | E10: M | F10: 335.2 | G10: 61.14 | H10: =(F10*G10)-0.01 -> 20494.118 | J10: 1 | K10: =TRUNC(J10*F10,2) -> 335.2 | L10: =TRUNC(K10*G10)+0.12 -> 20494.12 | U10: =TRUNC(G10*T10)+0 -> 0 | W10: =TRUNC(V10*F10,2) -> 0 | X10: =TRUNC(W10*G10)+0 -> 0 | Y10: =Z10/F10 -> 0 | AA10: =TRUNC(Z10*G10)+0 -> 0 | AB10: =AC10/F10 -> 0 | AD10: =TRUNC(AC10*G10) -> 0 | AE10: =AF10/F10 -> 0 | AG10: =TRUNC(AF10*G10) -> 0 | AH10: =SUM(J10,M10,P10,V10,Y10,AB10,AE10) -> 1 | AI10: =SUM(K10,N10,Q10,W10,Z10,T10,AC10) -> 335.2 | AJ10: =SUM(L10,O10,R10,X10,AA10,U10,AD10,AG10) -> 20494.12 | AK10: =IF(AH10=100%,"ITEM FINALIZADO",AH10) -> ITEM FINALIZADO
A11: 2.2 | B11: 93358 | C11: ESCAVAÇÃO MANUAL DE VALA COM PROFUNDIDADE MENOR OU IGUAL A 1,30M AF 02/2021 | D11: SINAPI | E11: M3 | F11: 81.25 | G11: 86.72 | H11: =F11*G11 -> 7046 | J11: 1 | K11: =TRUNC(J11*F11,2) -> 81.25 | L11: =TRUNC(K11*G11)+0 -> 7046 | U11: =TRUNC(G11*T11)+0 -> 0 | W11: =TRUNC(V11*F11,2) -> 0 | X11: =TRUNC(W11*G11)+0 -> 0 | Y11: =Z11/F11 -> 0 | AA11: =TRUNC(Z11*G11)+0 -> 0 | AB11: =AC11/F11 -> 0 | AD11: =TRUNC(AC11*G11) -> 0 | AE11: =AF11/F11 -> 0 | AG11: =TRUNC(AF11*G11) -> 0 | AH11: =SUM(J11,M11,P11,V11,Y11,AB11,AE11) -> 1 | AI11: =SUM(K11,N11,Q11,W11,Z11,T11,AC11) -> 81.25 | AJ11: =SUM(L11,O11,R11,X11,AA11,U11,AD11,AG11) -> 7046 | AK11: =IF(AH11=100%,"ITEM FINALIZADO",AH11) -> ITEM FINALIZADO
A12: 2.3 | B12: 94319 | C12: ATERRO MANUAL DE VALAS COM SOLO ARGILO-ARENOSO. AF_08/2023 | D12: SINAPI | E12: M3 | F12: 57.1 | G12: 72 | H12: =(F12*G12) -> 4111.2 | J12: 1 | K12: =TRUNC(J12*F12,2) -> 57.1 | L12: =TRUNC(K12*G12)+0.2 -> 4111.2 | U12: =TRUNC(G12*T12)+0 -> 0 | W12: =TRUNC(V12*F12,2) -> 0 | X12: =TRUNC(W12*G12)+0 -> 0 | Y12: =Z12/F12 -> 0 | AA12: =TRUNC(Z12*G12)+0 -> 0 | AB12: =AC12/F12 -> 0 | AD12: =TRUNC(AC12*G12) -> 0 | AE12: =AF12/F12 -> 0 | AG12: =TRUNC(AF12*G12) -> 0 | AH12: =SUM(J12,M12,P12,V12,Y12,AB12,AE12) -> 1 | AI12: =SUM(K12,N12,Q12,W12,Z12,T12,AC12) -> 57.1 | AJ12: =SUM(L12,O12,R12,X12,AA12,U12,AD12,AG12) -> 4111.2 | AK12: =IF(AH12=100%,"ITEM FINALIZADO",AH12) -> ITEM FINALIZADO
A13: 3 | B13: ESTRUTURA | H13: =SUM(H15,H22) -> 200390.71
A14: 3.1 | B14: INFRAESTUTURA | H14: =H15 -> 79073.708
A15: 3.1.1 | B15: FUNDAÇÃO | H15: =SUM(H16:H21) -> 79073.708
A16: 3.1.1.1 | B16: 102486 | C16: CONCRETO FCK = 15MPA, TRACO 13,4.3,4 (EM MASSA SECA DE CIMENTO / AREIA MÉDIA/ SEIXO ROLADO) - PREPARO MANUAL. AF_05/2021 | D16: SINAPI | E16: M3 | F16: 10.59 | G16: 569.3 | H16: =(F16*G16)-0.01 -> 6028.877 | J16: 0.8 | K16: =TRUNC(J16*F16,2) -> 8.47 | L16: =TRUNC(K16*G16)+0.1 -> 4821.1 | M16: 0.2 | N16: =TRUNC(M16*F16,2)+0.01 -> 2.12 | O16: =TRUNC(N16*G16)+1.78 -> 1207.78 | U16: =TRUNC(G16*T16)+0 -> 0 | W16: =TRUNC(V16*F16,2) -> 0 | X16: =TRUNC(W16*G16)+0 -> 0 | Y16: =Z16/F16 -> 0 | AA16: =TRUNC(Z16*G16)+0 -> 0 | AB16: =AC16/F16 -> 0 | AD16: =TRUNC(AC16*G16) -> 0 | AE16: =AF16/F16 -> 0 | AG16: =TRUNC(AF16*G16) -> 0 | AH16: =SUM(J16,M16,P16,V16,Y16,AB16,AE16) -> 1 | AI16: =SUM(K16,N16,Q16,W16,Z16,T16,AC16) -> 10.59 | AJ16: =SUM(L16,O16,R16,X16,AA16,U16,AD16,AG16) -> 6028.88 | AK16: =IF(AH16=100%,"ITEM FINALIZADO",AH16) -> ITEM FINALIZADO
A17: 3.1.1.2 | B17: 94965 | C17: CONCRETO FCK = 25MPA, TRACO 12,3:2,7 (EM MASSA SECA DE CIMENTO/ AREIA MEDIA/ BRITA 1) - PREPARO MECANICO COM BETONEIRA 400 L. AF 05/2021 | D17: SINAPI | E17: M3 | F17: 30.05 | G17: 433.53 | H17: =(F17*G17)-0.01 -> 13027.566 | J17: 0.8 | K17: =TRUNC(J17*F17,2) -> 24.04 | L17: =TRUNC(K17*G17)+0.05 -> 10422.05 | M17: 0.2 | N17: =TRUNC(M17*F17,2) -> 6.01 | O17: =TRUNC(N17*G17)+0.52 -> 2605.52 | U17: =TRUNC(G17*T17)+0 -> 0 | W17: =TRUNC(V17*F17,2) -> 0 | X17: =TRUNC(W17*G17)+0 -> 0 | Y17: =Z17/F17 -> 0 | AA17: =TRUNC(Z17*G17)+0 -> 0 | AB17: =AC17/F17 -> 0 | AD17: =TRUNC(AC17*G17) -> 0 | AE17: =AF17/F17 -> 0 | AG17: =TRUNC(AF17*G17) -> 0 | AH17: =SUM(J17,M17,P17,V17,Y17,AB17,AE17) -> 1 | AI17: =SUM(K17,N17,Q17,W17,Z17,T17,AC17) -> 30.05 | AJ17: =SUM(L17,O17,R17,X17,AA17,U17,AD17,AG17) -> 13027.57 | AK17: =IF(AH17=100%,"ITEM FINALIZADO",AH17) -> ITEM FINALIZADO
A18: 3.1.1.3 | B18: 96544 | C18: ARMAÇÃO DE BLOCO UTILIZANDO AÇO CA-50 DE 6,3 MM - MONTAGEM. AF 01/2024 | D18: SINAPI | E18: KG | F18: 33.4 | G18: 16.48 | H18: =(F18*G18) -> 550.432 | J18: 0.8 | K18: =TRUNC(J18*F18,2) -> 26.72 | L18: =TRUNC(K18*G18)+0.34 -> 440.34 | M18: 0.2 | N18: =TRUNC(M18*F18,2) -> 6.68 | O18: =TRUNC(N18*G18)+0.09 -> 110.09 | U18: =TRUNC(G18*T18)+0 -> 0 | W18: =TRUNC(V18*F18,2) -> 0 | X18: =TRUNC(W18*G18)+0 -> 0 | Y18: =Z18/F18 -> 0 | AA18: =TRUNC(Z18*G18)+0 -> 0 | AB18: =AC18/F18 -> 0 | AD18: =TRUNC(AC18*G18) -> 0 | AE18: =AF18/F18 -> 0 | AG18: =TRUNC(AF18*G18) -> 0 | AH18: =SUM(J18,M18,P18,V18,Y18,AB18,AE18) -> 1 | AI18: =SUM(K18,N18,Q18,W18,Z18,T18,AC18) -> 33.4 | AJ18: =SUM(L18,O18,R18,X18,AA18,U18,AD18,AG18) -> 550.43 | AK18: =IF(AH18=100%,"ITEM FINALIZADO",AH18) -> ITEM FINALIZADO
A19: 3.1.1.4 | B19: 98545 | C19: ARMAÇÃO DE BLOCO UTILZANDO AÇO CASO DE 8 MM - MONTAGEM. AF 01/2024 | D19: SINAPI | E19: KG | F19: 2842 | G19: 14.61 | H19: =(F19*G19) -> 41521.62 | J19: 0.8 | K19: =TRUNC(J19*F19,2) -> 2273.6 | L19: =TRUNC(K19*G19)+0.3 -> 33217.3 | M19: 0.2 | N19: =TRUNC(M19*F19,2) -> 568.4 | O19: =TRUNC(N19*G19)+0.32 -> 8304.32 | U19: =TRUNC(G19*T19)+0 -> 0 | W19: =TRUNC(V19*F19,2) -> 0 | X19: =TRUNC(W19*G19)+0 -> 0 | Y19: =Z19/F19 -> 0 | AA19: =TRUNC(Z19*G19)+0 -> 0 | AB19: =AC19/F19 -> 0 | AD19: =TRUNC(AC19*G19) -> 0 | AE19: =AF19/F19 -> 0 | AG19: =TRUNC(AF19*G19) -> 0 | AH19: =SUM(J19,M19,P19,V19,Y19,AB19,AE19) -> 1 | AI19: =SUM(K19,N19,Q19,W19,Z19,T19,AC19) -> 2842 | AJ19: =SUM(L19,O19,R19,X19,AA19,U19,AD19,AG19) -> 41521.62 | AK19: =IF(AH19=100%,"ITEM FINALIZADO",AH19) -> ITEM FINALIZADO
A20: 3.1.1.5 | B20: 96543 | C20: ARMAÇÃO DE BLOCO UTILIZANDO AÇO CA-60 DE 5 MM - MONTAGEM. AF 01/2024 | D20: SINAPI | E20: KG | F20: 580.1 | G20: 18.71 | H20: =(F20*G20) -> 10853.671 | J20: 0.8 | K20: =TRUNC(J20*F20,2) -> 464.08 | L20: =TRUNC(K20*G20)+0.94 -> 8682.94 | M20: 0.2 | N20: =TRUNC(M20*F20,2) -> 116.02 | O20: =TRUNC(N20*G20)+0.73 -> 2170.73 | U20: =TRUNC(G20*T20)+0 -> 0 | W20: =TRUNC(V20*F20,2) -> 0 | X20: =TRUNC(W20*G20)+0 -> 0 | Y20: =Z20/F20 -> 0 | AA20: =TRUNC(Z20*G20)+0 -> 0 | AB20: =AC20/F20 -> 0 | AD20: =TRUNC(AC20*G20) -> 0 | AE20: =AF20/F20 -> 0 | AG20: =TRUNC(AF20*G20) -> 0 | AH20: =SUM(J20,M20,P20,V20,Y20,AB20,AE20) -> 1 | AI20: =SUM(K20,N20,Q20,W20,Z20,T20,AC20) -> 580.1 | AJ20: =SUM(L20,O20,R20,X20,AA20,U20,AD20,AG20) -> 10853.67 | AK20: =IF(AH20=100%,"ITEM FINALIZADO",AH20) -> ITEM FINALIZADO
A21: 3.1.1.6 | B21: 98557 | C21: IMPERMEABILIZAÇÃO DE SUPERFÍCIE COM EMULSÃO ASFÁLTICA, 2 DEMÃOS. AF 09/2023 | D21: SINAPI | E21: M2 | F21: 154.03 | G21: 46.04 | H21: =(F21*G21) -> 7091.5412 | J21: 0.2 | K21: =TRUNC(J21*F21,2) -> 30.8 | L21: =TRUNC(K21*G21)+0.23 -> 1418.23 | M21: 0.8 | N21: =TRUNC(M21*F21,2) -> 123.22 | O21: =TRUNC(N21*G21)+0.31 -> 5673.31 | U21: =TRUNC(G21*T21)+0 -> 0 | W21: =TRUNC(V21*F21,2) -> 0 | X21: =TRUNC(W21*G21)+0 -> 0 | Y21: =Z21/F21 -> 0 | AA21: =TRUNC(Z21*G21)+0 -> 0 | AB21: =AC21/F21 -> 0 | AD21: =TRUNC(AC21*G21) -> 0 | AE21: =AF21/F21 -> 0 | AG21: =TRUNC(AF21*G21) -> 0 | AH21: =SUM(J21,M21,P21,V21,Y21,AB21,AE21) -> 1 | AI21: =SUM(K21,N21,Q21,W21,Z21,T21,AC21) -> 154.02 | AJ21: =SUM(L21,O21,R21,X21,AA21,U21,AD21,AG21) -> 7091.54 | AK21: =IF(AH21=100%,"ITEM FINALIZADO",AH21) -> ITEM FINALIZADO
A22: 3.2 | B22: SUPERESTRUTURA | H22: =SUM(H23,H30,H38)+0.01 -> 121317
A23: 3.2.1 | B23: PILARES | H23: =SUM(H24:H29) -> 46405.309
A24: 3.2.1.1 | B24: 102476 | C24: CONCRETO FCK = 25MPA, TRACO 1:2,2:2,5 (EM MASSA SECA DE CIMENTO/ AREIA MEDIA/ SEIXO ROLADO) - PREPARO MECANICO COM BETONEIRA 400 L. AF 05/2021 | D24: SINAPI | E24: M3 | F24: 15.1 | G24: 557.58 | H24: =(F24*G24)-0.01 -> 8419.448 | J24: 0.5 | K24: =TRUNC(J24*F24,2) -> 7.55 | L24: =TRUNC(K24*G24)+0.73 -> 4209.73 | M24: 0.4 | N24: =TRUNC(M24*F24,2) -> 6.04 | O24: =TRUNC(N24*G24)+0.78 -> 3367.78 | P24: 0.1 | Q24: =TRUNC(P24*F24,2) -> 1.51 | R24: =TRUNC(Q24*G24) -> 841 | U24: =TRUNC(G24*T24)+0 -> 0 | W24: =TRUNC(V24*F24,2) -> 0 | X24: =TRUNC(W24*G24)+0 -> 0 | Y24: =Z24/F24 -> 0 | AA24: =TRUNC(Z24*G24)+0 -> 0 | AB24: =AC24/F24 -> 0 | AD24: =TRUNC(AC24*G24) -> 0 | AE24: =AF24/F24 -> 0 | AG24: =TRUNC(AF24*G24) -> 0 | AH24: =SUM(J24,M24,P24,V24,Y24,AB24,AE24) -> 1 | AI24: =SUM(K24,N24,Q24,W24,Z24,T24,AC24) -> 15.1 | AJ24: =SUM(L24,O24,R24,X24,AA24,U24,AD24,AG24) -> 8418.51 | AK24: =IF(AH24=100%,"ITEM FINALIZADO",AH24) -> ITEM FINALIZADO
A25: 3.2.1.2 | B25: 96546 | C25: ARMAÇÃO DE BLOCO UTILIZANDO AÇO CA-SO DE 10 MM - MONTAGEM. AF 01/2024 | D25: SINAPI | E25: KG | F25: 90.3 | G25: 12.61 | H25: =(F25*G25) -> 1138.683 | J25: 0.5 | K25: =TRUNC(J25*F25,2) -> 45.15 | L25: =TRUNC(K25*G25)+0.34 -> 569.34 | M25: 0.4 | N25: =TRUNC(M25*F25,2) -> 36.12 | O25: =TRUNC(N25*G25)+0.47 -> 455.47 | P25: 0.1 | Q25: =TRUNC(P25*F25,2) -> 9.03 | R25: =TRUNC(Q25*G25) -> 113 | U25: =TRUNC(G25*T25)+0 -> 0 | W25: =TRUNC(V25*F25,2) -> 0 | X25: =TRUNC(W25*G25)+0 -> 0 | Y25: =Z25/F25 -> 0 | AA25: =TRUNC(Z25*G25)+0 -> 0 | AB25: =AC25/F25 -> 0 | AD25: =TRUNC(AC25*G25) -> 0 | AE25: =AF25/F25 -> 0 | AG25: =TRUNC(AF25*G25) -> 0 | AH25: =SUM(J25,M25,P25,V25,Y25,AB25,AE25) -> 1 | AI25: =SUM(K25,N25,Q25,W25,Z25,T25,AC25) -> 90.3 | AJ25: =SUM(L25,O25,R25,X25,AA25,U25,AD25,AG25) -> 1137.81 | AK25: =IF(AH25=100%,"ITEM FINALIZADO",AH25) -> ITEM FINALIZADO
A26: 3.2.1.3 | B26: 98543 | C26: ARMAÇÃO DE BLOCO UTILIZANDO AÇO CA-CO DE 5 MM - MONTAGEM. AF 01/2024 | D26: SINAPI | E26: KG | F26: 466.7 | G26: 18.71 | H26: =(F26*G26)-0.01 -> 8731.947 | J26: 1 | K26: =TRUNC(J26*F26,2) -> 466.7 | L26: =TRUNC(K26*G26)+0.95 -> 8731.95 | Q26: =TRUNC(P26*F26,2) -> 0 | R26: =TRUNC(Q26*G26) -> 0 | U26: =TRUNC(G26*T26)+0 -> 0 | W26: =TRUNC(V26*F26,2) -> 0 | X26: =TRUNC(W26*G26)+0 -> 0 | Y26: =Z26/F26 -> 0 | AA26: =TRUNC(Z26*G26)+0 -> 0 | AB26: =AC26/F26 -> 0 | AD26: =TRUNC(AC26*G26) -> 0 | AE26: =AF26/F26 -> 0 | AG26: =TRUNC(AF26*G26) -> 0 | AH26: =SUM(J26,M26,P26,V26,Y26,AB26,AE26) -> 1 | AI26: =SUM(K26,N26,Q26,W26,Z26,T26,AC26) -> 466.7 | AJ26: =SUM(L26,O26,R26,X26,AA26,U26,AD26,AG26) -> 8731.95 | AK26: =IF(AH26=100%,"ITEM FINALIZADO",AH26) -> ITEM FINALIZADO
A27: 3.2.1.4 | B27: 96545 | C27: ARMAÇÃO DE BLOCO UTILZANDO AÇO CA-50 DES MM - MONTAGEM, AF 01/2024 | D27: SINAPI | E27: KG | F27: 636.3 | G27: 14.61 | H27: =(F27*G27) -> 9296.343 | J27: 1 | K27: =TRUNC(J27*F27,2) -> 636.3 | L27: =TRUNC(K27*G27)+0.34 -> 9296.34 | Q27: =TRUNC(P27*F27,2) -> 0 | R27: =TRUNC(Q27*G27) -> 0 | U27: =TRUNC(G27*T27)+0 -> 0 | W27: =TRUNC(V27*F27,2) -> 0 | X27: =TRUNC(W27*G27)+0 -> 0 | Y27: =Z27/F27 -> 0 | AA27: =TRUNC(Z27*G27)+0 -> 0 | AB27: =AC27/F27 -> 0 | AD27: =TRUNC(AC27*G27) -> 0 | AE27: =AF27/F27 -> 0 | AG27: =TRUNC(AF27*G27) -> 0 | AH27: =SUM(J27,M27,P27,V27,Y27,AB27,AE27) -> 1 | AI27: =SUM(K27,N27,Q27,W27,Z27,T27,AC27) -> 636.3 | AJ27: =SUM(L27,O27,R27,X27,AA27,U27,AD27,AG27) -> 9296.34 | AK27: =IF(AH27=100%,"ITEM FINALIZADO",AH27) -> ITEM FINALIZADO
A28: 3.2.1.5 | B28: 96547 | C28: ARMAÇÃO DE BLOCO, VIGA BALDRAME OU SAPATA UTILIZANDO AÇO CA- 50 DE 12,5 MM - MONTAGEM. AF 06/2017 | D28: SINAPI | E28: KG | F28: 17.11 | G28: 9.6 | H28: =(F28*G28)-0.01 -> 164.246 | J28: 1 | K28: =TRUNC(J28*F28,2) -> 17.11 | L28: =TRUNC(K28*G28)+0.25 -> 164.25 | Q28: =TRUNC(P28*F28,2) -> 0 | R28: =TRUNC(Q28*G28) -> 0 | U28: =TRUNC(G28*T28)+0 -> 0 | W28: =TRUNC(V28*F28,2) -> 0 | X28: =TRUNC(W28*G28)+0 -> 0 | Y28: =Z28/F28 -> 0 | AA28: =TRUNC(Z28*G28)+0 -> 0 | AB28: =AC28/F28 -> 0 | AD28: =TRUNC(AC28*G28) -> 0 | AE28: =AF28/F28 -> 0 | AG28: =TRUNC(AF28*G28) -> 0 | AH28: =SUM(J28,M28,P28,V28,Y28,AB28,AE28) -> 1 | AI28: =SUM(K28,N28,Q28,W28,Z28,T28,AC28) -> 17.11 | AJ28: =SUM(L28,O28,R28,X28,AA28,U28,AD28,AG28) -> 164.25 | AK28: =IF(AH28=100%,"ITEM FINALIZADO",AH28) -> ITEM FINALIZADO
A29: 3.2.1.6 | B29: 103795 | C29: FABRICAÇÃO, MONTAGEM E DESMONTAGEM DE FÔRMA PARA ESCADA HIDRAULICA, EM CHAPA DE MADEIRA COMPENSADA RESINADA, E = 17 MM, 3 UTILIZAÇÕES. AF 08/2022 | D29: SINAPI | E29: M2 | F29: 227.69 | G29: 81.93 | H29: =(F29*G29) -> 18654.642 | J29: 0.5 | K29: =TRUNC(J29*F29,2) -> 113.84 | L29: =TRUNC(K29*G29)+1.32 -> 9327.32 | M29: 0.5 | N29: =TRUNC(M29*F29,2) -> 113.84 | O29: =TRUNC(N29*G29)+1.32 -> 9327.32 | P29: 0.1 | Q29: =TRUNC(P29*F29,2) -> 22.76 | R29: =TRUNC(Q29*G29) -> 1864 | T29: -22.76 | U29: =TRUNC(G29*T29)+0 -> -1864 | V29: -0.1 | W29: =TRUNC(V29*F29,2) -> -22.76 | Y29: =Z29/F29 -> 0 | AA29: =TRUNC(Z29*G29)+0 -> 0 | AB29: =AC29/F29 -> 0 | AD29: =TRUNC(AC29*G29) -> 0 | AE29: =AF29/F29 -> 0 | AG29: =TRUNC(AF29*G29) -> 0 | AH29: =SUM(J29,M29,P29,V29,Y29,AB29,AE29) -> 1 | AI29: =SUM(K29,N29,Q29,W29,Z29,T29,AC29) -> 204.92 | AJ29: =SUM(L29,O29,R29,X29,AA29,U29,AD29,AG29) -> 18654.64 | AK29: =IF(AH29=100%,"ITEM FINALIZADO",AH29) -> ITEM FINALIZADO
A30: 3.2.2 | B30: VIGAS | H30: =SUM(H31:H37) -> 32909.86 | AK30: =SUM(AK31) -> 0
A31: 3.2.2.1 | B31: 102476 | C31: CONCRETO FCK = 25MPA, TRAGO 12,2:2,5 (EM MASSA SECA DE CIMENTO/ AREIA MEDIA/ SEIXO ROLADO) - PREPARO MECANICO COM BETONEIRA 400 L. AF 05/2021 | D31: SINAPI | E31: M3 | F31: 15.81 | G31: 557.58 | H31: =(F31*G31)-0.01 -> 8815.3298 | M31: 0.4 | N31: =TRUNC(M31*F31,2) -> 6.32 | O31: =TRUNC(N31*G31)+3.13 -> 3526.13 | P31: 0.6 | Q31: =TRUNC(P31*F31,2) -> 9.48 | R31: =TRUNC(Q31*G31) -> 5285 | U31: =TRUNC(G31*T31)+0 -> 0 | W31: =TRUNC(V31*F31,2) -> 0 | X31: =TRUNC(W31*G31)+0 -> 0 | Y31: =Z31/F31 -> 0 | AA31: =TRUNC(Z31*G31)+0 -> 0 | AB31: =AC31/F31 -> 0 | AD31: =TRUNC(AC31*G31) -> 0 | AE31: =AF31/F31 -> 0 | AG31: =TRUNC(AF31*G31) -> 0 | AH31: =SUM(J31,M31,P31,V31,Y31,AB31,AE31) -> 1 | AI31: =SUM(K31,N31,Q31,W31,Z31,T31,AC31) -> 15.8 | AJ31: =SUM(L31,O31,R31,X31,AA31,U31,AD31,AG31) -> 8811.13 | AK31: =IF(AH31=100%,"ITEM FINALIZADO",AH31) -> ITEM FINALIZADO
A32: 3.2.2.2 | B32: 92760 | C32: ARMAÇÃO DE PILAR OU VIGA DE ESTRUTURA CONVENCIONAL DE CONCRETO ARMADO UTILIZANDO AÇO CA-50 06 8,3 MM - MONTAGEM. AF 06/2022 | D32: SINAPI | E32: KG | F32: 39.6 | G32: 11.8 | H32: =(F32*G32) -> 467.28 | M32: 0.8 | N32: =TRUNC(M32*F32,2) -> 31.68 | O32: =TRUNC(N32*G32)+0.82 -> 373.82 | P32: 0.2 | Q32: =TRUNC(P32*F32,2) -> 7.92 | R32: =TRUNC(Q32*G32) -> 93 | U32: =TRUNC(G32*T32)+0 -> 0 | W32: =TRUNC(V32*F32,2) -> 0 | X32: =TRUNC(W32*G32)+0 -> 0 | Y32: =Z32/F32 -> 0 | AA32: =TRUNC(Z32*G32)+0 -> 0 | AB32: =AC32/F32 -> 0 | AD32: =TRUNC(AC32*G32) -> 0 | AE32: =AF32/F32 -> 0 | AG32: =TRUNC(AF32*G32) -> 0 | AH32: =SUM(J32,M32,P32,V32,Y32,AB32,AE32) -> 1 | AI32: =SUM(K32,N32,Q32,W32,Z32,T32,AC32) -> 39.6 | AJ32: =SUM(L32,O32,R32,X32,AA32,U32,AD32,AG32) -> 466.82 | AK32: =IF(AH32=100%,"ITEM FINALIZADO",AH32) -> ITEM FINALIZADO
A33: 3.2.2.3 | B33: 92761 | C33: ARMAÇÃO DE PILAR OU VIGA DE ESTRUTURA CONVENCIONAL DE CONCRETO ARMADO UTILIZANDO AÇO CA-50 DE 8,0 MM - MONTAGEM. AF 06/2022 | D33: SINAPI | E33: KG | F33: 80 | G33: 10.88 | H33: =(F33*G33) -> 870.4 | M33: 0.8 | N33: =TRUNC(M33*F33,2) -> 64 | O33: =TRUNC(N33*G33)+0.32 -> 696.32 | P33: 0.2 | Q33: =TRUNC(P33*F33,2) -> 16 | R33: =TRUNC(Q33*G33) -> 174 | U33: =TRUNC(G33*T33)+0 -> 0 | W33: =TRUNC(V33*F33,2) -> 0 | X33: =TRUNC(W33*G33)+0 -> 0 | Y33: =Z33/F33 -> 0 | AA33: =TRUNC(Z33*G33)+0 -> 0 | AB33: =AC33/F33 -> 0 | AD33: =TRUNC(AC33*G33) -> 0 | AE33: =AF33/F33 -> 0 | AG33: =TRUNC(AF33*G33) -> 0 | AH33: =SUM(J33,M33,P33,V33,Y33,AB33,AE33) -> 1 | AI33: =SUM(K33,N33,Q33,W33,Z33,T33,AC33) -> 80 | AJ33: =SUM(L33,O33,R33,X33,AA33,U33,AD33,AG33) -> 870.32 | AK33: =IF(AH33=100%,"ITEM FINALIZADO",AH33) -> ITEM FINALIZADO
A34: 3.2.2.4 | B34: 92762 | C34: ARMAÇÃO DE PILAR OU VIGA DE ESTRUTURA CONVENCIONAL DE CONCRETO ARMADO UTILIZANDO AÇO CA-50 DE 10,0 MM - MONTAGEM. AF 06/2022 | D34: SINAPI | E34: KG | F34: 337.7 | G34: 9.61 | H34: =(F34*G34)-0.01 -> 3245.287 | M34: 0.8 | N34: =TRUNC(M34*F34,2) -> 270.16 | O34: =TRUNC(N34*G34)+0.23 -> 2596.23 | P34: 0.2 | Q34: =TRUNC(P34*F34,2) -> 67.54 | R34: =TRUNC(Q34*G34) -> 649 | U34: =TRUNC(G34*T34)+0 -> 0 | W34: =TRUNC(V34*F34,2) -> 0 | X34: =TRUNC(W34*G34)+0 -> 0 | Y34: =Z34/F34 -> 0 | AA34: =TRUNC(Z34*G34)+0 -> 0 | AB34: =AC34/F34 -> 0 | AD34: =TRUNC(AC34*G34) -> 0 | AE34: =AF34/F34 -> 0 | AG34: =TRUNC(AF34*G34) -> 0 | AH34: =SUM(J34,M34,P34,V34,Y34,AB34,AE34) -> 1 | AI34: =SUM(K34,N34,Q34,W34,Z34,T34,AC34) -> 337.7 | AJ34: =SUM(L34,O34,R34,X34,AA34,U34,AD34,AG34) -> 3245.23 | AK34: =IF(AH34=100%,"ITEM FINALIZADO",AH34) -> ITEM FINALIZADO
A35: 3.2.2.5 | B35: 92763 | C35: ARMAÇÃO DE PILAR OU VIGA DE ESTRUTURA CONVENCIONAL DE CONCRETO ARMADO UTILZANDO AÇO CA-50 DE 12,5 MM - MONTAGEM. AF 06/2022 | D35: SINAPI | E35: KG | F35: 189.7 | G35: 8.02 | H35: =(F35*G35) -> 1521.394 | M35: 0.8 | N35: =TRUNC(M35*F35,2) -> 151.76 | O35: =TRUNC(N35*G35)+0.11 -> 1217.11 | P35: 0.2 | Q35: =TRUNC(P35*F35,2) -> 37.94 | R35: =TRUNC(Q35*G35) -> 304 | U35: =TRUNC(G35*T35)+0 -> 0 | W35: =TRUNC(V35*F35,2) -> 0 | X35: =TRUNC(W35*G35)+0 -> 0 | Y35: =Z35/F35 -> 0 | AA35: =TRUNC(Z35*G35)+0 -> 0 | AB35: =AC35/F35 -> 0 | AD35: =TRUNC(AC35*G35) -> 0 | AE35: =AF35/F35 -> 0 | AG35: =TRUNC(AF35*G35) -> 0 | AH35: =SUM(J35,M35,P35,V35,Y35,AB35,AE35) -> 1 | AI35: =SUM(K35,N35,Q35,W35,Z35,T35,AC35) -> 189.7 | AJ35: =SUM(L35,O35,R35,X35,AA35,U35,AD35,AG35) -> 1521.11 | AK35: =IF(AH35=100%,"ITEM FINALIZADO",AH35) -> ITEM FINALIZADO
A36: 3.2.2.6 | B36: 92759 | C36: ARMAÇÃO DE PILAR OU VIGA DE ESTRUTURA CONVENCIONAL DE CONCRETO ARMADO UTILIZANDO AÇO CA-CO DE 5,0 MM - MONTAGEM. AF 06/2022 | D36: SINAPI | E36: KG | F36: 179.1 | G36: 12.82 | H36: =(F36*G36) -> 2296.062 | M36: 0.8 | N36: =TRUNC(M36*F36,2) -> 143.28 | O36: =TRUNC(N36*G36)+0.85 -> 1836.85 | P36: 0.2 | Q36: =TRUNC(P36*F36,2) -> 35.82 | R36: =TRUNC(Q36*G36) -> 459 | U36: =TRUNC(G36*T36)+0 -> 0 | W36: =TRUNC(V36*F36,2) -> 0 | X36: =TRUNC(W36*G36)+0 -> 0 | Y36: =Z36/F36 -> 0 | AA36: =TRUNC(Z36*G36)+0 -> 0 | AB36: =AC36/F36 -> 0 | AD36: =TRUNC(AC36*G36) -> 0 | AE36: =AF36/F36 -> 0 | AG36: =TRUNC(AF36*G36) -> 0 | AH36: =SUM(J36,M36,P36,V36,Y36,AB36,AE36) -> 1 | AI36: =SUM(K36,N36,Q36,W36,Z36,T36,AC36) -> 179.1 | AJ36: =SUM(L36,O36,R36,X36,AA36,U36,AD36,AG36) -> 2295.85 | AK36: =IF(AH36=100%,"ITEM FINALIZADO",AH36) -> ITEM FINALIZADO
A37: 3.2.2.7 | B37: 92265 | C37: FABRICAÇÃO DE FORMA PARA VIGAS, EM CHAPA DE MADEIRA COMPENSADA RESINADA, E = 17 MM. AF 09/2020 | D37: SINAPI | E37: M2 | F37: 154.03 | G37: 101.89 | H37: =(F37*G37)-0.01 -> 15694.107 | M37: 1 | N37: =TRUNC(M37*F37,2) -> 154.03 | O37: =TRUNC(N37*G37)+0.11 -> 15694.11 | U37: =TRUNC(G37*T37)+0 -> 0 | W37: =TRUNC(V37*F37,2) -> 0 | X37: =TRUNC(W37*G37)+0 -> 0 | Y37: =Z37/F37 -> 0 | AA37: =TRUNC(Z37*G37)+0 -> 0 | AB37: =AC37/F37 -> 0 | AD37: =TRUNC(AC37*G37) -> 0 | AE37: =AF37/F37 -> 0 | AG37: =TRUNC(AF37*G37) -> 0 | AH37: =SUM(J37,M37,P37,V37,Y37,AB37,AE37) -> 1 | AI37: =SUM(K37,N37,Q37,W37,Z37,T37,AC37) -> 154.03 | AJ37: =SUM(L37,O37,R37,X37,AA37,U37,AD37,AG37) -> 15694.11 | AK37: =IF(AH37=100%,"ITEM FINALIZADO",AH37) -> ITEM FINALIZADO
A38: 3.2.3 | B38: LAJE | H38: =SUM(H39:H44) -> 42001.827 | AK38: =SUM(AK39) -> 0
A39: 3.2.3.1 | B39: 94965 | C39: CONCRETO FCK = 25MPA, TRACO 1:2,3:2,7 (EM MASSA SECA DE CIMENTO/AREIA MEDIA/ BRITA 1) - PREPARO MECANICO COM BETONEIRA 400 L. AF 05/2021 | D39: SINAPI | E39: M3 | F39: 46.31 | G39: 433.53 | H39: =(F39*G39) -> 20076.774 | U39: =TRUNC(G39*T39)+0 -> 0 | V39: 0 | W39: =TRUNC(V39*F39,2) -> 0 | X39: =TRUNC(W39*G39)+0 -> 0 | Y39: =Z39/F39 -> 0 | AA39: =TRUNC(Z39*G39)+0 -> 0 | AB39: =AC39/F39 -> 0 | AD39: =TRUNC(AC39*G39) -> 0 | AE39: =AF39/F39 -> 0 | AG39: =TRUNC(AF39*G39) -> 0 | AH39: =SUM(J39,M39,P39,V39,Y39,AB39,AE39) -> 0 | AI39: =SUM(K39,N39,Q39,W39,Z39,T39,AC39) -> 0 | AJ39: =SUM(L39,O39,R39,X39,AA39,U39,AD39,AG39) -> 0 | AK39: =IF(AH39=100%,"ITEM FINALIZADO",AH39) -> 0
A40: 3.2.3.2 | B40: 92267 | C40: FABRICAÇÃO DE FÔRMA PARA LAJES, EM CHAPA DE MADEIRA COMPENSADA RESINADA, E = 17 MM. AF 09/2020 | D40: SINAPI | E40: M2 | F40: 312.27 | G40: 26.89 | H40: =(F40*G40) -> 8396.9403 | U40: =TRUNC(G40*T40)+0 -> 0 | V40: 0 | W40: =TRUNC(V40*F40,2) -> 0 | X40: =TRUNC(W40*G40)+0 -> 0 | Y40: =Z40/F40 -> 0 | AA40: =TRUNC(Z40*G40)+0 -> 0 | AB40: =AC40/F40 -> 0 | AD40: =TRUNC(AC40*G40) -> 0 | AE40: =AF40/F40 -> 0 | AG40: =TRUNC(AF40*G40) -> 0 | AH40: =SUM(J40,M40,P40,V40,Y40,AB40,AE40) -> 0 | AI40: =SUM(K40,N40,Q40,W40,Z40,T40,AC40) -> 0 | AJ40: =SUM(L40,O40,R40,X40,AA40,U40,AD40,AG40) -> 0 | AK40: =IF(AH40=100%,"ITEM FINALIZADO",AH40) -> 0
...

Sheet MEMORIAL DE CALCULO
B1: CONTRATAÇÃO DE UMA EMPRESA ESPECIALIZADA PARA CONSTRUÇÃO DE 01 (UM) CENTRO ESPECIALIZADO EM ATENÇÃO A SAÚDE MENTAL PARA ATENDER AS NECESSIDADES DA SECRETARIA MUNICIPAL DE SAÚDE EM COREMAS/PB | E1: BANCO DE DADOS: SINAPI - 05/2024-Paraiba ORSE - 0412024- Sergipe | AL1: B.D.I. = 22,47% ENCARGOS SOCIAIS: Nao Desonerado: embutido nos presos unitário dos insumos de mão de obra, de acordo com as bases.
A2: DADOS DO CONTRATANTE: Prefeitura Municipal de Coremas. CNPJ: 08.939.936/0001-94 POCESSO LICITATÓRIO: Processo Administrativo N°. 176/2024 e Concorrência Eletrônica N°. 0004/2024 CONTRATO N°. 328/2024 VALOR DA OBRA/CONTRATO: 1.150.000,00 (Um milhão, cento e cinquenta mil reais). | E2: NÚMERO DA MEDIÇÃO: 8ª MEDIÇÃO. | AL2: REFERÊNCIA/PERÍODO DA MEDIÇÃO: 11/08/2025 A 11/09/2025
A3: DADOS DO CONTRATADO: CL CONSTRUÇÕES E SERVIÇOS LTDA CNPJ: 09.335.002/0001-06 ENDEREÇO: Rua Cel. João Severino, SN - Sala D - Centro - Itaporanga - PB. | E3: FONTE DOS RECURSOS: Próprio (Diversos) do Município, prevista no orçamento da União, para o exercício de 2024. | BZ3: TOTAL DA MEDIÇÃO 01 = | CB3: =#REF! -> #REF! | CC3: TOTAL DA MEDIÇÃO 02 = | CE3: =#REF! -> #REF! | CF3: TOTAL DA MEDIÇÃO 03 = | CH3: =#REF! -> #REF! | CL3: TOTAL DA MEDIÇÃO 05 = | CN3: =#REF! -> #REF!
A4: MEMORIAL DE CALCULO 08 | BZ4: MEDIÇÕES | CC4: MEDIÇÕES | CF4: MEDIÇÕES | CL4: MEDIÇÕES
A5: ITEM | B5: CÓDIGO | C5: DESCRIÇÃO | D5: CALCULOS | BZ5: AVANÇO PERCENTUAL NO PERÍODO | CA5: QUANTIDADE MEDIDA NO PERÍODO | CB5: VALOR MEDIDO NO PERÍODO | CC5: AVANÇO PERCENTUAL NO PERÍODO | CD5: QUANTIDADE MEDIDA NO PERÍODO | CE5: VALOR MEDIDO NO PERÍODO | CF5: AVANÇO PERCENTUAL NO PERÍODO | CG5: QUANTIDADE MEDIDA NO PERÍODO | CH5: VALOR MEDIDO NO PERÍODO | CI5: AVANÇO PERCENTUAL NO PERÍODO | CJ5: QUANTIDADE MEDIDA NO PERÍODO | CK5: VALOR MEDIDO NO PERÍODO | CL5: AVANÇO PERCENTUAL NO PERÍODO | CM5: QUANTIDADE MEDIDA NO PERÍODO | CN5: VALOR MEDIDO NO PERÍODO
A6: 1 | B6: SERVIÇOS PRELIMINARES | BZ6: MEDIÇÃO 01 | CC6: MEDIÇÃO 02 | CF6: MEDIÇÃO 03 | CI6: MEDIÇÃO 04 | CL6: MEDIÇÃO 05
A7: 1.1 | B7: 51 | C7: Placa de obra em chapa aco galvanizado, instalada - Rev 02_O1/2022 | BZ7: 1 | CA7: =TRUNC(BZ7*AK7,2) -> 0 | CB7: =TRUNC(CA7*AL7)+0.46 -> 0.46 | CC7: 0 | CD7: =TRUNC(CC7*AK7,2) -> 0 | CE7: =TRUNC(CD7*AL7)+0 -> 0 | CF7: 0 | CG7: =TRUNC(CF7*AK7,2) -> 0 | CH7: =TRUNC(CG7*AL7) -> 0 | CK7: =TRUNC(AL7*CJ7)+0 -> 0 | CL7: 0 | CM7: =TRUNC(CL7*AK7,2) -> 0 | CN7: =TRUNC(CM7*AL7)+0 -> 0
A8: 1.2 | B8: 98524 | C8: LIMPEZA MANUAL DE VEGETAÇÃO EM TERRENO COM EXADA AF 03/2024 | BZ8: 1 | CA8: =TRUNC(BZ8*AK8,2) -> 0 | CB8: =TRUNC(CA8*AL8)+0.41 -> 0.41 | CK8: =TRUNC(AL8*CJ8)+0 -> 0 | CM8: =TRUNC(CL8*AK8,2) -> 0 | CN8: =TRUNC(CM8*AL8)+0 -> 0
A9: 2 | B9: MOVIMENTO DE TERRA
A10: 2.1 | B10: 99059 | C10: LOCAÇÃO CONVENCIONAL DE OBRA, UTILIZANDO DE GABARITO DE TÁBUAS CORRIDAS PONTALETADAS A CADA 2,00M - 2 UTILIZAÇÕES. AF_03/2024 | BZ10: 1 | CA10: =TRUNC(BZ10*AK10,2) -> 0 | CB10: =TRUNC(CA10*AL10)+0.12 -> 0.12 | CK10: =TRUNC(AL10*CJ10)+0 -> 0 | CM10: =TRUNC(CL10*AK10,2) -> 0 | CN10: =TRUNC(CM10*AL10)+0 -> 0
A11: 2.2 | B11: 93358 | C11: ESCAVAÇÃO MANUAL DE VALA COM PROFUNDIDADE MENOR OU IGUAL A 1,30M AF 02/2021 | BZ11: 1 | CA11: =TRUNC(BZ11*AK11,2) -> 0 | CB11: =TRUNC(CA11*AL11)+0 -> 0 | CK11: =TRUNC(AL11*CJ11)+0 -> 0 | CM11: =TRUNC(CL11*AK11,2) -> 0 | CN11: =TRUNC(CM11*AL11)+0 -> 0
A12: 2.3 | B12: 94319 | C12: ATERRO MANUAL DE VALAS COM SOLO ARGILO-ARENOSO. AF_08/2023 | BZ12: 1 | CA12: =TRUNC(BZ12*AK12,2) -> 0 | CB12: =TRUNC(CA12*AL12)+0.2 -> 0.2 | CK12: =TRUNC(AL12*CJ12)+0 -> 0 | CM12: =TRUNC(CL12*AK12,2) -> 0 | CN12: =TRUNC(CM12*AL12)+0 -> 0
A13: 3 | B13: ESTRUTURA
A14: 3.1 | B14: INFRAESTUTURA
A15: 3.1.1 | B15: FUNDAÇÃO
A16: 3.1.1.1 | B16: 102486 | C16: CONCRETO FCK = 15MPA, TRACO 13,4.3,4 (EM MASSA SECA DE CIMENTO / AREIA MÉDIA/ SEIXO ROLADO) - PREPARO MANUAL. AF_05/2021 | BZ16: 0.8 | CA16: =TRUNC(BZ16*AK16,2) -> 0 | CB16: =TRUNC(CA16*AL16)+0.1 -> 0.1 | CC16: 0.2 | CD16: =TRUNC(CC16*AK16,2)+0.01 -> 0.01 | CE16: =TRUNC(CD16*AL16)+1.78 -> 1.78 | CK16: =TRUNC(AL16*CJ16)+0 -> 0 | CM16: =TRUNC(CL16*AK16,2) -> 0 | CN16: =TRUNC(CM16*AL16)+0 -> 0
A17: 3.1.1.2 | B17: 94965 | C17: CONCRETO FCK = 25MPA, TRACO 12,3:2,7 (EM MASSA SECA DE CIMENTO/ AREIA MEDIA/ BRITA 1) - PREPARO MECANICO COM BETONEIRA 400 L. AF 05/2021 | BZ17: 0.8 | CA17: =TRUNC(BZ17*AK17,2) -> 0 | CB17: =TRUNC(CA17*AL17)+0.05 -> 0.05 | CC17: 0.2 | CD17: =TRUNC(CC17*AK17,2) -> 0 | CE17: =TRUNC(CD17*AL17)+0.52 -> 0.52 | CK17: =TRUNC(AL17*CJ17)+0 -> 0 | CM17: =TRUNC(CL17*AK17,2) -> 0 | CN17: =TRUNC(CM17*AL17)+0 -> 0
A18: 3.1.1.3 | B18: 96544 | C18: ARMAÇÃO DE BLOCO UTILIZANDO AÇO CA-50 DE 6,3 MM - MONTAGEM. AF 01/2024 | BZ18: 0.8 | CA18: =TRUNC(BZ18*AK18,2) -> 0 | CB18: =TRUNC(CA18*AL18)+0.34 -> 0.34 | CC18: 0.2 | CD18: =TRUNC(CC18*AK18,2) -> 0 | CE18: =TRUNC(CD18*AL18)+0.09 -> 0.09 | CK18: =TRUNC(AL18*CJ18)+0 -> 0 | CM18: =TRUNC(CL18*AK18,2) -> 0 | CN18: =TRUNC(CM18*AL18)+0 -> 0
A19: 3.1.1.4 | B19: 98545 | C19: ARMAÇÃO DE BLOCO UTILZANDO AÇO CASO DE 8 MM - MONTAGEM. AF 01/2024 | BZ19: 0.8 | CA19: =TRUNC(BZ19*AK19,2) -> 0 | CB19: =TRUNC(CA19*AL19)+0.3 -> 0.3 | CC19: 0.2 | CD19: =TRUNC(CC19*AK19,2) -> 0 | CE19: =TRUNC(CD19*AL19)+0.32 -> 0.32 | CK19: =TRUNC(AL19*CJ19)+0 -> 0 | CM19: =TRUNC(CL19*AK19,2) -> 0 | CN19: =TRUNC(CM19*AL19)+0 -> 0
A20: 3.1.1.5 | B20: 96543 | C20: ARMAÇÃO DE BLOCO UTILIZANDO AÇO CA-60 DE 5 MM - MONTAGEM. AF 01/2024 | BZ20: 0.8 | CA20: =TRUNC(BZ20*AK20,2) -> 0 | CB20: =TRUNC(CA20*AL20)+0.94 -> 0.94 | CC20: 0.2 | CD20: =TRUNC(CC20*AK20,2) -> 0 | CE20: =TRUNC(CD20*AL20)+0.73 -> 0.73 | CK20: =TRUNC(AL20*CJ20)+0 -> 0 | CM20: =TRUNC(CL20*AK20,2) -> 0 | CN20: =TRUNC(CM20*AL20)+0 -> 0
A21: 3.1.1.6 | B21: 98557 | C21: IMPERMEABILIZAÇÃO DE SUPERFÍCIE COM EMULSÃO ASFÁLTICA, 2 DEMÃOS. AF 09/2023 | BZ21: 0.2 | CA21: =TRUNC(BZ21*AK21,2) -> 0 | CB21: =TRUNC(CA21*AL21)+0.23 -> 0.23 | CC21: 0.8 | CD21: =TRUNC(CC21*AK21,2) -> 0 | CE21: =TRUNC(CD21*AL21)+0.31 -> 0.31 | CK21: =TRUNC(AL21*CJ21)+0 -> 0 | CM21: =TRUNC(CL21*AK21,2) -> 0 | CN21: =TRUNC(CM21*AL21)+0 -> 0
A22: 3.2 | B22: SUPERESTRUTURA
A23: 3.2.1 | B23: PILARES
A24: 3.2.1.1 | B24: 102476 | C24: CONCRETO FCK = 25MPA, TRACO 1:2,2:2,5 (EM MASSA SECA DE CIMENTO/ AREIA MEDIA/ SEIXO ROLADO) - PREPARO MECANICO COM BETONEIRA 400 L. AF 05/2021 | BZ24: 0.5 | CA24: =TRUNC(BZ24*AK24,2) -> 0 | CB24: =TRUNC(CA24*AL24)+0.73 -> 0.73 | CC24: 0.4 | CD24: =TRUNC(CC24*AK24,2) -> 0 | CE24: =TRUNC(CD24*AL24)+0.78 -> 0.78 | CF24: 0.1 | CG24: =TRUNC(CF24*AK24,2) -> 0 | CH24: =TRUNC(CG24*AL24) -> 0 | CK24: =TRUNC(AL24*CJ24)+0 -> 0 | CM24: =TRUNC(CL24*AK24,2) -> 0 | CN24: =TRUNC(CM24*AL24)+0 -> 0
A25: 3.2.1.2 | B25: 96546 | C25: ARMAÇÃO DE BLOCO UTILIZANDO AÇO CA-SO DE 10 MM - MONTAGEM. AF 01/2024 | BZ25: 0.5 | CA25: =TRUNC(BZ25*AK25,2) -> 0 | CB25: =TRUNC(CA25*AL25)+0.34 -> 0.34 | CC25: 0.4 | CD25: =TRUNC(CC25*AK25,2) -> 0 | CE25: =TRUNC(CD25*AL25)+0.47 -> 0.47 | CF25: 0.1 | CG25: =TRUNC(CF25*AK25,2) -> 0 | CH25: =TRUNC(CG25*AL25) -> 0 | CK25: =TRUNC(AL25*CJ25)+0 -> 0 | CM25: =TRUNC(CL25*AK25,2) -> 0 | CN25: =TRUNC(CM25*AL25)+0 -> 0
A26: 3.2.1.3 | B26: 98543 | C26: ARMAÇÃO DE BLOCO UTILIZANDO AÇO CA-CO DE 5 MM - MONTAGEM. AF 01/2024 | BZ26: 1 | CA26: =TRUNC(BZ26*AK26,2) -> 0 | CB26: =TRUNC(CA26*AL26)+0.95 -> 0.95 | CG26: =TRUNC(CF26*AK26,2) -> 0 | CH26: =TRUNC(CG26*AL26) -> 0 | CK26: =TRUNC(AL26*CJ26)+0 -> 0 | CM26: =TRUNC(CL26*AK26,2) -> 0 | CN26: =TRUNC(CM26*AL26)+0 -> 0
A27: 3.2.1.4 | B27: 96545 | C27: ARMAÇÃO DE BLOCO UTILZANDO AÇO CA-50 DES MM - MONTAGEM, AF 01/2024 | BZ27: 1 | CA27: =TRUNC(BZ27*AK27,2) -> 0 | CB27: =TRUNC(CA27*AL27)+0.34 -> 0.34 | CG27: =TRUNC(CF27*AK27,2) -> 0 | CH27: =TRUNC(CG27*AL27) -> 0 | CK27: =TRUNC(AL27*CJ27)+0 -> 0 | CM27: =TRUNC(CL27*AK27,2) -> 0 | CN27: =TRUNC(CM27*AL27)+0 -> 0
A28: 3.2.1.5 | B28: 96547 | C28: ARMAÇÃO DE BLOCO, VIGA BALDRAME OU SAPATA UTILIZANDO AÇO CA- 50 DE 12,5 MM - MONTAGEM. AF 06/2017 | BZ28: 1 | CA28: =TRUNC(BZ28*AK28,2) -> 0 | CB28: =TRUNC(CA28*AL28)+0.25 -> 0.25 | CG28: =TRUNC(CF28*AK28,2) -> 0 | CH28: =TRUNC(CG28*AL28) -> 0 | CK28: =TRUNC(AL28*CJ28)+0 -> 0 | CM28: =TRUNC(CL28*AK28,2) -> 0 | CN28: =TRUNC(CM28*AL28)+0 -> 0
A29: 3.2.1.6 | B29: 103795 | C29: FABRICAÇÃO, MONTAGEM E DESMONTAGEM DE FÔRMA PARA ESCADA HIDRAULICA, EM CHAPA DE MADEIRA COMPENSADA RESINADA, E = 17 MM, 3 UTILIZAÇÕES. AF 08/2022 | BZ29: 0.5 | CA29: =TRUNC(BZ29*AK29,2) -> 0 | CB29: =TRUNC(CA29*AL29)+1.32 -> 1.32 | CC29: 0.5 | CD29: =TRUNC(CC29*AK29,2) -> 0 | CE29: =TRUNC(CD29*AL29)+1.32 -> 1.32 | CF29: 0.1 | CG29: =TRUNC(CF29*AK29,2) -> 0 | CH29: =TRUNC(CG29*AL29) -> 0 | CJ29: -22.76 | CK29: =TRUNC(AL29*CJ29)+0 -> 0 | CL29: -0.1 | CM29: =TRUNC(CL29*AK29,2) -> 0
A30: 3.2.2 | B30: VIGAS
A31: 3.2.2.1 | B31: 102476 | C31: CONCRETO FCK = 25MPA, TRAGO 12,2:2,5 (EM MASSA SECA DE CIMENTO/ AREIA MEDIA/ SEIXO ROLADO) - PREPARO MECANICO COM BETONEIRA 400 L. AF 05/2021 | CC31: 0.4 | CD31: =TRUNC(CC31*AK31,2) -> 0 | CE31: =TRUNC(CD31*AL31)+3.13 -> 3.13 | CF31: 0.6 | CG31: =TRUNC(CF31*AK31,2) -> 0 | CH31: =TRUNC(CG31*AL31) -> 0 | CK31: =TRUNC(AL31*CJ31)+0 -> 0 | CM31: =TRUNC(CL31*AK31,2) -> 0 | CN31: =TRUNC(CM31*AL31)+0 -> 0
A32: 3.2.2.2 | B32: 92760 | C32: ARMAÇÃO DE PILAR OU VIGA DE ESTRUTURA CONVENCIONAL DE CONCRETO ARMADO UTILIZANDO AÇO CA-50 06 8,3 MM - MONTAGEM. AF 06/2022 | CC32: 0.8 | CD32: =TRUNC(CC32*AK32,2) -> 0 | CE32: =TRUNC(CD32*AL32)+0.82 -> 0.82 | CF32: 0.2 | CG32: =TRUNC(CF32*AK32,2) -> 0 | CH32: =TRUNC(CG32*AL32) -> 0 | CK32: =TRUNC(AL32*CJ32)+0 -> 0 | CM32: =TRUNC(CL32*AK32,2) -> 0 | CN32: =TRUNC(CM32*AL32)+0 -> 0
A33: 3.2.2.3 | B33: 92761 | C33: ARMAÇÃO DE PILAR OU VIGA DE ESTRUTURA CONVENCIONAL DE CONCRETO ARMADO UTILIZANDO AÇO CA-50 DE 8,0 MM - MONTAGEM. AF 06/2022 | CC33: 0.8 | CD33: =TRUNC(CC33*AK33,2) -> 0 | CE33: =TRUNC(CD33*AL33)+0.32 -> 0.32 | CF33: 0.2 | CG33: =TRUNC(CF33*AK33,2) -> 0 | CH33: =TRUNC(CG33*AL33) -> 0 | CK33: =TRUNC(AL33*CJ33)+0 -> 0 | CM33: =TRUNC(CL33*AK33,2) -> 0 | CN33: =TRUNC(CM33*AL33)+0 -> 0
A34: 3.2.2.4 | B34: 92762 | C34: ARMAÇÃO DE PILAR OU VIGA DE ESTRUTURA CONVENCIONAL DE CONCRETO ARMADO UTILIZANDO AÇO CA-50 DE 10,0 MM - MONTAGEM. AF 06/2022 | CC34: 0.8 | CD34: =TRUNC(CC34*AK34,2) -> 0 | CE34: =TRUNC(CD34*AL34)+0.23 -> 0.23 | CF34: 0.2 | CG34: =TRUNC(CF34*AK34,2) -> 0 | CH34: =TRUNC(CG34*AL34) -> 0 | CK34: =TRUNC(AL34*CJ34)+0 -> 0 | CM34: =TRUNC(CL34*AK34,2) -> 0 | CN34: =TRUNC(CM34*AL34)+0 -> 0
A35: 3.2.2.5 | B35: 92763 | C35: ARMAÇÃO DE PILAR OU VIGA DE ESTRUTURA CONVENCIONAL DE CONCRETO ARMADO UTILZANDO AÇO CA-50 DE 12,5 MM - MONTAGEM. AF 06/2022 | CC35: 0.8 | CD35: =TRUNC(CC35*AK35,2) -> 0 | CE35: =TRUNC(CD35*AL35)+0.11 -> 0.11 | CF35: 0.2 | CG35: =TRUNC(CF35*AK35,2) -> 0 | CH35: =TRUNC(CG35*AL35) -> 0 | CK35: =TRUNC(AL35*CJ35)+0 -> 0 | CM35: =TRUNC(CL35*AK35,2) -> 0 | CN35: =TRUNC(CM35*AL35)+0 -> 0
A36: 3.2.2.6 | B36: 92759 | C36: ARMAÇÃO DE PILAR OU VIGA DE ESTRUTURA CONVENCIONAL DE CONCRETO ARMADO UTILIZANDO AÇO CA-CO DE 5,0 MM - MONTAGEM. AF 06/2022 | CC36: 0.8 | CD36: =TRUNC(CC36*AK36,2) -> 0 | CE36: =TRUNC(CD36*AL36)+0.85 -> 0.85 | CF36: 0.2 | CG36: =TRUNC(CF36*AK36,2) -> 0 | CH36: =TRUNC(CG36*AL36) -> 0 | CK36: =TRUNC(AL36*CJ36)+0 -> 0 | CM36: =TRUNC(CL36*AK36,2) -> 0 | CN36: =TRUNC(CM36*AL36)+0 -> 0
A37: 3.2.2.7 | B37: 92265 | C37: FABRICAÇÃO DE FORMA PARA VIGAS, EM CHAPA DE MADEIRA COMPENSADA RESINADA, E = 17 MM. AF 09/2020 | CC37: 1 | CD37: =TRUNC(CC37*AK37,2) -> 0 | CE37: =TRUNC(CD37*AL37)+0.11 -> 0.11 | CK37: =TRUNC(AL37*CJ37)+0 -> 0 | CM37: =TRUNC(CL37*AK37,2) -> 0 | CN37: =TRUNC(CM37*AL37)+0 -> 0
A38: 3.2.3 | B38: LAJE
A39: 3.2.3.1 | B39: 94965 | C39: CONCRETO FCK = 25MPA, TRACO 1:2,3:2,7 (EM MASSA SECA DE CIMENTO/AREIA MEDIA/ BRITA 1) - PREPARO MECANICO COM BETONEIRA 400 L. AF 05/2021 | CK39: =TRUNC(AL39*CJ39)+0 -> 0 | CL39: 0 | CM39: =TRUNC(CL39*AK39,2) -> 0 | CN39: =TRUNC(CM39*AL39)+0 -> 0
A40: 3.2.3.2 | B40: 92267 | C40: FABRICAÇÃO DE FÔRMA PARA LAJES, EM CHAPA DE MADEIRA COMPENSADA RESINADA, E = 17 MM. AF 09/2020 | CK40: =TRUNC(AL40*CJ40)+0 -> 0 | CL40: 0 | CM40: =TRUNC(CL40*AK40,2) -> 0 | CN40: =TRUNC(CM40*AL40)+0 -> 0
...
