Workbook
Name JR_PAGE_ANCHOR_0_1: MEMORIAL!$A$5
Name JR_PAGE_ANCHOR_0_1: REPROGRAMAÇÃO!$A$5
Name JR_PAGE_ANCHOR_0_1: #REF!

Sheet REPROGRAMAÇÃO
A2: OBRA: | B2: CONSTRUÇÃO DE UMA CRECHE COM CAPACIDADE PARA 50 (CEM) CRIANÇAS | K2: PERIODO DA MEDIÇÃO: | N2: VALOR CONTRATADO R$: | V2: VALOR CONTRATADO R$: | X2: 912926.02 | Z2: VALOR CONTRATADO R$:
A3: OBJETO: | B3: PRESTAR SERVIÇOS DE ENGENHARIA PARA CONSTRUÇÃO DE 01 (UMA) CRECHE COM CAPACIDADE PARA 50 (CINQUENTA) CRIANÇAS, COM BASE NO PROGRAMA PARAÍBA PRIMEIRA INFÂNCIA NO MUNICIPIO DE COREMAS-PB. | K3: 13/08/2024 a 12/09/2024 | N3: VALOR REPROGRAMAÇÃO R$: | V3: VALOR REPROGRAMAÇÃO R$: | X3: =X326 -> 1025601.9 | Z3: VALOR REPROGRAMAÇÃO R$:
A4: LOCAL: | B4: COREMAS - PB | W4: BDI: | X4: 0.2247
A5: REPROGRAMAÇÃO
A6: ITEM | B6: CÓDIGO | C6: DESCRIÇÃO | D6: FONTE | E6: UNID | F6: QUANTIDADES CONTRATADA | I6: VALORES CONTRADO R$ | N6: QUANTIDADES MEDIDO | S6: QUANTIDADES A REPROGRAMAR | V6: VALORES MEDIDO R$
F7: QUANTIDADE | G7: SEM BDI | H7: COM BDI | I7: SEM BDI | J7: COM BDI | K7: ACUMULADO ANTERIOR | L7: MEDIÇÃO 04 | M7: MEDIÇÃO 05 | N7: MEDIÇÃO 06 | O7: MEDIÇÃO 07 | P7: MEDIÇÃO 08 | Q7: ACUMULADO INCLUINDO O PERÍODO | R7: PERCENTUAL DE EXECUÇÃO | S7: ACRESCIDA | T7: SUPRIMIDA | U7: A REPROGRAMAR | V7: TOTAL ACRESCIDO R$ | W7: TOTAL SUPRIMIDO R$ | X7: TOTAL A REPROGRAMAR R$
A8: 1 | B8: SERVIÇOS PRELIMINARES | I8: 14740.01 | J8: 18051.88 | V8: =SUM(V9:V12) -> 13098.94 | W8: =SUM(W9:W12) -> 11947.59 | X8: =SUM(X9:X12) -> 19203.23
A9: 1.1 | B9: PRO-46870444 | C9: PLACA INDICATIVA DA OBRA EM CHAPA DE AÇO GALVANIZADO (4,0M X 2,0M) | D9: Composições Próprias | E9: M² | F9: 1 | G9: 153.05 | H9: 187.44 | I9: 153.05 | J9: 187.44 | K9: =F9 -> 1 | L9: =0 -> 0 | Q9: =K9+L9+M9+N9+O9+P9 -> 1 | R9: =Q9/F9 -> 1 | S9: 7 | U9: =F9+S9-T9 -> 8 | V9: =ROUND(H9*S9,2) -> 1312.08 | W9: =ROUND(H9*T9,2) -> 0 | X9: =ROUND(H9*U9,2) -> 1499.52
A10: 1.2 | B10: 93584 | C10: EXECUÇÃO DE DEPÓSITO EM CANTEIRO DE OBRA EM CHAPA DE MADEIRA COMPENSADA, NÃO INCLUSO MOBILIÁRIO. AF_04/2016 | D10: SINAPI | E10: M2 | F10: 12.43 | G10: 784.84 | H10: 961.19 | I10: 9755.56 | J10: 11947.59 | K10: =F10 -> 12.43 | L10: =0 -> 0 | Q10: =K10+L10+M10+N10+O10+P10 -> 12.43 | R10: =Q10/F10 -> 1 | T10: =F10 -> 12.43 | U10: =F10+S10-T10 -> 0 | V10: =ROUND(H10*S10,2) -> 0 | W10: =ROUND(H10*T10,2) -> 11947.59 | X10: =ROUND(H10*U10,2) -> 0
A11: 1.3 | B11: 99059 | C11: LOCACAO CONVENCIONAL DE OBRA, UTILIZANDO GABARITO DE TÁBUAS CORRIDAS PONTALETADAS A CADA 2,00M - 2 UTILIZAÇÕES. AF_10/2018 | D11: SINAPI | E11: M | F11: 101.16 | G11: 47.76 | H11: 58.49 | I11: 4831.4 | J11: 5916.85 | K11: =F11 -> 101.16 | L11: =0 -> 0 | Q11: =K11+L11+M11+N11+O11+P11 -> 101.16 | R11: =Q11/F11 -> 1 | U11: =F11+S11-T11 -> 101.16 | V11: =ROUND(H11*S11,2) -> 0 | W11: =ROUND(H11*T11,2) -> 0 | X11: =ROUND(H11*U11,2) -> 5916.85
A12: 1.4 | B12: PRO-PREF-01 | C12: BARRACÃO DA OBRA EM ALVENARIA | D12: Composições Próprias | E12: M2 | G12: 351.70879 | H12: 430.73702 | I12: 9624.3 | J12: 11786.86 | S12: 27.3644 | U12: =F12+S12-T12 -> 27.3644 | V12: =ROUND(H12*S12,2) -> 11786.86 | W12: =ROUND(H12*T12,2) -> 0 | X12: =ROUND(H12*U12,2) -> 11786.86
A13: 2 | B13: MOVIMENTO DE TERRA | I13: 10582.87 | J13: 12961.54 | V13: =SUM(V14:V18) -> 3724.32 | W13: =SUM(W14:W18) -> 0 | X13: =SUM(X14:X18) -> 16685.86
A14: 2.1 | B14: 93382 | C14: REATERRO MANUAL DE VALAS COM COMPACTAÇÃO MECANIZADA. AF_04/2016 | D14: SINAPI | E14: M3 | F14: 136.71 | G14: 22.2 | H14: 27.19 | I14: 3034.96 | J14: 3717.14 | K14: =F14 -> 136.71 | L14: =0 -> 0 | Q14: =K14+L14+M14+N14+O14+P14 -> 136.71 | R14: =Q14/F14 -> 1 | U14: =F14+S14-T14 -> 136.71 | V14: =ROUND(H14*S14,2) -> 0 | W14: =ROUND(H14*T14,2) -> 0 | X14: =ROUND(H14*U14,2) -> 3717.14
A15: 2.2 | B15: 93358 | C15: ESCAVAÇÃO MANUAL DE VALA COM PROFUNDIDADE MENOR OU IGUAL A 1,30 M. AF_02/2021 | D15: SINAPI | E15: M3 | F15: 72.61 | G15: 59.58 | H15: 72.97 | I15: 4326.1 | J15: 5298.35 | K15: =F15 -> 72.61 | L15: =0 -> 0 | Q15: =K15+L15+M15+N15+O15+P15 -> 72.61 | R15: =Q15/F15 -> 1 | S15: =MEMORIAL!AJ87-F15 -> 21.78725 | U15: =F15+S15-T15 -> 94.39725 | V15: =ROUND(H15*S15,2) -> 1589.82 | W15: =ROUND(H15*T15,2) -> 0 | X15: =ROUND(H15*U15,2) -> 6888.17
A16: 2.3 | B16: 93382 | C16: REATERRO MANUAL DE VALAS COM COMPACTAÇÃO MECANIZADA. AF_04/2016 | D16: SINAPI | E16: M3 | F16: 54.55 | G16: 22.2 | H16: 27.19 | I16: 1211.01 | J16: 1483.21 | K16: =F16 -> 54.55 | L16: =0 -> 0 | Q16: =K16+L16+M16+N16+O16+P16 -> 54.55 | R16: =Q16/F16 -> 1 | U16: =F16+S16-T16 -> 54.55 | V16: =ROUND(H16*S16,2) -> 0 | W16: =ROUND(H16*T16,2) -> 0 | X16: =ROUND(H16*U16,2) -> 1483.21
A17: 2.4 | B17: 96995 | C17: REATERRO MANUAL APILOADO COM SOQUETE. AF_10/2017 | D17: SINAPI | E17: M3 | F17: 55.67 | G17: 36.12 | H17: 44.24 | I17: 2010.8 | J17: 2462.84 | K17: =F17 -> 55.67 | L17: =0 -> 0 | Q17: =K17+L17+M17+N17+O17+P17 -> 55.67 | R17: =Q17/F17 -> 1 | U17: =F17+S17-T17 -> 55.67 | V17: =ROUND(H17*S17,2) -> 0 | W17: =ROUND(H17*T17,2) -> 0 | X17: =ROUND(H17*U17,2) -> 2462.84
A18: 2.5 | B18: 94342 | C18: ATERRO MANUAL DE VALAS COM AREIA PARA ATERRO E COMPACTAÇÃO MECANIZADA. AF_05/2016 | D18: SINAPI | E18: M2 | G18: =92.87*0.980188611 -> 91.030116 | H18: =G18*1.2247 -> 111.48458 | S18: =MEMORIAL!AJ96 -> 19.14615 | U18: =F18+S18-T18 -> 19.14615 | V18: =ROUND(H18*S18,2) -> 2134.5 | W18: =ROUND(H18*T18,2) -> 0 | X18: =ROUND(H18*U18,2) -> 2134.5
A19: 3 | B19: SAPATAS | I19: 31022.9 | J19: 37991.85 | V19: =SUM(V20:V28) -> 0 | W19: =SUM(W20:W28) -> 0 | X19: =SUM(X20:X28) -> 37991.85
A20: 3.1 | B20: 96616 | C20: LASTRO DE CONCRETO MAGRO, APLICADO EM BLOCOS DE COROAMENTO OU SAPATAS. AF_08/2017 | D20: SINAPI | E20: M3 | F20: 1.46 | G20: 551.7 | H20: 675.67 | I20: 805.48 | J20: 986.48 | K20: =F20 -> 1.46 | L20: =0 -> 0 | Q20: =K20+L20+M20+N20+O20+P20 -> 1.46 | R20: =Q20/F20 -> 1 | U20: =F20+S20-T20 -> 1.46 | V20: =ROUND(H20*S20,2) -> 0 | W20: =ROUND(H20*T20,2) -> 0 | X20: =ROUND(H20*U20,2) -> 986.48
A21: 3.2 | B21: 96541 | C21: FABRICAÇÃO, MONTAGEM E DESMONTAGEM DE FÔRMA PARA SAPATA, EM CHAPA DE MADEIRA COMPENSADA RESINADA, E=17 MM, 4 UTILIZAÇÕES. AF_06/2017 | D21: SINAPI | E21: M2 | F21: 96.48 | G21: 160.48 | H21: 196.54 | I21: 15483.11 | J21: 18962.18 | K21: =F21 -> 96.48 | L21: =0 -> 0 | Q21: =K21+L21+M21+N21+O21+P21 -> 96.48 | R21: =Q21/F21 -> 1 | U21: =F21+S21-T21 -> 96.48 | V21: =ROUND(H21*S21,2) -> 0 | W21: =ROUND(H21*T21,2) -> 0 | X21: =ROUND(H21*U21,2) -> 18962.18
A22: 3.3 | B22: 94971 | C22: CONCRETO FCK = 25MPA, TRAÇO 1:2,3:2,7 (EM MASSA SECA DE CIMENTO/ AREIA MÉDIA/ BRITA 1) - PREPARO MECÂNICO COM BETONEIRA 600 L. AF_05/2021 | D22: SINAPI | E22: M3 | F22: 10.06 | G22: 451.82 | H22: 553.34 | I22: 4545.31 | J22: 5566.6 | K22: =F22 -> 10.06 | L22: =0 -> 0 | Q22: =K22+L22+M22+N22+O22+P22 -> 10.06 | R22: =Q22/F22 -> 1 | U22: =F22+S22-T22 -> 10.06 | V22: =ROUND(H22*S22,2) -> 0 | W22: =ROUND(H22*T22,2) -> 0 | X22: =ROUND(H22*U22,2) -> 5566.6
A23: 3.4 | B23: 103670 | C23: LANÇAMENTO COM USO DE BALDES, ADENSAMENTO E ACABAMENTO DE CONCRETO EM ESTRUTURAS. AF_02/2022 | D23: SINAPI | E23: M3 | F23: 10.06 | G23: 205.96 | H23: 252.24 | I23: 2071.96 | J23: 2537.53 | K23: =F23 -> 10.06 | L23: =0 -> 0 | Q23: =K23+L23+M23+N23+O23+P23 -> 10.06 | R23: =Q23/F23 -> 1 | U23: =F23+S23-T23 -> 10.06 | V23: =ROUND(H23*S23,2) -> 0 | W23: =ROUND(H23*T23,2) -> 0 | X23: =ROUND(H23*U23,2) -> 2537.53
A24: 3.5 | B24: 96544 | C24: ARMAÇÃO DE BLOCO, VIGA BALDRAME OU SAPATA UTILIZANDO AÇO CA-50 DE 6,3 MM - MONTAGEM. AF_06/2017 | D24: SINAPI | E24: KG | F24: 241 | G24: 15.37 | H24: 18.82 | I24: 3704.17 | J24: 4535.62 | K24: =F24 -> 241 | L24: =0 -> 0 | Q24: =K24+L24+M24+N24+O24+P24 -> 241 | R24: =Q24/F24 -> 1 | U24: =F24+S24-T24 -> 241 | V24: =ROUND(H24*S24,2) -> 0 | W24: =ROUND(H24*T24,2) -> 0 | X24: =ROUND(H24*U24,2) -> 4535.62
A25: 3.6 | B25: 96546 | C25: ARMAÇÃO DE BLOCO, VIGA BALDRAME OU SAPATA UTILIZANDO AÇO CA-50 DE 10 MM - MONTAGEM. AF_06/2017 | D25: SINAPI | E25: KG | F25: 235.2 | G25: 13.1 | H25: 16.04 | I25: 3081.12 | J25: 3772.61 | K25: =F25 -> 235.2 | L25: =0 -> 0 | Q25: =K25+L25+M25+N25+O25+P25 -> 235.2 | R25: =Q25/F25 -> 1 | U25: =F25+S25-T25 -> 235.2 | V25: =ROUND(H25*S25,2) -> 0 | W25: =ROUND(H25*T25,2) -> 0 | X25: =ROUND(H25*U25,2) -> 3772.61
A26: 3.7 | B26: 96547 | C26: ARMAÇÃO DE BLOCO, VIGA BALDRAME OU SAPATA UTILIZANDO AÇO CA-50 DE 12,5 MM - MONTAGEM. AF_06/2017 | D26: SINAPI | E26: KG | F26: 18.1 | G26: 11.14 | H26: 13.64 | I26: 201.63 | J26: 246.88 | K26: =F26 -> 18.1 | L26: =0 -> 0 | Q26: =K26+L26+M26+N26+O26+P26 -> 18.1 | R26: =Q26/F26 -> 1 | U26: =F26+S26-T26 -> 18.1 | V26: =ROUND(H26*S26,2) -> 0 | W26: =ROUND(H26*T26,2) -> 0 | X26: =ROUND(H26*U26,2) -> 246.88
A27: 3.8 | B27: 96548 | C27: ARMAÇÃO DE BLOCO, VIGA BALDRAME OU SAPATA UTILIZANDO AÇO CA-50 DE 16 MM - MONTAGEM. AF_06/2017 | D27: SINAPI | E27: KG | F27: 7.6 | G27: 10.62 | H27: 13.01 | I27: 80.71 | J27: 98.88 | K27: =F27 -> 7.6 | L27: =0 -> 0 | Q27: =K27+L27+M27+N27+O27+P27 -> 7.6 | R27: =Q27/F27 -> 1 | U27: =F27+S27-T27 -> 7.6 | V27: =ROUND(H27*S27,2) -> 0 | W27: =ROUND(H27*T27,2) -> 0 | X27: =ROUND(H27*U27,2) -> 98.88
A28: 3.9 | B28: 96543 | C28: ARMAÇÃO DE BLOCO, VIGA BALDRAME E SAPATA UTILIZANDO AÇO CA-60 DE 5 MM - MONTAGEM. AF_06/2017 | D28: SINAPI | E28: KG | F28: 65.1 | G28: 16.12 | H28: 19.74 | I28: 1049.41 | J28: 1285.07 | K28: =F28 -> 65.1 | L28: =0 -> 0 | Q28: =K28+L28+M28+N28+O28+P28 -> 65.1 | R28: =Q28/F28 -> 1 | U28: =F28+S28-T28 -> 65.1 | V28: =ROUND(H28*S28,2) -> 0 | W28: =ROUND(H28*T28,2) -> 0 | X28: =ROUND(H28*U28,2) -> 1285.07
A29: 4 | B29: VIGA BALDRAME | I29: 34492.45 | J29: 42240.62 | V29: =SUM(V30:V35) -> 741.07 | W29: =SUM(W30:W35) -> 0 | X29: =SUM(X30:X35) -> 42981.69
A30: 4.1 | B30: 95240 | C30: LASTRO DE CONCRETO MAGRO, APLICADO EM PISOS, LAJES SOBRE SOLO OU RADIERS, ESPESSURA DE 3 CM. AF_07/2016 | D30: SINAPI | E30: M2 | F30: 2.2 | G30: 16 | H30: 19.6 | I30: 35.2 | J30: 43.12 | K30: =F30 -> 2.2 | L30: =0 -> 0 | Q30: =K30+L30+M30+N30+O30+P30 -> 2.2 | R30: =Q30/F30 -> 1 | S30: =MEMORIAL!AJ193-F30 -> 37.8095 | U30: =F30+S30-T30 -> 40.0095 | V30: =ROUND(H30*S30,2) -> 741.07 | W30: =ROUND(H30*T30,2) -> 0 | X30: =ROUND(H30*U30,2) -> 784.19
A31: 4.2 | B31: 96542 | C31: FABRICAÇÃO, MONTAGEM E DESMONTAGEM DE FÔRMA PARA VIGA BALDRAME, EM CHAPA DE MADEIRA COMPENSADA RESINADA, E=17 MM, 4 UTILIZAÇÕES. AF_06/2017 | D31: SINAPI | E31: M2 | F31: 220.31 | G31: 74.24 | H31: 90.92 | I31: 16355.81 | J31: 20030.59 | K31: =F31 -> 220.31 | L31: =0 -> 0 | Q31: =K31+L31+M31+N31+O31+P31 -> 220.31 | R31: =Q31/F31 -> 1 | U31: =F31+S31-T31 -> 220.31 | V31: =ROUND(H31*S31,2) -> 0 | W31: =ROUND(H31*T31,2) -> 0 | X31: =ROUND(H31*U31,2) -> 20030.59
A32: 4.3 | B32: 94971 | C32: CONCRETO FCK = 25MPA, TRAÇO 1:2,3:2,7 (EM MASSA SECA DE CIMENTO/ AREIA MÉDIA/ BRITA 1) - PREPARO MECÂNICO COM BETONEIRA 600 L. AF_05/2021 | D32: SINAPI | E32: M3 | F32: 13.22 | G32: 451.82 | H32: 553.34 | I32: 5973.06 | J32: 7315.15 | K32: =F32 -> 13.22 | L32: =0 -> 0 | Q32: =K32+L32+M32+N32+O32+P32 -> 13.22 | R32: =Q32/F32 -> 1 | U32: =F32+S32-T32 -> 13.22 | V32: =ROUND(H32*S32,2) -> 0 | W32: =ROUND(H32*T32,2) -> 0 | X32: =ROUND(H32*U32,2) -> 7315.15
A33: 4.4 | B33: 103670 | C33: LANÇAMENTO COM USO DE BALDES, ADENSAMENTO E ACABAMENTO DE CONCRETO EM ESTRUTURAS. AF_02/2022 | D33: SINAPI | E33: M3 | F33: 13.22 | G33: 205.96 | H33: 252.24 | I33: 2722.79 | J33: 3334.61 | K33: =F33 -> 13.22 | L33: =0 -> 0 | Q33: =K33+L33+M33+N33+O33+P33 -> 13.22 | R33: =Q33/F33 -> 1 | U33: =F33+S33-T33 -> 13.22 | V33: =ROUND(H33*S33,2) -> 0 | W33: =ROUND(H33*T33,2) -> 0 | X33: =ROUND(H33*U33,2) -> 3334.61
A34: 4.5 | B34: 96544 | C34: ARMAÇÃO DE BLOCO, VIGA BALDRAME OU SAPATA UTILIZANDO AÇO CA-50 DE 6,3 MM - MONTAGEM. AF_06/2017 | D34: SINAPI | E34: KG | F34: 389.6 | G34: 15.37 | H34: 18.82 | I34: 5988.15 | J34: 7332.27 | K34: =F34 -> 389.6 | L34: =0 -> 0 | Q34: =K34+L34+M34+N34+O34+P34 -> 389.6 | R34: =Q34/F34 -> 1 | U34: =F34+S34-T34 -> 389.6 | V34: =ROUND(H34*S34,2) -> 0 | W34: =ROUND(H34*T34,2) -> 0 | X34: =ROUND(H34*U34,2) -> 7332.27
A35: 4.6 | B35: 96543 | C35: ARMAÇÃO DE BLOCO, VIGA BALDRAME E SAPATA UTILIZANDO AÇO CA-60 DE 5 MM - MONTAGEM. AF_06/2017 | D35: SINAPI | E35: KG | F35: 212 | G35: 16.12 | H35: 19.74 | I35: 3417.44 | J35: 4184.88 | K35: =F35 -> 212 | L35: =0 -> 0 | Q35: =K35+L35+M35+N35+O35+P35 -> 212 | R35: =Q35/F35 -> 1 | U35: =F35+S35-T35 -> 212 | V35: =ROUND(H35*S35,2) -> 0 | W35: =ROUND(H35*T35,2) -> 0 | X35: =ROUND(H35*U35,2) -> 4184.88
A36: 5 | B36: PILARES | I36: 25583.47 | J36: 31334.09 | V36: =SUM(V37:V43) -> 0 | W36: =SUM(W37:W43) -> 0 | X36: =SUM(X37:X43) -> 31334.09
A37: 5.1 | B37: 92445 | C37: MONTAGEM E DESMONTAGEM DE FÔRMA DE PILARES RETANGULARES E ESTRUTURAS SIMILARES, PÉ-DIREITO DUPLO, EM CHAPA DE MADEIRA COMPENSADA PLASTIFICADA, 18 UTILIZAÇÕES. AF_09/2020 | D37: SINAPI | E37: M2 | F37: 199.64 | G37: 41.17 | H37: 50.42 | I37: 8219.18 | J37: 10065.85 | K37: 199.64 | L37: 0 | Q37: =K37+L37+M37+N37+O37+P37 -> 199.64 | R37: =Q37/F37 -> 1 | U37: =F37+S37-T37 -> 199.64 | V37: =ROUND(H37*S37,2) -> 0 | W37: =ROUND(H37*T37,2) -> 0 | X37: =ROUND(H37*U37,2) -> 10065.85
A38: 5.2 | B38: 94971 | C38: CONCRETO FCK = 25MPA, TRAÇO 1:2,3:2,7 (EM MASSA SECA DE CIMENTO/ AREIA MÉDIA/ BRITA 1) - PREPARO MECÂNICO COM BETONEIRA 600 L. AF_05/2021 | D38: SINAPI | E38: M3 | F38: 10.08 | G38: 451.82 | H38: 553.34 | I38: 4554.35 | J38: 5577.67 | K38: 10.08 | L38: 0 | Q38: =K38+L38+M38+N38+O38+P38 -> 10.08 | R38: =Q38/F38 -> 1 | U38: =F38+S38-T38 -> 10.08 | V38: =ROUND(H38*S38,2) -> 0 | W38: =ROUND(H38*T38,2) -> 0 | X38: =ROUND(H38*U38,2) -> 5577.67
A39: 5.3 | B39: 103670 | C39: LANÇAMENTO COM USO DE BALDES, ADENSAMENTO E ACABAMENTO DE CONCRETO EM ESTRUTURAS. AF_02/2022 | D39: SINAPI | E39: M3 | F39: 10.08 | G39: 205.96 | H39: 252.24 | I39: 2076.08 | J39: 2542.58 | K39: 10.08 | L39: 0 | Q39: =K39+L39+M39+N39+O39+P39 -> 10.08 | R39: =Q39/F39 -> 1 | U39: =F39+S39-T39 -> 10.08 | V39: =ROUND(H39*S39,2) -> 0 | W39: =ROUND(H39*T39,2) -> 0 | X39: =ROUND(H39*U39,2) -> 2542.58
A40: 5.4 | B40: 92762 | C40: ARMAÇÃO DE PILAR OU VIGA DE ESTRUTURA CONVENCIONAL DE CONCRETO ARMADO UTILIZANDO AÇO CA-50 DE 10,0 MM - MONTAGEM. AF_06/2022 | D40: SINAPI | E40: KG | F40: 580.5 | G40: 11.83 | H40: 14.49 | I40: 6867.32 | J40: 8411.45 | K40: 580.5 | L40: 0 | Q40: =K40+L40+M40+N40+O40+P40 -> 580.5 | R40: =Q40/F40 -> 1 | U40: =F40+S40-T40 -> 580.5 | V40: =ROUND(H40*S40,2) -> 0 | W40: =ROUND(H40*T40,2) -> 0 | X40: =ROUND(H40*U40,2) -> 8411.45
A41: 5.5 | B41: 92763 | C41: ARMAÇÃO DE PILAR OU VIGA DE ESTRUTURA CONVENCIONAL DE CONCRETO ARMADO UTILIZANDO AÇO CA-50 DE 12,5 MM - MONTAGEM. AF_06/2022 | D41: SINAPI | E41: KG | F41: 59.1 | G41: 10.09 | H41: 12.36 | I41: 596.32 | J41: 730.48 | K41: 59.1 | L41: 0 | Q41: =K41+L41+M41+N41+O41+P41 -> 59.1 | R41: =Q41/F41 -> 1 | U41: =F41+S41-T41 -> 59.1 | V41: =ROUND(H41*S41,2) -> 0 | W41: =ROUND(H41*T41,2) -> 0 | X41: =ROUND(H41*U41,2) -> 730.48
...

Sheet MEMORIAL
A2: OBRA: | B2: CONSTRUÇÃO DE UMA CRECHE COM CAPACIDADE PARA 50 (CEM) CRIANÇAS
A3: OBJETO: | B3: PRESTAR SERVIÇOS DE ENGENHARIA PARA CONSTRUÇÃO DE 01 (UMA) CRECHE COM CAPACIDADE PARA 50 (CINQUENTA) CRIANÇAS, COM BASE NO PROGRAMA PARAÍBA PRIMEIRA INFÂNCIA NO MUNICIPIO DE COREMAS-PB.
A4: LOCAL: | B4: COREMAS - PB | AJ4: 0.2247
A5: MEMORIAL DE CALCULO
A6: ITEM | B6: CÓDIGO | C6: DESCRIÇÃO | D6: CÁLCULOS | AJ6: UNID
A7: 1 | B7: SERVIÇOS PRELIMINARES
A8: 1.1 | B8: PRO-46870444 | C8: PLACA INDICATIVA DA OBRA EM CHAPA DE AÇO GALVANIZADO (4,0M X 2,0M) | AJ8: M²
C9: PLACA | D9: 4 | E9: X | F9: 2 | AI9: = | AJ9: =D9*F9 -> 8
D10: TOTAL | AI10: = | AJ10: =AJ9 -> 8
A11: 1.2 | B11: 93584 | C11: EXECUÇÃO DE DEPÓSITO EM CANTEIRO DE OBRA EM CHAPA DE MADEIRA COMPENSADA, NÃO INCLUSO MOBILIÁRIO. AF_04/2016 | AJ11: M2
A12: 1.3 | B12: 99059 | C12: LOCACAO CONVENCIONAL DE OBRA, UTILIZANDO GABARITO DE TÁBUAS CORRIDAS PONTALETADAS A CADA 2,00M - 2 UTILIZAÇÕES. AF_10/2018 | AJ12: M
A13: 2.5 | B13: 94342 | C13: ATERRO MANUAL DE VALAS COM AREIA PARA ATERRO E COMPACTAÇÃO MECANIZADA. AF_05/2016 | AJ13: M2
A14: 2 | B14: MOVIMENTO DE TERRA
A15: 2.1 | B15: 93382 | C15: REATERRO MANUAL DE VALAS COM COMPACTAÇÃO MECANIZADA. AF_04/2016 | AJ15: M3
A16: 2.2 | B16: 93358 | C16: ESCAVAÇÃO MANUAL DE VALA COM PROFUNDIDADE MENOR OU IGUAL A 1,30 M. AF_02/2021 | AJ16: M3
C17: S1=S2=S3=S4=S5=S7=S8=S9=S12=S13=S15=S16=S17=S21=S22=S23=S24=S25=S28=S31=S32=S33=S34=S35=S36=S37=S38=S39=S40=S42=S43=S44=S45=S47=S48S=S49=S50=S52=S53=S54=S55=S56=S57=S58=S59=S60 | D17: 0.6 | E17: X | F17: 0.75 | G17: X | H17: 1 | AG17: x | AH17: 47 | AI17: = | AJ17: =(D17*F17*H17)*AH17 -> 21.15
C18: S11=S51 | D18: 0.65 | E18: X | F18: 0.65 | G18: X | H18: 1 | AG18: x | AH18: 2 | AI18: = | AJ18: =(D18*F18*H18)*AH18 -> 0.845
C19: S19 | D19: 0.55 | E19: X | F19: 1 | G19: X | H19: 1 | AG19: x | AH19: 1 | AI19: = | AJ19: =(D19*F19*H19)*AH19 -> 0.55
C20: S14=S18=S20=S27=S30 | D20: 0.7 | E20: X | F20: 0.85 | G20: X | H20: 1 | AG20: x | AH20: 5 | AI20: = | AJ20: =(D20*F20*H20)*AH20 -> 2.975
C21: S10 | D21: 0.75 | E21: X | F21: 0.75 | G21: X | H21: 1 | AG21: x | AH21: 1 | AI21: = | AJ21: =(D21*F21*H21)*AH21 -> 0.5625
C22: S46 | D22: 0.85 | E22: X | F22: 1 | G22: X | H22: 1 | AG22: x | AH22: 1 | AI22: = | AJ22: =(D22*F22*H22)*AH22 -> 0.85
C23: S26=S29=S41 | D23: 0.8 | E23: X | F23: 0.95 | G23: x | H23: 1 | AG23: x | AH23: 3 | AI23: = | AJ23: =(D23*F23*H23)*AH23 -> 2.28
B24: TOTAL | AI24: = | AJ24: =SUM(AJ17:AJ23) -> 29.2125
D25: ESCAVAÇÃO DAS VALAS HORIZONATAIS E VERTICAIS
C26: V1 | D26: 5.082 | E26: + | F26: 2.246 | G26: + | H26: 2.299 | I26: + | J26: 4.641 | K26: + | L26: 2.197 | AE26: x | AF26: 0.15 | AG26: x | AH26: 0.3 | AI26: = | AJ26: =(D26+F26+H26+J26+L26+N26)*AF26*AH26 -> 0.740925
C27: V2 | D27: 2.934 | E27: + | G27: + | AE27: x | AF27: 0.15 | AG27: x | AH27: 0.3 | AI27: = | AJ27: =(D27+F27+H27+J27+L27+N27)*AF27*AH27 -> 0.13203
C28: V3 | D28: 3.657 | E28: + | G28: + | AE28: x | AF28: 0.15 | AG28: x | AH28: 0.3 | AI28: = | AJ28: =(D28+F28+H28+J28+L28+N28)*AF28*AH28 -> 0.164565
C29: V4 | D29: 4.528 | E29: + | F29: 3.912 | G29: + | H29: 1.537 | AE29: x | AF29: 0.15 | AG29: x | AH29: 0.3 | AI29: = | AJ29: =(D29+F29+H29+J29+L29+N29)*AF29*AH29 -> 0.448965
C30: V5 | D30: 4.641 | E30: + | F30: 2.197 | G30: + | AE30: x | AF30: 0.15 | AG30: x | AH30: 0.3 | AI30: = | AJ30: =(D30+F30+H30+J30+L30+N30)*AF30*AH30 -> 0.30771
C31: V6 | D31: 2.934 | E31: + | G31: + | AE31: x | AF31: 0.15 | AG31: x | AH31: 0.3 | AI31: = | AJ31: =(D31+F31+H31+J31+L31+N31)*AF31*AH31 -> 0.13203
C32: V7 | D32: 3.807 | E32: + | G32: + | AE32: x | AF32: 0.15 | AG32: x | AH32: 0.3 | AI32: = | AJ32: =(D32+F32+H32+J32+L32+N32)*AF32*AH32 -> 0.171315
C33: V8 | D33: 4.553 | E33: + | F33: 3.962 | G33: + | H33: 1.712 | AE33: x | AF33: 0.15 | AG33: x | AH33: 0.3 | AI33: = | AJ33: =(D33+F33+H33+J33+L33+N33)*AF33*AH33 -> 0.460215
C34: V9 | D34: 5.157 | E34: + | AE34: x | AF34: 0.15 | AG34: x | AH34: 0.3 | AI34: = | AJ34: =(D34+F34+H34+J34+L34+N34)*AF34*AH34 -> 0.232065
C35: V10 | D35: 0 | E35: + | AE35: x | AF35: 0.15 | AG35: x | AH35: 0.3 | AI35: = | AJ35: =(D35+F35+H35+J35+L35+N35)*AF35*AH35 -> 0
C36: V11 | D36: 2.324 | E36: + | AE36: x | AF36: 0.15 | AG36: x | AH36: 0.3 | AI36: = | AJ36: =(D36+F36+H36+J36+L36+N36)*AF36*AH36 -> 0.10458
C37: V12 | D37: 2.295 | E37: + | AE37: x | AF37: 0.15 | AG37: x | AH37: 0.3 | AI37: = | AJ37: =(D37+F37+H37+J37+L37+N37)*AF37*AH37 -> 0.103275
C38: V13 | D38: 0.922 | E38: + | F38: 2.74 | AE38: x | AF38: 0.15 | AG38: x | AH38: 0.3 | AI38: = | AJ38: =(D38+F38+H38+J38+L38+N38)*AF38*AH38 -> 0.16479
C39: V14 | D39: 4.55 | E39: + | AE39: x | AF39: 0.15 | AG39: x | AH39: 0.3 | AI39: = | AJ39: =(D39+F39+H39+J39+L39+N39)*AF39*AH39 -> 0.20475
C40: V15 | D40: 3.962 | E40: + | AE40: x | AF40: 0.15 | AG40: x | AH40: 0.3 | AI40: = | AJ40: =(D40+F40+H40+J40+L40+N40)*AF40*AH40 -> 0.17829
C41: V16 | D41: 3.371 | E41: + | F41: 3.962 | AE41: x | AF41: 0.15 | AG41: x | AH41: 0.3 | AI41: = | AJ41: =(D41+F41+H41+J41+L41+N41)*AF41*AH41 -> 0.329985
...
